#VRML_SIM R2023b utf8

EXTERNPROTO "webots://projects/objects/backgrounds/protos/TexturedBackground.proto"
EXTERNPROTO "webots://projects/objects/backgrounds/protos/TexturedBackgroundLight.proto"
EXTERNPROTO "webots://projects/objects/floors/protos/CircleArena.proto"
EXTERNPROTO "webots://projects/objects/factory/containers/protos/WoodenBox.proto"

WorldInfo {
  info [
    "The user drives a Supervisor by the Keyboard which drives slaves robots by using an emitter device."
  ]
  title "Omniscience"
}
Viewpoint {
  orientation -0.23090429863285805 -0.01018523501343265 0.972923155167246 3.245268365009745
  position 2.7493370609021848 0.14270693160753067 1.601343978411531
}
TexturedBackground {
}
TexturedBackgroundLight {
}
CircleArena {
}
WoodenBox {
  translation -0.372612 0.06339 0.05
  rotation 0 0 1 0.5
  size 0.1 0.1 0.1
}
WoodenBox {
  translation 0.421524 -0.431299 0.05
  rotation 0 0 1 4.96782
  name "wooden box(1)"
  size 0.1 0.1 0.1
}
WoodenBox {
  translation -0.35471 -0.5 0.05
  rotation 0 0 1 5.36782
  name "wooden box(2)"
  size 0.1 0.1 0.1
}
WoodenBox {
  translation 0.36 0.3 0.05
  rotation 0 0 1 5.36782
  name "wooden box(3)"
  size 0.1 0.1 0.1
}
WoodenBox {
  translation -0.166689 0.612227 0.05
  rotation 0 0 1 5.36782
  name "wooden box(4)"
  size 0.1 0.1 0.1
}
DEF ROBOT1 Robot {
  translation -0.140251 0.362306 0
  rotation 0 0 -1 0.221754
  children [
    DEF MAIN_BODY Pose {
      translation 0 0 0.0415
      children [
        Shape {
          appearance PBRAppearance {
            baseColor 0.0820075 0.364731 0.8
            roughness 1
            metalness 0
          }
          geometry DEF BODY Cylinder {
            height 0.08
            radius 0.045
          }
        }
      ]
    }
    HingeJoint {
      jointParameters HingeJointParameters {
        axis 0 1 0
        anchor 0 0 0.025
      }
      device [
        RotationalMotor {
          name "left wheel motor"
        }
        PositionSensor {
          name "left wheel sensor"
        }
      ]
      endPoint DEF LEFT_WHEEL Solid {
        translation 0 0.045 0.025
        rotation 0 -1 0 4.98467
        children [
          DEF WHEEL Pose {
            rotation -1 0 0 1.57
            children [
              Shape {
                appearance PBRAppearance {
                  baseColor 1 0 0
                  roughness 1
                  metalness 0
                }
                geometry Cylinder {
                  height 0.01
                  radius 0.025
                }
              }
            ]
          }
        ]
        name "left wheel"
        boundingObject DEF WHEEL Pose {
          rotation -1 0 0 1.57
          children [
            Shape {
              appearance PBRAppearance {
                baseColor 1 0 0
                roughness 1
                metalness 0
              }
              geometry Cylinder {
                height 0.01
                radius 0.025
              }
            }
          ]
        }
        physics DEF PHYSICS_WHEEL Physics {
          density -1
          mass 0.05
        }
      }
    }
    HingeJoint {
      jointParameters HingeJointParameters {
        axis 0 1 0
        anchor 0 0 0.025
      }
      device [
        RotationalMotor {
          name "right wheel motor"
        }
        PositionSensor {
          name "right wheel sensor"
        }
      ]
      endPoint DEF RIGHT_WHEEL Solid {
        translation 0 -0.045 0.025
        rotation 0 -1 0 4.58735
        children [
          DEF WHEEL Pose {
            rotation -1 0 0 1.57
            children [
              Shape {
                appearance PBRAppearance {
                  baseColor 1 0 0
                  roughness 1
                  metalness 0
                }
                geometry Cylinder {
                  height 0.01
                  radius 0.025
                }
              }
            ]
          }
        ]
        name "right wheel"
        boundingObject USE WHEEL
        physics DEF PHYSICS_WHEEL Physics {
          density -1
          mass 0.05
        }
      }
    }
    DEF LEFT_EYE DistanceSensor {
      translation 0.042 0.02 0.063
      rotation 0 0 -1 -0.499205
      children [
        DEF INFRARED Pose {
          rotation 0.577656895078166 0.5771968951617173 -0.5771968951617173 -2.093935
          children [
            Shape {
              appearance PBRAppearance {
                baseColor 0.975691 0.981481 0.0252992
                roughness 1
                metalness 0
              }
              geometry Cylinder {
                height 0.004
                radius 0.008
              }
            }
          ]
        }
      ]
      name "ds0"
      lookupTable [
        0 1024 0
        0.05 1024 0
        0.15 0 0
      ]
      numberOfRays 2
      aperture 1
    }
    DEF RIGHT_EYE DistanceSensor {
      translation 0.042 -0.02 0.063
      rotation 0 0 1 -0.500795
      children [
        DEF INFRARED Pose {
          rotation 0.577656895078166 0.5771968951617173 -0.5771968951617173 -2.093935
          children [
            Shape {
              appearance PBRAppearance {
                baseColor 0.975691 0.981481 0.0252992
                roughness 1
                metalness 0
              }
              geometry Cylinder {
                height 0.004
                radius 0.008
              }
            }
          ]
        }
      ]
      name "ds1"
      lookupTable [
        0 1024 0
        0.05 1024 0
        0.15 0 0
      ]
      numberOfRays 2
      aperture 1
    }
    Receiver {
    }
    Camera {
      translation 0.045 0 0.045
      children [
        Pose {
          rotation 0 -1 0 1.57
          children [
            Shape {
              appearance PBRAppearance {
                baseColor 0.8 0.8 0.8
                roughness 1
                metalness 0
              }
              geometry Cylinder {
                height 0.01
                radius 0.007
              }
            }
          ]
        }
      ]
    }
  ]
  name "robot1"
  boundingObject DEF MYBOT_BOUNDING Pose {
    translation 0 0 0.0415
    children [
      DEF BODY Cylinder {
        height 0.08
        radius 0.045
      }
    ]
  }
  physics DEF MYBOT_PHYSICS Physics {
    density -1
    mass 0.5
  }
  controller "slave"
}
DEF ROBOT2 Robot {
  translation -0.511288 -0.288898 0
  rotation 0 0 -1 2.67372
  children [
    DEF MAIN_BODY Pose {
      translation 0 0 0.0415
      children [
        Shape {
          appearance PBRAppearance {
            baseColor 0.0820075 0.364731 0.8
            roughness 1
            metalness 0
          }
          geometry DEF BODY Cylinder {
            height 0.08
            radius 0.045
          }
        }
      ]
    }
    HingeJoint {
      jointParameters HingeJointParameters {
        axis 0 1 0
        anchor 0 0 0.025
      }
      device [
        RotationalMotor {
          name "left wheel motor"
        }
        PositionSensor {
          name "left wheel sensor"
        }
      ]
      endPoint DEF LEFT_WHEEL Solid {
        translation 0 0.045 0.025
        rotation 0 -1 0 4.98467
        children [
          DEF WHEEL Pose {
            rotation -1 0 0 1.57
            children [
              Shape {
                appearance PBRAppearance {
                  baseColor 1 0 0
                  roughness 1
                  metalness 0
                }
                geometry Cylinder {
                  height 0.01
                  radius 0.025
                }
              }
            ]
          }
        ]
        name "left wheel"
        boundingObject DEF WHEEL Pose {
          rotation -1 0 0 1.57
          children [
            Shape {
              appearance PBRAppearance {
                baseColor 1 0 0
                roughness 1
                metalness 0
              }
              geometry Cylinder {
                height 0.01
                radius 0.025
              }
            }
          ]
        }
        physics DEF PHYSICS_WHEEL Physics {
          density -1
          mass 0.05
        }
      }
    }
    HingeJoint {
      jointParameters HingeJointParameters {
        axis 0 1 0
        anchor 0 0 0.025
      }
      device [
        RotationalMotor {
          name "right wheel motor"
        }
        PositionSensor {
          name "right wheel sensor"
        }
      ]
      endPoint DEF RIGHT_WHEEL Solid {
        translation 0 -0.045 0.025
        rotation 0 -1 0 4.58735
        children [
          DEF WHEEL Pose {
            rotation -1 0 0 1.57
            children [
              Shape {
                appearance PBRAppearance {
                  baseColor 1 0 0
                  roughness 1
                  metalness 0
                }
                geometry Cylinder {
                  height 0.01
                  radius 0.025
                }
              }
            ]
          }
        ]
        name "right wheel"
        boundingObject USE WHEEL
        physics DEF PHYSICS_WHEEL Physics {
          density -1
          mass 0.05
        }
      }
    }
    DEF LEFT_EYE DistanceSensor {
      translation 0.042 0.02 0.063
      rotation 0 0 -1 -0.499205
      children [
        DEF INFRARED Pose {
          rotation 0.577656895078166 0.5771968951617173 -0.5771968951617173 -2.093935
          children [
            Shape {
              appearance PBRAppearance {
                baseColor 0.975691 0.981481 0.0252992
                roughness 1
                metalness 0
              }
              geometry Cylinder {
                height 0.004
                radius 0.008
              }
            }
          ]
        }
      ]
      name "ds0"
      lookupTable [
        0 1024 0
        0.05 1024 0
        0.15 0 0
      ]
      numberOfRays 2
      aperture 1
    }
    DEF RIGHT_EYE DistanceSensor {
      translation 0.042 -0.02 0.063
      rotation 0 0 1 -0.500795
      children [
        DEF INFRARED Pose {
          rotation 0.577656895078166 0.5771968951617173 -0.5771968951617173 -2.093935
          children [
            Shape {
              appearance PBRAppearance {
                baseColor 0.975691 0.981481 0.0252992
                roughness 1
                metalness 0
              }
              geometry Cylinder {
                height 0.004
                radius 0.008
              }
            }
          ]
        }
      ]
      name "ds1"
      lookupTable [
        0 1024 0
        0.05 1024 0
        0.15 0 0
      ]
      numberOfRays 2
      aperture 1
    }
    Receiver {
    }
    Camera {
      translation 0.045 0 0.045
      children [
        Pose {
          rotation 0 -1 0 1.57
          children [
            Shape {
              appearance PBRAppearance {
                baseColor 0.8 0.8 0.8
                roughness 1
                metalness 0
              }
              geometry Cylinder {
                height 0.01
                radius 0.007
              }
            }
          ]
        }
      ]
    }
  ]
  name "robot2"
  boundingObject DEF MYBOT_BOUNDING Pose {
    translation 0 0 0.0415
    children [
      DEF BODY Cylinder {
        height 0.08
        radius 0.045
      }
    ]
  }
  physics DEF MYBOT_PHYSICS Physics {
    density -1
    mass 0.5
  }
  controller "slave"
}
DEF ROBOT3 Robot {
  translation 0 -0.15 0
  rotation 0 0 1 2.54759
  children [
    DEF MAIN_BODY Pose {
      translation 0 0 0.0415
      children [
        Shape {
          appearance PBRAppearance {
            baseColor 0.0820075 0.364731 0.8
            roughness 1
            metalness 0
          }
          geometry DEF BODY Cylinder {
            height 0.08
            radius 0.045
          }
        }
      ]
    }
    HingeJoint {
      jointParameters HingeJointParameters {
        axis 0 1 0
        anchor 0 0 0.025
      }
      device [
        RotationalMotor {
          name "left wheel motor"
        }
        PositionSensor {
          name "left wheel sensor"
        }
      ]
      endPoint DEF LEFT_WHEEL Solid {
        translation 0 0.045 0.025
        rotation 0 -1 0 4.98467
        children [
          DEF WHEEL Pose {
            rotation -1 0 0 1.57
            children [
              Shape {
                appearance PBRAppearance {
                  baseColor 1 0 0
                  roughness 1
                  metalness 0
                }
                geometry Cylinder {
                  height 0.01
                  radius 0.025
                }
              }
            ]
          }
        ]
        name "left wheel"
        boundingObject DEF WHEEL Pose {
          rotation -1 0 0 1.57
          children [
            Shape {
              appearance PBRAppearance {
                baseColor 1 0 0
                roughness 1
                metalness 0
              }
              geometry Cylinder {
                height 0.01
                radius 0.025
              }
            }
          ]
        }
        physics DEF PHYSICS_WHEEL Physics {
          density -1
          mass 0.05
        }
      }
    }
    HingeJoint {
      jointParameters HingeJointParameters {
        axis 0 1 0
        anchor 0 0 0.025
      }
      device [
        RotationalMotor {
          name "right wheel motor"
        }
        PositionSensor {
          name "right wheel sensor"
        }
      ]
      endPoint DEF RIGHT_WHEEL Solid {
        translation 0 -0.045 0.025
        rotation 0 -1 0 4.58735
        children [
          DEF WHEEL Pose {
            rotation -1 0 0 1.57
            children [
              Shape {
                appearance PBRAppearance {
                  baseColor 1 0 0
                  roughness 1
                  metalness 0
                }
                geometry Cylinder {
                  height 0.01
                  radius 0.025
                }
              }
            ]
          }
        ]
        name "right wheel"
        boundingObject USE WHEEL
        physics DEF PHYSICS_WHEEL Physics {
          density -1
          mass 0.05
        }
      }
    }
    DEF LEFT_EYE DistanceSensor {
      translation 0.042 0.02 0.063
      rotation 0 0 -1 -0.499205
      children [
        DEF INFRARED Pose {
          rotation 0.577656895078166 0.5771968951617173 -0.5771968951617173 -2.093935
          children [
            Shape {
              appearance PBRAppearance {
                baseColor 0.975691 0.981481 0.0252992
                roughness 1
                metalness 0
              }
              geometry Cylinder {
                height 0.004
                radius 0.008
              }
            }
          ]
        }
      ]
      name "ds0"
      lookupTable [
        0 1024 0
        0.05 1024 0
        0.15 0 0
      ]
      numberOfRays 2
      aperture 1
    }
    DEF RIGHT_EYE DistanceSensor {
      translation 0.042 -0.02 0.063
      rotation 0 0 1 -0.500795
      children [
        DEF INFRARED Pose {
          rotation 0.577656895078166 0.5771968951617173 -0.5771968951617173 -2.093935
          children [
            Shape {
              appearance PBRAppearance {
                baseColor 0.975691 0.981481 0.0252992
                roughness 1
                metalness 0
              }
              geometry Cylinder {
                height 0.004
                radius 0.008
              }
            }
          ]
        }
      ]
      name "ds1"
      lookupTable [
        0 1024 0
        0.05 1024 0
        0.15 0 0
      ]
      numberOfRays 2
      aperture 1
    }
    Receiver {
    }
    Camera {
      translation 0.045 0 0.045
      children [
        Pose {
          rotation 0 -1 0 1.57
          children [
            Shape {
              appearance PBRAppearance {
                baseColor 0.8 0.8 0.8
                roughness 1
                metalness 0
              }
              geometry Cylinder {
                height 0.01
                radius 0.007
              }
            }
          ]
        }
      ]
    }
  ]
  name "robot3"
  boundingObject DEF MYBOT_BOUNDING Pose {
    translation 0 0 0.0415
    children [
      DEF BODY Cylinder {
        height 0.08
        radius 0.045
      }
    ]
  }
  physics DEF MYBOT_PHYSICS Physics {
    density -1
    mass 0.5
  }
  controller "slave"
}
Robot {
  children [
    Emitter {
    }
  ]
  name "Driver"
  controller "driver"
  supervisor TRUE
}
