#VRML_SIM R2023b utf8

PROTO ProtoHinge2 [
]
{
Robot {
  children [
    Robot {
      children [
        Hinge2Joint {
          jointParameters HingeJointParameters {
            position 2
            axis 1 1 0
            anchor 0 -1 0
            minStop -1
            maxStop 2
          }
          jointParameters2 JointParameters {
            position -1
            axis 0 0 -1
            minStop -2
            maxStop 2
          }
          device [
            PositionSensor {
            }
            RotationalMotor {
            }
          ]
          device2 [
            PositionSensor {
            }
            RotationalMotor {
            }
            Brake {
            }
          ]
          endPoint Solid {
            children [
              Shape {
                geometry Box {
                  size 0.1 0.1 0.1
                }
              }
            ]
          }
        }
      ]
    }
  ]
}
}
