#VRML_SIM R2021b utf8
WorldInfo {
  info [
    "In this example, the robot turns on a slope."
    "Its accelerometer sensor is used to switch on the bottommost LED."
  ]
  title "Accelerometer"
  basicTimeStep 8
  coordinateSystem "NUE"
  contactProperties [
    ContactProperties {
      material2 "body"
      coulombFriction [
        0
      ]
      softCFM 0.1
    }
  ]
}
Viewpoint {
  orientation -0.018008295695757834 0.9964734544044664 0.0819533767050745 2.3266085189652164
  position 0.44914816419424874 0.2852180850802933 -0.43614547208450727
}
TexturedBackground {
}
TexturedBackgroundLight {
}
RectangleArena {
}
PointLight {
  attenuation 0 0 1
  intensity 0.6
  location 0 0.6 0
}
DEF SLOPE Solid {
  translation 0 0.15 0
  rotation 1 0 0 -0.4
  children [
    Shape {
      appearance OsbWood {
        textureTransform TextureTransform {
          scale 0.5 2
        }
      }
      geometry DEF BOX0 Box {
        size 0.2 0.02 0.8
      }
    }
  ]
  name "green box"
  boundingObject USE BOX0
}
Robot {
  translation 0 0.165 0
  rotation 1 0 0 -0.4
  children [
    Accelerometer {
    }
    DEF FRONT_LED LED {
      translation 0 0.0825 -0.038
      children [
        Shape {
          appearance PBRAppearance {
            baseColor 0 0 0
            metalness 0
            emissiveIntensity 20
          }
          geometry Capsule {
            bottom FALSE
            height 0.008
            radius 0.005
          }
        }
        Shape {
          appearance BrushedAluminium {
          }
          geometry Cylinder {
            height 0.002
            radius 0.006
          }
        }
      ]
      name "front led"
    }
    DEF RIGHT_LED LED {
      translation 0.038 0.0825 0
      children [
        Shape {
          appearance PBRAppearance {
            baseColor 0 0 0
            metalness 0
            emissiveIntensity 20
          }
          geometry Capsule {
            bottom FALSE
            height 0.008
            radius 0.005
          }
        }
        Shape {
          appearance BrushedAluminium {
          }
          geometry Cylinder {
            height 0.002
            radius 0.006
          }
        }
      ]
      name "right led"
    }
    DEF BACK_LED LED {
      translation 0 0.0825 0.038
      children [
        Shape {
          appearance PBRAppearance {
            baseColor 0 0 0
            metalness 0
            emissiveIntensity 20
          }
          geometry Capsule {
            bottom FALSE
            height 0.008
            radius 0.005
          }
        }
        Shape {
          appearance BrushedAluminium {
          }
          geometry Cylinder {
            height 0.002
            radius 0.006
          }
        }
      ]
      name "back led"
    }
    DEF LEFT_LED LED {
      translation -0.038 0.0825 0
      children [
        Shape {
          appearance PBRAppearance {
            baseColor 0 0 0
            metalness 0
            emissiveIntensity 20
          }
          geometry Capsule {
            bottom FALSE
            height 0.008
            radius 0.005
          }
        }
        Shape {
          appearance BrushedAluminium {
          }
          geometry Cylinder {
            height 0.002
            radius 0.006
          }
        }
      ]
      name "left led"
    }
    Transform {
      translation 0 0.0415 0
      children [
        Shape {
          appearance PBRAppearance {
            baseColor 0.0820075 0.364731 0.8
            roughness 1
            metalness 0
          }
          geometry DEF BODY Cylinder {
            height 0.08
            radius 0.045
          }
        }
      ]
    }
    HingeJoint {
      jointParameters HingeJointParameters {
        axis -1 0 0
        anchor 0 0.025 0
      }
      device [
        RotationalMotor {
          name "left wheel motor"
          consumptionFactor 70
        }
        PositionSensor {
          name "left wheel sensor"
        }
      ]
      endPoint Solid {
        translation -0.045 0.025 0
        rotation -1 0 0 0
        children [
          DEF WHEEL Transform {
            rotation 0 0 1 1.57
            children [
              Shape {
                appearance PBRAppearance {
                  baseColor 1 0 0
                  roughness 1
                  metalness 0
                }
                geometry Cylinder {
                  height 0.01
                  radius 0.025
                }
              }
            ]
          }
        ]
        name "left wheel"
        boundingObject USE WHEEL
        physics DEF PHYSICS_WHEEL Physics {
          density -1
          mass 0.05
        }
      }
    }
    HingeJoint {
      jointParameters HingeJointParameters {
        axis -1 0 0
        anchor 0 0.025 0
      }
      device [
        RotationalMotor {
          name "right wheel motor"
          consumptionFactor 70
        }
        PositionSensor {
          name "right wheel sensor"
        }
      ]
      endPoint Solid {
        translation 0.045 0.025 0
        rotation -1 0 0 0
        children [
          USE WHEEL
        ]
        boundingObject USE WHEEL
        physics USE PHYSICS_WHEEL
      }
    }
    DistanceSensor {
      translation -0.02 0.063 -0.042
      rotation 0 1 0 2.07
      children [
        DEF SENSOR Transform {
          rotation 0 0 1 1.57
          children [
            Shape {
              appearance PBRAppearance {
                baseColor 0.975691 0.981481 0.0252992
                roughness 1
                metalness 0
              }
              geometry Cylinder {
                height 0.004
                radius 0.008
              }
            }
          ]
        }
      ]
      name "ds0"
      lookupTable [
        0 1024 0
        0.05 1024 0
        0.15 0 0
      ]
      numberOfRays 2
      aperture 1
    }
    DistanceSensor {
      translation 0.02 0.063 -0.042
      rotation 0 1 0 1.07
      children [
        USE SENSOR
      ]
      name "ds1"
      lookupTable [
        0 1024 0
        0.05 1024 0
        0.15 0 0
      ]
      numberOfRays 2
      aperture 1
    }
    DEF SMILE Transform {
      translation 0 0.025 -0.036
      rotation 0.7745972408364944 0.44721228048294853 0.4472139204829502 1.8234794
      children [
        Shape {
          appearance PBRAppearance {
            baseColor 0.721569 0.290196 0.290196
            roughness 1
            metalness 0
          }
          geometry Cylinder {
            height 0.018
            radius 0.009
            subdivision 3
          }
        }
      ]
    }
  ]
  name "MyBot"
  contactMaterial "body"
  boundingObject Transform {
    translation 0 0.0415 0
    children [
      USE BODY
    ]
  }
  physics Physics {
    density -1
    mass 0.5
  }
  controller "accelerometer"
}
