#VRML_SIM R2023b utf8

EXTERNPROTO "webots://projects/objects/backgrounds/protos/TexturedBackground.proto"
EXTERNPROTO "webots://projects/objects/backgrounds/protos/TexturedBackgroundLight.proto"
EXTERNPROTO "webots://projects/objects/floors/protos/RectangleArena.proto"
EXTERNPROTO "webots://projects/appearances/protos/OsbWood.proto"
EXTERNPROTO "webots://projects/appearances/protos/BrushedAluminium.proto"

WorldInfo {
  info [
    "In this example, the robot moves down a slope."
    "The altimeter is used to record the robots height."
  ]
  title "Altimeter"
  basicTimeStep 8
  contactProperties [
    ContactProperties {
      material2 "body"
      coulombFriction [
        0
      ]
      softCFM 0.1
    }
  ]
}
Viewpoint {
  orientation -0.2697386894881805 -0.5738397758675999 0.7732715894337653 5.538267366831801
  position -1.3027938487843664 0.7322307263554658 0.9385386981410703
}
TexturedBackground {
}
TexturedBackgroundLight {
}
RectangleArena {
}
PointLight {
  attenuation 0 0 1
  intensity 0.6
  location 0.6 0 0
}
DEF SLOPE Solid {
  translation 0 0 0.15
  rotation 0 1 0 -0.4
  children [
    Shape {
      appearance OsbWood {
        textureTransform TextureTransform {
          scale 0.5 2
        }
      }
      geometry DEF BOX0 Box {
        size 0.8 0.2 0.02
      }
    }
  ]
  name "green box"
  boundingObject USE BOX0
}
Robot {
  translation 0.28553 0 0.285719
  rotation -0.19866893085825738 0 0.9800666589123603 3.14159
  children [
    Altimeter {
    }
    DEF FRONT_LED LED {
      translation 0.038 0 0.0825
      children [
        Shape {
          appearance PBRAppearance {
            baseColor 0 0 0
            metalness 0
            emissiveIntensity 20
          }
          geometry Capsule {
            bottom FALSE
            height 0.008
            radius 0.005
          }
        }
        Shape {
          appearance BrushedAluminium {
          }
          geometry Cylinder {
            height 0.002
            radius 0.006
          }
        }
      ]
      name "front led"
    }
    DEF RIGHT_LED LED {
      translation 0 0.038 0.0825
      children [
        Shape {
          appearance PBRAppearance {
            baseColor 0 0 0
            metalness 0
            emissiveIntensity 20
          }
          geometry Capsule {
            bottom FALSE
            height 0.008
            radius 0.005
          }
        }
        Shape {
          appearance BrushedAluminium {
          }
          geometry Cylinder {
            height 0.002
            radius 0.006
          }
        }
      ]
      name "right led"
    }
    DEF BACK_LED LED {
      translation -0.038 0 0.0825
      children [
        Shape {
          appearance PBRAppearance {
            baseColor 0 0 0
            metalness 0
            emissiveIntensity 20
          }
          geometry Capsule {
            bottom FALSE
            height 0.008
            radius 0.005
          }
        }
        Shape {
          appearance BrushedAluminium {
          }
          geometry Cylinder {
            height 0.002
            radius 0.006
          }
        }
      ]
      name "back led"
    }
    DEF LEFT_LED LED {
      translation 0 -0.038 0.0825
      children [
        Shape {
          appearance PBRAppearance {
            baseColor 0 0 0
            metalness 0
            emissiveIntensity 20
          }
          geometry Capsule {
            bottom FALSE
            height 0.008
            radius 0.005
          }
        }
        Shape {
          appearance BrushedAluminium {
          }
          geometry Cylinder {
            height 0.002
            radius 0.006
          }
        }
      ]
      name "left led"
    }
    Pose {
      translation 0 0 0.0415
      children [
        Shape {
          appearance PBRAppearance {
            baseColor 0.0820075 0.364731 0.8
            roughness 1
            metalness 0
          }
          geometry DEF BODY Cylinder {
            height 0.08
            radius 0.045
          }
        }
      ]
    }
    HingeJoint {
      jointParameters HingeJointParameters {
        axis 0 1 0
        anchor 0 0 0.025
      }
      device [
        RotationalMotor {
          name "left wheel motor"
          consumptionFactor 70
        }
        PositionSensor {
          name "left wheel sensor"
        }
      ]
      endPoint Solid {
        translation 0 0.045 0.025
        rotation 0.5773502691896258 -0.5773502691896258 -0.5773502691896258 2.094395
        children [
          DEF WHEEL Pose {
            rotation 0.577656895078166 0.5771968951617173 -0.5771968951617173 -2.093935
            children [
              Shape {
                appearance PBRAppearance {
                  baseColor 1 0 0
                  roughness 1
                  metalness 0
                }
                geometry Cylinder {
                  height 0.01
                  radius 0.025
                }
              }
            ]
          }
        ]
        name "left wheel"
        boundingObject USE WHEEL
        physics DEF PHYSICS_WHEEL Physics {
          density -1
          mass 0.05
        }
      }
    }
    HingeJoint {
      jointParameters HingeJointParameters {
        axis 0 1 0
        anchor 0 0 0.025
      }
      device [
        RotationalMotor {
          name "right wheel motor"
          consumptionFactor 70
        }
        PositionSensor {
          name "right wheel sensor"
        }
      ]
      endPoint Solid {
        translation 0 -0.045 0.025
        rotation 0.5773502691896258 -0.5773502691896258 -0.5773502691896258 2.094395
        children [
          USE WHEEL
        ]
        boundingObject USE WHEEL
        physics USE PHYSICS_WHEEL
      }
    }
    DistanceSensor {
      translation 0.042 0.02 0.063
      rotation 0 0 -1 -0.499205
      children [
        DEF SENSOR Pose {
          rotation 0.577656895078166 0.5771968951617173 -0.5771968951617173 -2.093935
          children [
            Shape {
              appearance PBRAppearance {
                baseColor 0.975691 0.981481 0.0252992
                roughness 1
                metalness 0
              }
              geometry Cylinder {
                height 0.004
                radius 0.008
              }
            }
          ]
        }
      ]
      name "ds0"
      lookupTable [
        0 1024 0
        0.05 1024 0
        0.15 0 0
      ]
      numberOfRays 2
      aperture 1
    }
    DistanceSensor {
      translation 0.042 -0.02 0.063
      rotation 0 0 1 -0.500795
      children [
        USE SENSOR
      ]
      name "ds1"
      lookupTable [
        0 1024 0
        0.05 1024 0
        0.15 0 0
      ]
      numberOfRays 2
      aperture 1
    }
    DEF SMILE Pose {
      translation 0.036 0 0.025
      rotation 0.25056300542381216 -0.9351130202419243 -0.25056300542381216 1.637834
      children [
        Shape {
          appearance PBRAppearance {
            baseColor 0.721569 0.290196 0.290196
            roughness 1
            metalness 0
          }
          geometry Cylinder {
            height 0.018
            radius 0.009
            subdivision 3
          }
        }
      ]
    }
  ]
  name "MyBot"
  contactMaterial "body"
  boundingObject Pose {
    translation 0 0 0.0415
    rotation 0 0 1 -1.570796
    children [
      USE BODY
    ]
  }
  physics Physics {
    density -1
    mass 0.5
  }
  controller "altimeter"
}
