#VRML_SIM R2023b utf8

EXTERNPROTO "webots://projects/objects/backgrounds/protos/TexturedBackground.proto"
EXTERNPROTO "webots://projects/objects/backgrounds/protos/TexturedBackgroundLight.proto"
EXTERNPROTO "webots://projects/objects/floors/protos/RectangleArena.proto"
EXTERNPROTO "webots://projects/objects/drinks/protos/Can.proto"
EXTERNPROTO "webots://projects/objects/fruits/protos/Apple.proto"
EXTERNPROTO "webots://projects/objects/fruits/protos/Orange.proto"
EXTERNPROTO "webots://projects/objects/kitchen/breakfast/protos/JamJar.proto"
EXTERNPROTO "webots://projects/objects/kitchen/breakfast/protos/CerealBox.proto"
EXTERNPROTO "webots://projects/objects/obstacles/protos/OilBarrel.proto"
EXTERNPROTO "webots://projects/objects/kitchen/breakfast/protos/BiscuitBox.proto"
EXTERNPROTO "webots://projects/objects/toys/protos/RubberDuck.proto"

WorldInfo {
  info [
    "Example use of a color Camera device with recognition capability."
  ]
  title "Camera Image Recognition"
}
Viewpoint {
  orientation 0.4230646872725633 -0.029951437962670063 -0.9056043185337272 3.0485443866044966
  position 1.457257424142112 0.1382764770695935 1.5513929722001025
}
TexturedBackground {
}
TexturedBackgroundLight {
}
RectangleArena {
  floorSize 1.5 1.5
}
Can {
  translation 0.267626 0.290201 0.06
}
Can {
  translation -0.326272 -0.341474 0.06
  name "can(1)"
}
Apple {
  translation -0.260886 0.22946 0.05
}
Apple {
  translation -0.621889 0.56252 0.05
  name "apple(1)"
}
DEF ORANGE Solid {
  translation -0.002188 -0.063045 0
  children [
    Orange {
      translation -0.187654 0.182317 0.05
    }
  ]
  name "orange"
  recognitionColors [
    0.988235 0.686275 0.243137
  ]
}
DEF ORANGE Solid {
  translation 0.085807 -0.503005 0
  children [
    Orange {
      translation -0.187654 0.182317 0.05
    }
  ]
  name "orange(1)"
  recognitionColors [
    0.988235 0.686275 0.243137
  ]
}
JamJar {
  translation -0.33681 0.078775 0
  mass 0
}
JamJar {
  translation 0.314033 -0.288298 0
  rotation 0 0 1 2.094395
  name "jam jar(1)"
  mass 0
}
CerealBox {
  translation -0.43865 0.194464 0
  rotation 0 0 -1 0.523599
}
CerealBox {
  translation -0.450259 0.4153 0
  rotation 0 0 -1 0.785399
  name "cereal box(1)"
}
OilBarrel {
  translation -0.28712 -0.211927 0.07
  rotation 0 0 1 -1.5707953071795862
  height 0.14
  radius 0.06
}
OilBarrel {
  translation -0.240466 -0.485864 0.07
  rotation 0 0 1 -1.5707953071795862
  name "oil barrel(1)"
  height 0.14
  radius 0.06
}
OilBarrel {
  translation -0.464787 -0.437183 0.07
  rotation 0 0 1 -1.5707953071795862
  name "oil barrel(2)"
  height 0.14
  radius 0.06
}
BiscuitBox {
  translation 0.538412 -0.274668 0.04
  rotation 0.6947480600338772 -0.18615701608601462 -0.6947450600336179 -2.7734953071795863
}
RubberDuck {
  translation -0.243817 0.384468 0.01
  rotation 0 0 1 -2.3561953071795863
}
Robot {
  translation 0.08518 0.000516 0
  rotation 0 0 1 2
  children [
    Pose {
      translation 0 0 0.0415
      children [
        Shape {
          appearance PBRAppearance {
            baseColor 0.0820075 0.364731 0.8
            roughness 1
            metalness 0
          }
          geometry DEF BODY Cylinder {
            height 0.08
            radius 0.045
          }
        }
      ]
    }
    HingeJoint {
      jointParameters HingeJointParameters {
        axis 0 1 0
        anchor 0 0 0.025
      }
      device [
        RotationalMotor {
          name "left wheel motor"
          consumptionFactor 70
        }
        PositionSensor {
          name "left wheel sensor"
        }
      ]
      endPoint Solid {
        translation 0 0.045 0.025
        rotation 0 -1 0 4.98467
        children [
          DEF WHEEL Pose {
            rotation -1 0 0 1.57
            children [
              Shape {
                appearance PBRAppearance {
                  baseColor 1 0 0
                  roughness 1
                  metalness 0
                }
                geometry Cylinder {
                  height 0.01
                  radius 0.025
                }
              }
            ]
          }
        ]
        name "left wheel"
        boundingObject USE WHEEL
        physics DEF PHYSICS_WHEEL Physics {
          density -1
          mass 0.05
        }
      }
    }
    HingeJoint {
      jointParameters HingeJointParameters {
        axis 0 1 0
        anchor 0 0 0.025
      }
      device [
        RotationalMotor {
          name "right wheel motor"
          consumptionFactor 70
        }
        PositionSensor {
          name "right wheel sensor"
        }
      ]
      endPoint Solid {
        translation 0 -0.045 0.025
        rotation 0 -1 0 4.58735
        children [
          USE WHEEL
        ]
        name "right wheel"
        boundingObject USE WHEEL
        physics USE PHYSICS_WHEEL
      }
    }
    DistanceSensor {
      translation 0.042 0.02 0.063
      rotation 0 0 -1 -0.499205
      children [
        DEF SENSOR Pose {
          rotation 0 1 0 1.57
          children [
            Shape {
              appearance PBRAppearance {
                baseColor 0.975691 0.981481 0.0252992
                roughness 1
                metalness 0
              }
              geometry Cylinder {
                height 0.004
                radius 0.008
              }
            }
          ]
        }
      ]
      name "ds0"
      lookupTable [
        0 1024 0
        0.05 1024 0
        0.15 0 0
      ]
      numberOfRays 2
      aperture 1
    }
    DistanceSensor {
      translation 0.042 -0.02 0.063
      rotation 0 0 1 -0.500795
      children [
        USE SENSOR
      ]
      name "ds1"
      lookupTable [
        0 1024 0
        0.05 1024 0
        0.15 0 0
      ]
      numberOfRays 2
      aperture 1
    }
    Shape {
      appearance PBRAppearance {
        baseColor 0.8 0.8 0.8
        baseColorMap ImageTexture {
          url [
            "webots://projects/samples/devices/worlds/textures/mybot.png"
          ]
        }
        roughness 0.5
        metalness 0
      }
      geometry IndexedFaceSet {
        coord Coordinate {
          point [
            0.0435 -0.015 0.038
            0.0435 -0.015 0.023
            0.0455 0 0.023
            0.0435 0.015 0.023
            0.0435 0.015 0.038
            0.0455 0 0.038
          ]
        }
        texCoord TextureCoordinate {
          point [
            0 0
            0.5 0
            1 0
            1 1
            0.5 1
            0 1
          ]
        }
        coordIndex [
          0, 1, 2, 5, -1, 5, 2, 3, 4, -1
        ]
        texCoordIndex [
          5, 0, 1, 4, -1, 4, 1, 2, 3, -1
        ]
        creaseAngle 0.9
      }
    }
    Camera {
      translation 0.04 0 0.0915
      children [
        Pose {
          translation -0.015 0 0
          rotation 0 -1 0 1.57
          children [
            Shape {
              appearance PBRAppearance {
                roughness 1
                metalness 0
              }
              geometry Cylinder {
                height 0.03
                radius 0.01
              }
            }
          ]
        }
      ]
      fieldOfView 1.0472
      width 256
      height 128
      antiAliasing TRUE
      recognition Recognition {
        frameColor 0.929412 0.831373 0
        frameThickness 3
        segmentation TRUE
      }
    }
    Display {
      name "segmented image display"
      width 256
      height 128
    }
  ]
  name "MyBot"
  boundingObject Pose {
    translation 0 0 0.0415
    children [
      USE BODY
    ]
  }
  physics Physics {
    density -1
    mass 0.5
  }
  controller "camera_segmentation"
}
