#VRML_SIM R2021c utf8
WorldInfo {
  info [
    "Example use of a color Camera device with auto-focusing capabilities."
  ]
  title "Camera With Auto-Focus"
}
Viewpoint {
  orientation -0.31201884600605123 0.2791770423143426 0.9081323795469843 1.712070408418439
  position 0.03761810127163649 -1.1048611925112735 0.998687117170863
}
TexturedBackground {
}
TexturedBackgroundLight {
}
RectangleArena {
  floorTileSize 0.25 0.25
  wallHeight 0.15
  wallAppearance PBRAppearance {
    baseColorMap ImageTexture {
      url [
        "webots://projects/default/worlds/textures/red_brick_wall.jpg"
      ]
    }
    roughness 1
    metalness 0
    textureTransform TextureTransform {
      scale 6 7
    }
  }
}
Robot {
  translation -0.00356013 0.00773978 -2.22045e-16
  rotation 0 0 -1 2.1415953071795863
  children [
    Transform {
      translation 0 0 0.0415
      rotation 0 0 1 -1.570796
      children [
        Shape {
          appearance PBRAppearance {
            baseColor 0.0820075 0.364731 0.8
            roughness 1
            metalness 0
          }
          geometry DEF BODY Cylinder {
            height 0.08
            radius 0.045
          }
        }
      ]
    }
    HingeJoint {
      jointParameters HingeJointParameters {
        axis 0 1 0
        anchor 0 0 0.025
      }
      device [
        RotationalMotor {
          name "left wheel motor"
          consumptionFactor 70
        }
        PositionSensor {
          name "left wheel sensor"
        }
      ]
      endPoint Solid {
        translation 0 0.045 0.025
        rotation 0.13448695438559669 -0.13448695438559669 -0.9817466670176033 1.589217
        children [
          DEF WHEEL Transform {
            rotation 0.577656895078166 0.5771968951617173 -0.5771968951617173 -2.093935
            children [
              Shape {
                appearance PBRAppearance {
                  baseColor 1 0 0
                  roughness 1
                  metalness 0
                }
                geometry Cylinder {
                  height 0.01
                  radius 0.025
                }
              }
            ]
          }
        ]
        name "left wheel"
        boundingObject USE WHEEL
        physics DEF PHYSICS_WHEEL Physics {
          density -1
          mass 0.05
        }
      }
    }
    HingeJoint {
      jointParameters HingeJointParameters {
        axis 0 1 0
        anchor 0 0 0.025
      }
      device [
        RotationalMotor {
          name "right wheel motor"
          consumptionFactor 70
        }
        PositionSensor {
          name "right wheel sensor"
        }
      ]
      endPoint Solid {
        translation 0 -0.045 0.025
        rotation -0.06235700094427207 0.06235700094427207 -0.9961040150840031 1.5747
        children [
          USE WHEEL
        ]
        name "right wheel"
        boundingObject USE WHEEL
        physics USE PHYSICS_WHEEL
      }
    }
    DistanceSensor {
      translation 0.042 0.02 0.063
      rotation 0.940734994155684 0.2398099985101804 0.2398099985101804 1.631852
      lookupTable [
        0 0 0
        1 1000 0
      ]
    }
    DEF SMILE Transform {
      translation 0.036 0 0.025
      rotation 0.25056300542381216 -0.9351130202419243 -0.25056300542381216 1.637834
      children [
        Shape {
          appearance PBRAppearance {
            baseColor 0.721569 0.290196 0.290196
            roughness 1
            metalness 0
          }
          geometry Cylinder {
            height 0.018
            radius 0.009
            subdivision 3
          }
        }
      ]
    }
    Camera {
      translation 0.04 0 0.0915
      rotation -0.5773502691896258 0.5773502691896258 0.5773502691896258 0
      children [
        Transform {
          translation -0.015 0 0
          rotation -0.5771968951617173 -0.577656895078166 -0.5771968951617173 -2.093935
          children [
            Shape {
              appearance PBRAppearance {
                roughness 1
                metalness 0
              }
              geometry Cylinder {
                height 0.03
                radius 0.01
              }
            }
          ]
        }
      ]
      fieldOfView 1
      width 400
      height 300
      focus Focus {
        focalDistance 0.516532689268457
        focalLength 0.25
        maxFocalDistance 1
        minFocalDistance 0.1
      }
    }
    DEF RIGHT_EYE Transform {
      translation 0.042 0.02 0.063
      rotation 0.3871000691202075 0.6519791164167495 0.6519791164167495 2.40292
      children [
        Shape {
          appearance PBRAppearance {
            baseColor 0.975691 0.981481 0.0252992
            roughness 1
            metalness 0
          }
          geometry Cylinder {
            height 0.004
            radius 0.008
          }
        }
      ]
    }
    DEF LEFT_EYE Transform {
      translation 0.042 -0.02 0.063
      rotation 0.7664071928227091 0.45421311427685446 0.45421411427710606 1.83375
      children [
        Shape {
          appearance PBRAppearance {
            baseColor 0.975691 0.981481 0.0252992
            roughness 1
            metalness 0
          }
          geometry Cylinder {
            height 0.004
            radius 0.008
          }
        }
      ]
    }
  ]
  name "MyBot"
  boundingObject Transform {
    translation 0 0 0.0415
    rotation 0 0 1 -1.570796
    children [
      USE BODY
    ]
  }
  physics Physics {
    density -1
    mass 0.5
  }
  controller "camera_auto_focus"
}
Can {
  translation 0.28 0 0.06
  rotation -1.31948e-06 5.47828e-07 1 -3.1415853071795863
}
Apple {
  translation -0.26 0 0.05
  rotation 0 1 0 -5.307179586466759e-06
}
Book {
  translation -0.0866027 -0.29 0.1
  rotation 0 0 1 2.3562
}
OilBarrel {
  translation 0.143119 -0.169397 0.075
  rotation 0 0 1 1.5708
  height 0.2
  radius 0.05
}
SoccerBall {
  translation 0 0.29 0.11
}
