#VRML_SIM R2021c utf8
WorldInfo {
  info [
    "Example use of the Compass device."
  ]
  title "Compass"
  basicTimeStep 8
}
Viewpoint {
  orientation 0.019124938762317033 0.9974310423038564 0.06903298172598858 0.7675141975507517
  position -1.2063291583679796 -0.07168629435099041 1.3121407376583043
}
TexturedBackground {
}
TexturedBackgroundLight {
}
RectangleArena {
}
DEF GREEN_BOX Solid {
  translation 0.023478 0.438565 0.05
  rotation 0 0 1 1.5708
  children [
    Shape {
      appearance PBRAppearance {
        baseColor 0 1 0
        roughness 0.2189099510000001
        metalness 0
      }
      geometry DEF BOX0 Box {
        size 0.1 0.23 0.1
      }
    }
  ]
  name "green box"
  boundingObject Shape {
    appearance PBRAppearance {
      roughness 1.1102230246251565e-16
      metalness 0
    }
    geometry USE BOX0
  }
}
DEF BLUE_BOX Solid {
  translation 0.438027 -0.148478 0.05
  children [
    Shape {
      appearance PBRAppearance {
        baseColor 0 0 1
        roughness 0.519341125
        metalness 0
      }
      geometry DEF BOX1 Box {
        size 0.1 0.1 0.1
      }
    }
  ]
  name "blue box"
  boundingObject Shape {
    appearance PBRAppearance {
      roughness 1.1102230246251565e-16
      metalness 0
    }
    geometry USE BOX1
  }
}
DEF COMPASS_ROBOT Robot {
  rotation 0 0 1 1.5708
  children [
    Transform {
      translation 0 0 0.0415
      rotation 0 0 1 -1.570796
      children [
        Shape {
          appearance PBRAppearance {
            baseColor 0.0820075 0.364731 0.8
            roughness 1
            metalness 0
          }
          geometry DEF BODY Cylinder {
            height 0.08
            radius 0.045
          }
        }
      ]
    }
    HingeJoint {
      jointParameters HingeJointParameters {
        axis 0 1 0
        anchor 0 0 0.025
      }
      device [
        RotationalMotor {
          name "left wheel motor"
          consumptionFactor 70
        }
        PositionSensor {
          name "left wheel sensor"
        }
      ]
      endPoint Solid {
        translation 0 0.045 0.025
        rotation -0.134487 0.134487 0.981747 -1.589217
        children [
          DEF WHEEL Transform {
            rotation 0.577657 0.577197 -0.577197 -2.093935
            children [
              Shape {
                appearance PBRAppearance {
                  baseColor 1 0 0
                  roughness 1
                  metalness 0
                }
                geometry Cylinder {
                  height 0.01
                  radius 0.025
                }
              }
            ]
          }
        ]
        name "left wheel"
        boundingObject USE WHEEL
        physics DEF PHYSICS_WHEEL Physics {
          density -1
          mass 0.05
        }
      }
    }
    HingeJoint {
      jointParameters HingeJointParameters {
        axis 0 1 0
        anchor 0 0 0.025
      }
      device [
        RotationalMotor {
          name "right wheel motor"
          consumptionFactor 70
        }
        PositionSensor {
          name "right wheel sensor"
        }
      ]
      endPoint Solid {
        translation 0 -0.045 0.025
        rotation 0.062357 -0.062357 0.996104 -1.5747
        children [
          USE WHEEL
        ]
        name "right wheel"
        boundingObject USE WHEEL
        physics USE PHYSICS_WHEEL
      }
    }
    DEF LEFT_US DistanceSensor {
      translation 0.042 0.02 0.063
      rotation 0.940735 0.23981 0.23981 1.631852
      children [
        DEF SENSOR_TRANSFORM Transform {
          rotation 0.577657 0.577197 -0.577197 -2.093935
          children [
            Shape {
              appearance PBRAppearance {
                baseColor 0.975691 0.981481 0.0252992
                roughness 1
                metalness 0
              }
              geometry Cylinder {
                height 0.004
                radius 0.008
              }
            }
          ]
        }
      ]
      name "us0"
      lookupTable [
        0 0 0
        0.2 200 0
      ]
      type "sonar"
      numberOfRays 15
    }
    DEF RIGHT_US DistanceSensor {
      translation 0.042 -0.02 0.063
      rotation 0.940374 -0.240516 -0.240516 1.632235
      children [
        USE SENSOR_TRANSFORM
      ]
      name "us1"
      lookupTable [
        0 0 0
        0.2 200 0
      ]
      type "sonar"
      numberOfRays 15
    }
    Compass {
      translation 0 0.05 0
    }
    DEF SMILE Transform {
      translation 0.036 0 0.025
      rotation 0.250563 -0.935113 -0.250563 1.637834
      children [
        Shape {
          appearance PBRAppearance {
            baseColor 0.721569 0.290196 0.290196
            roughness 1
            metalness 0
          }
          geometry Cylinder {
            height 0.018
            radius 0.009
            subdivision 3
          }
        }
      ]
    }
    DEF PIVOT Transform {
      translation 0 0 0.06
      children [
        Shape {
          appearance PBRAppearance {
            baseColor 0.8 0.8 0.8
            roughness 1
            metalness 0
          }
          geometry Cylinder {
            height 0.1
            radius 0.002
          }
        }
      ]
    }
    DEF NEEDLE HingeJoint {
      jointParameters HingeJointParameters {
        axis 0 0 1
        anchor 0 0 0.1
      }
      device [
        RotationalMotor {
          name "arrow"
        }
      ]
      endPoint Solid {
        translation 0 0 0.1
        rotation 0.57735 -0.57735 -0.57735 2.094395
        children [
          DEF NEEDLE_BODY Transform {
            rotation 0 0 -1 -1.570795
            children [
              Shape {
                appearance DEF NEEDLE_APP PBRAppearance {
                  baseColor 1 1 0
                  roughness 1
                  metalness 0
                }
                geometry Cylinder {
                  height 0.1
                  radius 0.005
                }
              }
            ]
          }
          DEF NEEDLE_HEAD Transform {
            translation 0 0 0.05
            rotation 0 0 -1 -1.570795
            children [
              Shape {
                appearance USE NEEDLE_APP
                geometry Cone {
                  bottomRadius 0.01
                  height 0.02
                }
              }
            ]
          }
        ]
      }
    }
  ]
  name "MyBot"
  boundingObject DEF MYBOT_BOUNDING Transform {
    translation 0 0 0.0415
    rotation 0 0 1 -1.570796
    children [
      USE BODY
    ]
  }
  physics DEF MYBOT_PHYSICS Physics {
    density -1
    mass 0.5
  }
  controller "compass"
}
