#VRML_SIM R2021b utf8
WorldInfo {
  info [
    "Example use of the Compass device."
  ]
  title "Compass"
  basicTimeStep 8
  coordinateSystem "NUE"
}
Viewpoint {
  orientation -0.3789158794431957 -0.843261731705782 -0.38122487870855887 1.73166
  position -0.931506 1.07918 0.00404461
}
TexturedBackground {
}
TexturedBackgroundLight {
}
RectangleArena {
}
DEF GREEN_BOX Solid {
  translation 0.0234781 0.05 -0.438565
  children [
    Shape {
      appearance PBRAppearance {
        baseColor 0 1 0
        roughness 0.2189099510000001
        metalness 0
      }
      geometry DEF BOX0 Box {
        size 0.23 0.1 0.1
      }
    }
  ]
  name "green box"
  boundingObject Shape {
    appearance PBRAppearance {
      roughness 1.1102230246251565e-16
      metalness 0
    }
    geometry USE BOX0
  }
}
DEF BLUE_BOX Solid {
  translation 0.438027 0.05 0.148478
  children [
    Shape {
      appearance PBRAppearance {
        baseColor 0 0 1
        roughness 0.519341125
        metalness 0
      }
      geometry DEF BOX1 Box {
        size 0.1 0.1 0.1
      }
    }
  ]
  name "blue box"
  boundingObject Shape {
    appearance PBRAppearance {
      roughness 1.1102230246251565e-16
      metalness 0
    }
    geometry USE BOX1
  }
}
DEF COMPASS_ROBOT Robot {
  children [
    Transform {
      translation 0 0.0415 0
      children [
        Shape {
          appearance PBRAppearance {
            baseColor 0.0820075 0.364731 0.8
            roughness 1
            metalness 0
          }
          geometry DEF BODY Cylinder {
            height 0.08
            radius 0.045
          }
        }
      ]
    }
    HingeJoint {
      jointParameters HingeJointParameters {
        axis -1 0 0
        anchor 0 0.025 0
      }
      device [
        RotationalMotor {
          name "left wheel motor"
          consumptionFactor 70
        }
        PositionSensor {
          name "left wheel sensor"
        }
      ]
      endPoint Solid {
        translation -0.045 0.025 0
        rotation 1 0 0 4.98467
        children [
          DEF WHEEL Transform {
            rotation 0 0 1 1.57
            children [
              Shape {
                appearance PBRAppearance {
                  baseColor 1 0 0
                  roughness 1
                  metalness 0
                }
                geometry Cylinder {
                  height 0.01
                  radius 0.025
                }
              }
            ]
          }
        ]
        name "left wheel"
        boundingObject USE WHEEL
        physics DEF PHYSICS_WHEEL Physics {
          density -1
          mass 0.05
        }
      }
    }
    HingeJoint {
      jointParameters HingeJointParameters {
        axis -1 0 0
        anchor 0 0.025 0
      }
      device [
        RotationalMotor {
          name "right wheel motor"
          consumptionFactor 70
        }
        PositionSensor {
          name "right wheel sensor"
        }
      ]
      endPoint Solid {
        translation 0.045 0.025 0
        rotation 1 0 0 4.58735
        children [
          USE WHEEL
        ]
        name "right wheel"
        boundingObject USE WHEEL
        physics USE PHYSICS_WHEEL
      }
    }
    DEF LEFT_US DistanceSensor {
      translation -0.02 0.063 -0.042
      rotation 0 1 0 2.2253
      children [
        DEF SENSOR_TRANSFORM Transform {
          rotation 0 0 1 1.57
          children [
            Shape {
              appearance PBRAppearance {
                baseColor 0.975691 0.981481 0.0252992
                roughness 1
                metalness 0
              }
              geometry Cylinder {
                height 0.004
                radius 0.008
              }
            }
          ]
        }
      ]
      name "us0"
      lookupTable [
        0 0 0
        0.2 200 0
      ]
      type "sonar"
      numberOfRays 15
    }
    DEF RIGHT_US DistanceSensor {
      translation 0.02 0.063 -0.042
      rotation 0 1 0 0.9163
      children [
        USE SENSOR_TRANSFORM
      ]
      name "us1"
      lookupTable [
        0 0 0
        0.2 200 0
      ]
      type "sonar"
      numberOfRays 15
    }
    Compass {
      translation 0 0.05 0
    }
    DEF SMILE Transform {
      translation 0 0.025 -0.036
      rotation 0.7745972408364944 0.44721228048294853 0.4472139204829502 1.8234794
      children [
        Shape {
          appearance PBRAppearance {
            baseColor 0.721569 0.290196 0.290196
            roughness 1
            metalness 0
          }
          geometry Cylinder {
            height 0.018
            radius 0.009
            subdivision 3
          }
        }
      ]
    }
    DEF PIVOT Transform {
      translation 0 0.06 0
      children [
        Shape {
          appearance PBRAppearance {
            baseColor 0.8 0.8 0.8
            roughness 1
            metalness 0
          }
          geometry Cylinder {
            height 0.1
            radius 0.002
          }
        }
      ]
    }
    DEF NEEDLE HingeJoint {
      jointParameters HingeJointParameters {
        axis 0 1 0
        anchor 0 0.1 0
      }
      device [
        RotationalMotor {
          name "arrow"
        }
      ]
      endPoint Solid {
        translation 0 0.1 0
        children [
          DEF NEEDLE_BODY Transform {
            rotation 1 0 0 1.5708
            children [
              Shape {
                appearance DEF NEEDLE_APP PBRAppearance {
                  baseColor 1 1 0
                  roughness 1
                  metalness 0
                }
                geometry Cylinder {
                  height 0.1
                  radius 0.005
                }
              }
            ]
          }
          DEF NEEDLE_HEAD Transform {
            translation 0 0 0.05
            rotation 1 0 0 1.5708
            children [
              Shape {
                appearance USE NEEDLE_APP
                geometry Cone {
                  bottomRadius 0.01
                  height 0.02
                }
              }
            ]
          }
        ]
      }
    }
  ]
  name "MyBot"
  boundingObject DEF MYBOT_BOUNDING Transform {
    translation 0 0.0415 0
    children [
      USE BODY
    ]
  }
  physics DEF MYBOT_PHYSICS Physics {
    density -1
    mass 0.5
  }
  controller "compass"
}
