#VRML_SIM R2023b utf8

EXTERNPROTO "webots://projects/objects/backgrounds/protos/TexturedBackground.proto"
EXTERNPROTO "webots://projects/objects/backgrounds/protos/TexturedBackgroundLight.proto"
EXTERNPROTO "webots://projects/objects/floors/protos/RectangleArena.proto"

WorldInfo {
  info [
    "Example use of a Connector device."
  ]
  title "Connector"
}
Viewpoint {
  orientation -0.31839107274552725 -0.1128527872395881 0.9412180263935709 3.729172966528765
  position 1.275001830173748 0.7898828324006901 1.1626925306508054
}
TexturedBackground {
}
TexturedBackgroundLight {
}
RectangleArena {
}
DEF GREEN_BOX Solid {
  translation 0.35 0.05 0.05
  children [
    Shape {
      appearance PBRAppearance {
        baseColor 0 1 0
        roughness 0.2189099510000001
        metalness 0
      }
      geometry DEF BOX0 Box {
        size 0.1 0.23 0.1
      }
    }
  ]
  name "green box"
  boundingObject Shape {
    appearance PBRAppearance {
      roughness 1.1102230246251565e-16
      metalness 0
    }
    geometry USE BOX0
  }
}
DEF BLUE_BOX Solid {
  translation -0.27 -0.2 0.05
  rotation 0 0 1 0.31
  children [
    Shape {
      appearance PBRAppearance {
        baseColor 0 0 1
        roughness 0.519341125
        metalness 0
      }
      geometry DEF BOX1 Box {
        size 0.1 0.1 0.1
      }
    }
  ]
  name "blue box"
  boundingObject Shape {
    appearance PBRAppearance {
      roughness 1.1102230246251565e-16
      metalness 0
    }
    geometry USE BOX1
  }
}
DEF YELLOW_BOX Solid {
  translation -0.15 0.2 0.05
  rotation 0 0 1 0.4
  children [
    Shape {
      appearance PBRAppearance {
        baseColor 1 1 0
        roughness 0.03934117200000009
        metalness 0
      }
      geometry DEF BOX2 Box {
        size 0.3 0.05 0.1
      }
    }
  ]
  name "yellow box"
  boundingObject Shape {
    appearance PBRAppearance {
      roughness 1.1102230246251565e-16
      metalness 0
    }
    geometry USE BOX2
  }
}
DEF PINK_BOX Solid {
  translation 0.35 -0.42 0.05
  children [
    Shape {
      appearance PBRAppearance {
        baseColor 1 0.1 0.3
        roughness 0.16827074099999995
        metalness 0
      }
      geometry DEF BOX3 Box {
        size 0.08 0.15 0.1
      }
    }
  ]
  name "red box"
  boundingObject Shape {
    appearance PBRAppearance {
      roughness 1.1102230246251565e-16
      metalness 0
    }
    geometry USE BOX3
  }
}
DEF LIGHT_MYBOT Robot {
  translation 0.1 -0.42 0
  rotation 0 0 1 1.5708
  children [
    DEF LIGHT_BODY Pose {
      translation 0 0 0.0415
      rotation 0 0 1 1.570796
      children [
        Shape {
          appearance PBRAppearance {
            baseColor 0.117647 0.776471 1
            roughness 0.6980390000000001
            metalness 0
          }
          geometry DEF BODY Cylinder {
            height 0.08
            radius 0.045
          }
        }
      ]
    }
    HingeJoint {
      jointParameters HingeJointParameters {
        axis 0 1 0
        anchor 0 0 0.025
      }
      device [
        RotationalMotor {
          name "left wheel motor"
          consumptionFactor 70
        }
        PositionSensor {
          name "left wheel sensor"
          resolution 0.314159
        }
      ]
      endPoint Solid {
        translation 0 0.045 0.025
        rotation 0.1344869543855967 -0.1344869543855967 -0.9817466670176034 1.589218
        children [
          DEF WHEEL Pose {
            rotation 0.577656895078166 0.5771968951617173 -0.5771968951617173 -2.093935
            children [
              Shape {
                appearance PBRAppearance {
                  baseColor 1 0 0
                  roughness 1
                  metalness 0
                }
                geometry Cylinder {
                  height 0.01
                  radius 0.025
                }
              }
            ]
          }
        ]
        name "left wheel"
        boundingObject USE WHEEL
        physics DEF PHYSICS_WHEEL Physics {
          density -1
          mass 0.05
        }
      }
    }
    HingeJoint {
      jointParameters HingeJointParameters {
        axis 0 1 0
        anchor 0 0 0.025
      }
      device [
        RotationalMotor {
          name "right wheel motor"
          consumptionFactor 70
        }
        PositionSensor {
          name "right wheel sensor"
          resolution 0.314159
        }
      ]
      endPoint Solid {
        translation 0 -0.045 0.025
        rotation -0.06235700094427208 0.06235700094427208 -0.9961040150840033 1.5747
        children [
          USE WHEEL
        ]
        name "right wheel"
        boundingObject USE WHEEL
        physics USE PHYSICS_WHEEL
      }
    }
    DEF RIGHT_EYE Pose {
      translation 0.0385 -0.02 0.063
      rotation -0.7268278184260777 -0.4856548786751704 -0.4856548786751704 -1.884582
      children [
        DEF UNUSED_EYE Group {
          children [
            Pose {
              translation 0 0 1e-05
              rotation 0 0 1 0.8
              children [
                Shape {
                  appearance PBRAppearance {
                    baseColor 0.975691 0.981481 0.0252992
                    roughness 1
                    metalness 0
                  }
                  geometry Box {
                    size 0.02 0.005 0.005
                  }
                }
              ]
            }
            Pose {
              rotation 0 0 1 -0.8
              children [
                Shape {
                  appearance PBRAppearance {
                    baseColor 0.975691 0.981481 0.0252992
                    roughness 1
                    metalness 0
                  }
                  geometry Box {
                    size 0.02 0.005 0.005
                  }
                }
              ]
            }
          ]
        }
      ]
    }
    DEF LEFT_EYE Pose {
      translation 0.0385 0.02 0.063
      rotation -0.7268313515069925 0.4856522348690052 0.4856522348690052 -1.884578
      children [
        DEF UNUSED_EYE Group {
          children [
            Pose {
              translation 0 0 -1e-05
              rotation 0 0 1 0.8
              children [
                Shape {
                  appearance PBRAppearance {
                    baseColor 0.975691 0.981481 0.0252992
                    roughness 1
                    metalness 0
                  }
                  geometry Box {
                    size 0.02 0.005 0.005
                  }
                }
              ]
            }
            Pose {
              rotation 0 0 1 -0.8
              children [
                Shape {
                  appearance PBRAppearance {
                    baseColor 0.975691 0.981481 0.0252992
                    roughness 1
                    metalness 0
                  }
                  geometry Box {
                    size 0.02 0.005 0.005
                  }
                }
              ]
            }
          ]
        }
      ]
    }
    DEF SMILE Pose {
      translation 0.036 0 0.025
      rotation 0.25056300542381216 -0.9351130202419243 -0.25056300542381216 1.637834
      children [
        Shape {
          appearance PBRAppearance {
            baseColor 0.721569 0.290196 0.290196
            roughness 1
            metalness 0
          }
          geometry Cylinder {
            height 0.018
            radius 0.009
            subdivision 3
          }
        }
      ]
    }
    DEF HINGE_JOINT_DEVICE HingeJoint {
      jointParameters HingeJointParameters {
        axis 0 -1 0
        anchor 0 0 0.06
      }
      device [
        RotationalMotor {
          name "upper motor"
          maxVelocity 1
          minPosition -1.57
          maxPosition 1.57
        }
        PositionSensor {
          name "upper sensor"
        }
      ]
      endPoint Solid {
        translation 0 0 0.06
        children [
          DEF CONNECTOR_SHAPE Group {
            children [
              Pose {
                translation 0 -0.049 0.025
                children [
                  DEF SIDE_PART Shape {
                    appearance PBRAppearance {
                      baseColor 0.898039 0.898039 0.898039
                      roughness 0.25098
                      metalness 0
                    }
                    geometry Box {
                      size 0.015 0.008 0.05
                    }
                  }
                ]
              }
              Pose {
                translation 0 0.049 0.025
                children [
                  USE SIDE_PART
                ]
              }
              Pose {
                translation 0 0 0.05
                children [
                  Shape {
                    appearance PBRAppearance {
                      baseColor 0.898039 0.898039 0.898039
                      roughness 0.25098
                      metalness 0
                    }
                    geometry Box {
                      size 0.04 0.12 0.01
                    }
                  }
                ]
              }
            ]
          }
          DEF CONNECTOR_DEVICE Connector {
            translation 0 0 0.055
            rotation 0.0003979999369552231 -0.9999998415960378 -0.0003979999369552231 1.570796
            model "magnetic"
            autoLock TRUE
            axisTolerance 3.14
            rotationTolerance 3.14
          }
        ]
        boundingObject USE CONNECTOR_SHAPE
        physics DEF CONNECTOR_SHAPE_PHYSICS Physics {
          density -1
          mass 0.05
        }
      }
    }
  ]
  name "MyBot 1"
  boundingObject DEF MYBOT_BOUNDING Pose {
    translation 0 0 0.0415
    rotation 0 0 1 1.570796
    children [
      USE BODY
    ]
  }
  physics DEF MOVING_MYBOT_PHYSICS Physics {
    density -1
    mass 0.05
  }
  controller "connector"
}
DEF HEAVY_MYBOT Robot {
  translation 0.1 -0.15 0
  rotation 0 0 1 -1.57
  children [
    DEF MAIN_BODY Pose {
      translation 0 0 0.0415
      rotation 0 0 1 1.570796
      children [
        Shape {
          appearance PBRAppearance {
            baseColor 0.0820075 0.364731 0.8
            roughness 1
            metalness 0
          }
          geometry USE BODY
        }
      ]
    }
    HingeJoint {
      jointParameters HingeJointParameters {
        axis 0 1 0
        anchor 0 0 0.025
      }
      device [
        RotationalMotor {
          name "left wheel motor"
          consumptionFactor 70
        }
        PositionSensor {
          name "left wheel sensor"
          resolution 0.314159
        }
      ]
      endPoint Solid {
        translation 0 0.045 0.025
        rotation 0.1344869543855967 -0.1344869543855967 -0.9817466670176034 1.589218
        children [
          DEF WHEEL Pose {
            rotation 0.577656895078166 0.5771968951617173 -0.5771968951617173 -2.093935
            children [
              Shape {
                appearance PBRAppearance {
                  baseColor 1 0 0
                  roughness 1
                  metalness 0
                }
                geometry Cylinder {
                  height 0.01
                  radius 0.025
                }
              }
            ]
          }
        ]
        name "left wheel"
        boundingObject USE WHEEL
        physics DEF PHYSICS_WHEEL Physics {
          density -1
          mass 0.05
        }
      }
    }
    HingeJoint {
      jointParameters HingeJointParameters {
        axis 0 1 0
        anchor 0 0 0.025
      }
      device [
        RotationalMotor {
          name "right wheel motor"
          consumptionFactor 70
        }
        PositionSensor {
          name "right wheel sensor"
          resolution 0.314159
        }
      ]
      endPoint Solid {
        translation 0 -0.045 0.025
        rotation -0.06235700094427208 0.06235700094427208 -0.9961040150840033 1.5747
        children [
          USE WHEEL
        ]
        name "right wheel"
        boundingObject USE WHEEL
        physics USE PHYSICS_WHEEL
      }
    }
    USE LEFT_EYE
    USE RIGHT_EYE
    USE SMILE
    DEF HINGE_JOINT_DEVICE HingeJoint {
      jointParameters HingeJointParameters {
        axis 0 -1 0
        anchor 0 0 0.06
      }
      device [
        RotationalMotor {
          name "upper motor"
          maxVelocity 1
          minPosition -1.57
          maxPosition 1.57
        }
        PositionSensor {
          name "upper sensor"
        }
      ]
      endPoint Solid {
        translation 0 0 0.06
        children [
          DEF CONNECTOR_SHAPE Group {
            children [
              Pose {
                translation 0 -0.049 0.025
                children [
                  DEF SIDE_PART Shape {
                    appearance PBRAppearance {
                      baseColor 0.898039 0.898039 0.898039
                      roughness 0.25098
                      metalness 0
                    }
                    geometry Box {
                      size 0.015 0.008 0.05
                    }
                  }
                ]
              }
              Pose {
                translation 0 0.049 0.025
                children [
                  USE SIDE_PART
                ]
              }
              Pose {
                translation 0 0 0.05
                children [
                  Shape {
                    appearance PBRAppearance {
                      baseColor 0.898039 0.898039 0.898039
                      roughness 0.25098
                      metalness 0
                    }
                    geometry Box {
                      size 0.04 0.12 0.01
                    }
                  }
                ]
              }
            ]
          }
          DEF CONNECTOR_DEVICE Connector {
            translation 0 0 0.055
            rotation 0.0003979999369552231 -0.9999998415960378 -0.0003979999369552231 1.570796
            model "magnetic"
            autoLock TRUE
            axisTolerance 3.14
            rotationTolerance 3.14
          }
        ]
        boundingObject USE CONNECTOR_SHAPE
        physics DEF CONNECTOR_SHAPE_PHYSICS Physics {
          density -1
          mass 0.05
        }
      }
    }
  ]
  name "MyBot 2"
  boundingObject USE MYBOT_BOUNDING
  physics DEF STATIC_MYBOT_PHYSICS Physics {
    density -1
    mass 0.5
  }
  controller "connector"
}
DEF HEAVY_MYBOT Robot {
  translation 0.1 0.2 0
  rotation 0 0 1 -1.57
  children [
    USE MAIN_BODY
    HingeJoint {
      jointParameters HingeJointParameters {
        axis 0 1 0
        anchor 0 0 0.025
      }
      device [
        RotationalMotor {
          name "left wheel motor"
          consumptionFactor 70
        }
        PositionSensor {
          name "left wheel sensor"
          resolution 0.314159
        }
      ]
      endPoint Solid {
        translation 0 0.045 0.025
        rotation 0.1344869543855967 -0.1344869543855967 -0.9817466670176034 1.589218
        children [
          DEF WHEEL Pose {
            rotation 0.577656895078166 0.5771968951617173 -0.5771968951617173 -2.093935
            children [
              Shape {
                appearance PBRAppearance {
                  baseColor 1 0 0
                  roughness 1
                  metalness 0
                }
                geometry Cylinder {
                  height 0.01
                  radius 0.025
                }
              }
            ]
          }
        ]
        name "left wheel"
        boundingObject USE WHEEL
        physics DEF PHYSICS_WHEEL Physics {
          density -1
          mass 0.05
        }
      }
    }
    HingeJoint {
      jointParameters HingeJointParameters {
        axis 0 1 0
        anchor 0 0 0.025
      }
      device [
        RotationalMotor {
          name "right wheel motor"
          consumptionFactor 70
        }
        PositionSensor {
          name "right wheel sensor"
          resolution 0.314159
        }
      ]
      endPoint Solid {
        translation 0 -0.045 0.025
        rotation -0.06235700094427208 0.06235700094427208 -0.9961040150840033 1.5747
        children [
          USE WHEEL
        ]
        name "right wheel"
        boundingObject USE WHEEL
        physics USE PHYSICS_WHEEL
      }
    }
    USE LEFT_EYE
    USE RIGHT_EYE
    USE SMILE
    DEF HINGE_JOINT_DEVICE HingeJoint {
      jointParameters HingeJointParameters {
        axis 0 -1 0
        anchor 0 0 0.06
      }
      device [
        RotationalMotor {
          name "upper motor"
          maxVelocity 1
          minPosition -1.57
          maxPosition 1.57
        }
        PositionSensor {
          name "upper sensor"
        }
      ]
      endPoint Solid {
        translation 0 0 0.06
        children [
          DEF CONNECTOR_SHAPE Group {
            children [
              Pose {
                translation 0 -0.049 0.025
                children [
                  DEF SIDE_PART Shape {
                    appearance PBRAppearance {
                      baseColor 0.898039 0.898039 0.898039
                      roughness 0.25098
                      metalness 0
                    }
                    geometry Box {
                      size 0.015 0.008 0.05
                    }
                  }
                ]
              }
              Pose {
                translation 0 0.049 0.025
                children [
                  USE SIDE_PART
                ]
              }
              Pose {
                translation 0 0 0.05
                children [
                  Shape {
                    appearance PBRAppearance {
                      baseColor 0.898039 0.898039 0.898039
                      roughness 0.25098
                      metalness 0
                    }
                    geometry Box {
                      size 0.04 0.12 0.01
                    }
                  }
                ]
              }
            ]
          }
          DEF CONNECTOR_DEVICE Connector {
            translation 0 0 0.055
            rotation 0.0003979999369552231 -0.9999998415960378 -0.0003979999369552231 1.570796
            model "magnetic"
            autoLock TRUE
            axisTolerance 3.14
            rotationTolerance 3.14
          }
        ]
        boundingObject USE CONNECTOR_SHAPE
        physics DEF CONNECTOR_SHAPE_PHYSICS Physics {
          density -1
          mass 0.05
        }
      }
    }
  ]
  name "MyBot 3"
  boundingObject USE MYBOT_BOUNDING
  physics USE STATIC_MYBOT_PHYSICS
  controller "connector"
}
