#VRML_SIM R2020a utf8
WorldInfo {
  info [
    "Example use of a Display device."
  ]
  title "Display"
}
Viewpoint {
  orientation 0.999954412713123 -0.008134763357476649 -0.004999812063582125 5.18094
  position 0.00903084 1.44368 0.747339
}
TexturedBackground {
  texture "empty_office"
}
TexturedBackgroundLight {
}
SolidBox {
  translation 0.505 0.05 0
  name "wall 1"
  size 0.01 0.1 1
  appearance DEF SQUARE_ARENA_APPEARANCE_A PBRAppearance {
    baseColorMap ImageTexture {
      url [
        "textures/metal.jpg"
      ]
    }
    roughness 1
    metalness 0
    textureTransform TextureTransform {
      scale 2 2
    }
  }
}
SolidBox {
  translation -0.505 0.05 0
  name "wall 2"
  size 0.01 0.1 1
  appearance USE SQUARE_ARENA_APPEARANCE_A
}
SolidBox {
  translation 0 0.05 0.505
  name "wall 3"
  size 1.02 0.1 0.01
  appearance DEF SQUARE_ARENA_APPEARANCE_B PBRAppearance {
    baseColorMap ImageTexture {
      url [
        "textures/metal.jpg"
      ]
    }
    roughness 1
    metalness 0
    textureTransform TextureTransform {
      scale 2.04 2.04
    }
  }
}
SolidBox {
  translation 0 0.05 -0.505
  name "wall 4"
  size 1.02 0.1 0.01
  appearance USE SQUARE_ARENA_APPEARANCE_B
}
DEF BOX1 Solid {
  translation 0.264272 0.05 -0.217139
  rotation 0 1 0 1.87071
  children [
    Shape {
      appearance DEF YELLOW_APPEARANCE PBRAppearance {
        baseColor 1 1 0
        roughness 1
        metalness 0
      }
      geometry DEF GEOM1 Box {
        size 0.23 0.1 0.1
      }
    }
  ]
  name "box 1"
  boundingObject Shape {
    appearance PBRAppearance {
      roughness 1
      metalness 0
    }
    geometry USE GEOM1
  }
}
DEF BOX2 Solid {
  translation -0.273364 0.05 -0.257435
  rotation 0 1 0 0.31
  children [
    Shape {
      appearance USE YELLOW_APPEARANCE
      geometry DEF GEOM1 Box {
        size 0.1 0.1 0.1
      }
    }
  ]
  name "box 2"
  boundingObject Shape {
    appearance PBRAppearance {
      roughness 1
      metalness 0
    }
    geometry USE GEOM1
  }
}
DEF BOX3 Solid {
  translation -0.27077 0.05 0.208561
  rotation 0 -1 0 2.90528
  children [
    Shape {
      appearance USE YELLOW_APPEARANCE
      geometry DEF GEOM2 Box {
        size 0.05 0.1 0.3
      }
    }
  ]
  name "box 3"
  boundingObject Shape {
    appearance PBRAppearance {
      roughness 1
      metalness 0
    }
    geometry USE GEOM2
  }
}
DEF BOX4 Solid {
  translation 0.253659 0.05 0.284296
  children [
    Shape {
      appearance USE YELLOW_APPEARANCE
      geometry DEF GEOM4 Box {
        size 0.15 0.1 0.08
      }
    }
  ]
  name "box 4"
  boundingObject Shape {
    appearance PBRAppearance {
      roughness 1
      metalness 0
    }
    geometry USE GEOM4
  }
}
DEF MYBOT Robot {
  translation -0.131552 0 -0.202001
  rotation 0 1 0 3.63077
  children [
    Transform {
      translation 0 0.0415 0
      children [
        Shape {
          appearance PBRAppearance {
            baseColor 0.0820075 0.364731 0.8
            roughness 1
            metalness 0
          }
          geometry DEF BODY Cylinder {
            height 0.08
            radius 0.045
          }
        }
      ]
    }
    HingeJoint {
      jointParameters HingeJointParameters {
        axis -1 0 0
        anchor 0 0.025 0
      }
      device [
        RotationalMotor {
          name "left wheel motor"
          consumptionFactor 70
        }
        PositionSensor {
          name "left wheel sensor"
        }
      ]
      endPoint Solid {
        translation -0.045 0.025 0
        rotation 1 0 0 4.98467
        children [
          DEF WHEEL Transform {
            rotation 0 0 1 1.57
            children [
              Shape {
                appearance PBRAppearance {
                  baseColor 1 0 0
                  roughness 1
                  metalness 0
                }
                geometry Cylinder {
                  height 0.01
                  radius 0.025
                }
              }
            ]
          }
        ]
        name "left wheel"
        boundingObject USE WHEEL
        physics DEF PHYSICS_WHEEL Physics {
          density -1
          mass 0.05
        }
      }
    }
    HingeJoint {
      jointParameters HingeJointParameters {
        axis -1 0 0
        anchor 0 0.025 0
      }
      device [
        RotationalMotor {
          name "right wheel motor"
          consumptionFactor 70
        }
        PositionSensor {
          name "right wheel sensor"
        }
      ]
      endPoint Solid {
        translation 0.045 0.025 0
        rotation 1 0 0 4.58735
        children [
          USE WHEEL
        ]
        name "right wheel"
        boundingObject USE WHEEL
        physics USE PHYSICS_WHEEL
      }
    }
    DistanceSensor {
      translation -0.02 0.063 -0.042
      rotation 0 1 0 2.07
      children [
        DEF SENSOR Transform {
          rotation 0 0 1 1.57
          children [
            Shape {
              appearance PBRAppearance {
                baseColor 0.975691 0.981481 0.0252992
                roughness 1
                metalness 0
              }
              geometry Cylinder {
                height 0.004
                radius 0.008
              }
            }
          ]
        }
      ]
      name "ds0"
      lookupTable [
        0 1024 0
        0.05 1024 0
        0.15 0 0
      ]
      numberOfRays 4
      aperture 1.3
    }
    DistanceSensor {
      translation 0.02 0.063 -0.042
      rotation 0 1 0 1.07
      children [
        USE SENSOR
      ]
      name "ds1"
      lookupTable [
        0 1024 0
        0.05 1024 0
        0.15 0 0
      ]
      numberOfRays 4
      aperture 1.3
    }
    Camera {
      translation 0 0.0915 -0.04
      rotation 0 0 -1 0
      children [
        Transform {
          translation 0 0 0.015
          rotation 1 0 0 1.57
          children [
            Shape {
              appearance PBRAppearance {
                roughness 1
                metalness 0
              }
              geometry Cylinder {
                height 0.03
                radius 0.01
              }
            }
          ]
        }
      ]
      fieldOfView 1.047
      width 256
      height 128
    }
    DEF EMOTICONS Display {
      translation 0 0.13 0
      children [
        Shape {
          appearance PBRAppearance {
            baseColorMap ImageTexture {
            }
            roughness 1
            metalness 0
          }
          geometry IndexedFaceSet {
            coord Coordinate {
              point [
                0.04 0.04 -0.011
                0.04 -0.04 -0.011
                -0.04 -0.04 -0.011
                -0.04 0.04 -0.011
              ]
            }
            texCoord TextureCoordinate {
              point [
                0 1
                0 0
                1 0
                1 1
              ]
            }
            coordIndex [
              0, 1, 2, 3
            ]
            texCoordIndex [
              0, 1, 2, 3
            ]
          }
        }
        Shape {
          appearance PBRAppearance {
            baseColor 0.247059 0.788235 0.235294
            roughness 1
            metalness 0
          }
          geometry Box {
            size 0.1 0.1 0.02
          }
        }
      ]
      name "emoticon_display"
      width 14
      height 14
    }
    DEF CAMERA Display {
      name "camera_display"
      width 256
      height 128
    }
  ]
  name "MyBot"
  boundingObject Transform {
    translation 0 0.0415 0
    children [
      USE BODY
    ]
  }
  physics Physics {
    density -1
    mass 0.5
  }
  controller "display"
}
Robot {
  children [
    DEF GROUND Display {
      children [
        DEF SHAPE Shape {
          appearance PBRAppearance {
            baseColorMap ImageTexture {
              url [
                "textures/white256.png"
              ]
              filtering 0
            }
            roughness 1
            metalness 0
          }
          geometry Plane {
          }
        }
      ]
      name "ground_display"
      boundingObject USE SHAPE
    }
  ]
  controller "display_supervisor"
  supervisor TRUE
}
