#VRML_SIM R2021c utf8
WorldInfo {
  info [
    "Example use of a DistanceSensor device."
  ]
  title "Distance Sensor"
}
Viewpoint {
  orientation 0.028785645391644944 -0.9970897157287485 -0.07059380572932836 5.364766976817973
  position -1.4722030116586766 8.076455902941877e-05 1.8779833160032033
}
TexturedBackground {
}
TexturedBackgroundLight {
}
RectangleArena {
}
DEF GREEN_BOX Solid {
  translation 0.25 0.05 0.05
  children [
    Shape {
      appearance PBRAppearance {
        baseColor 0 1 0
        roughness 0.2189099510000001
        metalness 0
      }
      geometry DEF BOX0 Box {
        size 0.1 0.23 0.1
      }
    }
  ]
  name "green box"
  boundingObject Shape {
    appearance PBRAppearance {
      roughness 1.1102230246251565e-16
      metalness 0
    }
    geometry USE BOX0
  }
}
DEF BLUE_BOX Solid {
  translation -0.27 -0.2 0.05
  rotation 0 0 1 0.31
  children [
    Shape {
      appearance PBRAppearance {
        baseColor 0 0 1
        roughness 0.519341125
        metalness 0
      }
      geometry DEF BOX1 Box {
        size 0.1 0.1 0.1
      }
    }
  ]
  name "blue box"
  boundingObject Shape {
    appearance PBRAppearance {
      roughness 1.1102230246251565e-16
      metalness 0
    }
    geometry USE BOX1
  }
}
DEF YELLOW_BOX Solid {
  translation -0.15 0.2 0.05
  rotation 0 0 1 0.4
  children [
    Shape {
      appearance PBRAppearance {
        baseColor 1 1 0
        roughness 0.03934117200000009
        metalness 0
      }
      geometry DEF BOX2 Box {
        size 0.3 0.05 0.1
      }
    }
  ]
  name "yellow box"
  boundingObject Shape {
    appearance PBRAppearance {
      roughness 1.1102230246251565e-16
      metalness 0
    }
    geometry USE BOX2
  }
}
DEF PINK_BOX Solid {
  translation 0.1 -0.42 0.05
  children [
    Shape {
      appearance PBRAppearance {
        baseColor 1 0.1 0.3
        roughness 0.16827074099999995
        metalness 0
      }
      geometry DEF BOX3 Box {
        size 0.08 0.15 0.1
      }
    }
  ]
  name "red box"
  boundingObject Shape {
    appearance PBRAppearance {
      roughness 1.1102230246251565e-16
      metalness 0
    }
    geometry USE BOX3
  }
}
DEF VIOLET_CYLINDER Solid {
  translation -0.12 -0.42 0.05
  rotation -0.483581 0.729202 0.484164 1.88263
  children [
    DEF CYLINDER_SHAPE Shape {
      appearance PBRAppearance {
        baseColor 0.495903 0.078584 0.8
        roughness 1
        metalness 0
      }
      geometry Cylinder {
        height 0.1
        radius 0.05
      }
    }
  ]
  boundingObject USE CYLINDER_SHAPE
}
Robot {
  translation 0 -0.15 0
  rotation 0 0 1 1
  children [
    Transform {
      translation 0 0 0.0415
      rotation 0 0 1 -1.570796
      children [
        Shape {
          appearance PBRAppearance {
            baseColor 0.0820075 0.364731 0.8
            roughness 1
            metalness 0
          }
          geometry DEF BODY Cylinder {
            height 0.08
            radius 0.045
          }
        }
      ]
    }
    HingeJoint {
      jointParameters HingeJointParameters {
        axis 0 1 0
        anchor 0 0 0.025
      }
      device [
        RotationalMotor {
          name "left wheel motor"
          consumptionFactor 70
        }
        PositionSensor {
          name "left wheel sensor"
        }
      ]
      endPoint Solid {
        translation 0 0.045 0.025
        rotation 0.134487 -0.134487 -0.981747 1.589217
        children [
          DEF WHEEL Transform {
            rotation 0.577657 0.577197 -0.577197 -2.093935
            children [
              Shape {
                appearance PBRAppearance {
                  baseColor 1 0 0
                  roughness 1
                  metalness 0
                }
                geometry Cylinder {
                  height 0.01
                  radius 0.025
                }
              }
            ]
          }
        ]
        name "left wheel"
        boundingObject USE WHEEL
        physics DEF PHYSICS_WHEEL Physics {
          density -1
          mass 0.05
        }
      }
    }
    HingeJoint {
      jointParameters HingeJointParameters {
        axis 0 1 0
        anchor 0 0 0.025
      }
      device [
        RotationalMotor {
          name "right wheel motor"
          consumptionFactor 70
        }
        PositionSensor {
          name "right wheel sensor"
        }
      ]
      endPoint Solid {
        translation 0 -0.045 0.025
        rotation -0.062357 0.062357 -0.996104 1.5747
        children [
          USE WHEEL
        ]
        name "right wheel"
        boundingObject USE WHEEL
        physics USE PHYSICS_WHEEL
      }
    }
    DistanceSensor {
      translation 0.042 -0.02 0.063
      rotation -0.962638 0.191479 0.191479 -1.608865
      children [
        DEF SENSOR Transform {
          rotation 0.577657 0.577197 -0.577197 -2.093935
          children [
            Shape {
              appearance PBRAppearance {
                baseColor 0.975691 0.981481 0.0252992
                roughness 1
                metalness 0
              }
              geometry Cylinder {
                height 0.004
                radius 0.008
              }
            }
          ]
        }
      ]
      name "ds0"
      lookupTable [
        0 1024 0
        0.02 1024 0.1
        0.08 0 0.3
      ]
      aperture 1
    }
    DistanceSensor {
      translation 0.02 -0.042 0.063
      rotation -0.726831 0.485652 0.485652 -1.884578
      children [
        USE SENSOR
      ]
      name "ds1"
      lookupTable [
        0 1024 0
        0.02 1024 0.1
        0.08 0 0.3
      ]
      aperture 1
    }
    DistanceSensor {
      translation -0.02 -0.042 0.063
      rotation -0.427197 0.639337 0.639337 -2.334132
      children [
        USE SENSOR
      ]
      name "ds2"
      lookupTable [
        0 1024 0
        0.02 1024 0.1
        0.08 0 0.3
      ]
      aperture 1
    }
    DistanceSensor {
      translation -0.042 -0.02 0.063
      rotation -0.139286 0.700214 0.700214 -2.864802
      children [
        USE SENSOR
      ]
      name "ds3"
      lookupTable [
        0 1024 0
        0.02 1024 0.1
        0.08 0 0.3
      ]
      aperture 1
    }
    DistanceSensor {
      translation -0.042 0.02 0.063
      rotation -0.139278 -0.700215 -0.700215 -2.864818
      children [
        USE SENSOR
      ]
      name "ds4"
      lookupTable [
        0 1024 0
        0.02 1024 0.1
        0.08 0 0.3
      ]
      aperture 1
    }
    DistanceSensor {
      translation -0.02 0.042 0.063
      rotation -0.427189 -0.639339 -0.639339 -2.334146
      children [
        USE SENSOR
      ]
      name "ds5"
      lookupTable [
        0 1024 0
        0.02 1024 0.1
        0.08 0 0.3
      ]
      aperture 1
    }
    DistanceSensor {
      translation 0.02 0.042 0.063
      rotation -0.726828 -0.485655 -0.485655 -1.884582
      children [
        USE SENSOR
      ]
      name "ds6"
      lookupTable [
        0 1024 0
        0.02 1024 0.1
        0.08 0 0.3
      ]
      aperture 1
    }
    DistanceSensor {
      translation 0.042 0.02 0.063
      rotation -0.962636 -0.191483 -0.191483 -1.608867
      children [
        USE SENSOR
      ]
      name "ds7"
      lookupTable [
        0 1024 0
        0.02 1024 0.1
        0.08 0 0.3
      ]
      aperture 1
    }
    DEF SMILE Transform {
      translation 0.036 0 0.025
      rotation 0.250563 -0.935113 -0.250563 1.637834
      children [
        Shape {
          appearance PBRAppearance {
            baseColor 0.721569 0.290196 0.290196
            roughness 1
            metalness 0
          }
          geometry Cylinder {
            height 0.018
            radius 0.009
            subdivision 3
          }
        }
      ]
    }
    Transform {
      rotation 0 1 0 3.14
      children [
        USE SMILE
      ]
    }
  ]
  name "MyBot"
  boundingObject Transform {
    translation 0 0 0.0415
    rotation 0 0 1 -1.570796
    children [
      USE BODY
    ]
  }
  physics Physics {
    density -1
    mass 0.5
  }
  controller "distance_sensor"
}
