#VRML_SIM R2023b utf8

EXTERNPROTO "webots://projects/objects/backgrounds/protos/TexturedBackground.proto"
EXTERNPROTO "webots://projects/objects/backgrounds/protos/TexturedBackgroundLight.proto"
EXTERNPROTO "webots://projects/objects/floors/protos/RectangleArena.proto"

WorldInfo {
  info [
    "Example use of a Force TouchSensor device."
  ]
  title "Force Sensor"
  basicTimeStep 8
}
Viewpoint {
  orientation -0.3829053159974165 -0.519984584438691 0.7635440726814927 4.78329869917876
  position -0.44833230046662625 1.148097126572229 1.6498754709732173
}
TexturedBackground {
}
TexturedBackgroundLight {
}
RectangleArena {
}
DEF GREEN_BOX Solid {
  translation 0.25 0.05 0.05
  children [
    Shape {
      appearance PBRAppearance {
        baseColor 0 1 0
        roughness 0.2189099510000001
        metalness 0
      }
      geometry DEF BOX0 Box {
        size 0.1 0.23 0.1
      }
    }
  ]
  name "green box"
  boundingObject Shape {
    appearance PBRAppearance {
      roughness 1.1102230246251565e-16
      metalness 0
    }
    geometry USE BOX0
  }
}
DEF BLUE_BOX Solid {
  translation -0.27 -0.2 0.05
  rotation 0 0 1 0.31
  children [
    Shape {
      appearance PBRAppearance {
        baseColor 0 0 1
        roughness 0.519341125
        metalness 0
      }
      geometry DEF BOX1 Box {
        size 0.1 0.1 0.1
      }
    }
  ]
  name "blue box"
  boundingObject Shape {
    appearance PBRAppearance {
      roughness 1.1102230246251565e-16
      metalness 0
    }
    geometry USE BOX1
  }
}
DEF YELLOW_BOX Solid {
  translation -0.15 0.2 0.05
  rotation 0 0 1 0.4
  children [
    Shape {
      appearance PBRAppearance {
        baseColor 1 1 0
        roughness 0.03934117200000009
        metalness 0
      }
      geometry DEF BOX2 Box {
        size 0.3 0.05 0.1
      }
    }
  ]
  name "yellow box"
  boundingObject Shape {
    appearance PBRAppearance {
      roughness 1.1102230246251565e-16
      metalness 0
    }
    geometry USE BOX2
  }
}
DEF PINK_BOX Solid {
  translation 0.1 -0.42 0.05
  children [
    Shape {
      appearance PBRAppearance {
        baseColor 1 0.1 0.3
        roughness 0.16827074099999995
        metalness 0
      }
      geometry DEF BOX3 Box {
        size 0.08 0.15 0.1
      }
    }
  ]
  name "red box"
  boundingObject Shape {
    appearance PBRAppearance {
      roughness 1.1102230246251565e-16
      metalness 0
    }
    geometry USE BOX3
  }
}
Robot {
  translation 0 -0.15 0
  rotation 0 0 1 1
  children [
    Pose {
      translation 0 0 0.0415
      rotation 0 0 1 -1.570796
      children [
        Shape {
          appearance PBRAppearance {
            baseColor 0.0820075 0.364731 0.8
            roughness 1
            metalness 0
          }
          geometry DEF BODY Cylinder {
            height 0.08
            radius 0.045
          }
        }
      ]
    }
    HingeJoint {
      jointParameters HingeJointParameters {
        axis 0 1 0
        anchor 0 0 0.025
      }
      device [
        RotationalMotor {
          name "left wheel motor"
          consumptionFactor 70
        }
        PositionSensor {
          name "left wheel sensor"
        }
      ]
      endPoint Solid {
        translation 0 0.045 0.025
        rotation 0.13448695438559669 -0.13448695438559669 -0.9817466670176033 1.589217
        children [
          DEF WHEEL Pose {
            rotation 0.577656895078166 0.5771968951617173 -0.5771968951617173 -2.093935
            children [
              Shape {
                appearance PBRAppearance {
                  baseColor 1 0 0
                  roughness 1
                  metalness 0
                }
                geometry Cylinder {
                  height 0.01
                  radius 0.025
                }
              }
            ]
          }
        ]
        name "left wheel"
        boundingObject USE WHEEL
        physics DEF PHYSICS_WHEEL Physics {
          density -1
          mass 0.05
        }
      }
    }
    HingeJoint {
      jointParameters HingeJointParameters {
        axis 0 1 0
        anchor 0 0 0.025
      }
      device [
        RotationalMotor {
          name "right wheel motor"
          consumptionFactor 70
        }
        PositionSensor {
          name "right wheel sensor"
        }
      ]
      endPoint Solid {
        translation 0 -0.045 0.025
        rotation -0.06235700094427207 0.06235700094427207 -0.9961040150840031 1.5747
        children [
          USE WHEEL
        ]
        name "right wheel"
        boundingObject USE WHEEL
        physics USE PHYSICS_WHEEL
      }
    }
    Pose {
      translation 0.0385 -0.02 0.063
      rotation -0.7268278184260777 -0.4856548786751704 -0.4856548786751704 -1.884582
      children [
        DEF UNUSED_EYE Group {
          children [
            Pose {
              translation 1e-05 0 0
              rotation 0 0 1 0.8
              children [
                Shape {
                  appearance PBRAppearance {
                    baseColor 0.975691 0.981481 0.0252992
                    roughness 1
                    metalness 0
                  }
                  geometry Box {
                    size 0.005 0.02 0.005
                  }
                }
              ]
            }
            Pose {
              rotation 0 0 1 -0.8
              children [
                Shape {
                  appearance PBRAppearance {
                    baseColor 0.975691 0.981481 0.0252992
                    roughness 1
                    metalness 0
                  }
                  geometry Box {
                    size 0.005 0.02 0.005
                  }
                }
              ]
            }
          ]
        }
      ]
    }
    Pose {
      translation 0.0385 0.02 0.063
      rotation -0.7268313515069925 0.4856522348690052 0.4856522348690052 -1.884578
      children [
        USE UNUSED_EYE
      ]
    }
    Shape {
      appearance PBRAppearance {
        baseColor 0.8 0.8 0.8
        baseColorMap ImageTexture {
          url [
            "webots://projects/samples/devices/worlds/textures/mybot.png"
          ]
        }
        roughness 0.5
        metalness 0
      }
      geometry IndexedFaceSet {
        coord Coordinate {
          point [
            0.0435 -0.015 0.038
            0.0435 -0.015 0.023
            0.0455 0 0.023
            0.0435 0.015 0.023
            0.0435 0.015 0.038
            0.0455 0 0.038
          ]
        }
        texCoord TextureCoordinate {
          point [
            0 0
            0.5 0
            1 0
            1 1
            0.5 1
            0 1
          ]
        }
        coordIndex [
          0, 1, 2, 5, -1, 5, 2, 3, 4, -1
        ]
        texCoordIndex [
          5, 0, 1, 4, -1, 4, 1, 2, 3, -1
        ]
        creaseAngle 0.9
      }
    }
    TouchSensor {
      translation 0.045 0 0.02
      children [
        Shape {
          appearance PBRAppearance {
            baseColor 1 0.647059 0
            roughness 1
            metalness 0
          }
          geometry DEF BUMPER Box {
            size 0.02 0.09 0.02
          }
        }
      ]
      name "force"
      boundingObject USE BUMPER
      physics Physics {
        density -1
        mass 0.01
      }
      type "force"
      lookupTable [
        0 0 0
        1000 1000 0
      ]
    }
  ]
  name "MyBot"
  boundingObject Pose {
    translation 0 0 0.0415
    children [
      USE BODY
    ]
  }
  physics Physics {
    density -1
    mass 0.5
    centerOfMass [
      0 0 0
    ]
  }
  controller "force_sensor"
}
