#VRML_SIM R2023b utf8

EXTERNPROTO "webots://projects/objects/backgrounds/protos/TexturedBackground.proto"
EXTERNPROTO "webots://projects/objects/backgrounds/protos/TexturedBackgroundLight.proto"
EXTERNPROTO "webots://projects/objects/floors/protos/RectangleArena.proto"

WorldInfo {
  info [
    "Example world for testing/demonstrating the Gyro device."
  ]
  title "Gyro"
  basicTimeStep 8
}
Viewpoint {
  orientation 0.31866933044163714 0.27780002890931904 -0.9062433457818382 1.755665947792053
  position 0.009706541215105216 0.3717658195457598 0.4506359623963661
}
TexturedBackground {
}
TexturedBackgroundLight {
}
RectangleArena {
}
DEF GYROBOT Robot {
  translation 0 0 0.05
  children [
    DEF HINGE_JOINT_X HingeJoint {
      jointParameters HingeJointParameters {
        anchor 0 0 0.1
      }
      device [
        RotationalMotor {
          name "motor_x"
          controlPID 2 0 0
        }
      ]
      endPoint Solid {
        translation 0 0 0.1
        rotation 0 1 0 0
        children [
          DEF HINGE_JOINT_Y_Z Hinge2Joint {
            jointParameters HingeJointParameters {
              axis 0 1 0
            }
            jointParameters2 JointParameters {
            }
            device [
              RotationalMotor {
                name "motor_y"
                controlPID 2 0 0
              }
            ]
            device2 [
              RotationalMotor {
                name "motor_z"
                controlPID 2 0 0
              }
            ]
            endPoint Gyro {
              children [
                DEF RED_CYL Pose {
                  rotation -0.5773488553887604 -0.5773509760887603 0.5773509760887603 2.0943972231
                  children [
                    Shape {
                      appearance PBRAppearance {
                        baseColor 1 0 0
                        roughness 1
                        metalness 0
                      }
                      geometry Cylinder {
                        height 0.01
                        radius 0.04
                        subdivision 20
                      }
                    }
                  ]
                }
                DEF GREEN_CYL Pose {
                  rotation 1 0 0 -1.57079
                  children [
                    Shape {
                      appearance PBRAppearance {
                        baseColor 0 1 0
                        roughness 1
                        metalness 0
                      }
                      geometry Cylinder {
                        height 0.01
                        radius 0.04
                        subdivision 20
                      }
                    }
                  ]
                }
                DEF BLUE_CYL Pose {
                  children [
                    Shape {
                      appearance PBRAppearance {
                        baseColor 0 0 1
                        roughness 1
                        metalness 0
                      }
                      geometry Cylinder {
                        height 0.01
                        radius 0.04
                        subdivision 20
                      }
                    }
                  ]
                }
                DEF BOX Shape {
                  appearance PBRAppearance {
                    baseColor 0.8 0.8 0.8
                    roughness 1
                    metalness 0
                  }
                  geometry DEF BOX Box {
                    size 0.05 0.05 0.05
                  }
                }
              ]
              boundingObject USE BOX
              physics Physics {
              }
            }
          }
        ]
        boundingObject Box {
          size 0.01 0.01 0.01
        }
        physics Physics {
        }
      }
    }
    DEF BASIS Shape {
      appearance PBRAppearance {
        baseColor 0.8 0.8 0.8
        roughness 1
        metalness 0
      }
      geometry Box {
        size 0.2 0.2 0.1
      }
    }
  ]
  name "gyrobot"
  boundingObject USE BASIS
  controller "gyro"
}
