#VRML_SIM R2021c utf8
WorldInfo {
  info [
    "Example world for testing/demonstrating the Gyro device."
  ]
  title "Gyro"
  basicTimeStep 8
}
Viewpoint {
  orientation 0.23567285673898342 0.5925911836478117 -0.7702557975499906 0.8840144040386125
  position -0.18302530547618923 0.15861281453668324 0.3075843978563463
}
TexturedBackground {
}
TexturedBackgroundLight {
}
RectangleArena {
}
DEF GYROBOT Robot {
  translation 0 0 0.05
  children [
    DEF HINGE_JOINT_X HingeJoint {
      jointParameters HingeJointParameters {
        axis 0 1 0
        anchor 0 0 0.1
      }
      device [
        RotationalMotor {
          name "motor_x"
          controlPID 2 0 0
        }
      ]
      endPoint Solid {
        translation 0 0 0.1
        rotation 0 1 0 0
        children [
          DEF HINGE_JOINT_Y_Z Hinge2Joint {
            jointParameters HingeJointParameters {
              axis -1 0 0
            }
            jointParameters2 JointParameters {
            }
            device [
              RotationalMotor {
                name "motor_y"
                controlPID 2 0 0
              }
            ]
            device2 [
              RotationalMotor {
                name "motor_z"
                controlPID 2 0 0
              }
            ]
            endPoint Gyro {
              rotation 8.732169999950783e-07 -3.2417399999817296e-06 0.9999999999943643 1.5707953071795862
              children [
                DEF RED_CYL Transform {
                  rotation -0.5773488553887604 -0.5773509760887603 0.5773509760887603 2.0943972231
                  children [
                    Shape {
                      appearance PBRAppearance {
                        baseColor 1 0 0
                        roughness 1
                        metalness 0
                      }
                      geometry Cylinder {
                        height 0.01
                        radius 0.04
                        subdivision 20
                      }
                    }
                  ]
                }
                DEF GREEN_CYL Transform {
                  rotation 1 0 0 -1.57079
                  children [
                    Shape {
                      appearance PBRAppearance {
                        baseColor 0 1 0
                        roughness 1
                        metalness 0
                      }
                      geometry Cylinder {
                        height 0.01
                        radius 0.04
                        subdivision 20
                      }
                    }
                  ]
                }
                DEF BLUE_CYL Transform {
                  children [
                    Shape {
                      appearance PBRAppearance {
                        baseColor 0 0 1
                        roughness 1
                        metalness 0
                      }
                      geometry Cylinder {
                        height 0.01
                        radius 0.04
                        subdivision 20
                      }
                    }
                  ]
                }
                DEF BOX Shape {
                  appearance PBRAppearance {
                    baseColor 0.8 0.8 0.8
                    roughness 1
                    metalness 0
                  }
                  geometry DEF BOX Box {
                    size 0.05 0.05 0.05
                  }
                }
              ]
              boundingObject USE BOX
              physics Physics {
              }
            }
          }
        ]
        boundingObject Box {
          size 0.01 0.01 0.01
        }
        physics Physics {
        }
      }
    }
    DEF BASIS Shape {
      appearance PBRAppearance {
        baseColor 0.8 0.8 0.8
        roughness 1
        metalness 0
      }
      geometry Box {
        size 0.2 0.2 0.1
      }
    }
  ]
  name "gyrobot"
  boundingObject USE BASIS
  controller "gyro"
}
