#VRML_SIM R2023b utf8

EXTERNPROTO "webots://projects/objects/backgrounds/protos/TexturedBackground.proto"
EXTERNPROTO "webots://projects/objects/backgrounds/protos/TexturedBackgroundLight.proto"
EXTERNPROTO "webots://projects/objects/floors/protos/RectangleArena.proto"
EXTERNPROTO "webots://projects/devices/hokuyo/protos/HokuyoUtm30lx.proto"
EXTERNPROTO "webots://projects/devices/hokuyo/protos/HokuyoUrg04lx.proto"

WorldInfo {
  info [
    "Example use of the Hokuyo devices."
  ]
  title "Hokuyo"
  basicTimeStep 16
  contactProperties [
    ContactProperties {
      material2 "body"
      coulombFriction [
        0
      ]
    }
  ]
}
Viewpoint {
  orientation -0.16684935347099145 0.8430119806280636 0.5113629765282793 0.7385942664010073
  position -0.7284052257752637 -0.18304459867501638 0.6761560768893428
}
TexturedBackground {
}
TexturedBackgroundLight {
}
RectangleArena {
  floorAppearance PBRAppearance {
    baseColorMap ImageTexture {
      url [
        "webots://projects/default/worlds/textures/parquetry.jpg"
      ]
    }
    roughness 1
    metalness 0
  }
  wallHeight 0.30000000000000004
}
DEF GREEN_BOX Solid {
  translation -0.05 0.25 0.1
  rotation 0 0 1 -1.570795
  children [
    Shape {
      appearance PBRAppearance {
        baseColor 0 1 0
        roughness 0.2189099510000001
        metalness 0
      }
      geometry DEF BOX0 Box {
        size 0.1 0.23 0.2
      }
    }
  ]
  name "green box"
  boundingObject Shape {
    appearance PBRAppearance {
      roughness 1.1102230246251565e-16
      metalness 0
    }
    geometry USE BOX0
  }
}
DEF BLUE_BOX Solid {
  translation 0.2 -0.27 0.1
  rotation 0 0 -1 -1.880795
  children [
    Shape {
      appearance PBRAppearance {
        baseColor 0 0 1
        roughness 0.519341125
        metalness 0
      }
      geometry DEF BOX1 Box {
        size 0.1 0.1 0.2
      }
    }
  ]
  name "blue box"
  boundingObject Shape {
    appearance PBRAppearance {
      roughness 1.1102230246251565e-16
      metalness 0
    }
    geometry USE BOX1
  }
}
DEF WHITE_BOX Solid {
  translation -0.2 -0.15 0.1
  rotation 0 0 -1 -1.970795
  children [
    Shape {
      appearance PBRAppearance {
        baseColor 0.74902 0.74902 0.74902
        roughness 0.10196099999999997
        metalness 0
      }
      geometry DEF BOX2 Box {
        size 0.3 0.05 0.2
      }
    }
  ]
  name "gray box"
  boundingObject Shape {
    appearance PBRAppearance {
      roughness 1.1102230246251565e-16
      metalness 0
    }
    geometry USE BOX2
  }
}
DEF PINK_BOX Solid {
  translation 0.42 0.1 0.1
  rotation 0 0 1 -1.570795
  children [
    Shape {
      appearance PBRAppearance {
        baseColor 1 0.1 0.3
        roughness 0.16827074099999995
        metalness 0
      }
      geometry DEF BOX3 Box {
        size 0.08 0.15 0.2
      }
    }
  ]
  name "red box"
  boundingObject Shape {
    appearance PBRAppearance {
      roughness 1.1102230246251565e-16
      metalness 0
    }
    geometry USE BOX3
  }
}
Robot {
  translation 0.15 0 0
  rotation -0.023594990791903275 -0.006321997532799852 0.9997016098600249 2.61814
  children [
    HingeJoint {
      jointParameters HingeJointParameters {
        axis 0 1 0
        anchor 0 0 0.025
      }
      device [
        RotationalMotor {
          name "left wheel motor"
          consumptionFactor 70
        }
        PositionSensor {
          name "left wheel sensor"
        }
      ]
      endPoint Solid {
        translation 0 0.045 0.025
        rotation 0.1344869543855967 -0.1344869543855967 -0.9817466670176034 1.589218
        children [
          DEF WHEEL Pose {
            rotation 0.577656895078166 0.5771968951617173 -0.5771968951617173 -2.093935
            children [
              Shape {
                appearance PBRAppearance {
                  baseColor 1 0 0
                  roughness 1
                  metalness 0
                }
                geometry Cylinder {
                  height 0.01
                  radius 0.025
                }
              }
            ]
          }
        ]
        name "left wheel"
        boundingObject USE WHEEL
        physics DEF PHYSICS_WHEEL Physics {
          density -1
          mass 0.05
        }
      }
    }
    HingeJoint {
      jointParameters HingeJointParameters {
        axis 0 1 0
        anchor 0 0 0.025
      }
      device [
        RotationalMotor {
          name "right wheel motor"
          consumptionFactor 70
        }
        PositionSensor {
          name "right wheel sensor"
        }
      ]
      endPoint Solid {
        translation 0 -0.045 0.025
        rotation -0.06235700094427208 0.06235700094427208 -0.9961040150840033 1.5747
        children [
          USE WHEEL
        ]
        name "right wheel"
        boundingObject USE WHEEL
        physics USE PHYSICS_WHEEL
      }
    }
    Pose {
      translation 0 0 0.0415
      rotation 0 0 1 1.570796
      children [
        Shape {
          appearance PBRAppearance {
            baseColor 0.0820075 0.364731 0.8
            roughness 1
            metalness 0
          }
          geometry DEF BODY Cylinder {
            height 0.08
            radius 0.045
            subdivision 24
          }
        }
      ]
    }
    HokuyoUtm30lx {
      translation 0 0 0.136
      noise 0.01
    }
    HokuyoUrg04lx {
      translation -0.089 0 0.05
      rotation 0 1 0 -1.570805
      noise 0.01
    }
    Pose {
      translation 0.042 0.02 0.063
      rotation 0.940734994155684 0.2398099985101804 0.2398099985101804 1.631852
      children [
        DEF INFRARED Pose {
          rotation 0.577656895078166 0.5771968951617173 -0.5771968951617173 -2.093935
          children [
            Shape {
              appearance PBRAppearance {
                baseColor 0.975691 0.981481 0.0252992
                roughness 1
                metalness 0
              }
              geometry Cylinder {
                height 0.004
                radius 0.008
              }
            }
          ]
        }
      ]
    }
    Pose {
      translation 0.042 -0.02 0.063
      rotation 0.9403743985363968 -0.2405161019321887 -0.2405161019321887 1.632235
      children [
        USE INFRARED
      ]
    }
    DEF SMILE Pose {
      translation 0.036 0 0.025
      rotation 0.25056300542381216 -0.9351130202419243 -0.25056300542381216 1.637834
      children [
        Shape {
          appearance PBRAppearance {
            baseColor 0.721569 0.290196 0.290196
            roughness 1
            metalness 0
          }
          geometry Cylinder {
            height 0.018
            radius 0.009
            subdivision 3
          }
        }
      ]
    }
    Display {
      name "displayA"
      width 256
      height 256
    }
    Display {
      name "displayB"
      width 256
      height 256
    }
  ]
  name "MyBot"
  contactMaterial "body"
  boundingObject Pose {
    translation 0 0 0.0415
    rotation 0 0 1 -1.570796
    children [
      DEF BODY Cylinder {
        height 0.08
        radius 0.045
        subdivision 24
      }
    ]
  }
  physics Physics {
    density -1
    mass 0.5
    centerOfMass [
      0 0 -0.04
    ]
  }
  controller "hokuyo"
}
