#VRML_SIM R2023b utf8

EXTERNPROTO "webots://projects/objects/backgrounds/protos/TexturedBackground.proto"
EXTERNPROTO "webots://projects/objects/backgrounds/protos/TexturedBackgroundLight.proto"
EXTERNPROTO "webots://projects/objects/floors/protos/RectangleArena.proto"

WorldInfo {
  info [
    "Example of \"laser\" DistanceSensors used together with a Camera."
  ]
  title "Laser Pointers"
  basicTimeStep 8
}
Viewpoint {
  orientation -0.2978318379123601 0.007400890661101693 0.954589662181174 2.9637245380012422
  position 1.5296342684385094 -0.3432604029015913 1.1866899225845335
}
TexturedBackground {
}
TexturedBackgroundLight {
}
RectangleArena {
}
DEF GREEN_BOX Solid {
  translation 0.236526 0.069824 0.05
  rotation 0 0 1 0.683463
  children [
    Shape {
      appearance PBRAppearance {
        baseColor 0 1 0
        roughness 0.2189099510000001
        metalness 0
      }
      geometry DEF BOX0 Box {
        size 0.1 0.23 0.1
      }
    }
  ]
  name "green box"
  boundingObject Shape {
    appearance PBRAppearance {
      roughness 1.1102230246251565e-16
      metalness 0
    }
    geometry USE BOX0
  }
}
DEF BLUE_BOX Solid {
  translation -0.171792 -0.144097 0.05
  rotation 0 0 -1 1.60957
  children [
    Shape {
      appearance PBRAppearance {
        baseColor 0 0 1
        roughness 0.519341125
        metalness 0
      }
      geometry DEF BOX1 Box {
        size 0.1 0.1 0.1
      }
    }
  ]
  name "blue box"
  boundingObject Shape {
    appearance PBRAppearance {
      roughness 1.1102230246251565e-16
      metalness 0
    }
    geometry USE BOX1
  }
}
DEF GRAY_BOX Solid {
  translation -0.013507 0.326905 0.05
  rotation 0 0 -1 2.36098
  children [
    Shape {
      appearance PBRAppearance {
        baseColor 0.8 0.8 0.8
        roughness 1
        metalness 0
      }
      geometry DEF BOX2 Box {
        size 0.3 0.05 0.1
      }
    }
  ]
  name "gray box"
  boundingObject Shape {
    appearance PBRAppearance {
      roughness 1.1102230246251565e-16
      metalness 0
    }
    geometry USE BOX2
  }
}
DEF SPHERE Solid {
  translation -0.262077 0.125915 0.05
  rotation 0 0 -1 2.36098
  children [
    Shape {
      appearance PBRAppearance {
        baseColor 0.74902 0.74902 0.74902
        roughness 0.10196099999999997
        metalness 0
      }
      geometry DEF SPHERE Sphere {
        radius 0.1
        subdivision 3
      }
    }
  ]
  name "sphere"
  boundingObject USE SPHERE
}
DEF PINK_BOX Solid {
  translation 0.277033 -0.246966 0.05
  rotation 0 0 -1 0.856706
  children [
    Shape {
      appearance PBRAppearance {
        baseColor 1 0.1 0.3
        roughness 0.16827074099999995
        metalness 0
      }
      geometry DEF BOX3 Box {
        size 0.08 0.15 0.1
      }
    }
  ]
  name "pink box"
  boundingObject Shape {
    appearance PBRAppearance {
      roughness 1.1102230246251565e-16
      metalness 0
    }
    geometry USE BOX3
  }
}
DEF GRAY_CYLINDER Solid {
  translation 0.02009 -0.335524 0.05
  children [
    Shape {
      appearance PBRAppearance {
        baseColor 0.8 0.8 0.8
        roughness 1
        metalness 0
      }
      geometry DEF CYLINDER Cylinder {
        height 0.2
        radius 0.1
        subdivision 20
      }
    }
  ]
  name "gray cylinder"
  boundingObject USE CYLINDER
}
DEF ROBOT Robot {
  children [
    Pose {
      translation 0 0 0.0415
      rotation 0 0 1 -1.570796
      children [
        Shape {
          appearance PBRAppearance {
            baseColor 0.0820075 0.364731 0.8
            roughness 1
            metalness 0
          }
          geometry DEF BODY Cylinder {
            height 0.08
            radius 0.045
          }
        }
      ]
    }
    HingeJoint {
      jointParameters HingeJointParameters {
        axis 0 1 0
        anchor 0 0 0.025
      }
      device [
        RotationalMotor {
          name "left wheel motor"
          consumptionFactor 70
        }
        PositionSensor {
          name "left wheel sensor"
        }
      ]
      endPoint Solid {
        translation 0 0.045 0.025
        rotation 0.1344869543855967 -0.1344869543855967 -0.9817466670176034 1.589217
        children [
          DEF WHEEL Pose {
            rotation 0.577656895078166 0.5771968951617173 -0.5771968951617173 -2.093935
            children [
              Shape {
                appearance PBRAppearance {
                  baseColor 1 0 0
                  roughness 1
                  metalness 0
                }
                geometry Cylinder {
                  height 0.01
                  radius 0.025
                }
              }
            ]
          }
        ]
        name "left wheel"
        boundingObject USE WHEEL
        physics DEF PHYSICS_WHEEL Physics {
          density -1
          mass 0.05
        }
      }
    }
    HingeJoint {
      jointParameters HingeJointParameters {
        axis 0 1 0
        anchor 0 0 0.025
      }
      device [
        RotationalMotor {
          name "right wheel motor"
          consumptionFactor 70
        }
        PositionSensor {
          name "right wheel sensor"
        }
      ]
      endPoint Solid {
        translation 0 -0.045 0.025
        rotation -0.06235700094427208 0.06235700094427208 -0.9961040150840033 1.5747
        children [
          USE WHEEL
        ]
        name "right wheel"
        boundingObject USE WHEEL
        physics USE PHYSICS_WHEEL
      }
    }
    DistanceSensor {
      translation 0.042 0.02 0.063
      children [
        DEF LASER_SENSOR Pose {
          rotation 0.577656895078166 0.5771968951617173 -0.5771968951617173 -2.093935
          children [
            Shape {
              appearance PBRAppearance {
                baseColor 0.975691 0.981481 0.0252992
                roughness 1
                metalness 0
              }
              geometry Cylinder {
                height 0.004
                radius 0.008
              }
            }
          ]
        }
      ]
      name "laser0"
      lookupTable [
        0 0 0
        10 10 0
      ]
      type "laser"
      aperture 0.005
    }
    DistanceSensor {
      translation 0.042 -0.02 0.063
      children [
        USE LASER_SENSOR
      ]
      name "laser1"
      lookupTable [
        0 0 0
        10 10 0
      ]
      type "laser"
      aperture 0.005
    }
    DEF SMILE Pose {
      translation 0.036 0 0.025
      rotation 0.25056300542381216 -0.9351130202419243 -0.25056300542381216 1.637834
      children [
        Shape {
          appearance PBRAppearance {
            baseColor 0.721569 0.290196 0.290196
            roughness 1
            metalness 0
          }
          geometry Cylinder {
            height 0.018
            radius 0.009
            subdivision 3
          }
        }
      ]
    }
    Camera {
      translation 0.05 0 0.0615
      children [
        Pose {
          translation -0.015 0 0
          rotation 0 1 0 -1.570795
          children [
            Shape {
              appearance PBRAppearance {
                roughness 1
                metalness 0
              }
              geometry Cylinder {
                height 0.03
                radius 0.01
              }
            }
          ]
        }
      ]
      fieldOfView 1.047
      width 80
      height 60
      near 0.001
      antiAliasing TRUE
    }
  ]
  name "MyBot"
  boundingObject Pose {
    translation 0 0 0.0415
    rotation 0 0 1 -1.570796
    children [
      USE BODY
    ]
  }
  physics Physics {
    density -1
    mass 0.5
  }
  controller "laser_pointer"
}
