#VRML_SIM R2021c utf8
WorldInfo {
  info [
    "Example use of a LED device."
  ]
  title "LED"
}
Viewpoint {
  orientation -0.2448688771030332 -0.4616380625966467 0.8526016257246489 5.0983227352999485
  position -0.7228105524100202 1.412612959579108 1.210561978654367
}
TexturedBackground {
  texture "dusk"
}
TexturedBackgroundLight {
  texture "dusk"
}
RectangleArena {
}
DEF GREEN_BOX Solid {
  translation -0.05 0.25 0.05
  rotation 1 0 0 1.570796
  children [
    Shape {
      appearance PBRAppearance {
        baseColor 0 1 0
        roughness 0.2189099510000001
        metalness 0
      }
      geometry DEF BOX0 Box {
        size 0.23 0.1 0.1
      }
    }
  ]
  name "green box"
  boundingObject Shape {
    appearance PBRAppearance {
      roughness 1.1102230246251565e-16
      metalness 0
    }
    geometry USE BOX0
  }
}
DEF BLUE_BOX Solid {
  translation 0.2 -0.27 0.05
  rotation 0.976444 0.152573 0.152573 1.594632
  children [
    Shape {
      appearance PBRAppearance {
        baseColor 0 0 1
        roughness 0.519341125
        metalness 0
      }
      geometry DEF BOX1 Box {
        size 0.1 0.1 0.1
      }
    }
  ]
  name "blue box"
  boundingObject Shape {
    appearance PBRAppearance {
      roughness 1.1102230246251565e-16
      metalness 0
    }
    geometry USE BOX1
  }
}
DEF YELLOW_BOX Solid {
  translation -0.2 -0.15 0.05
  rotation 0.96128 0.194861 0.194861 1.610276
  children [
    Shape {
      appearance PBRAppearance {
        baseColor 1 1 0
        roughness 0.03934117200000009
        metalness 0
      }
      geometry DEF BOX2 Box {
        size 0.05 0.1 0.3
      }
    }
  ]
  name "yellow box"
  boundingObject Shape {
    appearance PBRAppearance {
      roughness 1.1102230246251565e-16
      metalness 0
    }
    geometry USE BOX2
  }
}
DEF PINK_BOX Solid {
  translation 0.413794 0.106373 0.05
  rotation 1 0 0 1.570796
  children [
    Shape {
      appearance PBRAppearance {
        baseColor 1 0.1 0.3
        roughness 0.16827074099999995
        metalness 0
      }
      geometry DEF BOX3 Box {
        size 0.15 0.1 0.08
      }
    }
  ]
  name "red box"
  boundingObject Shape {
    appearance PBRAppearance {
      roughness 1.1102230246251565e-16
      metalness 0
    }
    geometry USE BOX3
  }
}
Robot {
  translation 0 -0.15 0
  rotation 0.923642 -0.271004 -0.271004 1.650144
  children [
    Transform {
      translation 0 0 0.0415
      rotation 0 0 1 -1.570796
      children [
        Shape {
          appearance PBRAppearance {
            baseColor 0.0820075 0.364731 0.8
            roughness 1
            metalness 0
          }
          geometry DEF BODY Cylinder {
            height 0.08
            radius 0.045
          }
        }
      ]
    }
    HingeJoint {
      jointParameters HingeJointParameters {
        axis 0 1 0
        anchor 0 0 0.025
      }
      device [
        RotationalMotor {
          name "left wheel motor"
          consumptionFactor 70
        }
        PositionSensor {
          name "left wheel sensor"
        }
      ]
      endPoint Solid {
        translation 0 0.045 0.025
        rotation -0.134487 0.134487 0.981747 -1.589217
        children [
          DEF WHEEL Transform {
            rotation 0.577657 0.577197 -0.577197 -2.093935
            children [
              Shape {
                appearance PBRAppearance {
                  baseColor 1 0 0
                  roughness 1
                  metalness 0
                }
                geometry Cylinder {
                  height 0.01
                  radius 0.025
                }
              }
            ]
          }
        ]
        name "left wheel"
        boundingObject USE WHEEL
        physics DEF PHYSICS_WHEEL Physics {
          density -1
          mass 0.05
        }
      }
    }
    HingeJoint {
      jointParameters HingeJointParameters {
        axis 0 1 0
        anchor 0 0 0.025
      }
      device [
        RotationalMotor {
          name "right wheel motor"
          consumptionFactor 70
        }
        PositionSensor {
          name "right wheel sensor"
        }
      ]
      endPoint Solid {
        translation 0 -0.045 0.025
        rotation 0.062357 -0.062357 0.996104 -1.5747
        children [
          USE WHEEL
        ]
        name "right wheel"
        boundingObject USE WHEEL
        physics USE PHYSICS_WHEEL
      }
    }
    DistanceSensor {
      translation 0.042 0.02 0.063
      rotation 0.940735 0.23981 0.23981 1.631852
      children [
        DEF SENSOR Transform {
          rotation 0.577657 0.577197 -0.577197 -2.093935
          children [
            Shape {
              appearance PBRAppearance {
                baseColor 0.975691 0.981481 0.0252992
                roughness 1
                metalness 0
              }
              geometry Cylinder {
                height 0.004
                radius 0.008
              }
            }
          ]
        }
      ]
      name "ds0"
      lookupTable [
        0 1024 0
        0.05 1024 0
        0.15 0 0
      ]
      numberOfRays 2
      aperture 1
    }
    DistanceSensor {
      translation 0.042 -0.02 0.063
      rotation 0.940374 -0.240516 -0.240516 1.632235
      children [
        USE SENSOR
      ]
      name "ds1"
      lookupTable [
        0 1024 0
        0.05 1024 0
        0.15 0 0
      ]
      numberOfRays 2
      aperture 1
    }
    DEF SMILE Transform {
      translation 0.036 0 0.025
      rotation 0.250563 -0.935113 -0.250563 1.637834
      children [
        Shape {
          appearance PBRAppearance {
            baseColor 0.721569 0.290196 0.290196
            roughness 1
            metalness 0
          }
          geometry Cylinder {
            height 0.018
            radius 0.009
            subdivision 3
          }
        }
      ]
    }
    LED {
      translation 0 -0.015 0.08
      rotation 0.57735 -0.57735 -0.57735 2.094395
      children [
        Group {
          children [
            Shape {
              appearance PBRAppearance {
                baseColor 0.74902 0.74902 0.74902
                roughness 1
                metalness 0
              }
              geometry DEF LED_SHAPE Sphere {
                radius 0.01
              }
            }
            PointLight {
              attenuation 0 0 1
              color 0 0 0
              intensity 0.5
              location 0 0 0.03
              on FALSE
              castShadows TRUE
            }
          ]
        }
      ]
      name "led0"
      color [
        1 0 0
        0 1 0
        0 0 1
        1 1 0
        0 1 1
        1 0 1
        1 0.647059 0
        0.627451 0.12549 0.941176
        0.545098 0.411765 0.0784314
      ]
    }
    LED {
      translation 0 0.015 0.08
      rotation 0.57735 -0.57735 -0.57735 2.094395
      children [
        Group {
          children [
            Shape {
              appearance PBRAppearance {
                baseColor 0.74902 0.74902 0.74902
                roughness 1
                metalness 0
              }
              geometry USE LED_SHAPE
            }
            PointLight {
              attenuation 0 0 1
              color 0 0 0
              intensity 0.5
              location 0 0 0.03
              on FALSE
              castShadows TRUE
            }
          ]
        }
      ]
      name "led1"
      gradual TRUE
    }
    LED {
      translation -0.02 0 0.08
      rotation 0.57735 -0.57735 -0.57735 2.094395
      children [
        Group {
          children [
            Shape {
              appearance PBRAppearance {
                baseColor 0.74902 0.74902 0.74902
                roughness 1
                metalness 0
              }
              geometry USE LED_SHAPE
            }
            PointLight {
              attenuation 0 0 1
              color 0 0 0
              intensity 0.5
              location 0 0 0.03
              on FALSE
              castShadows TRUE
            }
          ]
        }
      ]
      name "led2"
      color []
      gradual TRUE
    }
  ]
  name "MyBot"
  boundingObject Transform {
    translation 0 0 0.0415
    rotation 0 0 1 -1.570796
    children [
      USE BODY
    ]
  }
  physics Physics {
    density -1
    mass 0.5
  }
  controller "led"
}
