#VRML_SIM R2020b utf8
WorldInfo {
  info [
    "Example use of a rotating Lidar in point-cloud mode."
  ]
  title "Lidar Point-Cloud"
  basicTimeStep 8
  coordinateSystem "NUE"
  lineScale 0.15
}
Viewpoint {
  orientation 0.7237188841159703 0.6614618940847455 0.19672096850045087 5.15422
  position -8.46697 12.5762 7.85831
  follow "MyBot"
}
TexturedBackground {
}
TexturedBackgroundLight {
}
RectangleArena {
  floorSize 10 10
  wallThickness 0.5
  wallHeight 1.4
}
DEF GREEN_OBJECT1 Solid {
  translation -1.15115 0.2 -3.04661
  rotation 0 1 0 3.13621
  children [
    DEF BOX_SHAPE Shape {
      appearance PBRAppearance {
        baseColor 0 1 0
        roughness 0.2189099510000001
        metalness 0
      }
      geometry Box {
        size 0.8 0.4 0.4
      }
    }
  ]
  name "green object 1"
  boundingObject USE BOX_SHAPE
}
DEF GREEN_OBJECT2 Solid {
  translation -0.500815 0.56 -3.05763
  rotation 0 1 0 3.13621
  children [
    USE BOX_SHAPE
  ]
  name "green object 2"
  boundingObject USE BOX_SHAPE
}
DEF GREEN_OBJECT3 Solid {
  translation 0.201689 0.2 -3.04806
  rotation 0 1 0 3.13621
  children [
    USE BOX_SHAPE
  ]
  name "green object 3"
  boundingObject USE BOX_SHAPE
}
DEF GREEN_OBJECT4 Solid {
  translation 2.90426 0.3 -3.07656
  rotation 0 1 0 3.13621
  scale 1.6009 1.6009 1.6009
  children [
    USE BOX_SHAPE
  ]
  name "green object 4"
  boundingObject USE BOX_SHAPE
}
DEF GREEN_OBJECT5 Solid {
  translation 1.5167 0.3 2.72018
  rotation 0 1 0 3.65981
  scale 1.80916 1.80916 1.80916
  children [
    USE BOX_SHAPE
  ]
  name "green object 5"
  boundingObject USE BOX_SHAPE
}
DEF BLUE_OBJECT1 Solid {
  translation -3.52129 0.37 -1.70691
  rotation 0 1 0 0.31
  scale 1.63795 1.63795 1.63795
  children [
    DEF SPHERE_SHAPE Shape {
      appearance PBRAppearance {
        baseColor 0 0 1
        roughness 0.519341125
        metalness 0
      }
      geometry Sphere {
        radius 0.35
        subdivision 2
      }
    }
  ]
  name "blue object 1"
  boundingObject USE SPHERE_SHAPE
}
DEF BLUE_OBJECT2 Solid {
  translation 1.24157 0.27 -1.19355
  rotation 0 1 0 0.31
  scale 1.66973 1.66973 1.66973
  children [
    USE SPHERE_SHAPE
  ]
  name "blue object 2"
  boundingObject USE SPHERE_SHAPE
}
DEF BLUE_OBJECT3 Solid {
  translation -1.52701 0.27 2.81239
  rotation 0.8560859204349502 -0.49922295360197116 -0.1337659875677228 5.67652
  scale 1.64056 1.64056 1.64056
  children [
    USE SPHERE_SHAPE
  ]
  name "blue object 3"
  boundingObject USE SPHERE_SHAPE
}
DEF PINK_OBJECT1 Solid {
  translation -1.59552 0.55 -1.88475
  scale 1.46599 1.46599 1.46599
  children [
    DEF CYLINDER_SHAPE Shape {
      appearance PBRAppearance {
        baseColor 1 0.1 0.3
        roughness 0.16827074099999995
        metalness 0
      }
      geometry Cylinder {
        height 0.8
        radius 0.3
        subdivision 20
      }
    }
  ]
  name "pink object 1"
  boundingObject USE CYLINDER_SHAPE
}
DEF PINK_OBJECT2 Solid {
  translation -3.12471 0.47 0.367641
  scale 1.34833 1.34833 1.34833
  children [
    USE CYLINDER_SHAPE
  ]
  name "pink object 2"
  boundingObject USE CYLINDER_SHAPE
}
DEF PINK_OBJECT3 Solid {
  translation 2.51755 0.54 0.58295
  scale 1.51649 1.51649 1.51649
  children [
    USE CYLINDER_SHAPE
  ]
  name "pink object 3"
  boundingObject USE CYLINDER_SHAPE
}
DEF ROBOT Robot {
  children [
    Transform {
      translation 0 0.1245 0
      children [
        Shape {
          appearance PBRAppearance {
            baseColor 0.74902 0.74902 0.74902
            roughness 1
            metalness 0
          }
          geometry DEF BODY Cylinder {
            height 0.24
            radius 0.135
          }
        }
      ]
    }
    HingeJoint {
      jointParameters HingeJointParameters {
        axis -1 0 0
        anchor 0 0.075 0
      }
      device [
        RotationalMotor {
          name "left wheel motor"
          consumptionFactor 70
          maxVelocity 100
        }
        PositionSensor {
          name "left wheel sensor"
        }
      ]
      endPoint Solid {
        translation -0.135 0.075 0
        rotation 1 0 0 4.98467
        children [
          DEF WHEEL Transform {
            rotation 0 0 1 1.57
            children [
              Shape {
                appearance PBRAppearance {
                  baseColor 0.301961 0.301961 0.301961
                  roughness 1
                  metalness 0
                }
                geometry Cylinder {
                  height 0.03
                  radius 0.075
                }
              }
            ]
          }
        ]
        name "left wheel"
        boundingObject USE WHEEL
        physics DEF PHYSICS_WHEEL Physics {
          density -1
          mass 0.05
        }
      }
    }
    HingeJoint {
      jointParameters HingeJointParameters {
        axis -1 0 0
        anchor 0 0.075 0
      }
      device [
        RotationalMotor {
          name "right wheel motor"
          consumptionFactor 70
          maxVelocity 100
        }
        PositionSensor {
          name "right wheel sensor"
        }
      ]
      endPoint Solid {
        translation 0.135 0.075 0
        rotation 1 0 0 4.58735
        children [
          USE WHEEL
        ]
        name "right wheel"
        boundingObject USE WHEEL
        physics USE PHYSICS_WHEEL
      }
    }
    DEF US0 DistanceSensor {
      translation -0.07 0.189 -0.115
      rotation 0 1 0 2.07
      children [
        DEF SONAR_SENSOR Transform {
          rotation 0 0 1 1.57
          children [
            Shape {
              appearance PBRAppearance {
                baseColor 0.301961 0.301961 0.301961
                roughness 1
                metalness 0
              }
              geometry Cylinder {
                height 0.01
                radius 0.024
              }
            }
          ]
        }
      ]
      name "us0"
      lookupTable [
        0 0.7 0.01
        2 0 0
      ]
      type "sonar"
      numberOfRays 20
    }
    DEF US1 DistanceSensor {
      translation 0.07 0.189 -0.115
      rotation 0 1 0 1.07
      children [
        USE SONAR_SENSOR
      ]
      name "us1"
      lookupTable [
        0 0.7 0.1
        2 0 0
      ]
      type "sonar"
      numberOfRays 20
    }
    DEF LIDAR Lidar {
      translation 0 0.45 0
      children [
        Transform {
          translation 0 -0.01 0
          rotation 1 0 0 -1.5708
          scale 6 5 3
          children [
            DEF STRUCTURE_AXES Shape {
              appearance Appearance {
                material Material {
                  diffuseColor 0.02 0.02 0.02
                }
              }
              geometry IndexedLineSet {
                coord Coordinate {
                  point [
                    0 0 0.01
                    0.01 0 -0.08
                    -0.01 0 -0.08
                    0 0.01 -0.08
                    0 -0.01 -0.08
                  ]
                }
                coordIndex [
                  0, 1, 0, 2, 0, 3, 0, 4
                ]
              }
            }
          ]
        }
      ]
      tiltAngle -0.1
      horizontalResolution 256
      fieldOfView 1.57
      numberOfLayers 6
      near 0.05
      minRange 0.05
      maxRange 8
      type "rotating"
      noise 0.1
      defaultFrequency 2
      rotatingHead Solid {
        children [
          Transform {
            translation 0 0 -0.03
            children [
              DEF LENS Shape {
                appearance PBRAppearance {
                  baseColor 0 0 0
                  roughness 1.1102230246251565e-16
                  metalness 0
                }
                geometry Sphere {
                  radius 0.015
                  subdivision 2
                }
              }
            ]
          }
          DEF CAMERA_SHAPE Transform {
            rotation 1 0 0 1.57
            children [
              DEF CAMERA_OUTLINE Shape {
                appearance PBRAppearance {
                  baseColor 0.898039 0.898039 0.898039
                  roughness 1
                  metalness 0
                }
                geometry Cylinder {
                  height 0.06
                  radius 0.024
                }
              }
            ]
          }
        ]
      }
    }
  ]
  name "MyBot"
  boundingObject Transform {
    translation 0 0.1245 0
    children [
      USE BODY
    ]
  }
  physics Physics {
    density -1
    mass 1.5
    centerOfMass [
      0 0.15 0
    ]
  }
  controller "lidar"
}
