#VRML_SIM R2023b utf8

EXTERNPROTO "webots://projects/objects/backgrounds/protos/TexturedBackground.proto"
EXTERNPROTO "webots://projects/objects/floors/protos/RectangleArena.proto"
EXTERNPROTO "webots://projects/objects/backgrounds/protos/TexturedBackgroundLight.proto"

WorldInfo {
  info [
    "Example use of a LightSensor device."
  ]
  title "Light Sensor"
  basicTimeStep 8
}
Viewpoint {
  orientation -0.38636154264624156 -0.00305209646263084 0.9223423676006645 3.1502780411636526
  position 1.6703492644126905 0.04330207281002885 1.6690729873260608
}
TexturedBackground {
}
RectangleArena {
}
DEF LAMP Solid {
  translation 0 -0.1 0.095
  rotation 0 0 1 -1.570795
  children [
    Shape {
      appearance PBRAppearance {
        baseColor 0.8 0.8 0.8
        roughness 1
        metalness 0
        emissiveColor 1 1 1
      }
      geometry Sphere {
        radius 0.01
      }
    }
    PointLight {
      attenuation 0 0 5
    }
  ]
}
DEF ROBOT Robot {
  translation -0.3955 0.3636 0
  rotation 0 0 1 -1.6199353071795866
  children [
    Pose {
      translation 0 0 0.0415
      rotation 0 0 1 1.570796
      children [
        Shape {
          appearance PBRAppearance {
            baseColor 0.0820075 0.364731 0.8
            roughness 1
            metalness 0
          }
          geometry DEF BODY Cylinder {
            height 0.08
            radius 0.045
          }
        }
      ]
    }
    HingeJoint {
      jointParameters HingeJointParameters {
        axis 0 1 0
        anchor 0 0 0.025
      }
      device [
        RotationalMotor {
          name "left wheel motor"
          consumptionFactor 70
        }
        PositionSensor {
          name "left wheel sensor"
        }
      ]
      endPoint Solid {
        translation 0 0.045 0.025
        rotation 0.13448695438559669 -0.13448695438559669 -0.9817466670176032 1.589218
        children [
          DEF WHEEL Pose {
            rotation 0.577656895078166 0.5771968951617173 -0.5771968951617173 -2.093935
            children [
              Shape {
                appearance PBRAppearance {
                  baseColor 1 0 0
                  roughness 1
                  metalness 0
                }
                geometry Cylinder {
                  height 0.01
                  radius 0.025
                }
              }
            ]
          }
        ]
        name "left wheel"
        boundingObject USE WHEEL
        physics DEF PHYSICS_WHEEL Physics {
          density -1
          mass 0.05
        }
      }
    }
    HingeJoint {
      jointParameters HingeJointParameters {
        axis 0 1 0
        anchor 0 0 0.025
      }
      device [
        RotationalMotor {
          name "right wheel motor"
          consumptionFactor 70
        }
        PositionSensor {
          name "right wheel sensor"
        }
      ]
      endPoint Solid {
        translation 0 -0.045 0.025
        rotation -0.06235700094427207 0.06235700094427207 -0.9961040150840031 1.5747
        children [
          USE WHEEL
        ]
        name "right wheel"
        boundingObject USE WHEEL
        physics USE PHYSICS_WHEEL
      }
    }
    Pose {
      translation 0.0385 -0.02 0.063
      rotation -0.726828171413359 -0.4856551145357015 -0.48565411453546564 -1.884582
      children [
        DEF UNUSED_EYE Group {
          children [
            Pose {
              translation 0 0 1e-05
              rotation 0 0 1 0.8
              children [
                Shape {
                  appearance PBRAppearance {
                    baseColor 0.975691 0.981481 0.0252992
                    roughness 1
                    metalness 0
                  }
                  geometry Box {
                    size 0.02 0.005 0.005
                  }
                }
              ]
            }
            Pose {
              rotation 0 0 1 -0.8
              children [
                Shape {
                  appearance PBRAppearance {
                    baseColor 0.975691 0.981481 0.0252992
                    roughness 1
                    metalness 0
                  }
                  geometry Box {
                    size 0.02 0.005 0.005
                  }
                }
              ]
            }
          ]
        }
      ]
    }
    Pose {
      translation 0.0385 0.02 0.063
      rotation -0.7268306455324123 0.4856527631523045 0.4856527631523045 -1.884578
      children [
        USE UNUSED_EYE
      ]
    }
    LightSensor {
      translation 0.042 0.02 0.07
      rotation 0 0 -1 -0.499205
      name "ls0"
      lookupTable [
        0 0 0
        4 1024 0
      ]
    }
    LightSensor {
      translation 0.042 -0.02 0.07
      rotation 0 0 1 -0.500795
      name "ls1"
      lookupTable [
        0 0 0
        4 1024 0
      ]
    }
    DEF SMILE Pose {
      translation 0.036 0 0.025
      rotation 0.25056300542381216 -0.9351130202419243 -0.25056300542381216 1.637834
      children [
        Shape {
          appearance PBRAppearance {
            baseColor 0.721569 0.290196 0.290196
            roughness 1
            metalness 0
          }
          geometry Cylinder {
            height 0.018
            radius 0.009
            subdivision 3
          }
        }
      ]
    }
  ]
  name "MyBot"
  boundingObject Pose {
    translation 0 0 0.0415
    rotation 0 0 1 1.570796
    children [
      USE BODY
    ]
  }
  physics Physics {
    density -1
    mass 0.5
  }
  controller "light_sensor"
}
TexturedBackgroundLight {
}
