#VRML_SIM R2021c utf8
WorldInfo {
  info [
    "Example world demonstrating the use of a controlled BallJoint."
  ]
  title "Motor 3"
  lineScale 0.3
}
Viewpoint {
  orientation -0.35730876951780977 -0.33897606175913836 0.8703020583567143 4.346516511988484
  position 0.10821044296103861 0.399664809576071 0.46098275588899734
}
TexturedBackground {
}
TexturedBackgroundLight {
}
RectangleArena {
  floorAppearance ThreadMetalPlate {
    textureTransform TextureTransform {
      scale 2 2
    }
  }
}
Robot {
  children [
    SolidRoundedBox {
      size 0.2 0.2 0.01
      borderRadius 0.005
      appearance GalvanizedMetal {
      }
    }
    SolidTorus {
      majorRadius 0.03
      minorRadius 0.02
      appearance BrushedAluminium {
      }
    }
    CapScrew {
      translation 0.08 0.08 0.005
      rotation -0.57735 -0.57735 0.57735 -2.094395
    }
    CapScrew {
      translation 0.08 -0.08 0.005
      rotation -0.57735 -0.57735 0.57735 -2.094395
      name "cap screw(1)"
    }
    CapScrew {
      translation -0.08 -0.08 0.005
      rotation -0.57735 -0.57735 0.57735 -2.094395
      name "cap screw(2)"
    }
    CapScrew {
      translation -0.08 0.08 0.005
      rotation -0.57735 -0.57735 0.57735 -2.094395
      name "cap screw(4)"
    }
    Solid {
      translation 0 0 0.06
      rotation 0 0 1 -1.570805
      children [
        Shape {
          appearance BrushedAluminium {
            textureTransform TextureTransform {
              rotation 1.5708
            }
          }
          geometry DEF CYLINDER Cylinder {
            height 0.1
            radius 0.02
          }
        }
        BallJoint {
          jointParameters BallJointParameters {
            axis 0 -1 0
            anchor 0 0 0.05
          }
          device [
            RotationalMotor {
              name "motor 1"
              maxVelocity 1
            }
          ]
          device2 [
            RotationalMotor {
              name "motor 2"
              maxVelocity 1
              minPosition -1.5707963267948966
              maxPosition 1.5707963267948966
            }
          ]
          device3 [
            RotationalMotor {
              name "motor 3"
              maxVelocity 1
            }
          ]
          endPoint Solid {
            translation 0 0 0.05
            children [
              Shape {
                appearance BrushedAluminium {
                }
                geometry DEF SPHERE Sphere {
                  radius 0.03
                  subdivision 32
                  ico FALSE
                }
              }
              Solid {
                translation 0 0 0.067
                rotation 0 0 1 -1.570805
                children [
                  Shape {
                    appearance HammeredCopper {
                      textureTransform TextureTransform {
                        scale 0.2 1
                      }
                    }
                    geometry DEF BOX Box {
                      size 0.02 0.02 0.1
                    }
                  }
                ]
                boundingObject USE BOX
                physics Physics {
                }
              }
            ]
            boundingObject USE SPHERE
            physics Physics {
            }
          }
        }
      ]
      boundingObject USE CYLINDER
      physics Physics {
      }
    }
  ]
  controller "motor3"
}
