#VRML_SIM R2023b utf8

EXTERNPROTO "webots://projects/objects/backgrounds/protos/TexturedBackground.proto"
EXTERNPROTO "webots://projects/objects/backgrounds/protos/TexturedBackgroundLight.proto"
EXTERNPROTO "webots://projects/objects/floors/protos/RectangleArena.proto"
EXTERNPROTO "webots://projects/appearances/protos/ThreadMetalPlate.proto"
EXTERNPROTO "webots://projects/objects/solids/protos/SolidRoundedBox.proto"
EXTERNPROTO "webots://projects/appearances/protos/GalvanizedMetal.proto"
EXTERNPROTO "webots://projects/objects/solids/protos/SolidTorus.proto"
EXTERNPROTO "webots://projects/appearances/protos/BrushedAluminium.proto"
EXTERNPROTO "webots://projects/objects/factory/tools/protos/CapScrew.proto"
EXTERNPROTO "webots://projects/appearances/protos/HammeredCopper.proto"

WorldInfo {
  info [
    "Example world demonstrating the use of a controlled BallJoint."
  ]
  title "Motor 3"
  lineScale 0.3
}
Viewpoint {
  orientation -0.27021832244357913 -0.21661337078774587 0.9381155077130686 4.201359629380958
  position 0.18875508850382353 0.4626511721342722 0.45953678868227127
}
TexturedBackground {
}
TexturedBackgroundLight {
}
RectangleArena {
  floorAppearance ThreadMetalPlate {
    textureTransform TextureTransform {
      scale 2 2
    }
  }
}
Robot {
  children [
    SolidRoundedBox {
      translation 0 0 0
      size 0.2 0.2 0.01
      borderRadius 0.005
      appearance GalvanizedMetal {
      }
    }
    SolidTorus {
      translation 0 0 0
      majorRadius 0.03
      minorRadius 0.02
      appearance BrushedAluminium {
      }
    }
    CapScrew {
      translation 0.08 0.08 0.005
      rotation -0.5773502691896258 -0.5773502691896258 0.5773502691896258 -2.094395
    }
    CapScrew {
      translation 0.08 -0.08 0.005
      rotation -0.5773502691896258 -0.5773502691896258 0.5773502691896258 -2.094395
      name "cap screw(1)"
    }
    CapScrew {
      translation -0.08 -0.08 0.005
      rotation -0.5773502691896258 -0.5773502691896258 0.5773502691896258 -2.094395
      name "cap screw(2)"
    }
    CapScrew {
      translation -0.08 0.08 0.005
      rotation -0.5773502691896258 -0.5773502691896258 0.5773502691896258 -2.094395
      name "cap screw(4)"
    }
    Solid {
      translation 0 0 0.06
      rotation 0 0 1 -1.570805
      children [
        Shape {
          appearance BrushedAluminium {
            textureTransform TextureTransform {
              rotation 1.5708
            }
          }
          geometry DEF CYLINDER Cylinder {
            height 0.1
            radius 0.02
          }
        }
        BallJoint {
          jointParameters BallJointParameters {
            anchor 0 0 0.05
          }
          device [
            RotationalMotor {
              name "motor 3"
              maxVelocity 1
            }
          ]
          device2 [
            RotationalMotor {
              name "motor 1"
              maxVelocity 1
              minPosition -1.5707963267948966
              maxPosition 1.5707963267948966
            }
          ]
          device3 [
            RotationalMotor {
              name "motor 2"
              maxVelocity 1
              minPosition -1.5707963267948966
              maxPosition 1.5707963267948966
            }
          ]
          endPoint Solid {
            translation 0 0 0.05
            children [
              Shape {
                appearance BrushedAluminium {
                }
                geometry DEF SPHERE Sphere {
                  radius 0.03
                  subdivision 32
                  ico FALSE
                }
              }
              Solid {
                translation 0 0 0.067
                rotation 0 0 1 -1.570805
                children [
                  Shape {
                    appearance HammeredCopper {
                      textureTransform TextureTransform {
                        scale 0.2 1
                      }
                    }
                    geometry DEF BOX Box {
                      size 0.02 0.02 0.1
                    }
                  }
                ]
                boundingObject USE BOX
                physics Physics {
                }
              }
            ]
            boundingObject USE SPHERE
            physics Physics {
            }
          }
        }
      ]
      boundingObject USE CYLINDER
      physics Physics {
      }
    }
  ]
  controller "motor3"
}
