#VRML_SIM R2020a utf8
WorldInfo {
  info [
    "Example world demonstrating the use of a simple Motor device."
  ]
  title "Motor"
  basicTimeStep 4
}
Viewpoint {
  orientation 0.12721312999228063 -0.9897589099399406 -0.06476202399607019 5.2504127
  position 0.20910846 0.11100923 0.083845121
}
TexturedBackground {
}
TexturedBackgroundLight {
}
RectangleArena {
}
DEF ROBOT Robot {
  children [
    HingeJoint {
      jointParameters HingeJointParameters {
        position 1.5708
        axis 0 1 0
        dampingConstant 1
      }
      device [
        RotationalMotor {
          name "motor"
          consumptionFactor 100
          maxVelocity 2
          maxTorque 20
        }
      ]
      endPoint Solid {
        rotation 0 1 0 1.5708
        children [
          DEF AXIS Group {
            children [
              Transform {
                translation 0 0.063 0
                children [
                  Shape {
                    appearance DEF METAL_APPEARANCE PBRAppearance {
                      baseColor 0.5 0.5 0.5
                      roughness 1
                      metalness 0
                    }
                    geometry Cylinder {
                      bottom FALSE
                      height 0.005
                      radius 0.04
                    }
                  }
                ]
              }
              Transform {
                translation 0 0.063 0
                children [
                  Shape {
                    appearance DEF METAL_APPEARANCE PBRAppearance {
                      baseColor 0.666667 0.666667 0.498039
                      roughness 1
                      metalness 0
                    }
                    geometry Cylinder {
                      bottom FALSE
                      height 0.008
                      radius 0.03
                      subdivision 6
                    }
                  }
                ]
              }
              Transform {
                translation 0 0.063 0.05
                rotation 1 0 0 1.5708
                children [
                  Shape {
                    appearance PBRAppearance {
                      baseColor 1 0.333333 0.498039
                      roughness 1
                      metalness 0
                    }
                    geometry Cylinder {
                      bottom FALSE
                      height 0.02
                      radius 0.001
                    }
                  }
                ]
              }
            ]
          }
        ]
        boundingObject USE AXIS
        physics Physics {
          density -1
          mass 1
        }
      }
    }
    DEF BASIS_GROUP Group {
      children [
        Transform {
          translation 0 0.02 0
          children [
            Shape {
              appearance USE METAL_APPEARANCE
              geometry Cylinder {
                bottom FALSE
                height 0.04
                radius 0.1
              }
            }
          ]
        }
        Transform {
          translation 0 0.04 0
          children [
            Shape {
              appearance PBRAppearance {
                baseColorMap ImageTexture {
                  url [
                    "textures/compass.jpg"
                  ]
                }
                roughness 1
                metalness 0
                textureTransform TextureTransform {
                  rotation 1.5708
                }
              }
              geometry Cylinder {
                bottom FALSE
                height 0.04
                radius 0.07
                side FALSE
              }
            }
          ]
        }
        Transform {
          translation 0 0.04 0
          children [
            Shape {
              appearance PBRAppearance {
                baseColor 1 0.866667 0
                roughness 1
                metalness 0
              }
              geometry Cylinder {
                bottom FALSE
                height 0.04
                radius 0.07
                top FALSE
              }
            }
          ]
        }
      ]
    }
  ]
  boundingObject USE BASIS_GROUP
  physics Physics {
    density -1
    mass 8
  }
  controller "motor"
  battery [
    3600, 36000, 5
  ]
  cpuConsumption 5
}
SolidBox {
  translation 0.04741181 0.0655 -0.019659258
  rotation 0 1 0 0.26179939
  size 0.01 0.01 0.01
  appearance PBRAppearance {
    baseColorMap ImageTexture {
      url [
        "textures/wood.jpg"
      ]
    }
    roughness 1
    metalness 0
  }
  physics Physics {
    density -1
    mass 10
  }
}
