#VRML_SIM R2021b utf8
WorldInfo {
  info [
    "Example use of a Pen device using evaporating ink."
  ]
  title "Pen"
  inkEvaporation 0.1
  coordinateSystem "NUE"
}
Viewpoint {
  orientation 0.9991023978354155 0.04067681619721673 -0.011823504708034852 5.48134
  position -0.0657712 1.12817 1.19341
}
TexturedBackground {
}
TexturedBackgroundLight {
}
RectangleArena {
  floorTileSize 1 1
}
DEF GREEN_BOX Solid {
  translation -0.05 0.05 -0.25
  children [
    Shape {
      appearance PBRAppearance {
        baseColor 0 1 0
        roughness 0.2189099510000001
        metalness 0
      }
      geometry DEF BOX0 Box {
        size 0.23 0.1 0.1
      }
    }
  ]
  name "green box"
  boundingObject Shape {
    appearance PBRAppearance {
      roughness 1.1102230246251565e-16
      metalness 0
    }
    geometry USE BOX0
  }
}
DEF BLUE_BOX Solid {
  translation 0.2 0.05 0.27
  rotation 0 1 0 0.31
  children [
    Shape {
      appearance PBRAppearance {
        baseColor 0 0 1
        roughness 0.519341125
        metalness 0
      }
      geometry DEF BOX1 Box {
        size 0.1 0.1 0.1
      }
    }
  ]
  name "blue box"
  boundingObject Shape {
    appearance PBRAppearance {
      roughness 1.1102230246251565e-16
      metalness 0
    }
    geometry USE BOX1
  }
}
DEF YELLOW_BOX Solid {
  translation -0.2 0.05 0.15
  rotation 0 1 0 0.4
  children [
    Shape {
      appearance PBRAppearance {
        baseColor 1 1 0
        roughness 0.03934117200000009
        metalness 0
      }
      geometry DEF BOX2 Box {
        size 0.05 0.1 0.3
      }
    }
  ]
  name "yellow box"
  boundingObject Shape {
    appearance PBRAppearance {
      roughness 1.1102230246251565e-16
      metalness 0
    }
    geometry USE BOX2
  }
}
DEF PINK_BOX Solid {
  translation 0.42 0.05 -0.1
  children [
    Shape {
      appearance PBRAppearance {
        baseColor 1 0.1 0.3
        roughness 0.16827074099999995
        metalness 0
      }
      geometry DEF BOX3 Box {
        size 0.15 0.1 0.08
      }
    }
  ]
  name "red box"
  boundingObject Shape {
    appearance PBRAppearance {
      roughness 1.1102230246251565e-16
      metalness 0
    }
    geometry USE BOX3
  }
}
Robot {
  translation 0.15 0 0
  rotation 0 1 0 4.00425
  children [
    Transform {
      translation 0 0.0415 0
      children [
        Shape {
          appearance PBRAppearance {
            baseColor 0.0820075 0.364731 0.8
            roughness 1
            metalness 0
          }
          geometry DEF BODY Cylinder {
            height 0.08
            radius 0.045
          }
        }
      ]
    }
    HingeJoint {
      jointParameters HingeJointParameters {
        axis -1 0 0
        anchor -0.045 0.025 0
      }
      device [
        RotationalMotor {
          name "left wheel motor"
          consumptionFactor 70
          maxVelocity 15
        }
        PositionSensor {
          name "left wheel sensor"
        }
      ]
      endPoint Solid {
        translation -0.045 0.025 0
        rotation 1 0 0 4.98467
        children [
          DEF WHEEL Transform {
            rotation 0 0 1 1.57
            children [
              Shape {
                appearance PBRAppearance {
                  baseColor 1 0 0
                  roughness 1
                  metalness 0
                }
                geometry Cylinder {
                  height 0.01
                  radius 0.025
                }
              }
            ]
          }
        ]
        name "left wheel"
        boundingObject USE WHEEL
        physics DEF PHYSICS_WHEEL Physics {
          density -1
          mass 0.05
        }
      }
    }
    HingeJoint {
      jointParameters HingeJointParameters {
        axis -1 0 0
        anchor 0.045 0.025 0
      }
      device [
        RotationalMotor {
          name "right wheel motor"
          consumptionFactor 70
          maxVelocity 15
        }
        PositionSensor {
          name "right wheel sensor"
        }
      ]
      endPoint Solid {
        translation 0.045 0.025 0
        rotation 1 0 0 4.58735
        children [
          USE WHEEL
        ]
        name "right wheel"
        boundingObject USE WHEEL
        physics USE PHYSICS_WHEEL
      }
    }
    DistanceSensor {
      translation -0.02 0.063 -0.042
      rotation 0 1 0 2.07
      children [
        DEF SENSOR Transform {
          rotation 0 0 1 1.57
          children [
            Shape {
              appearance PBRAppearance {
                baseColor 0.975691 0.981481 0.0252992
                roughness 1
                metalness 0
              }
              geometry Cylinder {
                height 0.004
                radius 0.008
              }
            }
          ]
        }
      ]
      name "ds0"
      lookupTable [
        0 1024 0
        0.05 1024 0
        0.15 0 0
      ]
      numberOfRays 2
      aperture 1
    }
    DistanceSensor {
      translation 0.02 0.063 -0.042
      rotation 0 1 0 1.07
      children [
        USE SENSOR
      ]
      name "ds1"
      lookupTable [
        0 1024 0
        0.05 1024 0
        0.15 0 0
      ]
      numberOfRays 2
      aperture 1
    }
    DEF SMILE Transform {
      translation 0 0.025 -0.036
      rotation 0.7745972408364944 0.44721228048294853 0.4472139204829502 1.8234794
      children [
        Shape {
          appearance PBRAppearance {
            baseColor 0.721569 0.290196 0.290196
            roughness 1
            metalness 0
          }
          geometry Cylinder {
            height 0.018
            radius 0.009
            subdivision 3
          }
        }
      ]
    }
    Pen {
      translation 0 0.001 0
      children [
        Transform {
          translation 0 0.07 0
          children [
            Shape {
              appearance PBRAppearance {
                baseColor 1 0.692371 0
                roughness 0.3707939685999999
                metalness 0
              }
              geometry Cylinder {
                height 0.14
                radius 0.004
              }
            }
          ]
        }
      ]
      leadSize 0.01
    }
  ]
  name "MyBot"
  boundingObject Transform {
    translation 0 0.0415 0
    children [
      USE BODY
    ]
  }
  physics Physics {
    density -1
    mass 0.5
    centerOfMass [
      0 0 0
    ]
  }
  controller "pen"
}
