#VRML_SIM R2020a utf8
WorldInfo {
  info [
    "Description: Sample of robot mounted by a Sick LMS 291."
  ]
  title "Sick LMS 291"
  lineScale 0.5
}
Viewpoint {
  orientation -0.10639501977774378 0.9680541479777618 0.2270490395257009 1.195
  position 2.269059 1.0160229 0.99623413
  follow "robot"
  followSmoothness 0
}
TexturedBackground {
}
TexturedBackgroundLight {
}
RectangleArena {
  floorSize 100 100
  floorTileSize 1 1
  floorAppearance PBRAppearance {
    baseColorMap ImageTexture {
      url [
        "textures/checkered_marble.jpg"
      ]
    }
    roughness 1
    metalness 0
  }
  wallThickness 0.2
  wallHeight 2
}
DEF OBSTACLE_1 Solid {
  translation 15.7489 1 12.6243
  children [
    DEF OBSTACLE_SHAPE Shape {
      appearance PBRAppearance {
        baseColor 0 0.462745 0.0823529
        roughness 1.1102230246251565e-16
        metalness 0
      }
      geometry Cylinder {
        radius 0.5
        subdivision 20
      }
    }
  ]
  name "obstacle 1"
  boundingObject USE OBSTACLE_SHAPE
}
DEF OBSTACLE_2 Solid {
  translation -34.6061 1 -40.1723
  children [
    USE OBSTACLE_SHAPE
  ]
  name "obstacle 2"
  boundingObject USE OBSTACLE_SHAPE
}
DEF OBSTACLE_3 Solid {
  translation 21.5945 1 -30.3883
  children [
    USE OBSTACLE_SHAPE
  ]
  name "obstacle 3"
  boundingObject USE OBSTACLE_SHAPE
}
DEF OBSTACLE_4 Solid {
  translation 27.5208 1 -6.81157
  children [
    USE OBSTACLE_SHAPE
  ]
  name "obstacle 4"
  boundingObject USE OBSTACLE_SHAPE
}
DEF OBSTACLE_5 Solid {
  translation -9.56429 1 -38.4751
  children [
    USE OBSTACLE_SHAPE
  ]
  name "obstacle 5"
  boundingObject USE OBSTACLE_SHAPE
}
DEF OBSTACLE_6 Solid {
  translation -9.60517 1 -23.2236
  children [
    USE OBSTACLE_SHAPE
  ]
  name "obstacle 6"
  boundingObject USE OBSTACLE_SHAPE
}
DEF OBSTACLE_7 Solid {
  translation 18.6698 1 2.60164
  children [
    USE OBSTACLE_SHAPE
  ]
  name "obstacle 7"
  boundingObject USE OBSTACLE_SHAPE
}
DEF OBSTACLE_8 Solid {
  translation 39.3642 1 39.2094
  children [
    USE OBSTACLE_SHAPE
  ]
  name "obstacle 8"
  boundingObject USE OBSTACLE_SHAPE
}
DEF OBSTACLE_9 Solid {
  translation -21.5071 1 19.6972
  children [
    USE OBSTACLE_SHAPE
  ]
  name "obstacle 9"
  boundingObject USE OBSTACLE_SHAPE
}
DEF OBSTACLE_10 Solid {
  translation -4.27785 1 48.5003
  children [
    USE OBSTACLE_SHAPE
  ]
  name "obstacle 10"
  boundingObject USE OBSTACLE_SHAPE
}
DEF OBSTACLE_11 Solid {
  translation -33.6898 1 -23.5403
  children [
    USE OBSTACLE_SHAPE
  ]
  name "obstacle 11"
  boundingObject USE OBSTACLE_SHAPE
}
DEF OBSTACLE_12 Solid {
  translation -41.2214 1 -16.8073
  children [
    USE OBSTACLE_SHAPE
  ]
  name "obstacle 12"
  boundingObject USE OBSTACLE_SHAPE
}
DEF OBSTACLE_13 Solid {
  translation -37.9358 1 16.9674
  children [
    USE OBSTACLE_SHAPE
  ]
  name "obstacle 13"
  boundingObject USE OBSTACLE_SHAPE
}
DEF OBSTACLE_14 Solid {
  translation -14.6176 1 37.8329
  children [
    USE OBSTACLE_SHAPE
  ]
  name "obstacle 14"
  boundingObject USE OBSTACLE_SHAPE
}
DEF OBSTACLE_15 Solid {
  translation 20.3623 1 45.3412
  children [
    USE OBSTACLE_SHAPE
  ]
  name "obstacle 15"
  boundingObject USE OBSTACLE_SHAPE
}
DEF OBSTACLE_16 Solid {
  translation 29.3483 1 18.8565
  children [
    USE OBSTACLE_SHAPE
  ]
  name "obstacle 16"
  boundingObject USE OBSTACLE_SHAPE
}
DEF OBSTACLE_17 Solid {
  translation 39.7762 1 7.66315
  children [
    USE OBSTACLE_SHAPE
  ]
  name "obstacle 17"
  boundingObject USE OBSTACLE_SHAPE
}
DEF OBSTACLE_18 Solid {
  translation 35.098 1 -20.3285
  children [
    USE OBSTACLE_SHAPE
  ]
  name "obstacle 18"
  boundingObject USE OBSTACLE_SHAPE
}
DEF OBSTACLE_19 Solid {
  translation 34.6685 1 -35.3054
  children [
    USE OBSTACLE_SHAPE
  ]
  name "obstacle 19"
  boundingObject USE OBSTACLE_SHAPE
}
DEF OBSTACLE_20 Solid {
  translation 10.1839 1 -44.3846
  children [
    USE OBSTACLE_SHAPE
  ]
  name "obstacle 20"
  boundingObject USE OBSTACLE_SHAPE
}
DEF OBSTACLE_21 Solid {
  translation -18.7385 1 -10.3187
  children [
    USE OBSTACLE_SHAPE
  ]
  name "obstacle 21"
  boundingObject USE OBSTACLE_SHAPE
}
DEF OBSTACLE_22 Solid {
  translation -31.7044 1 34.2097
  children [
    USE OBSTACLE_SHAPE
  ]
  name "obstacle 22"
  boundingObject USE OBSTACLE_SHAPE
}
DEF OBSTACLE_23 Solid {
  translation -29.4344 1 1.27298
  children [
    USE OBSTACLE_SHAPE
  ]
  name "obstacle 23"
  boundingObject USE OBSTACLE_SHAPE
}
DEF OBSTACLE_24 Solid {
  translation 22.2993 1 -17.8686
  children [
    USE OBSTACLE_SHAPE
  ]
  name "obstacle 24"
  boundingObject USE OBSTACLE_SHAPE
}
DEF OBSTACLE_25 Solid {
  translation 2.01148 1 -31.4765
  children [
    USE OBSTACLE_SHAPE
  ]
  name "obstacle 25"
  boundingObject USE OBSTACLE_SHAPE
}
DEF OBSTACLE_26 Solid {
  translation -1.07563 1 41.9155
  children [
    USE OBSTACLE_SHAPE
  ]
  name "obstacle 26"
  boundingObject USE OBSTACLE_SHAPE
}
DEF OBSTACLE_27 Solid {
  translation 13.7977 1 31.39
  children [
    USE OBSTACLE_SHAPE
  ]
  name "obstacle 27"
  boundingObject USE OBSTACLE_SHAPE
}
DEF OBSTACLE_28 Solid {
  translation -11.9969 1 25.2891
  children [
    USE OBSTACLE_SHAPE
  ]
  name "obstacle 28"
  boundingObject USE OBSTACLE_SHAPE
}
DEF OBSTACLE_29 Solid {
  translation -46.1252 1 28.9556
  children [
    USE OBSTACLE_SHAPE
  ]
  name "obstacle 29"
  boundingObject USE OBSTACLE_SHAPE
}
DEF OBSTACLE_30 Solid {
  translation -41.1759 1 2.15042
  children [
    USE OBSTACLE_SHAPE
  ]
  name "obstacle 30"
  boundingObject USE OBSTACLE_SHAPE
}
DEF OBSTACLE_31 Solid {
  translation -1.71767 1 7.68168
  children [
    USE OBSTACLE_SHAPE
  ]
  name "obstacle 31"
  boundingObject USE OBSTACLE_SHAPE
}
DEF OBSTACLE_32 Solid {
  translation -25.1618 1 10.2537
  children [
    USE OBSTACLE_SHAPE
  ]
  name "obstacle 32"
  boundingObject USE OBSTACLE_SHAPE
}
DEF OBSTACLE_33 Solid {
  translation 45.3906 1 -45.0979
  children [
    USE OBSTACLE_SHAPE
  ]
  name "obstacle 33"
  boundingObject USE OBSTACLE_SHAPE
}
DEF OBSTACLE_34 Solid {
  translation -8.6755 1 -4.50206
  children [
    USE OBSTACLE_SHAPE
  ]
  name "obstacle 34"
  boundingObject USE OBSTACLE_SHAPE
}
DEF OBSTACLE_35 Solid {
  translation -22.6311 1 46.3206
  children [
    USE OBSTACLE_SHAPE
  ]
  name "obstacle 35"
  boundingObject USE OBSTACLE_SHAPE
}
DEF OBSTACLE_36 Solid {
  translation 27.3199 1 32.4912
  children [
    USE OBSTACLE_SHAPE
  ]
  name "obstacle 36"
  boundingObject USE OBSTACLE_SHAPE
}
DEF OBSTACLE_37 Solid {
  translation 29.7965 1 7.52276
  children [
    USE OBSTACLE_SHAPE
  ]
  name "obstacle 37"
  boundingObject USE OBSTACLE_SHAPE
}
DEF OBSTACLE_38 Solid {
  translation 42.7781 1 -9.19469
  children [
    USE OBSTACLE_SHAPE
  ]
  name "obstacle 38"
  boundingObject USE OBSTACLE_SHAPE
}
DEF OBSTACLE_39 Solid {
  translation 7.03998 1 6.59248
  children [
    USE OBSTACLE_SHAPE
  ]
  name "obstacle 39"
  boundingObject USE OBSTACLE_SHAPE
}
DEF OBSTACLE_40 Solid {
  translation -21.5776 1 -47.2582
  children [
    USE OBSTACLE_SHAPE
  ]
  name "obstacle 40"
  boundingObject USE OBSTACLE_SHAPE
}
DEF OBSTACLE_41 Solid {
  translation -48.4807 1 -31.886
  children [
    USE OBSTACLE_SHAPE
  ]
  name "obstacle 41"
  boundingObject USE OBSTACLE_SHAPE
}
DEF OBSTACLE_42 Solid {
  translation 0.918569 1 23.2265
  children [
    USE OBSTACLE_SHAPE
  ]
  name "obstacle 42"
  boundingObject USE OBSTACLE_SHAPE
}
DEF OBSTACLE_43 Solid {
  translation 47.5682 1 19.6871
  children [
    USE OBSTACLE_SHAPE
  ]
  name "obstacle 43"
  boundingObject USE OBSTACLE_SHAPE
}
DEF OBSTACLE_44 Solid {
  translation -0.0294536 1 -14.0603
  children [
    USE OBSTACLE_SHAPE
  ]
  name "obstacle 44"
  boundingObject USE OBSTACLE_SHAPE
}
DEF OBSTACLE_45 Solid {
  translation -23.1081 1 -27.2096
  children [
    USE OBSTACLE_SHAPE
  ]
  name "obstacle 45"
  boundingObject USE OBSTACLE_SHAPE
}
DEF OBSTACLE_46 Solid {
  translation 11.2096 1 -20.8318
  children [
    USE OBSTACLE_SHAPE
  ]
  name "obstacle 46"
  boundingObject USE OBSTACLE_SHAPE
}
Robot {
  translation 0 0.35 0
  children [
    DEF BODY Shape {
      appearance PBRAppearance {
        baseColor 0.243137 0.360784 1
        roughness 1.1102230246251565e-16
        metalness 0
      }
      geometry Box {
        size 0.8 0.3 0.6
      }
    }
    DEF DIRECTION HingeJoint {
      jointParameters HingeJointParameters {
        axis 0 1 0
        anchor 0.4 -0.15 0
      }
      device [
        RotationalMotor {
          name "direction"
          minPosition -0.5
          maxPosition 0.5
          maxTorque 100
        }
      ]
      endPoint Solid {
        translation 0.4 -0.15 0
        children [
          DEF PASSIVEFRONT_WHEEL HingeJoint {
            jointParameters HingeJointParameters {
              axis 0 0 1
            }
            device [
              RotationalMotor {
                name "passive"
              }
            ]
            endPoint Solid {
              rotation 0 0 1 0
              children [
                DEF WHEEL_TRANSFORM Transform {
                  rotation 1 0 0 1.5708
                  children [
                    Shape {
                      appearance PBRAppearance {
                        baseColor 1 0.266667 0.266667
                        roughness 1.1102230246251565e-16
                        metalness 0
                      }
                      geometry Cylinder {
                        height 0.1
                        radius 0.17
                        subdivision 32
                      }
                    }
                  ]
                }
              ]
              name "front wheel"
              boundingObject USE WHEEL_TRANSFORM
              physics DEF WHEEL_PHYSICS Physics {
                density -1
                mass 3
              }
            }
          }
        ]
        boundingObject Cylinder {
          height 0.02
          radius 0.01
        }
        physics USE WHEEL_PHYSICS
      }
    }
    DEF BACK_RIGHT_WHEEL HingeJoint {
      jointParameters HingeJointParameters {
        axis 0 0 -1
        anchor -0.4 -0.15 0.2
      }
      device [
        RotationalMotor {
          name "back_right_wheel"
          maxVelocity 100
          maxTorque 100
        }
      ]
      endPoint Solid {
        translation -0.4 -0.15 0.2
        rotation 0 0 -1 0
        children [
          USE WHEEL_TRANSFORM
        ]
        name "back right wheel"
        boundingObject USE WHEEL_TRANSFORM
        physics DEF WHEEL_PHYSICS Physics {
          density -1
          mass 3
        }
      }
    }
    DEF BACK_LEFT_WHEEL HingeJoint {
      jointParameters HingeJointParameters {
        axis 0 0 -1
        anchor -0.4 -0.15 -0.2
      }
      device [
        RotationalMotor {
          name "back_left_wheel"
          maxVelocity 100
          maxTorque 100
        }
      ]
      endPoint Solid {
        translation -0.4 -0.15 -0.2
        rotation 0 0 -1 0
        children [
          USE WHEEL_TRANSFORM
        ]
        name "back left wheel"
        boundingObject USE WHEEL_TRANSFORM
        physics USE WHEEL_PHYSICS
      }
    }
    DEF LMS_291 SickLms291 {
      translation 0 0.22 0
      rotation 0 1 0 -1.5708
    }
    DEF DISPLAY Display {
      width 200
      height 110
    }
  ]
  boundingObject USE BODY
  physics Physics {
    density -1
    mass 20
  }
  controller "sick"
}
