#VRML_SIM R2023b utf8

EXTERNPROTO "webots://projects/objects/backgrounds/protos/TexturedBackground.proto"
EXTERNPROTO "webots://projects/objects/backgrounds/protos/TexturedBackgroundLight.proto"
EXTERNPROTO "webots://projects/objects/floors/protos/RectangleArena.proto"

WorldInfo {
  info [
    "Example use of a Speaker device."
  ]
  title "Speaker"
}
Viewpoint {
  fieldOfView 1.5
  orientation 0 0 1 1.49337
  position 0 0 0.05
}
TexturedBackground {
}
TexturedBackgroundLight {
}
RectangleArena {
  floorSize 2 2
}
Robot {
  translation 0.016513 0.49961 0
  rotation 0 0 1 -3.14157
  children [
    Pose {
      translation 0 0 0.0415
      rotation 0 0 1 1.570796
      children [
        Shape {
          appearance PBRAppearance {
            baseColor 0.0820075 0.364731 0.8
            roughness 1
            metalness 0
          }
          geometry DEF BODY Cylinder {
            height 0.08
            radius 0.045
          }
        }
      ]
    }
    HingeJoint {
      jointParameters HingeJointParameters {
        axis 0 1 0
        anchor 0 0 0.025
      }
      device [
        RotationalMotor {
          name "left wheel motor"
          consumptionFactor 70
        }
        PositionSensor {
          name "left wheel sensor"
        }
      ]
      endPoint Solid {
        translation 0 0.045 0.025
        rotation 0.1344869543855967 -0.1344869543855967 -0.9817466670176034 1.589218
        children [
          DEF WHEEL Pose {
            rotation 0.577656895078166 0.5771968951617173 -0.5771968951617173 -2.093935
            children [
              Shape {
                appearance PBRAppearance {
                  baseColor 1 0 0
                  roughness 1
                  metalness 0
                }
                geometry Cylinder {
                  height 0.01
                  radius 0.025
                }
              }
            ]
          }
        ]
        name "left wheel"
        boundingObject USE WHEEL
        physics DEF PHYSICS_WHEEL Physics {
          density -1
          mass 0.05
        }
      }
    }
    HingeJoint {
      jointParameters HingeJointParameters {
        axis 0 1 0
        anchor 0 0 0.025
      }
      device [
        RotationalMotor {
          name "right wheel motor"
          consumptionFactor 70
        }
        PositionSensor {
          name "right wheel sensor"
        }
      ]
      endPoint Solid {
        translation 0 -0.045 0.025
        rotation -0.06235700094427208 0.06235700094427208 -0.9961040150840033 1.5747
        children [
          USE WHEEL
        ]
        name "right wheel"
        boundingObject USE WHEEL
        physics USE PHYSICS_WHEEL
      }
    }
    Pose {
      translation 0.0385 -0.02 0.063
      rotation -0.726828171413359 -0.4856551145357015 -0.48565411453546564 -1.884582
      children [
        DEF UNUSED_EYE Group {
          children [
            Pose {
              translation 0 0 1e-05
              rotation 0 0 1 0.8
              children [
                Shape {
                  appearance PBRAppearance {
                    baseColor 0.975691 0.981481 0.0252992
                    roughness 1
                    metalness 0
                  }
                  geometry Box {
                    size 0.02 0.005 0.005
                  }
                }
              ]
            }
            Pose {
              rotation 0 0 1 -0.8
              children [
                Shape {
                  appearance PBRAppearance {
                    baseColor 0.975691 0.981481 0.0252992
                    roughness 1
                    metalness 0
                  }
                  geometry Box {
                    size 0.02 0.005 0.005
                  }
                }
              ]
            }
          ]
        }
      ]
    }
    Pose {
      translation 0.0385 0.02 0.063
      rotation -0.7268306455324123 0.4856527631523045 0.4856527631523045 -1.884578
      children [
        USE UNUSED_EYE
      ]
    }
    DEF SMILE Pose {
      translation 0.036 0 0.025
      rotation 0.25056300542381216 -0.9351130202419243 -0.25056300542381216 1.637834
      children [
        Shape {
          appearance PBRAppearance {
            baseColor 0.721569 0.290196 0.290196
            roughness 1
            metalness 0
          }
          geometry Cylinder {
            height 0.018
            radius 0.009
            subdivision 3
          }
        }
      ]
    }
    Speaker {
      translation 0 0 0.085
      children [
        Shape {
          appearance PBRAppearance {
            baseColor 0.2 0.2 0.2
            baseColorMap ImageTexture {
              url [
                "webots://projects/samples/devices/worlds/textures/speaker.png"
              ]
            }
            roughness 0.5
            metalness 0
          }
          geometry Cylinder {
            height 0.01
            radius 0.03
            side FALSE
            subdivision 24
          }
        }
        Shape {
          appearance PBRAppearance {
            baseColor 0.2 0.2 0.2
            roughness 1
            metalness 0
          }
          geometry Cylinder {
            height 0.01
            radius 0.03
            top FALSE
            subdivision 24
          }
        }
      ]
    }
  ]
  name "mybot"
  boundingObject Pose {
    translation 0 0 0.0415
    rotation 0 0 1 1.570796
    children [
      USE BODY
    ]
  }
  physics Physics {
    density -1
    mass 0.5
  }
  controller "speaker"
}
