#VRML_SIM R2020a utf8
WorldInfo {
  info [
    "Example use of a Speaker devide to perform text-to-speech."
  ]
  title "Speaker Text-To-Speech"
}
Viewpoint {
  orientation -0.22902003976051613 -0.931236161673321 -0.2834590492117551 1.87902
  position -0.736953 0.536537 -0.250621
}
TexturedBackground {
}
TexturedBackgroundLight {
}
RectangleArena {
}
Robot {
  translation 0.15 0 0
  rotation 0 1 0 1.2618
  children [
    Transform {
      translation 0 0.0415 0
      children [
        Shape {
          appearance PBRAppearance {
            baseColor 0.0820075 0.364731 0.8
            roughness 1
            metalness 0
          }
          geometry DEF BODY Cylinder {
            height 0.08
            radius 0.045
          }
        }
      ]
    }
    HingeJoint {
      jointParameters HingeJointParameters {
        axis -1 0 0
        anchor 0 0.025 0
      }
      device [
        RotationalMotor {
          name "left wheel motor"
          consumptionFactor 70
        }
        PositionSensor {
          name "left wheel sensor"
        }
      ]
      endPoint Solid {
        translation -0.045 0.025 0
        rotation 1 0 0 4.98467
        children [
          DEF WHEEL Transform {
            rotation 0 0 1 1.57
            children [
              Shape {
                appearance PBRAppearance {
                  baseColor 1 0 0
                  roughness 1
                  metalness 0
                }
                geometry Cylinder {
                  height 0.01
                  radius 0.025
                }
              }
            ]
          }
        ]
        name "left wheel"
        boundingObject USE WHEEL
        physics DEF PHYSICS_WHEEL Physics {
          density -1
          mass 0.05
        }
      }
    }
    HingeJoint {
      jointParameters HingeJointParameters {
        axis -1 0 0
        anchor 0 0.025 0
      }
      device [
        RotationalMotor {
          name "right wheel motor"
          consumptionFactor 70
        }
        PositionSensor {
          name "right wheel sensor"
        }
      ]
      endPoint Solid {
        translation 0.045 0.025 0
        rotation 1 0 0 4.58735
        children [
          USE WHEEL
        ]
        name "right wheel"
        boundingObject USE WHEEL
        physics USE PHYSICS_WHEEL
      }
    }
    Transform {
      translation 0.02 0.063 -0.0385
      rotation 0 1 0 2.7489
      children [
        DEF UNUSED_EYE Group {
          children [
            Transform {
              translation 0 0 -1e-05
              rotation 0 0 1 0.8
              children [
                Shape {
                  appearance PBRAppearance {
                    baseColor 0.975691 0.981481 0.0252992
                    roughness 1
                    metalness 0
                  }
                  geometry Box {
                    size 0.02 0.005 0.005
                  }
                }
              ]
            }
            Transform {
              rotation 0 0 1 -0.8
              children [
                Shape {
                  appearance PBRAppearance {
                    baseColor 0.975691 0.981481 0.0252992
                    roughness 1
                    metalness 0
                  }
                  geometry Box {
                    size 0.02 0.005 0.005
                  }
                }
              ]
            }
          ]
        }
      ]
    }
    Transform {
      translation -0.02 0.063 -0.0385
      rotation 0 1 0 0.3927
      children [
        USE UNUSED_EYE
      ]
    }
    DEF SMILE Transform {
      translation 0 0.025 -0.036
      rotation 0.7745972408364944 0.44721228048294853 0.4472139204829502 1.8234794
      children [
        Shape {
          appearance PBRAppearance {
            baseColor 0.721569 0.290196 0.290196
            roughness 1
            metalness 0
          }
          geometry Cylinder {
            height 0.018
            radius 0.009
            subdivision 3
          }
        }
      ]
    }
    Speaker {
      translation 0 0.085 0
      children [
        Shape {
          appearance PBRAppearance {
            baseColor 0.2 0.2 0.2
            baseColorMap ImageTexture {
              url [
                "textures/speaker.png"
              ]
            }
            roughness 0.5
            metalness 0
          }
          geometry Cylinder {
            height 0.01
            radius 0.03
            side FALSE
            subdivision 24
          }
        }
        Shape {
          appearance PBRAppearance {
            baseColor 0.2 0.2 0.2
            roughness 1
            metalness 0
          }
          geometry Cylinder {
            height 0.01
            radius 0.03
            top FALSE
            subdivision 24
          }
        }
      ]
    }
  ]
  name "mybot"
  boundingObject Transform {
    translation 0 0.0415 0
    children [
      USE BODY
    ]
  }
  physics Physics {
    density -1
    mass 0.5
  }
  controller "speaker_text_to_speech"
}
