#VRML_SIM R2022b utf8
# license: Copyright Cyberbotics Ltd. Licensed for use only with Webots.
# license url: https://cyberbotics.com/webots_assets_license
# A model of the Fanatec CSL Elite Racing Wheel to insert in the 'steeringWheel' field of some vehicles.

EXTERNPROTO "webots://projects/appearances/protos/ShinyLeather.proto"

PROTO FanatecCslEliteSteeringWheel [
  field SFString name "Fanatec CSL Elite steering wheel"
]
{
  Slot {
    type "vehicle steering wheel"
    endPoint HingeJoint {
      jointParameters HingeJointParameters {
        axis 0 -0.88 2.6
        anchor 0.004 0.014 0
      }
      device [
        RotationalMotor {
          name "steering_wheel_motor"
          sound ""
        }
      ]
      endPoint Solid {
        name IS name
        children [
          DEF CENTER_REAR Shape {
            appearance DEF BLACK_PAINTED_METAL PBRAppearance {
              baseColor 0.1 0.1 0.1
              roughness 0.4
            }
            geometry Mesh {
              url "FanatecCslEliteSteeringWheel/meshes/center_rear.obj"
            }
          }
          DEF CENTER_FRONT Shape {
            appearance USE BLACK_PAINTED_METAL
            geometry Mesh {
              url "FanatecCslEliteSteeringWheel/meshes/center_front.obj"
            }
          }
          DEF BUTTONS Transform {
            translation 0.411311 -1.168101 -0.87312
            rotation 0 0.7073942228302764 0.7068192226491505 3.141593
            scale 0.001147 0.001147 0.001147
            children [
              Shape {
                appearance PBRAppearance {
                  baseColorMap ImageTexture {
                    url "FanatecCslEliteSteeringWheel/textures/fanatec_csl_elite_steering_wheel.jpg"
                  }
                  metalness 0
                  roughness 0.2
                }
                geometry Mesh {
                  url "FanatecCslEliteSteeringWheel/meshes/buttons.obj"
                }
              }
            ]
          }
          DEF WHEEL Transform {
            translation 0.411311 -1.168101 -0.873120
            rotation 0.000000 0.707394 0.706819 3.141593
            scale 0.001147 0.001147 0.001147
            children [
              Shape {
                appearance ShinyLeather {
                  colorOverride 0.111 0.111 0.111
                  textureTransform TextureTransform {
                    scale 3 3
                  }
                }
                geometry Mesh {
                  url "FanatecCslEliteSteeringWheel/meshes/wheel.obj"
                }
              }
              DEF PLASTIC Shape {
                appearance PBRAppearance {
                  baseColor 0 0 0
                  roughness 0.15
                }
                geometry Mesh {
                  url "FanatecCslEliteSteeringWheel/meshes/plastic.obj"
                }
              }
              DEF LED Shape {
                appearance PBRAppearance {
                  baseColor 0.9372549019607843 0.9372549019607843 0.9372549019607843
                  metalness 0
                  roughness 0.2
                }
                geometry Mesh {
                  url "FanatecCslEliteSteeringWheel/meshes/led.obj"
                }
              }
            ]
          }
        ]
      }
    }
  }
}
