#VRML_SIM R2023b utf8
# license: Apache License 2.0
# license url: https://www.apache.org/licenses/LICENSE-2.0
# documentation url: https://webots.cloud/run?url=https://github.com/cyberbotics/webots/blob/released/projects/robots/fp_robotics/p-rob3/protos/P-Grip.proto
# keywords: robot/extension, actuator/gripper
# A P-Grip gripper rom F&P Robotics

EXTERNPROTO "webots://projects/appearances/protos/Leather.proto"
EXTERNPROTO "webots://projects/appearances/protos/Rubber.proto"
EXTERNPROTO "P-GripDistanceSensor.proto"

PROTO P-Grip [
  field SFVec3f    translation     0 0 0.07775         # Is `Pose.translation`.
  field SFRotation rotation        0 0 1 0             # Is `Pose.rotation`.
  field SFString   name            "link_base_tcp180"  # Is `Solid.name`.
  field SFString   model           "180 deg"           # Is `Solid.model`.
  field SFColor    mainColor       0.98 0.98 0.98      # Defines the main color of the robot.
  field SFColor    secondaryColor  0.036 0.3 0.615     # Defines the secondary color of the robot.
]
{
  DEF GRIPPER Solid {
    translation IS translation
    rotation IS rotation
    children [
      Shape {
        appearance DEF MAIN_APPEARANCE Leather {
          colorOverride IS mainColor
          type "grain"
          textureTransform TextureTransform {
            scale 4 4
          }
        }
        geometry Mesh {
          url "meshes/grip_link_0.obj"
        }
      }
      Shape {
        appearance DEF SECONDARY_APPEARANCE Leather {
          colorOverride IS secondaryColor
          type "grain"
          textureTransform TextureTransform {
            scale 4 4
          }
        }
        geometry Mesh {
          url "meshes/grip_link_1.obj"
        }
      }
      Shape {
        appearance Rubber {
          textureTransform TextureTransform {
            scale 10 10
          }
        }
        geometry Mesh {
          url "meshes/grip_link_2.obj"
        }
      }
      DEF RIGHT_FINGER HingeJoint {
        jointParameters HingeJointParameters {
          axis -1 0 0
          anchor 0 0 0.058
          minStop -0.001
          maxStop 1.048
        }
        device [
          RotationalMotor {
            name "gripper::right"
            acceleration 17.4533
            controlPID 3 0 0
            maxVelocity 1.0472
            maxPosition 1.0472
            maxTorque 5.44164
          }
          PositionSensor {
            name "gripper::right sensor"
          }
        ]
        endPoint Solid {
          translation 0 0 0.058
          rotation 1 0 0 0.343
          children [
            DEF FINGER_SHAPE Pose {
              translation -0.0007002 0.0360533 -0.0141252
              rotation 0.5871667893278232 0.5572018000790946 0.5871637893288996 2.12488
              children [
                DEF FINGER Shape {
                  appearance Rubber {
                    textureTransform TextureTransform {
                      scale 10 10
                    }
                  }
                  geometry Mesh {
                    url "meshes/finger.obj"
                  }
                }
                DEF SCREW Shape {
                  appearance PBRAppearance {
                  }
                  geometry Mesh {
                    url "meshes/screw.obj"
                  }
                }
              ]
              translationStep 0.0001
              rotationStep 0.0261799
            }
            DEF FINGER_CONNECTOR_SHAPE Transform {
              translation 1.44397e-12 -3.29597e-17 -4.1346e-15
              rotation -0.577350402522952 -0.5773502025229511 -0.5773502025229511 2.094395
              scale 0.01 0.01 0.01
              children [
                Shape {
                  appearance PBRAppearance {
                  }
                  geometry Mesh {
                    url "meshes/finger_connector_shape.obj"
                  }
                }
              ]
            }
            P-GripDistanceSensor {
              translation 0.013 0.02 0.118
              rotation 1 0 0 0.523599
              name "right finger sensor 0"
            }
            P-GripDistanceSensor {
              translation -0.013 0.02 0.118
              rotation 0 0.2588189595935602 0.9659258492010602 3.14159
              name "right finger sensor 1"
            }
            P-GripDistanceSensor {
              translation -7.548e-10 0.0214379 0.13449
              rotation -0.2843081537207692 -0.7040203806523063 -0.6507873518700783 1.65885
              name "right finger sensor 2"
            }
            P-GripDistanceSensor {
              translation -6.75982e-08 0.0173238 0.0871813
              rotation 0.1294270015850925 0.37946400464729574 0.9161090112195871 1.58784
              name "right finger sensor 3"
            }
          ]
          name "right finger"
          contactMaterial "p-grip finger"
          boundingObject DEF FINGER_BO Group {
            children [
              DEF FINGER_BOX_0 Pose {
                translation 0 0.0437334 0.0442707
                rotation 1 0 0 -0.2879853071795866
                children [
                  Box {
                    size 0.034 0.023 0.07
                  }
                ]
              }
              DEF FINGER_BOX_1 Pose {
                translation 0 0.0561311 0.0865105
                rotation 1 0 0 -0.3926996938995747
                children [
                  Box {
                    size 0.03 0.02 0.04
                  }
                ]
              }
              DEF FINGER_BOX_2 Pose {
                translation 0 0.0566597 0.105248
                rotation 1 0 0 0.261798
                children [
                  Box {
                    size 0.026 0.021 0.03
                  }
                ]
              }
              DEF FINGER_BOX_3 Pose {
                translation 0 0.048226 0.127972
                rotation -1 0 0 0.314166
                children [
                  Box {
                    size 0.026 0.004 0.025
                  }
                ]
              }
              DEF FINGER_BOX_4 Pose {
                translation 0 0.058726 0.127073
                rotation 1 0 0 0.62831
                children [
                  Box {
                    size 0.024 0.007 0.025
                  }
                ]
              }
              DEF FINGER_BOX_5 Pose {
                translation 0 0.052619 0.121813
                rotation 1 0 0 1.23045
                children [
                  Box {
                    size 0.022 0.014 0.014
                  }
                ]
              }
              DEF FINGER_BOX_6 Pose {
                translation 0 0.0673743 0.108562
                rotation -1 0 0 -0.23558530717958615
                children [
                  Box {
                    size 0.024 0.007 0.02
                  }
                ]
              }
            ]
          }
          physics DEF FINGER_PHYSICS Physics {
          }
        }
      }
      DEF LEFT_FINGER HingeJoint {
        jointParameters HingeJointParameters {
          anchor 0 0 0.058
          minStop -0.001
          maxStop 1.048
        }
        device [
          RotationalMotor {
            name "gripper::left"
            acceleration 17.4533
            controlPID 3 0 0
            maxVelocity 1.0472
            maxPosition 1.0472
            maxTorque 5.44164
          }
          PositionSensor {
            name "gripper::left sensor"
          }
        ]
        endPoint Solid {
          translation 0 0 0.058
          rotation 0 0.1706609670777107 0.9853298099195521 3.14159
          children [
            USE FINGER_SHAPE
            USE FINGER_CONNECTOR_SHAPE
            P-GripDistanceSensor {
              translation 0.013 0.02 0.118
              rotation 1 0 0 0.523602
              name "left finger sensor 0"
            }
            P-GripDistanceSensor {
              translation -0.013 0.02 0.118
              rotation 0 0.2588189595935754 0.965925849201117 3.14159
              name "left finger sensor 1"
            }
            P-GripDistanceSensor {
              translation -7.548e-10 0.0214379 0.13449
              rotation -0.2843081537207692 -0.7040203806523063 -0.6507873518700783 1.65885
              name "left finger sensor 2"
            }
            P-GripDistanceSensor {
              translation -6.75982e-08 0.0173238 0.0871813
              rotation -0.1294270015850925 -0.37946400464729574 -0.9161090112195871 -1.5878453071795864
              name "left finger sensor 3"
            }
          ]
          name "left finger"
          contactMaterial "p-grip finger"
          boundingObject USE FINGER_BO
          physics USE FINGER_PHYSICS
        }
      }
      DistanceSensor {
        translation 0 0 0.085
        rotation 0 1 0 -1.5707896938995747
        name "gripper middle distance sensor"
        model "Sharp GP2Y0A60SZ0F"
        lookupTable [
          0.1 100 0
          1.5 1500 0
        ]
      }
    ]
    name IS name
    model IS model
    boundingObject Group {
      children [
        Pose {
          translation 0 0 0.026
          children [
            Sphere {
              radius 0.08
              subdivision 2
            }
          ]
        }
        Pose {
          translation 0 1.34683e-07 -0.014
          children [
            Cylinder {
              height 0.07
              radius 0.08
            }
          ]
        }
      ]
    }
    physics Physics {
      density -1
      mass 1.525
      centerOfMass [
        0.0002 0.0008 0.0238
      ]
      inertiaMatrix [
        0.01444 0.01389 0.00338
        0 0 0
      ]
    }
  }
}
