#VRML_SIM R2023b utf8
# license: Apache License 2.0
# license url: https://www.apache.org/licenses/LICENSE-2.0
# documentation url: https://webots.cloud/run?url=https://github.com/cyberbotics/webots/blob/released/projects/robots/fp_robotics/p-rob3/protos/P-Rob3.proto
# keywords: robot/arm
# A P-Rob3 robotic arm from F&P Robotics.
# template language: javascript

EXTERNPROTO "P-Grip.proto"
EXTERNPROTO "webots://projects/appearances/protos/Leather.proto"
EXTERNPROTO "webots://projects/objects/factory/tools/protos/CapScrew.proto"
EXTERNPROTO "webots://projects/appearances/protos/BrushedAluminium.proto"

PROTO P-Rob3 [
  field SFVec3f    translation     0 0 0            # Is `Pose.translation`.
  field SFRotation rotation        0 0 1 0          # Is `Pose.rotation`.
  field SFString   name            "P-Rob3"         # Is `Solid.name`.
  field SFString   controller      "<generic>"      # Is `Robot.controller`.
  field MFString   controllerArgs  []               # Is `Robot.controllerArgs`.
  field SFString   window          "<generic>"      # Is `Robot.window`.
  field SFBool     supervisor      FALSE            # Is `Robot.supervisor`.
  field SFBool     synchronization TRUE             # Is `Robot.synchronization`.
  field SFBool     selfCollision   TRUE             # Is `Robot.selfCollision`.
  field SFColor    mainColor       0.98 0.98 0.98   # Defines the main color of the robot.
  field SFColor    secondaryColor  0.036 0.3 0.615  # Defines the secondary color of the robot.
  field MFNode     toolSlot        [ P-Grip { } ]   # Extend the robot with new nodes at the end of the arm.
  field SFBool     staticBase      TRUE             # Defines if the robot base should be pinned to the static environment.
]
{
  Robot {
    translation IS translation
    rotation IS rotation
    children [
      Shape {
        appearance PBRAppearance {
        }
        geometry Mesh {
          url "meshes/base_link_0.obj"
        }
      }
      Shape {
        appearance DEF SECONDARY_APPEARANCE Leather {
          colorOverride IS secondaryColor
          type "grain"
          textureTransform TextureTransform {
            scale 4 4
          }
        }
        geometry Mesh {
          url "meshes/base_link_1.obj"
        }
      }
      Shape {
        appearance USE SECONDARY_APPEARANCE
        geometry Mesh {
          url "meshes/base_link_2.obj"
        }
      }
      Shape {
        appearance DEF MAIN_APPEARANCE Leather {
          colorOverride IS mainColor
          type "grain"
          textureTransform TextureTransform {
            scale 4 4
          }
        }
        geometry Mesh {
          url "meshes/base_link_3.obj"
        }
      }
      CapScrew {
        translation 0.0962 0 0.099
        rotation 0 0 1 3.141592653
        appearance BrushedAluminium {
        }
        screwRadius 0.005
        screwLength 0.01
      }
      HingeJoint {
        jointParameters HingeJointParameters {
          axis 0 0 1
          anchor 0 0 0.212
        }
        device [
          RotationalMotor {
            name "motor 1"
            acceleration 2.61799
            controlPID 3 0 0
            maxVelocity 1.74533
            minPosition -2.95903
            maxPosition 2.95903
            maxTorque 159.6959
          }
          PositionSensor {
            name "motor 1 sensor"
          }
        ]
        endPoint Solid {
          translation 0 0 0.2305
          children [
            Shape {
              appearance USE SECONDARY_APPEARANCE
              geometry Mesh {
                url "meshes/link_1_2_0.obj"
              }
            }
            Shape {
              appearance USE MAIN_APPEARANCE
              geometry Mesh {
                url "meshes/link_1_2_1.obj"
              }
            }
            Shape {
              appearance USE MAIN_APPEARANCE
              geometry Mesh {
                url "meshes/link_1_2_2.obj"
              }
            }
            Shape {
              appearance USE SECONDARY_APPEARANCE
              geometry Mesh {
                url "meshes/link_1_2_3.obj"
              }
            }
            HingeJoint {
              jointParameters HingeJointParameters {
                axis 0 1 0
                anchor 0 0 0.132
              }
              device [
                RotationalMotor {
                  name "motor 2"
                  acceleration 2.61799
                  controlPID 3 0 0
                  maxVelocity 1.74533
                  minPosition -1.91148
                  maxPosition 1.91148
                  maxTorque 159.6959
                }
                PositionSensor {
                  name "motor 2 sensor"
                }
              ]
              endPoint Solid {
                translation 0 0 0.277
                children [
                  Shape {
                    appearance USE SECONDARY_APPEARANCE
                    geometry Mesh {
                      url "meshes/link_2_3_0.obj"
                    }
                  }
                  Shape {
                    appearance USE MAIN_APPEARANCE
                    geometry Mesh {
                      url "meshes/link_2_3_1.obj"
                    }
                  }
                  Shape {
                    appearance USE MAIN_APPEARANCE
                    geometry Mesh {
                      url "meshes/link_2_3_2.obj"
                    }
                  }
                  HingeJoint {
                    jointParameters HingeJointParameters {
                      axis 0 1 0
                      anchor 0 0 0.145
                    }
                    device [
                      RotationalMotor {
                        name "motor 3"
                        acceleration 4.36332
                        controlPID 3 0 0
                        maxVelocity 2.44346
                        minPosition -1.99927
                        maxPosition 1.99927
                        maxTorque 80.1455
                      }
                      PositionSensor {
                        name "motor 3 sensor"
                      }
                    ]
                    endPoint Solid {
                      translation 0 0 0.3145
                      children [
                        Shape {
                          appearance USE MAIN_APPEARANCE
                          geometry Mesh {
                            url "meshes/link_3_4_0.obj"
                          }
                        }
                        Shape {
                          appearance USE SECONDARY_APPEARANCE
                          geometry Mesh {
                            url "meshes/link_3_4_1.obj"
                          }
                        }
                        Shape {
                          appearance USE SECONDARY_APPEARANCE
                          geometry Mesh {
                            url "meshes/link_3_4_2.obj"
                          }
                        }
                        Shape {
                          appearance USE MAIN_APPEARANCE
                          geometry Mesh {
                            url "meshes/link_3_4_3.obj"
                          }
                        }
                        HingeJoint {
                          jointParameters HingeJointParameters {
                            axis 0 0 1
                            anchor 0 0 -0.0055
                          }
                          device [
                            RotationalMotor {
                              name "motor 4"
                              acceleration 3.49066
                              controlPID 3 0 0
                              maxVelocity 2.79253
                              minPosition -2.95153
                              maxPosition 2.95153
                              maxTorque 30.1005
                            }
                            PositionSensor {
                              name "motor 4 sensor"
                            }
                          ]
                          endPoint Solid {
                            translation 0 0 0.00650001
                            children [
                              Shape {
                                appearance USE MAIN_APPEARANCE
                                geometry Mesh {
                                  url "meshes/link_4_5_0.obj"
                                }
                              }
                              Shape {
                                appearance USE SECONDARY_APPEARANCE
                                geometry Mesh {
                                  url "meshes/link_4_5_1.obj"
                                }
                              }
                              Shape {
                                appearance USE MAIN_APPEARANCE
                                geometry Mesh {
                                  url "meshes/link_4_5_2.obj"
                                }
                              }
                              HingeJoint {
                                jointParameters HingeJointParameters {
                                  axis 0 1 0
                                  anchor 0 0 0.1335
                                }
                                device [
                                  RotationalMotor {
                                    name "motor 5"
                                    acceleration 3.49066
                                    controlPID 3 0 0
                                    maxVelocity 2.79253
                                    minPosition -1.9977
                                    maxPosition 1.9977
                                    maxTorque 30.1005
                                  }
                                  PositionSensor {
                                    name "motor 5 sensor"
                                  }
                                ]
                                endPoint Solid {
                                  translation 0 0 0.268
                                  children [
                                    Shape {
                                      appearance USE MAIN_APPEARANCE
                                      geometry Mesh {
                                        url "meshes/link_5_6_0.obj"
                                      }
                                    }
                                    Shape {
                                      appearance USE SECONDARY_APPEARANCE
                                      geometry Mesh {
                                        url "meshes/link_5_6_1.obj"
                                      }
                                    }
                                    Shape {
                                      appearance USE MAIN_APPEARANCE
                                      geometry Mesh {
                                        url "meshes/link_5_6_2.obj"
                                      }
                                    }
                                    HingeJoint {
                                      jointParameters HingeJointParameters {
                                        axis 0 0 1
                                        anchor 0 0 -0.0055
                                      }
                                      device [
                                        RotationalMotor {
                                          name "motor 6"
                                          acceleration 6.98132
                                          controlPID 3 0 0
                                          maxVelocity 2.79253
                                          minPosition -2.95833
                                          maxPosition 2.95833
                                          maxTorque 16.4816
                                        }
                                        PositionSensor {
                                          name "motor 6 sensor"
                                        }
                                      ]
                                      endPoint Solid {
                                        translation 0 0 0.01525
                                        children [
                                          Shape {
                                            appearance USE MAIN_APPEARANCE
                                            geometry Mesh {
                                              url "meshes/link_6_top_0.obj"
                                            }
                                          }
                                          TouchSensor {
                                            translation -0.0501799 0.0432036 0.0089
                                            rotation 0.820226959977301 0.40449211001254 -0.404492110014521 -1.767685965976011
                                            children [
                                              Shape {
                                                appearance PBRAppearance {
                                                  baseColor IS secondaryColor
                                                  baseColorMap ImageTexture {
                                                    url [
                                                      "textures/button_1.png"
                                                    ]
                                                  }
                                                  roughness 1
                                                  metalness 0
                                                  textureTransform TextureTransform {
                                                    rotation 3.14159
                                                  }
                                                }
                                                geometry DEF BUTTON_CYLINDER Cylinder {
                                                  height 0.005
                                                  radius 0.007
                                                  side FALSE
                                                }
                                              }
                                            ]
                                            name "button 0"
                                            boundingObject USE BUTTON_CYLINDER
                                            physics DEF BUTTON_PHYSICS Physics {
                                            }
                                            translationStep 0.0001
                                          }
                                          TouchSensor {
                                            translation -0.0643129 0.0151085 0.0089
                                            rotation 0.677660201948261 0.519988774250365 -0.519988774252911 -1.950442762558445
                                            children [
                                              Shape {
                                                appearance PBRAppearance {
                                                  baseColor IS secondaryColor
                                                  baseColorMap ImageTexture {
                                                    url [
                                                      "textures/button_2.png"
                                                    ]
                                                  }
                                                  roughness 1
                                                  metalness 0
                                                  textureTransform TextureTransform {
                                                    rotation 3.14159
                                                  }
                                                }
                                                geometry USE BUTTON_CYLINDER
                                              }
                                            ]
                                            name "button 1"
                                            boundingObject USE BUTTON_CYLINDER
                                            physics USE BUTTON_PHYSICS
                                            translationStep 0.0001
                                          }
                                          TouchSensor {
                                            translation -0.0642012 -0.0156443 0.0089
                                            rotation 0.489350331366683 0.616658841332707 -0.616658841335727 -2.23140938423899
                                            children [
                                              Shape {
                                                appearance PBRAppearance {
                                                  baseColor IS secondaryColor
                                                  baseColorMap ImageTexture {
                                                    url [
                                                      "textures/button_3.png"
                                                    ]
                                                  }
                                                  roughness 1
                                                  metalness 0
                                                  textureTransform TextureTransform {
                                                    rotation 3.14159
                                                  }
                                                }
                                                geometry USE BUTTON_CYLINDER
                                              }
                                            ]
                                            name "button 2"
                                            boundingObject USE BUTTON_CYLINDER
                                            physics USE BUTTON_PHYSICS
                                            translationStep 0.0001
                                          }
                                          TouchSensor {
                                            translation -0.0505297 -0.0431944 0.0089
                                            rotation 0.309065263601754 0.67248742100888 -0.672487421012173 -2.542087331833661
                                            children [
                                              Shape {
                                                appearance PBRAppearance {
                                                  baseColor IS secondaryColor
                                                  baseColorMap ImageTexture {
                                                    url [
                                                      "textures/button_4.png"
                                                    ]
                                                  }
                                                  roughness 1
                                                  metalness 0
                                                  textureTransform TextureTransform {
                                                    rotation 3.14159
                                                  }
                                                }
                                                geometry USE BUTTON_CYLINDER
                                              }
                                            ]
                                            name "button 3"
                                            boundingObject USE BUTTON_CYLINDER
                                            physics USE BUTTON_PHYSICS
                                            translationStep 0.0001
                                          }
                                          TouchSensor {
                                            translation 0.0502593 -0.0432647 0.0089
                                            rotation 0.820226959977301 0.40449211001254 -0.404492110014521 -1.767685965976011
                                            children [
                                              Shape {
                                                appearance PBRAppearance {
                                                  baseColor IS secondaryColor
                                                  baseColorMap ImageTexture {
                                                    url [
                                                      "textures/button_1.png"
                                                    ]
                                                  }
                                                  roughness 1
                                                  metalness 0
                                                }
                                                geometry USE BUTTON_CYLINDER
                                              }
                                            ]
                                            name "button 4"
                                            boundingObject USE BUTTON_CYLINDER
                                            physics USE BUTTON_PHYSICS
                                            translationStep 0.0001
                                          }
                                          TouchSensor {
                                            translation 0.064216 -0.0150831 0.0089
                                            rotation 0.677660201948261 0.519988774250365 -0.519988774252911 -1.950442762558445
                                            children [
                                              Shape {
                                                appearance PBRAppearance {
                                                  baseColor IS secondaryColor
                                                  baseColorMap ImageTexture {
                                                    url [
                                                      "textures/button_2.png"
                                                    ]
                                                  }
                                                  roughness 1
                                                  metalness 0
                                                }
                                                geometry USE BUTTON_CYLINDER
                                              }
                                            ]
                                            name "button 5"
                                            boundingObject USE BUTTON_CYLINDER
                                            physics USE BUTTON_PHYSICS
                                            translationStep 0.0001
                                          }
                                          TouchSensor {
                                            translation 0.0642009 0.0156447 0.0089
                                            rotation 0.489350331366683 0.616658841332707 -0.616658841335727 -2.23140938423899
                                            children [
                                              Shape {
                                                appearance PBRAppearance {
                                                  baseColor IS secondaryColor
                                                  baseColorMap ImageTexture {
                                                    url [
                                                      "textures/button_3.png"
                                                    ]
                                                  }
                                                  roughness 1
                                                  metalness 0
                                                }
                                                geometry USE BUTTON_CYLINDER
                                              }
                                            ]
                                            name "button 6"
                                            boundingObject USE BUTTON_CYLINDER
                                            physics USE BUTTON_PHYSICS
                                            translationStep 0.0001
                                          }
                                          TouchSensor {
                                            translation 0.0503023 0.042999 0.0089
                                            rotation 0.309065263601754 0.67248742100888 -0.672487421012173 -2.542087331833661
                                            children [
                                              Shape {
                                                appearance PBRAppearance {
                                                  baseColor IS secondaryColor
                                                  baseColorMap ImageTexture {
                                                    url [
                                                      "textures/button_4.png"
                                                    ]
                                                  }
                                                  roughness 1
                                                  metalness 0
                                                }
                                                geometry USE BUTTON_CYLINDER
                                              }
                                            ]
                                            name "button 7"
                                            boundingObject USE BUTTON_CYLINDER
                                            physics USE BUTTON_PHYSICS
                                            translationStep 0.0001
                                          }
                                          Group {
                                            children IS toolSlot
                                          }
                                        ]
                                        name "link_6_top"
                                        boundingObject Pose {
                                          translation 0 0 0.007
                                          children [
                                            Cylinder {
                                              height 0.04
                                              radius 0.0683
                                            }
                                          ]
                                        }
                                        physics Physics {
                                          density -1
                                          mass 0.5164
                                          centerOfMass [
                                            -0.001 0 0.00625
                                          ]
                                          inertiaMatrix [
                                            0.0009 0.0009 0.0009
                                            0 0 0
                                          ]
                                        }
                                      }
                                    }
                                  ]
                                  name "link_5_6"
                                  boundingObject Group {
                                    children [
                                      Pose {
                                        translation 0 -0.05 -0.14
                                        rotation 1 0 0 -1.5707996938995747
                                        children [
                                          Cylinder {
                                            height 0.095
                                            radius 0.071
                                          }
                                        ]
                                      }
                                      Pose {
                                        translation 0 0 -0.03
                                        children [
                                          Cylinder {
                                            height 0.07
                                            radius 0.073
                                          }
                                        ]
                                      }
                                    ]
                                  }
                                  physics Physics {
                                    density -1
                                    mass 1.5372
                                    centerOfMass [
                                      -0.0007 -0.0177 -0.0654
                                    ]
                                    inertiaMatrix [
                                      0.0139 0.0127 0.0031
                                      0 0 0
                                    ]
                                  }
                                }
                              }
                            ]
                            name "link_4_5"
                            boundingObject Group {
                              children [
                                Pose {
                                  translation 0 0 0.037
                                  children [
                                    Cylinder {
                                      height 0.07
                                      radius 0.08
                                    }
                                  ]
                                }
                                Pose {
                                  translation 0 0.05 0.13
                                  rotation 1 0 0 -1.5707996938995747
                                  children [
                                    Cylinder {
                                      height 0.09
                                      radius 0.069
                                    }
                                  ]
                                }
                              ]
                            }
                            physics Physics {
                              density -1
                              mass 1.5869
                              centerOfMass [
                                -0.0006 0.0204 0.0973
                              ]
                              inertiaMatrix [
                                0.0256 0.0246 0.003
                                0 0 0
                              ]
                            }
                          }
                        }
                      ]
                      name "link_3_4"
                      boundingObject Group {
                        children [
                          Pose {
                            translation 0 0.055 -0.17
                            rotation 1 0 0 -1.5707996938995747
                            children [
                              Cylinder {
                                height 0.1
                                radius 0.07
                              }
                            ]
                          }
                          Pose {
                            translation 0 0 -0.047
                            children [
                              Cylinder {
                                height 0.09
                                radius 0.08
                              }
                            ]
                          }
                        ]
                      }
                      physics Physics {
                        density -1
                        mass 1.771
                        centerOfMass [
                          0 0.0191 -0.0816
                        ]
                        inertiaMatrix [
                          0.0244 0.0227 0.004
                          0 0 0
                        ]
                      }
                    }
                  }
                ]
                name "link_2_3"
                boundingObject Group {
                  children [
                    Pose {
                      translation 0 -0.05 -0.14
                      rotation 1 0 0 -1.5707996938995747
                      children [
                        Cylinder {
                          height 0.09
                          radius 0.09
                        }
                      ]
                    }
                    Pose {
                      translation 0 0 -0.03
                      children [
                        Cylinder {
                          height 0.06
                          radius 0.08
                        }
                      ]
                    }
                    Pose {
                      translation 0 -0.055 0.14
                      rotation 1 0 0 -1.5707996938995747
                      children [
                        Cylinder {
                          height 0.1
                          radius 0.07
                        }
                      ]
                    }
                    Pose {
                      translation 0 0 0.035
                      children [
                        Cylinder {
                          height 0.07
                          radius 0.085
                        }
                      ]
                    }
                  ]
                }
                physics Physics {
                  density -1
                  mass 4.0206
                  centerOfMass [
                    0.0005 -0.0285 0.0538
                  ]
                  inertiaMatrix [
                    0.2185 0.2154 0.0093
                    0 0 0
                  ]
                }
              }
            }
          ]
          name "link_1_2"
          boundingObject Group {
            children [
              Pose {
                translation 0 0 0.037
                children [
                  Cylinder {
                    height 0.07
                    radius 0.09
                  }
                ]
              }
              Pose {
                translation 0 0.05 0.13
                rotation 1 0 0 -1.5707996938995747
                children [
                  Cylinder {
                    height 0.09
                    radius 0.085
                  }
                ]
              }
            ]
          }
          physics Physics {
            density -1
            mass 3.8021
            centerOfMass [
              -0.0004 0.0187 0.0967
            ]
            inertiaMatrix [
              0.0675 0.0669 0.0081
              0 0 0
            ]
          }
        }
      }
    ]
    name IS name
    controller IS controller
    controllerArgs IS controllerArgs
    window IS window
    supervisor IS supervisor
    synchronization IS synchronization
    selfCollision IS selfCollision
    boundingObject Group {
      children [
        Pose {
          translation 0 0 0.173
          children [
            Cylinder {
              height 0.1
              radius 0.09
            }
          ]
        }
        Pose {
          translation 0 0 0.051
          children [
            Box {
              size 0.21 0.32 0.1
            }
          ]
        }
        Pose {
          translation 0 0 0.151
          children [
            Box {
              size 0.21 0.22 0.1
            }
          ]
        }
      ]
    }
    %< if (!fields.staticBase.value) { >%
    physics Physics {
      density -1
      mass 7.7251
      centerOfMass [
        -0.001 0.004 0.094
      ]
      inertiaMatrix [
        0.1572 0.1296 0.0607
        0 0 0
      ]
    }
    %< } >%
  }
}
