#VRML_SIM R2023b utf8

EXTERNPROTO "webots://projects/objects/backgrounds/protos/TexturedBackground.proto"
EXTERNPROTO "webots://projects/objects/backgrounds/protos/TexturedBackgroundLight.proto"
EXTERNPROTO "webots://projects/objects/floors/protos/Floor.proto"

WorldInfo {
  info [
    "Model of pedal racer."
    "A simple example of a passive system including a mechanical loop"
    "Biorob, EPFL"
  ]
  lineScale 0.2
}
Viewpoint {
  orientation -0.21718578410966824 -0.40095154530249383 0.8899821310005113 5.310931635465038
  position -2.729989433682151 2.9947015491392612 1.8155424715721302
}
TexturedBackground {
}
TexturedBackgroundLight {
}
Floor {
}
DEF PEDAL_RACER Solid {
  translation 0 0 0.075
  children [
    DEF RIGHT_PEDAL_GROUP Group {
      children [
        DEF FRONT_CYLINDER Pose {
          translation -0.09 -0.08 0.038
          children [
            DEF PEDAL_FRONT_HALF_CYLINDER Shape {
              appearance DEF RED_PLASTIC PBRAppearance {
                baseColor 0.8 0.094453 0.068437
                roughness 0.04174483200000001
                metalness 0
              }
              geometry Cylinder {
                height 0.0249
                radius 0.055
                subdivision 24
              }
            }
          ]
        }
        DEF MIDDLE_BOX Pose {
          translation 0 -0.08 0.038
          children [
            Shape {
              appearance USE RED_PLASTIC
              geometry Box {
                size 0.2 0.11 0.025
              }
            }
          ]
        }
        DEF BACK_CYLINDER Pose {
          translation 0.09 -0.08 0.038
          children [
            DEF PEDAL_FRONT_HALF_CYLINDER Shape {
              appearance DEF RED_PLASTIC PBRAppearance {
                baseColor 0.8 0.094453 0.068437
                roughness 0.04174483200000001
                metalness 0
              }
              geometry Cylinder {
                height 0.0249
                radius 0.055
                subdivision 24
              }
            }
          ]
        }
      ]
    }
    DEF PLASTIC_HINGES Group {
      children [
        DEF BACK_HINGE Pose {
          translation -0.11 -0.144 0.038
          rotation -1 0 0 1.5708
          children [
            Shape {
              appearance USE RED_PLASTIC
              geometry Cylinder {
                height 0.036
                radius 0.013
                subdivision 24
              }
            }
          ]
        }
        DEF FRONT_HINGE Pose {
          translation 0.11 -0.144 0.038
          rotation -1 0 0 1.5708
          children [
            Shape {
              appearance USE RED_PLASTIC
              geometry Cylinder {
                height 0.036
                radius 0.013
                subdivision 24
              }
            }
          ]
        }
      ]
    }
    DEF BACK_RIGHT_AXLE_HINGE HingeJoint {
      jointParameters HingeJointParameters {
        axis 0 1 0
        anchor -0.11 -0.08 0.038
      }
      endPoint DEF BACK_AXLE Solid {
        rotation 1 0 0 0
        children [
          DEF BACK_RIGHT_WHEEL Solid {
            rotation 0 -1 0 0
            children [
              Group {
                children [
                  DEF BLACK_TIRE Pose {
                    translation -0.11 -0.2125 0
                    rotation -1 0 0 1.5708
                    children [
                      Shape {
                        appearance PBRAppearance {
                          baseColor 0.036484 0.036484 0.036484
                          roughness 0.2772110000000001
                          metalness 0
                        }
                        geometry Cylinder {
                          height 0.025
                          radius 0.075
                          subdivision 24
                        }
                      }
                    ]
                  }
                  DEF RED_RIM Pose {
                    translation -0.11 -0.2125 0
                    rotation -1 0 0 1.5708
                    children [
                      Shape {
                        appearance USE RED_PLASTIC
                        geometry Cylinder {
                          height 0.0255
                          radius 0.058
                          subdivision 24
                        }
                      }
                    ]
                  }
                  DEF ANCHOR Pose {
                    translation -0.11 -0.19 0.038
                    rotation -1 0 0 1.5708
                    children [
                      Shape {
                        appearance USE RED_PLASTIC
                        geometry Cylinder {
                          height 0.025
                          radius 0.013
                          subdivision 24
                        }
                      }
                    ]
                  }
                ]
              }
            ]
            name "back right wheel"
            boundingObject USE BLACK_TIRE
            physics DEF PLASTIC_DENSITY Physics {
              density 750
            }
          }
          DEF BACK_LEFT_WHEEL Solid {
            rotation 0 -1 0 0
            children [
              Group {
                children [
                  DEF BLACK_TIRE Pose {
                    translation -0.11 0.2125 0
                    rotation -1 0 0 1.5708
                    children [
                      Shape {
                        appearance PBRAppearance {
                          baseColor 0.036484 0.036484 0.036484
                          roughness 0.2772110000000001
                          metalness 0
                        }
                        geometry Cylinder {
                          height 0.025
                          radius 0.075
                          subdivision 24
                        }
                      }
                    ]
                  }
                  DEF RED_RIM Pose {
                    translation -0.11 0.2125 0
                    rotation -1 0 0 1.5708
                    children [
                      Shape {
                        appearance USE RED_PLASTIC
                        geometry Cylinder {
                          height 0.0255
                          radius 0.058
                          subdivision 24
                        }
                      }
                    ]
                  }
                  DEF ANCHOR Pose {
                    translation -0.11 0.19 -0.038
                    rotation -1 0 0 1.5708
                    children [
                      Shape {
                        appearance USE RED_PLASTIC
                        geometry Cylinder {
                          height 0.025
                          radius 0.013
                          subdivision 24
                        }
                      }
                    ]
                  }
                ]
              }
            ]
            name "back left wheel"
            boundingObject USE BLACK_TIRE
            physics USE PLASTIC_DENSITY
          }
          DEF LEFT_PEDAL_HINGE HingeJoint {
            jointParameters HingeJointParameters {
              axis 0 1 0
              anchor -0.11 0.08 -0.038
            }
            endPoint DEF LEFT_PEDAL Solid {
              rotation 1 0 0 0
              children [
                DEF LEFT_PEDAL_GROUP Group {
                  children [
                    DEF FRONT_CYLINDER Pose {
                      translation -0.09 0.08 -0.038
                      children [
                        DEF PEDAL_FRONT_HALF_CYLINDER Shape {
                          appearance DEF RED_PLASTIC PBRAppearance {
                            baseColor 0.8 0.094453 0.068437
                            roughness 0.04174483200000001
                            metalness 0
                          }
                          geometry Cylinder {
                            height 0.0249
                            radius 0.055
                            subdivision 24
                          }
                        }
                      ]
                    }
                    DEF MIDDLE_BOX Pose {
                      translation 0 0.08 -0.038
                      children [
                        Shape {
                          appearance USE RED_PLASTIC
                          geometry Box {
                            size 0.2 0.11 0.025
                          }
                        }
                      ]
                    }
                    DEF BACK_CYLINDER Pose {
                      translation 0.09 0.08 -0.038
                      children [
                        DEF PEDAL_FRONT_HALF_CYLINDER Shape {
                          appearance DEF RED_PLASTIC PBRAppearance {
                            baseColor 0.8 0.094453 0.068437
                            roughness 0.04174483200000001
                            metalness 0
                          }
                          geometry Cylinder {
                            height 0.0249
                            radius 0.055
                            subdivision 24
                          }
                        }
                      ]
                    }
                  ]
                }
                DEF PLASTIC_HINGES Group {
                  children [
                    DEF BACK_HINGE Pose {
                      translation -0.11 0.144 -0.038
                      rotation -1 0 0 1.5708
                      children [
                        Shape {
                          appearance USE RED_PLASTIC
                          geometry Cylinder {
                            height 0.036
                            radius 0.013
                            subdivision 24
                          }
                        }
                      ]
                    }
                    DEF FRONT_HINGE Pose {
                      translation 0.11 0.144 -0.038
                      rotation -1 0 0 1.5708
                      children [
                        Shape {
                          appearance USE RED_PLASTIC
                          geometry Cylinder {
                            height 0.036
                            radius 0.013
                            subdivision 24
                          }
                        }
                      ]
                    }
                  ]
                }
                DEF FRONT_AXLE_HINGE HingeJoint {
                  jointParameters HingeJointParameters {
                    axis 0 1 0
                    anchor 0.11 0.08 -0.038
                  }
                  endPoint SolidReference {
                    solidName "front axle"
                  }
                }
              ]
              name "left pedal"
              boundingObject USE LEFT_PEDAL_GROUP
              physics USE PLASTIC_DENSITY
            }
          }
          DEF AXLE_GROUP Group {
            children [
              DEF MIDDLE_SEGMENT Pose {
                translation -0.11 0 0
                rotation -1 0 0 -0.5
                children [
                  DEF SMALL_CAPSULE Shape {
                    appearance DEF METAL PBRAppearance {
                      baseColor 0.556786 0.618021 0.668055
                      roughness 0.10093799999999997
                      metalness 0
                    }
                    geometry DEF SMALL_CAPSULE_SEGMENT Capsule {
                      height 0.07
                      radius 0.007
                    }
                  }
                ]
              }
              DEF UPPER_SEGMENT Pose {
                translation -0.11 -0.105 0.038
                rotation -1 0 0 1.5708
                children [
                  DEF LONG_CAPSULE Shape {
                    appearance DEF METAL PBRAppearance {
                      baseColor 0.556786 0.618021 0.668055
                      roughness 0.10093799999999997
                      metalness 0
                    }
                    geometry Capsule {
                      height 0.17
                      radius 0.007
                    }
                  }
                ]
              }
              DEF LOWER_SEGMENT Pose {
                translation -0.11 0.105 -0.038
                rotation -1 0 0 1.5708
                children [
                  USE LONG_CAPSULE
                ]
              }
            ]
          }
        ]
        name "back axle"
        boundingObject USE AXLE_GROUP
        physics DEF METAL_DENSITY Physics {
          density 2500
        }
      }
    }
    DEF FRONT_RIGHT_AXLE_HINGE HingeJoint {
      jointParameters HingeJointParameters {
        axis 0 1 0
        anchor 0.11 -0.08 0.038
      }
      endPoint DEF FRONT_AXLE Solid {
        rotation 1 0 0 0
        children [
          DEF FRONT_RIGHT_WHEEL Solid {
            rotation 0 -1 0 0
            children [
              Group {
                children [
                  DEF BLACK_TIRE Pose {
                    translation 0.11 -0.2125 0
                    rotation -1 0 0 1.5708
                    children [
                      Shape {
                        appearance PBRAppearance {
                          baseColor 0.036484 0.036484 0.036484
                          roughness 0.2772110000000001
                          metalness 0
                        }
                        geometry Cylinder {
                          height 0.025
                          radius 0.075
                          subdivision 24
                        }
                      }
                    ]
                  }
                  DEF RED_RIM Pose {
                    translation 0.11 -0.2125 0
                    rotation -1 0 0 1.5708
                    children [
                      Shape {
                        appearance USE RED_PLASTIC
                        geometry Cylinder {
                          height 0.0255
                          radius 0.058
                          subdivision 24
                        }
                      }
                    ]
                  }
                  DEF ANCHOR Pose {
                    translation 0.11 -0.19 0.038
                    rotation -1 0 0 1.5708
                    children [
                      Shape {
                        appearance USE RED_PLASTIC
                        geometry Cylinder {
                          height 0.025
                          radius 0.013
                          subdivision 24
                        }
                      }
                    ]
                  }
                ]
              }
            ]
            name "front right wheel"
            boundingObject USE BLACK_TIRE
            physics USE PLASTIC_DENSITY
          }
          DEF FRONT_LEFT_WHEEL Solid {
            rotation 0 -1 0 0
            children [
              Group {
                children [
                  DEF BLACK_TIRE Pose {
                    translation 0.11 0.2125 0
                    rotation -1 0 0 1.5708
                    children [
                      Shape {
                        appearance PBRAppearance {
                          baseColor 0.036484 0.036484 0.036484
                          roughness 0.2772110000000001
                          metalness 0
                        }
                        geometry Cylinder {
                          height 0.025
                          radius 0.075
                          subdivision 24
                        }
                      }
                    ]
                  }
                  DEF RED_RIM Pose {
                    translation 0.11 0.2125 0
                    rotation -1 0 0 1.5708
                    children [
                      Shape {
                        appearance USE RED_PLASTIC
                        geometry Cylinder {
                          height 0.0255
                          radius 0.058
                          subdivision 24
                        }
                      }
                    ]
                  }
                  DEF ANCHOR Pose {
                    translation 0.11 0.19 -0.038
                    rotation -1 0 0 1.5708
                    children [
                      Shape {
                        appearance USE RED_PLASTIC
                        geometry Cylinder {
                          height 0.025
                          radius 0.013
                          subdivision 24
                        }
                      }
                    ]
                  }
                ]
              }
            ]
            name "front left wheel"
            boundingObject USE BLACK_TIRE
            physics USE PLASTIC_DENSITY
          }
          DEF AXLE_GROUP Group {
            children [
              DEF MIDDLE_SEGMENT Pose {
                translation 0.11 0 0
                rotation -1 0 0 -0.5
                children [
                  USE SMALL_CAPSULE
                ]
              }
              DEF UPPER_SEGMENT Pose {
                translation 0.11 -0.105 0.038
                rotation -1 0 0 1.5708
                children [
                  USE LONG_CAPSULE
                ]
              }
              DEF LOWER_SEGMENT Pose {
                translation 0.11 0.105 -0.038
                rotation -1 0 0 1.5708
                children [
                  USE LONG_CAPSULE
                ]
              }
            ]
          }
        ]
        name "front axle"
        boundingObject USE AXLE_GROUP
        physics USE METAL_DENSITY
      }
    }
  ]
  name "robot"
  boundingObject USE RIGHT_PEDAL_GROUP
  physics USE PLASTIC_DENSITY
}
