#VRML_SIM R2023b utf8
# license: Copyright Cyberbotics Ltd. Licensed for use only with Webots.
# license url: https://cyberbotics.com/webots_assets_license
# documentation url: https://webots.cloud/run?url=https://github.com/cyberbotics/webots/blob/released/projects/robots/k-team/khepera1/protos/Khepera1.proto
# keywords: robot/wheeled
# The "Khepera" robot is a two-wheeled robot produced by K-Team.
# template language: javascript

PROTO Khepera1 [
  field SFVec3f    translation     0 0 0         # Is `Pose.translation`.
  field SFRotation rotation        0 0 1 0       # Is `Pose.rotation`.
  field SFString   name            "Khepera"     # Is `Solid.name`.
  field SFString   controller      "braitenberg" # Is `Robot.controller`.
  field MFString   controllerArgs  []            # Is `Robot.controllerArgs`.
  field SFString   window          "<generic>"   # Is `Robot.window`.
  field SFString   customData      ""            # Is `Robot.customData`.
  field SFBool     supervisor      FALSE         # Is `Robot.supervisor`.
  field SFBool     synchronization TRUE          # Is `Robot.synchronization`.
  field MFNode     extensionSlot   []            # Extends the robot with new nodes in the extension slot.
  field SFBool     kinematic       FALSE         # Defines whether the robot motion and its sensors are computed according to a 2D kinematics algorithm.
]
{
  %<
    const kinematic = fields.kinematic.value;
  >%
  Robot {
    translation IS translation
    rotation IS rotation
    controller IS controller
    controllerArgs IS controllerArgs
    window IS window
    customData IS customData
    supervisor IS supervisor
    synchronization IS synchronization
    name IS name
    children [
      Group {
        children IS extensionSlot
      }
      Shape {
        appearance PBRAppearance {
          baseColor 0.0539951 0.505576 0.0897663
          roughness 0.4
          metalness 0
        }
        geometry IndexedFaceSet {
          coord Coordinate {
            point [
              0.009 -0.0276 0.0025 0.0194 -0.0215 0.0025 0.0265 -0.0118 0.0025 0.029 0 0.0025 0.0265 0.0118 0.0025 0.0194 0.0215 0.0025 0.009 0.0276 0.0025 0.009 0.0236 0.02 -0.009 0.0236 0.02 -0.009 -0.0236 0.02 0.009 -0.0236 0.02 -0.009 0.0276 0.0025 -0.0194 0.0215 0.0025 -0.0265 0.0118 0.0025 -0.029 0 0.0025 -0.0265 -0.0118 0.0025 -0.0194 -0.0215 0.0025 -0.009 -0.0276 0.0025 0.009 -0.0276 0.001 0.0194 -0.0215 0.001 0.0265 -0.0118 0.001 0.029 0 0.001 0.0265 0.0118 0.001 0.0194 0.0215 0.001 0.009 0.0276 0.001 0.009 0.0236 0.001 -0.009 0.0236 0.001 -0.009 -0.0236 0.001 0.009 -0.0236 0.001 -0.009 0.0276 0.001 -0.0194 0.0215 0.001 -0.0265 0.0118 0.001 -0.029 0 0.001 -0.0265 -0.0118 0.001 -0.0194 -0.0215 0.001 -0.009 -0.0276 0.001
            ]
          }
          coordIndex [
            0, 1, 2, 3, 4, 5, 6, -1, 11, 12, 13, 14, 15, 16, 17, -1, 24, 23, 22, 21, 20, 19, 18, -1, 35, 34, 33, 32, 31, 30, 29, -1, 1, 0, 18, 19, -1, 2, 1, 19, 20, -1, 3, 2, 20, 21, -1, 4, 3, 21, 22, -1, 5, 4, 22, 23, -1, 6, 5, 23, 24, -1, 0, 6, 24, 18, -1, 17, 16, 34, 35, -1, 16, 15, 33, 34, -1, 15, 14, 32, 33, -1, 14, 13, 31, 32, -1, 13, 12, 30, 31, -1, 12, 11, 29, 30, -1, 11, 17, 35, 29, -1, 7, 10, 28, 25, -1, 9, 8, 26, 27, -1, 8, 7, 25, 26, -1, 10, 9, 27, 28, -1, 28, 27, 26, 25, -1
          ]
          creaseAngle 0.5
        }
      }
      HingeJoint {
        jointParameters HingeJointParameters {
          axis 0 1 0
          anchor 0 0 0.0075
        }
        device [
          RotationalMotor {
            name "left wheel motor"
          }
          PositionSensor {
            name "left wheel sensor"
            resolution 0.0314
          }
        ]
        endPoint Solid {
          translation 0 0.026 0.0075
          rotation 0.65025 -0.65025 0.392872 -2.392899
          children [
            DEF WHEEL Pose {
              rotation 0.577387 -0.577332 0.577332 -2.094339
              children [
                Shape {
                  appearance PBRAppearance {
                    baseColor 0.778497 0.793743 0.8
                    metalness 0
                    roughness 0.3
                  }
                  geometry Cylinder {
                    height 0.003
                    radius 0.0075
                  }
                }
              ]
            }
          ]
          name "left wheel"
          boundingObject USE WHEEL
          %< if (!kinematic) { >%
            physics Physics {
            }
          %< } >%
        }
      }
      HingeJoint {
        jointParameters HingeJointParameters {
          axis 0 1 0
          anchor 0 0 0.0075
        }
        device [
          RotationalMotor {
            name "right wheel motor"
          }
          PositionSensor {
            name "right wheel sensor"
            resolution 0.0314
          }
        ]
        endPoint Solid {
          translation 0 -0.026 0.0075
          rotation 0.643415 -0.643415 0.41477 -2.355245
          children [
            USE WHEEL
          ]
          name "right wheel"
          boundingObject USE WHEEL
          %< if (!kinematic) { >%
            physics Physics {
            }
          %< } >%
        }
      }
      Pose {
        translation 0 0 0.02
        rotation 0 0 1 -1.570796
        children [
          Shape {
            appearance PBRAppearance {
              baseColor 0.015 0.48 0.1796
              metalness 0
              roughness 0.4
            }
            geometry Cylinder {
              height 0.0015
              radius 0.028
            }
          }
        ]
      }
      DEF DS0 DistanceSensor {
        translation 0.012 0.0245 0.0145
        rotation 0.610934 0.559803 0.559803 2.044752
        children [
          DEF SFH900 Group {
            children [
              Shape {
                appearance PBRAppearance {
                  baseColor 0.3 0.2 0.2
                  metalness 0
                  roughness 0.5
                }
                geometry Box {
                  size 0.002 0.003 0.006
                }
              }
              Shape {
                appearance Appearance {
                  material Material {
                    diffuseColor 0.02 0.02 0.02
                  }
                }
                geometry IndexedLineSet {
                  coord Coordinate {
                    point [
                      0 0 0
                      0 -0.013 0
                      0 0 0.0015
                      0 -0.013 0.0015
                      0 0 -0.0015
                      0 -0.013 -0.0015
                    ]
                  }
                  coordIndex [
                    0, 1, -1, 2, 3, -1, 4, 5, -1
                  ]
                }
              }
            ]
          }
        ]
        name "ds0"
        model "SFH900"
        description "infra-red"
        lookupTable [
          0 1023 0
          0.05 0 0.01
        ]
        type "infra-red"
      }
      DEF DS1 DistanceSensor {
        translation 0.021 0.0185 0.0145
        rotation 0.862854 0.357409 0.357409 1.717773
        children [
          USE SFH900
        ]
        name "ds1"
        model "SFH900"
        description "infra-red"
        lookupTable [
          0 1023 0
          0.05 0 0.01
        ]
        type "infra-red"
      }
      DEF DS2 DistanceSensor {
        translation 0.027 0.0075 0.0145
        rotation -1 0 0 -1.570796
        children [
          USE SFH900
        ]
        name "ds2"
        lookupTable [
          0 1023 0
          0.05 0 0.01
        ]
        type "infra-red"
      }
      DEF DS3 DistanceSensor {
        translation 0.027 -0.0075 0.0145
        rotation -1 0 0 -1.570796
        children [
          USE SFH900
        ]
        name "ds3"
        lookupTable [
          0 1023 0
          0.05 0 0.01
        ]
        type "infra-red"
      }
      DEF DS4 DistanceSensor {
        translation 0.021 -0.0185 0.0145
        rotation 0.862857 -0.357406 -0.357406 1.717771
        children [
          USE SFH900
        ]
        name "ds4"
        lookupTable [
          0 1023 0
          0.05 0 0.01
        ]
        type "infra-red"
      }
      DEF DS5 DistanceSensor {
        translation 0.012 -0.0245 0.0145
        rotation 0.610937 -0.559802 -0.559802 2.044747
        children [
          USE SFH900
        ]
        name "ds5"
        lookupTable [
          0 1023 0
          0.05 0 0.01
        ]
        type "infra-red"
      }
      DEF DS6 DistanceSensor {
        translation -0.026 -0.009 0.0145
        rotation 0 -0.707107 -0.707107 -3.14159
        children [
          USE SFH900
        ]
        name "ds6"
        lookupTable [
          0 1023 0
          0.05 0 0.01
        ]
        type "infra-red"
      }
      DEF DS7 DistanceSensor {
        translation -0.026 0.009 0.0145
        rotation 0 -0.707107 -0.707107 -3.14159
        children [
          USE SFH900
        ]
        name "ds7"
        lookupTable [
          0 1023 0
          0.05 0 0.01
        ]
        type "infra-red"
      }
      DEF LS0 LightSensor {
        translation 0.012 0.0245 0.0144
        rotation 0.610934 0.559803 0.559803 2.044752
        name "ls0"
        lookupTable [
          0 500 0.1
          0.2 10 0.1
        ]
      }
      DEF LS1 LightSensor {
        translation 0.021 0.0185 0.0144
        rotation 0.862854 0.357409 0.357409 1.717773
        name "ls1"
        lookupTable [
          0 500 0.1
          0.2 10 0.1
        ]
      }
      DEF LS2 LightSensor {
        translation 0.027 0.0075 0.0144
        rotation -1 0 0 -1.570796
        name "ls2"
        lookupTable [
          0 500 0.1
          0.2 10 0.1
        ]
      }
      DEF LS3 LightSensor {
        translation 0.027 -0.0075 0.0144
        rotation -1 0 0 -1.570796
        name "ls3"
        lookupTable [
          0 500 0.1
          0.2 10 0.1
        ]
      }
      DEF LS4 LightSensor {
        translation 0.021 -0.0185 0.0144
        rotation 0.862857 -0.357406 -0.357406 1.717771
        name "ls4"
        lookupTable [
          0 500 0.1
          0.2 10 0.1
        ]
      }
      DEF LS5 LightSensor {
        translation 0.012 -0.0245 0.0144
        rotation 0.610937 -0.559802 -0.559802 2.044747
        name "ls5"
        lookupTable [
          0 500 0.1
          0.2 10 0.1
        ]
      }
      DEF LS6 LightSensor {
        translation -0.026 -0.009 0.0144
        rotation 0 -0.707107 -0.707107 -3.14159
        name "ls6"
        lookupTable [
          0 500 0.1
          0.2 10 0.1
        ]
      }
      DEF LS7 LightSensor {
        translation -0.026 0.009 0.0144
        rotation 0 -0.707107 -0.707107 -3.14159
        name "ls7"
        lookupTable [
          0 500 0.1
          0.2 10 0.1
        ]
      }
      DEF LED0 LED {
        translation 0.022 -0.013 0.021
        rotation 0.57735 -0.57735 -0.57735 2.094395
        children [
          Shape {
            appearance PBRAppearance {
              baseColor 0.501961 0.501961 0.501961
              metalness 0
            }
            geometry Box {
              size 0.002 0.002 0.002
            }
          }
        ]
        name "led0"
      }
      DEF LED1 LED {
        translation 0.024 -0.01 0.021
        rotation 0.57735 -0.57735 -0.57735 2.094395
        children [
          Shape {
            appearance PBRAppearance {
              baseColor 0.501961 0.501961 0.501961
              metalness 0
            }
            geometry Box {
              size 0.002 0.002 0.002
            }
          }
        ]
        name "led1"
      }
      DEF RS232_OUT Emitter {
        name "rs232_out"
        type "serial"
        range 1000
        baudRate 57600
      }
      DEF RS232_IN Receiver {
        name "rs232_in"
        type "serial"
        baudRate 57600
      }
    ]
    model "Khepera"
    description "A mini mobile robot by K-Team SA"
    contactMaterial "khepera"
    boundingObject Pose {
      translation 0 0 0.012
      rotation 0 0 1 -1.570796
      children [
        Cylinder {
          height 0.02
          radius 0.0285
        }
      ]
    }
    %< if (!kinematic) { >%
      physics Physics {
        centerOfMass [
          0 0 0.005
        ]
      }
    %< } >%
  }
}
