#VRML_SIM R2023b utf8

EXTERNPROTO "webots://projects/objects/backgrounds/protos/TexturedBackground.proto"
EXTERNPROTO "webots://projects/objects/backgrounds/protos/TexturedBackgroundLight.proto"
EXTERNPROTO "webots://projects/objects/floors/protos/Floor.proto"

WorldInfo {
  info [
    "Robot walking down a slope using passive dynamics"
    "Author: Sasha Voloshina, University of Michigan"
  ]
  title "Passive Dynamic Walker"
  basicTimeStep 6
  contactProperties [
    ContactProperties {
      bounce 0
    }
  ]
}
Viewpoint {
  orientation -0.23830648969618556 0.04583240692404771 0.9701079359763172 2.623402661380206
  position 2.4525452714054423 -1.5943439993260093 1.5647257640359626
}
TexturedBackground {
}
TexturedBackgroundLight {
}
Floor {
}
DEF SLOPE Solid {
  translation 0 -0.26 -0.054
  rotation 1 0 0 0.155
  children [
    DEF slope Shape {
      appearance PBRAppearance {
        baseColor 0.501961 0.501961 0.501961
        roughness 1
        metalness 0
        emissiveColor 0.501961 0.501961 0.501961
      }
      geometry DEF BOX Box {
        size 0.465 1.3 0.26
      }
    }
  ]
  boundingObject DEF slope Shape {
    appearance PBRAppearance {
      baseColor 0.501961 0.501961 0.501961
      roughness 1
      metalness 0
      emissiveColor 0.501961 0.501961 0.501961
    }
    geometry USE BOX
  }
}
DEF walker Solid {
  translation 0 0.32 0.275659
  rotation -1 0 0 6
  children [
    DEF outer_upper Group {
      children [
        Pose {
          translation 0.05 0 0.08
          children [
            Shape {
              appearance PBRAppearance {
                baseColor 0.501961 0.501961 0.501961
                roughness 1
                metalness 0
              }
              geometry Box {
                size 0.01 0.01 0.1
              }
            }
          ]
        }
        Pose {
          translation -0.05 0 0.08
          children [
            Shape {
              appearance PBRAppearance {
                baseColor 0.501961 0.501961 0.501961
                roughness 1
                metalness 0
              }
              geometry Box {
                size 0.01 0.01 0.1
              }
            }
          ]
        }
        Pose {
          translation 0 0 0.125
          rotation 0 -1 0 1.571
          children [
            Shape {
              appearance PBRAppearance {
                baseColor 0.501961 0.501961 0.501961
                roughness 1
                metalness 0
              }
              geometry Box {
                size 0.01 0.01 0.1
              }
            }
          ]
        }
      ]
    }
    DEF inner_upper HingeJoint {
      jointParameters HingeJointParameters {
        axis -1 0 0
        anchor 0 0 0.13
        minStop -1.19048
        maxStop 1.19048
      }
      endPoint Solid {
        translation 0 0 0.13
        rotation -1 0 0 0.6
        children [
          DEF motor_top Group {
            children [
              Pose {
                translation -0.03 0 -0.05
                children [
                  Shape {
                    appearance PBRAppearance {
                      baseColor 0.501961 0 1
                      roughness 1
                      metalness 0
                      emissiveColor 0 0 0.627451
                    }
                    geometry Box {
                      size 0.01 0.01 0.1
                    }
                  }
                ]
              }
              Pose {
                translation 0.03 0 -0.05
                children [
                  Shape {
                    appearance PBRAppearance {
                      baseColor 0.501961 0 1
                      roughness 1
                      metalness 0
                      emissiveColor 0 0 0.627451
                    }
                    geometry Box {
                      size 0.01 0.01 0.1
                    }
                  }
                ]
              }
            ]
          }
          DEF inner_lower HingeJoint {
            jointParameters HingeJointParameters {
              axis -1 0 0
              anchor 0 0 -0.095
              minStop -3.14
              maxStop 0.1
            }
            endPoint Solid {
              translation 0 0 -0.095
              rotation -1 0 0 0
              children [
                DEF inner_lower Group {
                  children [
                    Pose {
                      translation 0.03 0 -0.05
                      children [
                        Shape {
                          appearance PBRAppearance {
                            baseColor 0.501961 0 1
                            roughness 1
                            metalness 0
                            emissiveColor 0 0 0.627451
                          }
                          geometry Box {
                            size 0.01 0.01 0.1
                          }
                        }
                      ]
                    }
                    Pose {
                      translation -0.03 0 -0.05
                      children [
                        Shape {
                          appearance PBRAppearance {
                            baseColor 0.501961 0 1
                            roughness 1
                            metalness 0
                            emissiveColor 0 0 0.627451
                          }
                          geometry Box {
                            size 0.01 0.01 0.1
                          }
                        }
                      ]
                    }
                  ]
                }
                DEF inner_foot HingeJoint {
                  jointParameters HingeJointParameters {
                    axis -1 0 0
                    anchor 0 0 -0.1
                    staticFriction 10
                  }
                  endPoint Solid {
                    translation 0 0 -0.1
                    rotation -1 0 0 0
                    children [
                      DEF inner_foot Group {
                        children [
                          Pose {
                            translation -0.03 0 0
                            rotation 0 -1 0 4.71
                            children [
                              Shape {
                                appearance PBRAppearance {
                                  baseColor 0.8 0.8 0.8
                                  roughness 1
                                  metalness 0
                                }
                                geometry Cylinder {
                                  height 0.01
                                  radius 0.005
                                }
                              }
                            ]
                          }
                          Pose {
                            translation -0.03 -0.0027 -0.00175
                            rotation 0 -1 0 4.71
                            children [
                              Shape {
                                appearance PBRAppearance {
                                  baseColor 0.8 0.8 0.8
                                  roughness 1
                                  metalness 0
                                }
                                geometry Cylinder {
                                  height 0.01
                                  radius 0.005
                                }
                              }
                            ]
                          }
                          Pose {
                            translation -0.03 -0.0056 -0.00315
                            rotation 0 -1 0 4.71
                            children [
                              Shape {
                                appearance PBRAppearance {
                                  baseColor 0.8 0.8 0.8
                                  roughness 1
                                  metalness 0
                                }
                                geometry Cylinder {
                                  height 0.01
                                  radius 0.005
                                }
                              }
                            ]
                          }
                          Pose {
                            translation -0.03 -0.00865 -0.0042
                            rotation 0 -1 0 4.71
                            children [
                              Shape {
                                appearance PBRAppearance {
                                  baseColor 0.8 0.8 0.8
                                  roughness 1
                                  metalness 0
                                }
                                geometry Cylinder {
                                  height 0.01
                                  radius 0.005
                                }
                              }
                            ]
                          }
                          Pose {
                            translation -0.03 -0.0118 -0.0048
                            rotation 0 -1 0 4.71
                            children [
                              Shape {
                                appearance PBRAppearance {
                                  baseColor 0.8 0.8 0.8
                                  roughness 1
                                  metalness 0
                                }
                                geometry Cylinder {
                                  height 0.01
                                  radius 0.005
                                }
                              }
                            ]
                          }
                          Pose {
                            translation -0.03 -0.015 -0.005
                            rotation 0 -1 0 4.71
                            children [
                              Shape {
                                appearance PBRAppearance {
                                  baseColor 0.8 0.8 0.8
                                  roughness 1
                                  metalness 0
                                }
                                geometry Cylinder {
                                  height 0.01
                                  radius 0.005
                                }
                              }
                            ]
                          }
                          Pose {
                            translation -0.03 -0.0182 -0.0048
                            rotation 0 -1 0 4.71
                            children [
                              Shape {
                                appearance PBRAppearance {
                                  baseColor 0.8 0.8 0.8
                                  roughness 1
                                  metalness 0
                                }
                                geometry Cylinder {
                                  height 0.01
                                  radius 0.005
                                }
                              }
                            ]
                          }
                          Pose {
                            translation -0.03 -0.02135 -0.0042
                            rotation 0 -1 0 4.71
                            children [
                              Shape {
                                appearance PBRAppearance {
                                  baseColor 0.8 0.8 0.8
                                  roughness 1
                                  metalness 0
                                }
                                geometry Cylinder {
                                  height 0.01
                                  radius 0.005
                                }
                              }
                            ]
                          }
                          Pose {
                            translation -0.03 -0.0244 -0.00315
                            rotation 0 -1 0 4.71
                            children [
                              Shape {
                                appearance PBRAppearance {
                                  baseColor 0.8 0.8 0.8
                                  roughness 1
                                  metalness 0
                                }
                                geometry Cylinder {
                                  height 0.01
                                  radius 0.005
                                }
                              }
                            ]
                          }
                          Pose {
                            translation -0.03 -0.0273 -0.00175
                            rotation 0 -1 0 4.71
                            children [
                              Shape {
                                appearance PBRAppearance {
                                  baseColor 0.8 0.8 0.8
                                  roughness 1
                                  metalness 0
                                }
                                geometry Cylinder {
                                  height 0.01
                                  radius 0.005
                                }
                              }
                            ]
                          }
                          Pose {
                            translation 0.03 0 0
                            rotation 0 -1 0 4.71
                            children [
                              Shape {
                                appearance PBRAppearance {
                                  baseColor 0.8 0.8 0.8
                                  roughness 1
                                  metalness 0
                                }
                                geometry Cylinder {
                                  height 0.01
                                  radius 0.005
                                }
                              }
                            ]
                          }
                          Pose {
                            translation 0.03 -0.0027 -0.00175
                            rotation 0 -1 0 4.71
                            children [
                              Shape {
                                appearance PBRAppearance {
                                  baseColor 0.8 0.8 0.8
                                  roughness 1
                                  metalness 0
                                }
                                geometry Cylinder {
                                  height 0.01
                                  radius 0.005
                                }
                              }
                            ]
                          }
                          Pose {
                            translation 0.03 -0.0056 -0.00315
                            rotation 0 -1 0 4.71
                            children [
                              Shape {
                                appearance PBRAppearance {
                                  baseColor 0.8 0.8 0.8
                                  roughness 1
                                  metalness 0
                                }
                                geometry Cylinder {
                                  height 0.01
                                  radius 0.005
                                }
                              }
                            ]
                          }
                          Pose {
                            translation 0.03 -0.00865 -0.0042
                            rotation 0 -1 0 4.71
                            children [
                              Shape {
                                appearance PBRAppearance {
                                  baseColor 0.8 0.8 0.8
                                  roughness 1
                                  metalness 0
                                }
                                geometry Cylinder {
                                  height 0.01
                                  radius 0.005
                                }
                              }
                            ]
                          }
                          Pose {
                            translation 0.03 -0.0118 -0.0048
                            rotation 0 -1 0 4.71
                            children [
                              Shape {
                                appearance PBRAppearance {
                                  baseColor 0.8 0.8 0.8
                                  roughness 1
                                  metalness 0
                                }
                                geometry Cylinder {
                                  height 0.01
                                  radius 0.005
                                }
                              }
                            ]
                          }
                          Pose {
                            translation 0.03 -0.015 -0.005
                            rotation 0 -1 0 4.71
                            children [
                              Shape {
                                appearance PBRAppearance {
                                  baseColor 0.8 0.8 0.8
                                  roughness 1
                                  metalness 0
                                }
                                geometry Cylinder {
                                  height 0.01
                                  radius 0.005
                                }
                              }
                            ]
                          }
                          Pose {
                            translation 0.03 -0.0182 -0.0048
                            rotation 0 -1 0 4.71
                            children [
                              Shape {
                                appearance PBRAppearance {
                                  baseColor 0.8 0.8 0.8
                                  roughness 1
                                  metalness 0
                                }
                                geometry Cylinder {
                                  height 0.01
                                  radius 0.005
                                }
                              }
                            ]
                          }
                          Pose {
                            translation 0.03 -0.02135 -0.0042
                            rotation 0 -1 0 4.71
                            children [
                              Shape {
                                appearance PBRAppearance {
                                  baseColor 0.8 0.8 0.8
                                  roughness 1
                                  metalness 0
                                }
                                geometry Cylinder {
                                  height 0.01
                                  radius 0.005
                                }
                              }
                            ]
                          }
                          Pose {
                            translation 0.03 -0.0244 -0.00315
                            rotation 0 -1 0 4.71
                            children [
                              Shape {
                                appearance PBRAppearance {
                                  baseColor 0.8 0.8 0.8
                                  roughness 1
                                  metalness 0
                                }
                                geometry Cylinder {
                                  height 0.01
                                  radius 0.005
                                }
                              }
                            ]
                          }
                          Pose {
                            translation 0.03 -0.0273 -0.00175
                            rotation 0 -1 0 4.71
                            children [
                              Shape {
                                appearance PBRAppearance {
                                  baseColor 0.8 0.8 0.8
                                  roughness 1
                                  metalness 0
                                }
                                geometry Cylinder {
                                  height 0.01
                                  radius 0.005
                                }
                              }
                            ]
                          }
                        ]
                      }
                    ]
                    boundingObject USE inner_foot
                    physics Physics {
                      density -1
                      mass 0.4
                      centerOfMass [
                        0 -0.01 -0.005
                      ]
                      inertiaMatrix [
                        4.33902e-05 0.000368007 0.00040205
                        -1.81807e-20 1.99081e-09 4.4e-07
                      ]
                    }
                  }
                }
              ]
              boundingObject USE inner_lower
              physics DEF INNER_LOWER_PHYSICS Physics {
                density -1
                mass 1
                centerOfMass [
                  0 0 -0.05
                ]
                inertiaMatrix [
                  0.000841667 0.00174167 0.000916667
                  0 0 0
                ]
              }
            }
          }
        ]
        name "inner legs"
        boundingObject USE motor_top
        physics USE INNER_LOWER_PHYSICS
      }
    }
    DEF outer_lower HingeJoint {
      jointParameters HingeJointParameters {
        axis -1 0 0
        anchor 0.05 0 0.035
        minStop -3.14
        maxStop 0.1
      }
      endPoint Solid {
        translation 0.05 0 0.035
        rotation -1 0 0 0
        children [
          DEF outer_lower Group {
            children [
              Pose {
                translation 0 0 -0.05
                children [
                  Shape {
                    appearance PBRAppearance {
                      baseColor 0.501961 0.501961 0.501961
                      roughness 1
                      metalness 0
                    }
                    geometry Box {
                      size 0.01 0.01 0.1
                    }
                  }
                ]
              }
              Pose {
                translation -0.1 0 -0.05
                children [
                  Shape {
                    appearance PBRAppearance {
                      baseColor 0.501961 0.501961 0.501961
                      roughness 1
                      metalness 0
                    }
                    geometry Box {
                      size 0.01 0.01 0.1
                    }
                  }
                ]
              }
            ]
          }
          DEF left_foot HingeJoint {
            jointParameters HingeJointParameters {
              axis -1 0 0
              anchor 0 0 -0.1
              staticFriction 10
            }
            endPoint Solid {
              translation 0 0 -0.1
              rotation -1 0 0 0
              children [
                DEF left_foot Group {
                  children [
                    Pose {
                      rotation 0 -1 0 4.71
                      children [
                        Shape {
                          appearance PBRAppearance {
                            baseColor 0.8 0.8 0.8
                            roughness 1
                            metalness 0
                          }
                          geometry Cylinder {
                            height 0.01
                            radius 0.005
                          }
                        }
                      ]
                    }
                    Pose {
                      translation 0 -0.0027 -0.00175
                      rotation 0 -1 0 4.71
                      children [
                        Shape {
                          appearance PBRAppearance {
                            baseColor 0.8 0.8 0.8
                            roughness 1
                            metalness 0
                          }
                          geometry Cylinder {
                            height 0.01
                            radius 0.005
                          }
                        }
                      ]
                    }
                    Pose {
                      translation 0 -0.0056 -0.00315
                      rotation 0 -1 0 4.71
                      children [
                        Shape {
                          appearance PBRAppearance {
                            baseColor 0.8 0.8 0.8
                            roughness 1
                            metalness 0
                          }
                          geometry Cylinder {
                            height 0.01
                            radius 0.005
                          }
                        }
                      ]
                    }
                    Pose {
                      translation 0 -0.00865 -0.0042
                      rotation 0 -1 0 4.71
                      children [
                        Shape {
                          appearance PBRAppearance {
                            baseColor 0.8 0.8 0.8
                            roughness 1
                            metalness 0
                          }
                          geometry Cylinder {
                            height 0.01
                            radius 0.005
                          }
                        }
                      ]
                    }
                    Pose {
                      translation 0 -0.0118 -0.0048
                      rotation 0 -1 0 4.71
                      children [
                        Shape {
                          appearance PBRAppearance {
                            baseColor 0.8 0.8 0.8
                            roughness 1
                            metalness 0
                          }
                          geometry Cylinder {
                            height 0.01
                            radius 0.005
                          }
                        }
                      ]
                    }
                    Pose {
                      translation 0 -0.015 -0.005
                      rotation 0 -1 0 4.71
                      children [
                        Shape {
                          appearance PBRAppearance {
                            baseColor 0.8 0.8 0.8
                            roughness 1
                            metalness 0
                          }
                          geometry Cylinder {
                            height 0.01
                            radius 0.005
                          }
                        }
                      ]
                    }
                    Pose {
                      translation 0 -0.0182 -0.0048
                      rotation 0 -1 0 4.71
                      children [
                        Shape {
                          appearance PBRAppearance {
                            baseColor 0.8 0.8 0.8
                            roughness 1
                            metalness 0
                          }
                          geometry Cylinder {
                            height 0.01
                            radius 0.005
                          }
                        }
                      ]
                    }
                    Pose {
                      translation 0 -0.02135 -0.0042
                      rotation 0 -1 0 4.71
                      children [
                        Shape {
                          appearance PBRAppearance {
                            baseColor 0.8 0.8 0.8
                            roughness 1
                            metalness 0
                          }
                          geometry Cylinder {
                            height 0.01
                            radius 0.005
                          }
                        }
                      ]
                    }
                    Pose {
                      translation 0 -0.0244 -0.00315
                      rotation 0 -1 0 4.71
                      children [
                        Shape {
                          appearance PBRAppearance {
                            baseColor 0.8 0.8 0.8
                            roughness 1
                            metalness 0
                          }
                          geometry Cylinder {
                            height 0.01
                            radius 0.005
                          }
                        }
                      ]
                    }
                    Pose {
                      translation 0 -0.0273 -0.00175
                      rotation 0 -1 0 4.71
                      children [
                        Shape {
                          appearance PBRAppearance {
                            baseColor 0.8 0.8 0.8
                            roughness 1
                            metalness 0
                          }
                          geometry Cylinder {
                            height 0.01
                            radius 0.005
                          }
                        }
                      ]
                    }
                    Pose {
                      translation -0.1 0 0
                      rotation 0 -1 0 4.71
                      children [
                        Shape {
                          appearance PBRAppearance {
                            baseColor 0.8 0.8 0.8
                            roughness 1
                            metalness 0
                          }
                          geometry Cylinder {
                            height 0.01
                            radius 0.005
                          }
                        }
                      ]
                    }
                    Pose {
                      translation -0.1 -0.0027 -0.00175
                      rotation 0 -1 0 4.71
                      children [
                        Shape {
                          appearance PBRAppearance {
                            baseColor 0.8 0.8 0.8
                            roughness 1
                            metalness 0
                          }
                          geometry Cylinder {
                            height 0.01
                            radius 0.005
                          }
                        }
                      ]
                    }
                    Pose {
                      translation -0.1 -0.0056 -0.00315
                      rotation 0 -1 0 4.71
                      children [
                        Shape {
                          appearance PBRAppearance {
                            baseColor 0.8 0.8 0.8
                            roughness 1
                            metalness 0
                          }
                          geometry Cylinder {
                            height 0.01
                            radius 0.005
                          }
                        }
                      ]
                    }
                    Pose {
                      translation -0.1 -0.00865 -0.0042
                      rotation 0 -1 0 4.71
                      children [
                        Shape {
                          appearance PBRAppearance {
                            baseColor 0.8 0.8 0.8
                            roughness 1
                            metalness 0
                          }
                          geometry Cylinder {
                            height 0.01
                            radius 0.005
                          }
                        }
                      ]
                    }
                    Pose {
                      translation -0.1 -0.0118 -0.0048
                      rotation 0 -1 0 4.71
                      children [
                        Shape {
                          appearance PBRAppearance {
                            baseColor 0.8 0.8 0.8
                            roughness 1
                            metalness 0
                          }
                          geometry Cylinder {
                            height 0.01
                            radius 0.005
                          }
                        }
                      ]
                    }
                    Pose {
                      translation -0.1 -0.015 -0.005
                      rotation 0 -1 0 4.71
                      children [
                        Shape {
                          appearance PBRAppearance {
                            baseColor 0.8 0.8 0.8
                            roughness 1
                            metalness 0
                          }
                          geometry Cylinder {
                            height 0.01
                            radius 0.005
                          }
                        }
                      ]
                    }
                    Pose {
                      translation -0.1 -0.0182 -0.0048
                      rotation 0 -1 0 4.71
                      children [
                        Shape {
                          appearance PBRAppearance {
                            baseColor 0.8 0.8 0.8
                            roughness 1
                            metalness 0
                          }
                          geometry Cylinder {
                            height 0.01
                            radius 0.005
                          }
                        }
                      ]
                    }
                    Pose {
                      translation -0.1 -0.02135 -0.0042
                      rotation 0 -1 0 4.71
                      children [
                        Shape {
                          appearance PBRAppearance {
                            baseColor 0.8 0.8 0.8
                            roughness 1
                            metalness 0
                          }
                          geometry Cylinder {
                            height 0.01
                            radius 0.005
                          }
                        }
                      ]
                    }
                    Pose {
                      translation -0.1 -0.0244 -0.00315
                      rotation 0 -1 0 4.71
                      children [
                        Shape {
                          appearance PBRAppearance {
                            baseColor 0.8 0.8 0.8
                            roughness 1
                            metalness 0
                          }
                          geometry Cylinder {
                            height 0.01
                            radius 0.005
                          }
                        }
                      ]
                    }
                    Pose {
                      translation -0.1 -0.0273 -0.00175
                      rotation 0 -1 0 4.71
                      children [
                        Shape {
                          appearance PBRAppearance {
                            baseColor 0.8 0.8 0.8
                            roughness 1
                            metalness 0
                          }
                          geometry Cylinder {
                            height 0.01
                            radius 0.005
                          }
                        }
                      ]
                    }
                  ]
                }
              ]
              boundingObject USE left_foot
              physics Physics {
                density -1
                mass 0.4
                centerOfMass [
                  -0.05 -0.01 -0.005
                ]
                inertiaMatrix [
                  4.33902e-05 0.00100801 0.00104205
                  -5.58512e-21 1.99081e-09 4.4e-07
                ]
              }
            }
          }
        ]
        name "outer lower legs"
        boundingObject USE outer_lower
        physics Physics {
          density -1
          mass 1
          centerOfMass [
            -0.05 0 -0.05
          ]
          inertiaMatrix [
            0.000841667 0.00334167 0.00251667
            0 0 0
          ]
        }
      }
    }
  ]
  name "walker"
  boundingObject USE outer_upper
  physics Physics {
    density -1
    mass 1
    centerOfMass [
      0 0 0.07
    ]
    inertiaMatrix [
      0.00164167 0.00358333 0.00195833
      0 -5.60101e-08 0
    ]
  }
}
