#VRML_SIM R2020a utf8
# license: Copyright Cyberbotics Ltd. Licensed for use only with Webots.
# license url: https://cyberbotics.com/webots_assets_license
# documentation url: https://www.cyberbotics.com/doc/guide/shrimp
# The "Shrimp" robot is a mobile platform for rough terrain from Bluebotics.
# It has 6 wheels and a passive structure that adapts to the terrain profile and climbs obstacles.

PROTO Shrimp [
  field SFVec3f    translation     0 0 0    # Is `Transform.translation`.
  field SFRotation rotation        0 1 0 0  # Is `Transform.rotation`.
  field SFString   name            "Shrimp" # Is `Solid.name`.
  field SFString   controller      "shrimp" # Is `Robot.controller`.
  field SFString   controllerArgs  ""       # Is `Robot.controllerArgs`.
  field SFString   customData      ""       # Is `Robot.customData`.
  field SFBool     supervisor      FALSE    # Is `Robot.supervisor`.
  field SFBool     synchronization TRUE     # Is `Robot.synchronization`.
  field MFNode     extensionSlot   []       # Extends the robot with new nodes in the extension slot.
]
{
  Robot {
    translation IS translation
    rotation IS rotation
    controller IS controller
    controllerArgs IS controllerArgs
    customData IS customData
    supervisor IS supervisor
    synchronization IS synchronization
    name IS name
    children [
      Group {
        children IS extensionSlot
      }
      Group {
        children [
          Transform {
            translation 0 0.159 0
            children [
              DEF BASE Shape {
                appearance DEF BLUE PBRAppearance {
                  metalness 0.8
                  baseColor 0.19 0.69 1.0
                  roughness 0.2
                  baseColorMap ImageTexture {
                    url [
                      "textures/metal.jpg"
                    ]
                  }
                }
                geometry IndexedFaceSet {
                  coord Coordinate {
                    point [
                      0.135 0 -0.015, 0.125 0 -0.025, 0.125 0 -0.09, 0.113 0 -0.102, 0.009 0 -0.102, 0.009 0 -0.039, -0.009 0 -0.039, -0.009 0 -0.102, -0.113 0 -0.102, -0.125 0 -0.09, -0.125 0 -0.025, -0.135 0 -0.015, -0.135 0 0.015, -0.125 0 0.025, -0.125 0 0.09, -0.01 0 0.165, 0.01 0 0.165, 0.125 0 0.09, 0.125 0 0.025, 0.135 0 0.015, 0.135 0 -0.015, 0.135 0.002 -0.015, 0.125 0.002 -0.025, 0.125 0.002 -0.09, 0.113 0.002 -0.102, 0.009 0.002 -0.102, 0.009 0.002 -0.039, -0.009 0.002 -0.039, -0.009 0.002 -0.102, -0.113 0.002 -0.102, -0.125 0.002 -0.09, -0.125 0.002 -0.025, -0.135 0.002 -0.015, -0.135 0.002 0.015, -0.125 0.002 0.025, -0.125 0.002 0.09, -0.01 0.002 0.165, 0.01 0.002 0.165, 0.125 0.002 0.09, 0.125 0.002 0.025, 0.135 0.002 0.015, 0.135 0.002 -0.015
                    ]
                  }
                  coordIndex [
                    20, 19, 18, 17, 16, 15, 14, 13, 12, 11, 10, 9, 8, 7, 6, 5, 4, 3, 2, 1, 0, -1, 21, 22, 23, 24, 25, 26, 27, 28, 29, 30, 31, 32, 33, 34, 35, 36, 37, 38, 39, 40, 41, -1, 0, 1, 22, 21, -1, 1, 2, 23, 22, -1, 2, 3, 24, 23, -1, 3, 4, 25, 24, -1, 4, 5, 26, 25, -1, 5, 6, 27, 26, -1, 6, 7, 28, 27, -1, 7, 8, 29, 28, -1, 8, 9, 30, 29, -1, 9, 10, 31, 30, -1, 10, 11, 32, 31, -1, 11, 12, 33, 32, -1, 12, 13, 34, 33, -1, 13, 14, 35, 34, -1, 14, 15, 36, 35, -1, 15, 16, 37, 36, -1, 16, 17, 38, 37, -1, 17, 18, 39, 38, -1, 18, 19, 40, 39, -1, 19, 20, 41, 40, -1
                  ]
                  creaseAngle 0.3
                }
              }
            ]
          }
          Transform {
            translation 0 0.226 0
            children [
              USE BASE
            ]
          }
          Transform {
            translation -0.131 0.193 0
            children [
              DEF LATERAL_SUPPORT Shape {
                appearance USE BLUE
                geometry Box {
                  size 0.008 0.068 0.03
                }
              }
            ]
          }
          Transform {
            translation 0.131 0.193 0
            children [
              USE LATERAL_SUPPORT
            ]
          }
          Transform {
            translation -0.013 0.193 -0.062
            children [
              USE LATERAL_SUPPORT
            ]
          }
          Transform {
            translation 0.013 0.193 -0.062
            children [
              USE LATERAL_SUPPORT
            ]
          }
          Transform {
            translation 0 0.193 0.161
            children [
              Shape {
                appearance USE BLUE
                geometry Box {
                  size 0.02 0.068 0.008
                }
              }
            ]
          }
          Transform {
            translation 0 0.1455 -0.034
            children [
              Shape {
                appearance USE BLUE
                geometry Box {
                  size 0.25 0.027 0.058
                }
              }
            ]
          }
          Transform {
            translation -0.011 0.173 0.1745
            children [
              DEF FRONT_WHEEL_LATERAL_SUPPORT Shape {
                appearance USE BLUE
                geometry Box {
                  size 0.002 0.01 0.035
                }
              }
            ]
          }
          Transform {
            translation 0.011 0.173 0.1745
            children [
              USE FRONT_WHEEL_LATERAL_SUPPORT
            ]
          }
          Transform {
            translation 0 0.1755 0.186
            rotation 1 0 0 -0.478
            children [
              Shape {
                appearance USE BLUE
                geometry Box {
                  size 0.0201 0.102 0.015
                }
              }
            ]
          }
          DEF ROTATIONAL_MOTOR Group {
            children [
              Transform {
                translation 0 0.138 0.234
                rotation 0 0 1 0
                children [
                  Shape {
                    appearance USE BLUE
                    geometry Box {
                      size 0.02 0.01 0.047
                    }
                  }
                ]
              }
              Transform {
                translation -0.011 0.153 0.23
                rotation 0 0 1 0
                children [
                  DEF MOTOR_SUPPORT Shape {
                    appearance USE BLUE
                    geometry Box {
                      size 0.002 0.04 0.02
                    }
                  }
                ]
              }
              Transform {
                translation 0.011 0.153 0.23
                rotation 0 0 1 0
                children [
                  USE MOTOR_SUPPORT
                ]
              }
              Transform {
                translation 0 0.178 0.236
                rotation 0 0 1 0
                children [
                  DEF MOTOR Shape {
                    appearance DEF BLACK PBRAppearance {
                      baseColor 0.1 0.1 0.1
                      metalness 0
                      roughness 1
                    }
                    geometry Box {
                      size 0.02 0.037 0.04
                    }
                  }
                ]
              }
            ]
          }
          Transform {
            translation 0.14 0.2195 0
            rotation 0 0 1 1.57
            children [
              DEF BOGIE_AXE Shape {
                appearance USE BLACK
                geometry Cylinder {
                  height 0.038
                  radius 0.005
                  subdivision 24
                }
              }
            ]
          }
          Transform {
            translation 0.14 0.1695 0
            rotation 0 0 1 1.57
            children [
              USE BOGIE_AXE
            ]
          }
          Transform {
            translation -0.14 0.2195 0
            rotation 0 0 1 1.57
            children [
              USE BOGIE_AXE
            ]
          }
          Transform {
            translation -0.14 0.1695 0
            rotation 0 0 1 1.57
            children [
              USE BOGIE_AXE
            ]
          }
          Transform {
            translation 0 0.2195 -0.053
            rotation 0 0 1 1.57
            children [
              USE BOGIE_AXE
            ]
          }
          Transform {
            translation 0 0.1695 -0.072
            rotation 0 0 1 1.57
            children [
              USE BOGIE_AXE
            ]
          }
        ]
      }
      DEF BACK_WHEEL_HINGE HingeJoint {
        jointParameters HingeJointParameters {
          axis 0 1 0
          anchor 0 0.138 0.252
        }
        device [
          RotationalMotor {
            name "back wheel rotation"
            minPosition -1.5708
            maxPosition 1.5708
          }
        ]
        endPoint DEF BACK_WHEEL Solid {
          translation 0 0.138 0.252
          children [
            DEF ROTATIONAL_SUPPORT Group {
              children [
                Transform {
                  translation -0.013 -0.009 0
                  rotation 0 0 1 0
                  children [
                    Shape {
                      appearance USE BLUE
                      geometry Box {
                        size 0.039 0.008 0.01
                      }
                    }
                  ]
                }
                Transform {
                  translation -0.0285 -0.0425 0
                  rotation 0 0 1 0
                  children [
                    Shape {
                      appearance USE BLUE
                      geometry Box {
                        size 0.008 0.059 0.01
                      }
                    }
                  ]
                }
                Transform {
                  translation -0.02 -0.08 0
                  rotation 0 0 1 1.57
                  children [
                    DEF WHEEL_AXE Shape {
                      appearance USE BLUE
                      geometry Cylinder {
                        height 0.04
                        radius 0.0125
                        subdivision 24
                      }
                    }
                  ]
                }
              ]
            }
            DEF BACK_TIRE_HINGE HingeJoint {
              jointParameters HingeJointParameters {
                anchor 0 -0.08 0
              }
              device [
                RotationalMotor {
                  name "wheel motor 05"
                  maxTorque 0.754
                }
                PositionSensor {
                  name "wheel sensor 05"
                }
              ]
              endPoint DEF BACK_TIRE Solid {
                translation 0 -0.08 0
                rotation 1 0 0 0
                children [
                  DEF WHEEL Group {
                    children [
                      Transform {
                        rotation 0 0 1 1.57
                        children [
                          Shape {
                            appearance USE BLACK
                            geometry Cylinder {
                              height 0.041
                              radius 0.058
                              subdivision 24
                            }
                          }
                        ]
                      }
                      Transform {
                        translation 0.02 0 0
                        rotation 0 0 1 -1.57
                        children [
                          Shape {
                            appearance USE BLUE
                            geometry IndexedFaceSet {
                              coord Coordinate {
                                point [
                                  0.007 0.013 -0.002
                                  0.047 0 -0.012
                                  0.035 0 -0.034
                                  0.006 0.013 -0.005
                                  0.007 0.013 0.002
                                  0.047 0 0.013
                                  0.006 0.013 0.005
                                  0.035 0 0.034
                                  0.002 0.013 0.007
                                  0.013 0 0.047
                                  -0.001 0.013 0.007
                                  -0.012 0 0.047
                                  -0.005 0.013 0.005
                                  -0.034 0 0.034
                                  -0.007 0.013 0.002
                                  -0.046 0 0.013
                                  -0.046 0 -0.012
                                  -0.005 0.013 -0.005
                                  -0.034 0 -0.034
                                  -0.012 0 -0.047
                                  0.013 0 -0.047
                                  0 0 0
                                  -0.007 0.013 -0.002
                                  0.002 0.013 -0.007
                                  -0.001 0.013 -0.007
                                ]
                              }
                              coordIndex [
                                1, 0, 4, -1, 4, 5, 1, -1, 5, 4, 6, -1, 6, 7, 5, -1, 7, 6, 8, -1, 8, 9, 7, -1, 9, 8, 10, -1, 10, 11, 9, -1, 11, 10, 12, -1, 12, 13, 11, -1, 2, 1, 21, -1, 1, 5, 21, -1, 5, 7, 21, -1, 7, 9, 21, -1, 9, 11, 21, -1, 11, 13, 21, -1, 13, 15, 21, -1, 15, 16, 21, -1, 16, 18, 21, -1, 18, 19, 21, -1, 19, 20, 21, -1, 2, 21, 20, -1, 0, 1, 2, -1, 0, 2, 3, -1, 2, 20, 3, -1, 3, 20, 23, -1, 19, 23, 20, -1, 19, 24, 23, -1, 18, 24, 19, -1, 17, 24, 18, -1, 16, 17, 18, -1, 16, 22, 17, -1, 15, 22, 16, -1, 14, 22, 15, -1, 13, 14, 15, -1, 12, 14, 13, -1, 3, 23, 12, -1, 12, 23, 14, -1, 14, 23, 24, -1, 14, 24, 22, -1, 17, 22, 24, -1, 3, 12, 10, -1, 0, 3, 10, -1, 0, 10, 8, -1, 0, 8, 4, -1, 4, 8, 6, -1
                              ]
                              creaseAngle 0.3
                            }
                          }
                        ]
                      }
                    ]
                  }
                ]
                boundingObject DEF BOUNDING_WHEEL Transform {
                  translation 0.004 0 0
                  rotation 0 0 1 1.57
                  children [
                    Shape {
                      geometry Cylinder {
                        height 0.05
                        radius 0.058
                        subdivision 24
                      }
                    }
                  ]
                }
                physics DEF PHYSICS_WHEEL Physics {
                  density -1
                  mass 0.222
                }
              }
            }
          ]
          name "back wheel"
          boundingObject DEF BOUNDING_ROTATIONAL_SUPPORT Group {
            children [
              Transform {
                translation -0.013 -0.0425 0
                rotation 0 0 1 0
                children [
                  Shape {
                    geometry Box {
                      size 0.039 0.075 0.01
                    }
                  }
                ]
              }
              Transform {
                translation -0.02 -0.08 0
                rotation 0 0 1 1.57
                children [
                  DEF BOUNDING_WHEEL_AXE Shape {
                    geometry Cylinder {
                      bottom FALSE
                      height 0.04
                      radius 0.0125
                      subdivision 24
                    }
                  }
                ]
              }
            ]
          }
          physics DEF PHYSICS_ROTATIONAL_SUPPORT Physics {
            density -1
            mass 0.178
            centerOfMass [
              -0.015 -0.06 0
            ]
            inertiaMatrix [
              0.000117613 2.89259e-5 0.000139178
              -1.08718e-5 0 0
            ]
          }
        }
      }
      DEF UPPER_RIGHT_BOGIE_HINGE HingeJoint {
        jointParameters HingeJointParameters {
          anchor 0.1465 0.2195 0
          minStop -1.35566
          maxStop 1.35566
        }
        endPoint DEF UPPER_RIGHT_BOGIE Solid {
          translation 0.1465 0.2195 0
          rotation 1 0 0 0
          children [
            Transform {
              children [
                DEF BOGIE_HORIZONTAL Shape {
                  appearance USE BLUE
                  geometry DEF BOUNDING_BOGIE_HORIZONTAL Box {
                    size 0.015 0.015 0.183
                  }
                }
              ]
            }
            DEF BACK_RIGHT_BOGIE_HINGE HingeJoint {
              jointParameters HingeJointParameters {
                anchor 0 0 0.089
              }
              endPoint DEF BACK_RIGHT_BOGIE Solid {
                translation 0 -0.2195 0.089
                rotation 1 0 0 0
                children [
                  Transform {
                    translation 0 0.147 0
                    children [
                      DEF BOGIE_VERTICAL Shape {
                        appearance USE BLUE
                        geometry DEF BOUNDING_BOGIE_VERTICAL Box {
                          size 0.02 0.16 0.015
                        }
                      }
                    ]
                  }
                  Transform {
                    translation 0.0165 0.058 0
                    rotation 0 0 1 1.57
                    children [
                      USE WHEEL_AXE
                    ]
                  }
                  DEF BACK_RIGHT_TIRE_HINGE HingeJoint {
                    jointParameters HingeJointParameters {
                      anchor 0.0355 0.058 0
                    }
                    device [
                      RotationalMotor {
                        name "wheel motor 04"
                        maxTorque 0.754
                      }
                      PositionSensor {
                        name "wheel sensor 04"
                      }
                    ]
                    endPoint DEF BACK_RIGHT_TIRE_SOLID Solid {
                      translation 0.0355 0.058 0
                      rotation 1 0 0 0
                      children [
                        USE WHEEL
                      ]
                      boundingObject USE BOUNDING_WHEEL
                      physics USE PHYSICS_WHEEL
                    }
                  }
                ]
                name "back right bogie"
                boundingObject DEF BOUNDING_BOGIE_VERTICAL_AXE Group {
                  children [
                    Transform {
                      translation 0 0.147 0
                      children [
                        USE BOUNDING_BOGIE_VERTICAL
                      ]
                    }
                    Transform {
                      translation 0.0165 0.058 0
                      rotation 0 0 1 1.57
                      children [
                        USE BOUNDING_WHEEL_AXE
                      ]
                    }
                  ]
                }
                physics DEF PHYSICS_BOGIE_VERTICAL Physics {
                  density -1
                  mass 0.23263
                  centerOfMass [
                    0 0.09 0
                  ]
                  inertiaMatrix [
                    0.000966127 3.86276e-5 0.000993287
                    3.56632e-5 0 0
                  ]
                }
              }
            }
            DEF FRONT_RIGHT_BOGIE_HINGE HingeJoint {
              jointParameters HingeJointParameters {
                anchor 0 0 -0.089
              }
              endPoint DEF FRONT_RIGHT_BOGIE Solid {
                translation 0 -0.2195 -0.089
                rotation 1 0 0 0
                children [
                  Transform {
                    translation 0 0.147 0
                    children [
                      USE BOGIE_VERTICAL
                    ]
                  }
                  Transform {
                    translation 0.0165 0.058 0
                    rotation 0 0 1 1.57
                    children [
                      USE WHEEL_AXE
                    ]
                  }
                  DEF FRONT_RIGHT_TIRE_HINGE HingeJoint {
                    jointParameters HingeJointParameters {
                      anchor 0.0355 0.058 0
                    }
                    device [
                      RotationalMotor {
                        name "wheel motor 02"
                        maxTorque 0.754
                      }
                      PositionSensor {
                        name "wheel sensor 02"
                      }
                    ]
                    endPoint DEF FRONT_RIGHT_TIRE Solid {
                      translation 0.0355 0.058 0
                      rotation 1 0 0 0
                      children [
                        USE WHEEL
                      ]
                      boundingObject USE BOUNDING_WHEEL
                      physics USE PHYSICS_WHEEL
                    }
                  }
                ]
                name "front right bogie"
                boundingObject USE BOUNDING_BOGIE_VERTICAL_AXE
                physics USE PHYSICS_BOGIE_VERTICAL
              }
            }
          ]
          name "upper right bogie"
          boundingObject USE BOUNDING_BOGIE_HORIZONTAL
          physics DEF PHYSICS_BOGIE_HORIZONTAL Physics {
            density -1
            mass 0.05737
            centerOfMass [
              0 0 0
            ]
            inertiaMatrix [
              0.000115681 0.000115681 1.54406e-5
              0 0 0
            ]
          }
        }
      }
      DEF LOWER_RIGHT_BOGIE_HINGE HingeJoint {
        jointParameters HingeJointParameters {
          anchor 0.1465 0.1695 0
          minStop -1.35566
          maxStop 1.35566
        }
        endPoint DEF LOWER_RIGHT_BOGIE Solid {
          translation 0.1465 0.1695 0
          rotation 1 0 0 0
          children [
            Transform {
              children [
                USE BOGIE_HORIZONTAL
              ]
            }
            DEF BACK_RIGHT_BOGIE_HINGE HingeJoint {
              jointParameters HingeJointParameters {
                anchor 0 0 0.089
              }
              endPoint SolidReference {
                solidName "back right bogie"
              }
            }
            DEF FRONT_RIGHT_BOGIE_HINGE HingeJoint {
              jointParameters HingeJointParameters {
                anchor 0 0 -0.089
              }
              endPoint SolidReference {
                solidName "front right bogie"
              }
            }
          ]
          name "lower right bogie"
          boundingObject USE BOUNDING_BOGIE_HORIZONTAL
          physics USE PHYSICS_BOGIE_HORIZONTAL
        }
      }
      DEF UPPER_LEFT_BOGIE_HINGE HingeJoint {
        jointParameters HingeJointParameters {
          anchor -0.1465 0.2195 0
          minStop -1.35566
          maxStop 1.35566
        }
        endPoint DEF UPPER_LEFT_BOGIE Solid {
          translation -0.1465 0.2195 0
          rotation 1 0 0 0
          children [
            Transform {
              children [
                DEF BOGIE_HORIZONTAL Shape {
                  appearance USE BLUE
                  geometry USE BOUNDING_BOGIE_HORIZONTAL
                }
              ]
            }
            DEF BACK_LEFT_BOGIE_HINGE HingeJoint {
              jointParameters HingeJointParameters {
                anchor 0 0 0.089
              }
              endPoint DEF BACK_LEFT_BOGIE Solid {
                translation 0 -0.2195 0.089
                rotation 0 1 0 3.1415
                children [
                  Transform {
                    translation 0 0.147 0
                    children [
                      DEF BOGIE_VERTICAL Shape {
                        appearance USE BLUE
                        geometry USE BOUNDING_BOGIE_VERTICAL
                      }
                    ]
                  }
                  Transform {
                    translation 0.0165 0.058 0
                    rotation 0 0 1 1.57
                    children [
                      USE WHEEL_AXE
                    ]
                  }
                  DEF BACK_LEFT_TIRE_HINGE HingeJoint {
                    jointParameters HingeJointParameters {
                      anchor 0.0355 0.058 0
                    }
                    device [
                      RotationalMotor {
                        name "wheel motor 03"
                        maxTorque 0.754
                      }
                      PositionSensor {
                        name "wheel sensor 03"
                      }
                    ]
                    endPoint DEF BACK_LEFT_TIRE Solid {
                      translation 0.0355 0.058 0
                      rotation 1 0 0 0
                      children [
                        USE WHEEL
                      ]
                      boundingObject USE BOUNDING_WHEEL
                      physics USE PHYSICS_WHEEL
                    }
                  }
                ]
                name "back left bogie"
                boundingObject USE BOUNDING_BOGIE_VERTICAL_AXE
                physics USE PHYSICS_BOGIE_VERTICAL
              }
            }
            DEF FRONT_LEFT_BOGIE_HINGE HingeJoint {
              jointParameters HingeJointParameters {
                anchor 0 0 -0.089
              }
              endPoint DEF FRONT_LEFT_BOGIE Solid {
                translation 0 -0.2195 -0.089
                rotation 0 1 0 3.1415
                children [
                  Transform {
                    translation 0 0.147 0
                    children [
                      USE BOGIE_VERTICAL
                    ]
                  }
                  Transform {
                    translation 0.0165 0.058 0
                    rotation 0 0 1 1.57
                    children [
                      USE WHEEL_AXE
                    ]
                  }
                  DEF FRONT_LEFT_TIRE_HINGE HingeJoint {
                    jointParameters HingeJointParameters {
                      anchor 0.0355 0.058 0
                    }
                    device [
                      RotationalMotor {
                        name "wheel motor 01"
                        maxTorque 0.754
                      }
                      PositionSensor {
                        name "wheel sensor 01"
                      }
                    ]
                    endPoint DEF FRONT_LEFT_TIRE Solid {
                      translation 0.0355 0.058 0
                      rotation 1 0 0 0
                      children [
                        USE WHEEL
                      ]
                      boundingObject USE BOUNDING_WHEEL
                      physics USE PHYSICS_WHEEL
                    }
                  }
                ]
                name "front left bogie"
                boundingObject USE BOUNDING_BOGIE_VERTICAL_AXE
                physics USE PHYSICS_BOGIE_VERTICAL
              }
            }
          ]
          name "upper left bogie"
          boundingObject USE BOUNDING_BOGIE_HORIZONTAL
          physics USE PHYSICS_BOGIE_HORIZONTAL
        }
      }
      DEF LOWER_LEFT_BOGIE_HINGE HingeJoint {
        jointParameters HingeJointParameters {
          anchor -0.1465 0.1695 0
          minStop -1.35566
          maxStop 1.35566
        }
        endPoint DEF LOWER_LEFT_BOGIE Solid {
          translation -0.1465 0.1695 0
          rotation 1 0 0 0
          children [
            Transform {
              children [
                USE BOGIE_HORIZONTAL
              ]
            }
            DEF BACK_LEFT_BOGIE_HINGE HingeJoint {
              jointParameters HingeJointParameters {
                anchor 0 0 0.089
              }
              endPoint SolidReference {
                solidName "back left bogie"
              }
            }
            DEF FRONT_LEFT_BOGIE_HINGE HingeJoint {
              jointParameters HingeJointParameters {
                anchor 0 0 -0.089
              }
              endPoint SolidReference {
                solidName "front left bogie"
              }
            }
          ]
          name "lower left bogie"
          boundingObject USE BOUNDING_BOGIE_HORIZONTAL
          physics USE PHYSICS_BOGIE_HORIZONTAL
        }
      }
      DEF UPPER_FORK_HINGE HingeJoint {
        jointParameters HingeJointParameters {
          anchor 0 0.2195 -0.053
          minStop -1.93
          maxStop 1.32
        }
        endPoint DEF UPPER_FORK Solid {
          translation 0 0.2445 -0.102
          rotation 1 0 0 0.4712
          children [
            Transform {
              translation 0 0 0.0025
              children [
                Shape {
                  appearance USE BLUE
                  geometry Box {
                    size 0.015 0.015 0.115
                  }
                }
              ]
            }
            DEF FRONT_FORK_HINGE HingeJoint {
              jointParameters HingeJointParameters {
                anchor 0 -0.000225406 -0.0535313
              }
              endPoint DEF FRONT_FORK Solid {
                translation 0 -0.171613 -0.102237
                rotation -1 0 0 0.4712
                children [
                  Transform {
                    translation 0 0.0613 0.0813
                    rotation 1 0 0 -1.04845
                    children [
                      Shape {
                        appearance USE BLUE
                        geometry Box {
                          size 0.02 0.015 0.175
                        }
                      }
                      DEF LOGO Transform {
                        translation 0 0.0085 0.035
                        rotation 1 0 0 0
                        children [
                          Shape {
                            appearance PBRAppearance {
                              metalness 0
                              roughness 0.3
                              baseColorMap ImageTexture {
                                url [
                                  "textures/bluebotics_logo.png"
                                ]
                              }
                            }
                            geometry IndexedFaceSet {
                              coord Coordinate {
                                point [
                                  0.009 0 -0.05
                                  0.009 0 0.05
                                  -0.009 0 0.05
                                  -0.009 0 -0.05
                                ]
                              }
                              texCoord TextureCoordinate {
                                point [
                                  0 1
                                  0 0
                                  1 0
                                  1 1
                                ]
                              }
                              coordIndex [
                                0, 3, 2, 1, -1
                              ]
                              texCoordIndex [
                                0, 1, 2, 3, -1
                              ]
                            }
                          }
                        ]
                      }
                    ]
                  }
                  Transform {
                    translation 0 -0.138 0.251
                    rotation 0 1 0 3.1415
                    children [
                      USE ROTATIONAL_MOTOR
                    ]
                  }
                  DEF FRONT_WHEEL_HINGE HingeJoint {
                    jointParameters HingeJointParameters {
                      axis 0 1 0
                    }
                    device [
                      RotationalMotor {
                        name "front wheel rotation"
                        minPosition -1.5708
                        maxPosition 1.5708
                      }
                    ]
                    endPoint DEF FRONT_WHEEL Solid {
                      children [
                        USE ROTATIONAL_SUPPORT
                        DEF FRONT_TIRE_HINGE HingeJoint {
                          jointParameters HingeJointParameters {
                            anchor 0 -0.08 0
                          }
                          device [
                            RotationalMotor {
                              name "wheel motor 00"
                              maxTorque 0.754
                            }
                            PositionSensor {
                              name "wheel sensor 00"
                            }
                          ]
                          endPoint DEF FRONT_TIRE Solid {
                            translation 0 -0.08 0
                            rotation 1 0 0 0
                            children [
                              USE WHEEL
                            ]
                            boundingObject USE BOUNDING_WHEEL
                            physics USE PHYSICS_WHEEL
                          }
                        }
                      ]
                      boundingObject USE BOUNDING_ROTATIONAL_SUPPORT
                      physics USE PHYSICS_ROTATIONAL_SUPPORT
                    }
                  }
                ]
                name "front fork"
                boundingObject Group {
                  children [
                    Transform {
                      translation 0 0.0613 0.0813
                      rotation 1 0 0 -1.04845
                      children [
                        Shape {
                          geometry Box {
                            size 0.02 0.015 0.175
                          }
                        }
                      ]
                    }
                    Transform {
                      translation 0 0.027 0.015
                      rotation 0 0 1 0
                      children [
                        Shape {
                          geometry Box {
                            size 0.024 0.062 0.04
                          }
                        }
                      ]
                    }
                  ]
                }
                physics Physics {
                  density -1
                  mass 0.1159
                  centerOfMass [
                    0 0.03 0.05
                  ]
                  inertiaMatrix [
                    0.000350003 0.000176901 0.000182635
                    0 0 -0.00011918
                  ]
                }
              }
            }
            DEF UPPER_SPRINGS_HINGE HingeJoint {
              jointParameters HingeJointParameters {
                anchor 0 -2.40438e-5 -0.0150266
              }
              endPoint DEF UPPER_SPRINGS Solid {
                translation 0 -0.0196439 -0.0191718
                rotation 1 0 0 0.20808
                children [
                  DEF RIGHT_SPRING Transform {
                    translation -0.015 0 0
                    rotation 1 0 0 0
                    children [
                      DEF SPRING Shape {
                        appearance USE BLACK
                        geometry Cylinder {
                          height 0.04
                          radius 0.0075
                          subdivision 24
                        }
                      }
                    ]
                  }
                  DEF LEFT_SPRING Transform {
                    translation 0.015 0 0
                    rotation 1 0 0 0
                    children [
                      USE SPRING
                    ]
                  }
                ]
                name "upper springs"
                boundingObject DEF BOUNDING_SPRINGS Group {
                  children [
                    Transform {
                      translation 0.015 0 0
                      children [
                        USE SPRING
                      ]
                    }
                    Transform {
                      translation -0.015 0 0
                      children [
                        USE SPRING
                      ]
                    }
                  ]
                }
                physics DEF PHYSICS_SPRINGS Physics {
                  density -1
                  mass 0.02
                }
              }
            }
          ]
          name "upper fork"
          boundingObject Transform {
            children [
              Shape {
                geometry Box {
                  size 0.015 0.015 0.12
                }
              }
            ]
          }
          physics Physics {
            density -1
            mass 0.03806
            centerOfMass [
              0 -0.015 0
            ]
            inertiaMatrix [
              5.49491e-5 4.63856e-5 9.99075e-6
              0 0 0
            ]
          }
        }
      }
      DEF LOWER_FORK_HINGE HingeJoint {
        jointParameters HingeJointParameters {
          anchor 0 0.1695 -0.072
        }
        endPoint DEF LOWER_FORK Solid {
          translation 0 0.18875 -0.128825
          rotation 1 0 0 0.3506
          children [
            Transform {
              translation 0 0 0.0025
              children [
                Shape {
                  appearance USE BLUE
                  geometry Box {
                    size 0.015 0.015 0.125
                  }
                }
              ]
            }
            DEF FRONT_FORK_HINGE HingeJoint {
              jointParameters HingeJointParameters {
                anchor 0 -0.00223624 -0.0618707
              }
              endPoint SolidReference {
                solidName "front fork"
              }
            }
            DEF LOWER_SPRINGS_HINGE HingeJoint {
              jointParameters HingeJointParameters {
                anchor 0 0.001436 -0.0299928
              }
              endPoint DEF LOWER_SPRINGS Solid {
                translation 0 0.0204146 -0.0235173
                rotation 1 0 0 0.32868
                children [
                  USE RIGHT_SPRING
                  USE LEFT_SPRING
                  DEF UPPER_SPRINGS_SLIDER SliderJoint {
                    jointParameters JointParameters {
                      axis 0 0.778025 -0.628233
                      springConstant 4905
                    }
                    endPoint SolidReference {
                      solidName "upper springs"
                    }
                  }
                ]
                name "lower springs"
                boundingObject USE BOUNDING_SPRINGS
                physics USE PHYSICS_SPRINGS
              }
            }
          ]
          name "lower fork"
          boundingObject Box {
            size 0.015 0.015 0.13
          }
          physics Physics {
            density -1
            mass 0.04492
            centerOfMass [
              0 0 0
            ]
            inertiaMatrix [
              0.000417422 0.000417422 1.09687e-5
              0 0 0
            ]
          }
        }
      }
    ]
    boundingObject DEF BOUNDING_BODY Group {
      children [
        Transform {
          translation 0 0.193 -0.005
          children [
            Shape {
              geometry Box {
                size 0.25 0.068 0.192
              }
            }
          ]
        }
        Transform {
          translation 0.0523 0.193 0.109
          rotation 0 1 0 0.578
          children [
            DEF BOUNDING_BASE Shape {
              geometry Box {
                size 0.14 0.068 0.05
              }
            }
          ]
        }
        Transform {
          translation -0.0523 0.193 0.109
          rotation 0 1 0 -0.578
          children [
            USE BOUNDING_BASE
          ]
        }
        Transform {
          translation 0 0.1455 -0.034
          children [
            Shape {
              geometry Box {
                size 0.25 0.027 0.058
              }
            }
          ]
        }
        Transform {
          translation 0 0.193 0.1
          children [
            Shape {
              geometry Box {
                size 0.06 0.068 0.03
              }
            }
          ]
        }
        Transform {
          translation 0 0.1755 0.186
          rotation 1 0 0 -0.478
          children [
            Shape {
              geometry Box {
                size 0.02 0.102 0.015
              }
            }
          ]
        }
        Transform {
          translation 0 0.165 0.236
          rotation 0 0 1 0
          children [
            Shape {
              geometry Box {
                size 0.024 0.062 0.04
              }
            }
          ]
        }
      ]
    }
    physics Physics {
      density -1
      mass 3.322
      centerOfMass [
        0 0.13785 0.03604
      ]
      inertiaMatrix [
        0.0288494 0.0342201 0.0261036
        7.00127e-20 1.83044e-20 0.00196405
      ]
    }
  }
}
