#VRML_SIM R2021b utf8
WorldInfo {
  info [
    "This example shows an integration of OpenAI Gym with Webots."
  ]
  title "OpenAI Gym Environment"
}
Viewpoint {
  orientation 0.5467221553550105 -0.5918346831085609 -0.5923061646764798 2.140275848036169
  position -3.19564172871877 0.3114654193957642 0.40859318447231485
}
TexturedBackground {
}
TexturedBackgroundLight {
}
Pioneer3at {
  rotation 0 0 1 1.5708
  controller "openai_gym"
  supervisor TRUE
  extensionSlot [
    HingeJoint {
      jointParameters HingeJointParameters {
        axis 0 1 0
        anchor 0 0 0.21
        minStop -1
        maxStop 1
      }
      device [
        PositionSensor {
        }
      ]
      endPoint Solid {
        translation 0 0 0.51
        rotation 1 0 0 1.5707999999999998
        children [
          DEF POLE_ENDPOINT Solid {
            translation 0 0.26 0
            children [
              DEF BALL_SHAPE Shape {
                appearance CorrodedMetal {
                }
                geometry Sphere {
                  radius 0.1
                  subdivision 3
                }
              }
            ]
            boundingObject USE BALL_SHAPE
            physics Physics {
              density -1
              mass 0.2
            }
          }
          DEF POLE_SHAPE Shape {
            appearance OsbWood {
            }
            geometry Cylinder {
              height 0.5
              radius 0.011
            }
          }
        ]
        boundingObject USE POLE_SHAPE
        physics Physics {
        }
      }
    }
  ]
}
Floor {
  rotation 1 0 0 1.57
  appearance Parquetry {
    type "light strip"
  }
}
