#VRML_SIM R2023b utf8

EXTERNPROTO "webots://projects/objects/backgrounds/protos/TexturedBackground.proto"
EXTERNPROTO "webots://projects/objects/backgrounds/protos/TexturedBackgroundLight.proto"
EXTERNPROTO "webots://projects/robots/adept/pioneer3/protos/Pioneer3at.proto"
EXTERNPROTO "webots://projects/appearances/protos/CorrodedMetal.proto"
EXTERNPROTO "webots://projects/appearances/protos/OsbWood.proto"
EXTERNPROTO "webots://projects/objects/floors/protos/Floor.proto"
EXTERNPROTO "webots://projects/appearances/protos/Parquetry.proto"

WorldInfo {
  info [
    "This example shows an integration of OpenAI Gym with Webots."
  ]
  title "OpenAI Gym Environment"
}
Viewpoint {
  orientation 0.039620786212746346 0.046648105252169975 -0.9981253165691502 1.6348167552564403
  position 0.325429139559551 4.811657001240169 0.6473423548515526
}
TexturedBackground {
}
TexturedBackgroundLight {
}
Pioneer3at {
  controller "openai_gym"
  supervisor TRUE
  extensionSlot [
    HingeJoint {
      jointParameters HingeJointParameters {
        axis 0 1 0
        anchor 0 0 0.21
        minStop -1
        maxStop 1
      }
      device [
        PositionSensor {
        }
      ]
      endPoint Solid {
        translation 0 0 0.51
        children [
          DEF POLE_ENDPOINT Solid {
            translation 0 0 0.26
            children [
              DEF BALL_SHAPE Shape {
                appearance CorrodedMetal {
                }
                geometry Sphere {
                  radius 0.1
                  subdivision 3
                }
              }
            ]
            boundingObject USE BALL_SHAPE
            physics Physics {
              density -1
              mass 0.2
            }
          }
          DEF POLE_SHAPE Shape {
            appearance OsbWood {
            }
            geometry Cylinder {
              height 0.5
              radius 0.011
            }
          }
        ]
        boundingObject USE POLE_SHAPE
        physics Physics {
        }
      }
    }
  ]
}
Floor {
  appearance Parquetry {
    type "light strip"
  }
}
