#VRML_SIM R2021b utf8
# license: Copyright Cyberbotics Ltd. Licensed for use only with Webots.
# license url: https://cyberbotics.com/webots_assets_license
# tags: static
# This extension of the hinge joint allows to model the effect of backlash.

PROTO Hinge2JointWithBacklash [
  field SFNode                                 jointParameters   HingeJointParameters {}
  field SFNode                                 jointParameters2  JointParameters {}
  field SFFloat                                backlash          0.01   # Defines the gear clearence for axis, [0, inf).
  field SFFloat                                backlash2         0.01   # Defines the gear clearence for axis2, [0, inf).
  field SFFloat                                gearMass          0.01   # Defines the gear mass for axis, [0, inf).
  field SFFloat                                gearMass2         0.01   # Defines the gear mass for axis2, [0, inf).
  field MFNode                                 device            [ ]    # {RotationalMotor, PositionSensor, Brake}.
  field MFNode                                 device2           [ ]    # {RotationalMotor, PositionSensor, Brake}.
  field MFNode{PositionSensor{}}               outputSensor      [ ]    # {PositionSensor}.
  field MFNode{PositionSensor{}}               outputSensor2     [ ]    # {PositionSensor}.
  field MFNode{Group{}, Transform{}, Shape{}}  startPoint        NULL   # {Group, Transform, or Shape}.
  field SFNode                                 endPoint          NULL   # {Solid, SolidReference, or Slot}.
]
{
  %{
    -- load modules
    local os = require('os')
    local wbrandom = require('wbrandom')
    wbrandom.seed(os.clock() + os.time())
    -- parameter retrieval
    local axis = fields.jointParameters.value.fields.axis.value
    local axis2 = fields.jointParameters2.value.fields.axis.value
    local anchor = fields.jointParameters.value.fields.anchor.value
    -- parameter sanity check
    local backlash = fields.backlash.value
    if backlash < 0 then
      io.stderr:write("'backlash' value must be greater or equal to 0. Using default value.\n")
      backlash = fields.backlash.defaultValue
    elseif backlash > 0 and backlash < 0.01 then
      print("Values of 'backlash' smaller than 0.01 are unlikely to be correctly enforced by the physics engine.")
    end

    local backlash2 = fields.backlash2.value
    if backlash2 < 0 then
      io.stderr:write("'backlash2' value must be greater or equal to 0. Using default value.\n")
      backlash2 = fields.backlash2.defaultValue
    elseif backlash2 > 0 and backlash2 < 0.01 then
      print("Values of 'backlash2' smaller than 0.01 are unlikely to be correctly enforced by the physics engine.")
    end

    local gearMass = fields.gearMass.value
    if gearMass <= 0 then
      io.stderr:write("'gearMass' value must be positive. Using default value.\n")
      gearMass = fields.gearMass.defaultValue
    end

    local gearMass2 = fields.gearMass2.value
    if gearMass2 <= 0 then
      io.stderr:write("'gearMass2' value must be positive. Using default value.\n")
      gearMass2 = fields.gearMass2.defaultValue
    end

    if (backlash == 0 and backlash2 == 0) then
      print("No backlash on either axis, 'Hinge2JointWithBacklash' reverted to a 'Hinge2Joint'. All other parameters are ignored.")
    elseif (backlash == 0 and backlash2 ~= 0) then
      print("No backlash on the first axis. 'gearMass' and 'outputSensor' are ignored.")
    elseif (backlash ~= 0 and backlash2 == 0) then
      print("No backlash on the second axis. 'gearMass2' and 'outputSensor2' are ignored.")
    end
  }%
  Hinge2Joint {
    jointParameters IS jointParameters
    jointParameters2 IS jointParameters2
    device IS device
    device2 IS device2
    %{ if backlash == 0 then }% # skip first limiter
      %{ if backlash2 == 0 then }% # skip second limiter
        endPoint IS endPoint # revert PROTO to a classic Hinge2Joint
      %{ else }% # insert limiter2
        endPoint Solid {
          name %{= '"limiter_axis2_'..wbrandom.integer(0, 100000)..'"' }% # prevent name clashes
          children [
            %{ if fields.startPoint.value ~= nil then}%
            Group {
              children IS startPoint
            }
            %{ end }%
            HingeJoint {
              jointParameters HingeJointParameters {
                axis %{= axis2.x }% %{= axis2.y }% %{= axis2.z }%
                anchor %{= anchor.x }% %{= anchor.y }% %{= anchor.z }%
                minStop %{= - backlash2*0.5 }%
                maxStop %{= backlash2*0.5 }%
                stopERP 0
              }
              device IS outputSensor2
              endPoint IS endPoint
            }
          ]
          physics Physics {
            inertiaMatrix [ 4e-9 4e-9 4e-9, 0.0 0.0 0.0 ] # sphere of radius 0.001
            centerOfMass %{= anchor.x }% %{= anchor.y }% %{= anchor.z }%
            density -1
            mass %{= gearMass2 }%
          }
        }
      %{ end }%
    %{ else }% # insert first limiter
      endPoint Solid {
        name %{= '"limiter_axis_'..wbrandom.integer(0, 100000)..'"' }% # prevent name clashes
        children [
          %{ if fields.startPoint.value ~= nil then}%
          Group {
            children IS startPoint
          }
          %{ end }%
          HingeJoint {
            jointParameters HingeJointParameters {
              axis %{= axis.x }% %{= axis.y }% %{= axis.z }%
              anchor %{= anchor.x }% %{= anchor.y }% %{= anchor.z }%
              minStop %{= - backlash*0.5 }%
              maxStop %{= backlash*0.5 }%
              stopERP 0
            }
            device IS outputSensor
            %{ if backlash2 == 0 then }% # finish
              endPoint IS endPoint
            %{ else }% # insert limiter2
              endPoint Solid {
                name %{= '"limiter_axis2_'..wbrandom.integer(0, 100000)..'"' }% # prevent name clashes
                children [
                  HingeJoint {
                    jointParameters HingeJointParameters {
                      axis %{= axis2.x }% %{= axis2.y }% %{= axis2.z }%
                      anchor %{= anchor.x }% %{= anchor.y }% %{= anchor.z }%
                      minStop %{= - backlash2*0.5 }%
                      maxStop %{= backlash2*0.5 }%
                      stopERP 0
                    }
                    device IS outputSensor2
                    endPoint IS endPoint
                  }
                ]
                physics Physics {
                  inertiaMatrix [ 4e-9 4e-9 4e-9, 0.0 0.0 0.0 ] # sphere of radius 0.001
                  centerOfMass %{= anchor.x }% %{= anchor.y }% %{= anchor.z }%
                  density -1
                  mass %{= gearMass2 }%
                }
              }
            %{ end }%
          }
        ]
        physics Physics {
          inertiaMatrix [ 4e-9 4e-9 4e-9, 0.0 0.0 0.0 ] # sphere of radius 0.001
          centerOfMass %{= anchor.x }% %{= anchor.y }% %{= anchor.z }%
          density -1
          mass %{= gearMass }%
        }
      }
    %{ end }%
  }
}
