#VRML_SIM R2023b utf8
# license: Copyright Cyberbotics Ltd. Licensed for use only with Webots.
# license url: https://cyberbotics.com/webots_assets_license
# documentation url: https://webots.cloud/run?url=https://github.com/cyberbotics/webots/blob/released/projects/joints/protos/HingeJointWithBacklash.proto
# keywords: primitive/joint
# This extension of the hinge joint allows to model the effect of backlash.
# tags: no3dView
# template language: javascript

PROTO HingeJointWithBacklash [
  field SFNode                                         jointParameters   HingeJointParameters {}
  field SFFloat                                        backlash          0.01   # Defines the gear clearence, [0, inf).
  field SFFloat                                        gearMass          0.1    # Defines the gear mass, [0, inf).
  field MFNode                                         device            [ ]    # {RotationalMotor, PositionSensor, Brake}.
  field MFNode{PositionSensor{}}                       outputSensor      [ ]    # {PositionSensor}.
  field MFNode{Group{}, Pose{}, Transform{}, Shape{}}  startPoint        [ ]    # {Group, Pose, Transform, or Shape}.
  field SFNode                                         endPoint          NULL   # {Solid, SolidReference, or Slot}.
]
{
  %<
    // parameter retrieval
    const axis = fields.jointParameters.value.fields.axis.value;
    const anchor = fields.jointParameters.value.fields.anchor.value;
    // parameter sanity check
    let backlash = fields.backlash.value;
    if (backlash < 0) {
      backlash = fields.backlash.defaultValue;
      console.error('\'backlash\' value must be greater or equal to 0. Value reset to ' + backlash + '.');
    } else if (backlash > 0 && backlash < 0.01)
      console.log('Values of \'backlash\' smaller than 0.01 are unlikely to be correctly modeled by the physics engine unless the timestep is very low.');

    let gearMass = fields.gearMass.value;
    if (gearMass <= 0) {
      gearMass = fields.gearMass.defaultValue;
      console.error('\'gearMass\' must be strictly positive. Value reset to ' + gearMass + '.');
    }

    if ((backlash === 0 && gearMass > 0) || (backlash === 0 && fields.startPoint.value !== undefined) ||
        (backlash === 0 && fields.outputSensor.value !== undefined))
      console.log('Without backlash \'HingeJointWithBacklash\' is replaced with a \'HingeJoint\'. \'gearMass\', \'startPoint\' and \'outputSensor\' are being ignored. You should consider replacing the node.');
  >%
  HingeJoint {
    jointParameters IS jointParameters
    device IS device
    %< if (backlash === 0) { >% # use a normal hinge
      endPoint IS endPoint
    %< } else { >%
      endPoint Solid {
        name %<= '"start_point_' + context.id + '"' >% # prevent name clashes
        children [
          Group {
            children IS startPoint
          }
          HingeJoint {
            jointParameters HingeJointParameters {
              axis %<= axis.x >% %<= axis.y >% %<= axis.z >%
              anchor %<= anchor.x >% %<= anchor.y >% %<= anchor.z >%
              minStop %<= - backlash*0.5 >%
              maxStop %<= backlash*0.5 >%
              stopERP 0
            }
            device IS outputSensor
            endPoint IS endPoint
          }
        ]
        physics Physics {
          inertiaMatrix [ 4e-8 4e-8 4e-8, 0.0 0.0 0.0 ] # sphere of radius 0.01
          centerOfMass %<= anchor.x >% %<= anchor.y >% %<= anchor.z >%
          density -1
          mass %<= gearMass >%
        }
      }
    %< } >%
  }
}
