#VRML_SIM R2023b utf8
# license: Copyright Cyberbotics Ltd. Licensed for use only with Webots.
# license url: https://cyberbotics.com/webots_assets_license
# documentation url: https://webots.cloud/run?url=https://github.com/cyberbotics/webots/blob/released/projects/joints/protos/Hinge2JointWithBacklash.proto
# keywords: primitive/joint
# This extension of the hinge2joint allows to model the effect of backlash.
# tags: no3dView
# template language: javascript

PROTO Hinge2JointWithBacklash [
  field SFNode                                         jointParameters   HingeJointParameters {}
  field SFNode                                         jointParameters2  JointParameters {}
  field SFFloat                                        backlash          0.01   # Defines the gear clearence for axis, [0, inf).
  field SFFloat                                        backlash2         0.01   # Defines the gear clearence for axis2, [0, inf).
  field SFFloat                                        gearMass          0.1    # Defines the gear mass for axis, [0, inf).
  field SFFloat                                        gearMass2         0.1    # Defines the gear mass for axis2, [0, inf).
  field MFNode                                         device            [ ]    # {RotationalMotor, PositionSensor, Brake}.
  field MFNode                                         device2           [ ]    # {RotationalMotor, PositionSensor, Brake}.
  field MFNode{PositionSensor{}}                       outputSensor      [ ]    # {PositionSensor}.
  field MFNode{PositionSensor{}}                       outputSensor2     [ ]    # {PositionSensor}.
  field MFNode{Group{}, Pose{}, Transform{}, Shape{}}  startPoint        [ ]    # {Group, Pose, Transform, or Shape}.
  field MFNode{Group{}, Pose{}, Transform{}, Shape{}}  startPoint2       [ ]    # {Group, Pose, Transform, or Shape}.
  field SFNode                                         endPoint          NULL   # {Solid, SolidReference, or Slot}.
]
{
  %<
    // parameter retrieval
    const axis = fields.jointParameters.value.fields.axis.value
    const axis2 = fields.jointParameters2.value.fields.axis.value
    const anchor = fields.jointParameters.value.fields.anchor.value
    // parameter sanity check
    let backlash = fields.backlash.value;
    if (backlash < 0) {
      backlash = fields.backlash.defaultValue;
      console.error('\'backlash\' value must be greater or equal to 0. Value reset to ' + backlash + '.');
    } else if (backlash > 0 && backlash < 0.01)
      console.log('Values of \'backlash\' smaller than 0.01 are unlikely to be correctly modeled by the physics engine unless the timestep is very low.');

    let backlash2 = fields.backlash2.value;
    if (backlash2 < 0) {
      backlash2 = fields.backlash2.defaultValue;
      console.error('\'backlash2\' value must be greater or equal to 0. Value reset to ' + backlash2 + '.');
    } else if (backlash2 > 0 && backlash2 < 0.01)
      console.log('Values of \'backlash2\' smaller than 0.01 are unlikely to be correctly modeled by the physics engine unless the timestep is very low.');

    let gearMass = fields.gearMass.value;
    if (gearMass <= 0) {
      gearMass = fields.gearMass.defaultValue;
      console.error('\'gearMass\' must be strictly positive. Value reset to ' + gearMass + '.');
    }

    let gearMass2 = fields.gearMass2.value;
    if (gearMass2 <= 0) {
      gearMass2 = fields.gearMass2.defaultValue;
      console.error('\'gearMass2\' must be strictly positive. Value reset to ' + gearMass2 + '.');
    }

    if (backlash === 0 && backlash2 === 0)
      console.log('No backlash on either axis, \'Hinge2JointWithBacklash\' reverted to a \'Hinge2Joint\'. All other parameters are ignored.');
    else if (backlash === 0 && backlash2 > 0)
      console.log('No backlash on the first axis. \'outputSensor\' and \'startPoint\' are ignored.');
    else if (backlash > 0 && backlash2 === 0)
      console.log('No backlash on the second axis. \'outputSensor2\' and \'startPoint2\' are ignored.');
  >%
  %< if (backlash === 0) { >% # skip first limiter
    %< if (backlash2 === 0) { >% # skip second limiter
      Hinge2Joint { # revert PROTO to a classic Hinge2Joint
        jointParameters IS jointParameters
        jointParameters2 IS jointParameters2
        device IS device
        device2 IS device2
        endPoint IS endPoint
      }
    %< } else { >% # only limiter2 is present
      Hinge2Joint { # free to move
        jointParameters IS jointParameters
        jointParameters2 IS jointParameters2
        device IS device
        device2 IS device2
        endPoint Solid {
          name %<= '"limiter_axis2_' + context.id + '"' >% # prevent name clashes
          children [
            Group {
              children IS startPoint2
            }
            HingeJoint {
              jointParameters HingeJointParameters {
                axis %<= axis2.x >% %<= axis2.y >% %<= axis2.z >%
                anchor %<= anchor.x >% %<= anchor.y >% %<= anchor.z >%
                minStop %<= - backlash2*0.5 >%
                maxStop %<= backlash2*0.5 >%
                stopERP 0
              }
              device IS outputSensor2
              endPoint IS endPoint
            }
          ]
          physics Physics {
            inertiaMatrix [ 4e-8 4e-8 4e-8, 0.0 0.0 0.0 ] # sphere of radius 0.01
            centerOfMass %<= anchor.x >% %<= anchor.y >% %<= anchor.z >%
            density -1
            mass %<= gearMass2 >%
          }
        }
      }
    %< } >%
  %< } else { >%
    HingeJoint { # the first HingeJoint is free to turn, the Hinge2 will be the limiter
      jointParameters IS jointParameters
      device IS device
      endPoint Solid {
        name %<= '"limiter_axis_' + context.id + '"' >% # prevent name clashes
        children [
          Group {
            children IS startPoint
          }
          Hinge2Joint {
            jointParameters HingeJointParameters {
              axis %<= axis.x >% %<= axis.y >% %<= axis.z >%
              anchor %<= anchor.x >% %<= anchor.y >% %<= anchor.z >%
              minStop %<= - backlash*0.5 >%
              maxStop %<= backlash*0.5 >%
              stopERP 0
            }
            jointParameters2 IS jointParameters2
            device IS outputSensor
            device2 IS device2
            %< if (backlash2 === 0) { >% # no need for limiter2
              endPoint IS endPoint
            %< } else { >%
              endPoint Solid {
                name %<= '"limiter_axis2_' + context.id + '"' >% # prevent name clashes
                children [
                  Group {
                    children IS startPoint2
                  }
                  HingeJoint {
                    jointParameters HingeJointParameters {
                      axis %<= axis2.x >% %<= axis2.y >% %<= axis2.z >%
                      anchor %<= anchor.x >% %<= anchor.y >% %<= anchor.z >%
                      minStop %<= - backlash2*0.5 >%
                      maxStop %<= backlash2*0.5 >%
                      stopERP 0
                    }
                    device IS outputSensor2
                    endPoint IS endPoint
                  }
                ]
                physics Physics {
                  inertiaMatrix [ 4e-8 4e-8 4e-8, 0.0 0.0 0.0 ] # sphere of radius 0.01
                  centerOfMass %<= anchor.x >% %<= anchor.y >% %<= anchor.z >%
                  density -1
                  mass %<= gearMass2 >%
                }
              }
            %< } >%
          }
        ]
        physics Physics {
          inertiaMatrix [ 4e-8 4e-8 4e-8, 0.0 0.0 0.0 ] # sphere of radius 0.01
          centerOfMass %<= anchor.x >% %<= anchor.y >% %<= anchor.z >%
          density -1
          mass %<= gearMass >%
        }
      }
    }
  %< } >%
}
