#VRML_SIM R2023b utf8
# license: Copyright Cyberbotics Ltd. Licensed for use only with Webots.
# license url: https://cyberbotics.com/webots_assets_license
# documentation url: https://webots.cloud/run?url=https://github.com/cyberbotics/webots/blob/released/projects/robots/k-team/koala/protos/Koala.proto
# keywords: robot/wheeled
# The "Koala" robot is a six-wheeled indoor robot produced by K-Team.

PROTO Koala [
  field SFVec3f    translation     0 0 0       # Is `Pose.translation`.
  field SFRotation rotation        0 0 1 0     # Is `Pose.rotation`.
  field SFString   name            "Koala"     # Is `Solid.name`.
  field SFString   controller      "koala"     # Is `Robot.controller`.
  field MFString   controllerArgs  []          # Is `Robot.controllerArgs`.
  field SFString   window          "<generic>" # Is `Robot.window`.
  field SFString   customData      ""          # Is `Robot.customData`.
  field SFBool     supervisor      FALSE       # Is `Robot.supervisor`.
  field SFBool     synchronization TRUE        # Is `Robot.synchronization`.
  field MFNode     extensionSlot   []          # Extends the robot with new nodes in the extension slot.
]
{
  Robot {
    translation IS translation
    rotation IS rotation
    controller IS controller
    controllerArgs IS controllerArgs
    window IS window
    customData IS customData
    supervisor IS supervisor
    synchronization IS synchronization
    name IS name
    children [
      Group {
        children IS extensionSlot
      }
      Shape {
        appearance DEF MID_GRAY PBRAppearance {
          baseColor 0.681481 0.681481 0.681481
          metalness 0
          roughness 0.4
        }
        geometry IndexedFaceSet {
          coord Coordinate {
            point [
              -0.0830008 -0.1400006 0.0849982 0.1059992 -0.1400013 0.0849989 0.1269992 -0.1330013 0.0849991 0.1389992 -0.1250014 0.0849992 0.1489993 -0.1130014 0.0849993 0.1579994 -0.0910015 0.0849996 0.1699996 -0.0350015 0.0850002 0.1749997 -1.5e-06 0.0850006 0.1699998 0.0349985 0.085001 0.158 0.0909985 0.0850015 0.1490001 0.1129986 0.0850017 0.1390001 0.1249986 0.0850018 0.1270002 0.1329987 0.0850019 0.1060002 0.1399987 0.0850019 -0.0829998 0.1399994 0.0850012 -0.1039998 0.1329995 0.085001 -0.1159999 0.1249995 0.0850009 -0.1259999 0.1129996 0.0850007 -0.13 0.0909996 0.0850005 -0.1300006 -0.0910004 0.0849986 -0.1260007 -0.1130004 0.0849984 -0.1160008 -0.1250005 0.0849983 -0.1040008 -0.1330005 0.0849982 -0.0830008 -0.1400006 0.0849982 -0.083001 -0.1400011 0.1349982 0.105999 -0.1400018 0.1349989 0.126999 -0.1330019 0.1349991 0.1389991 -0.1250019 0.1349992 0.1489991 -0.113002 0.1349993 0.1579992 -0.091002 0.1349996 0.1699994 -0.035002 0.1350002 0.1749995 -2e-06 0.1350006 0.1699996 0.034998 0.135001 0.1579998 0.090998 0.1350015 0.1489999 0.112998 0.1350017 0.139 0.1249981 0.1350018 0.127 0.1329981 0.1350019 0.106 0.1399982 0.1350019 -0.083 0.1399989 0.1350012 -0.104 0.132999 0.135001 -0.116 0.124999 0.1350009 -0.1260001 0.112999 0.1350007 -0.1300002 0.090999 0.1350005 -0.1300008 -0.091001 0.1349986 -0.1260009 -0.113001 0.1349984 -0.1160009 -0.125001 0.1349983 -0.104001 -0.133001 0.1349982 -0.083001 -0.1400011 0.1349982
            ]
          }
          coordIndex [
            23, 22, 21, 20, 19, 18, 17, 16, 15, 14, 13, 12, 11, 10, 9, 8, 7, 6, 5, 4, 3, 2, 1, 0, -1, 24, 25, 26, 27, 28, 29, 30, 31, 32, 33, 34, 35, 36, 37, 38, 39, 40, 41, 42, 43, 44, 45, 46, 47, -1, 0, 1, 25, 24, -1, 1, 2, 26, 25, -1, 2, 3, 27, 26, -1, 3, 4, 28, 27, -1, 4, 5, 29, 28, -1, 5, 6, 30, 29, -1, 6, 7, 31, 30, -1, 7, 8, 32, 31, -1, 8, 9, 33, 32, -1, 9, 10, 34, 33, -1, 10, 11, 35, 34, -1, 11, 12, 36, 35, -1, 12, 13, 37, 36, -1, 13, 14, 38, 37, -1, 14, 15, 39, 38, -1, 15, 16, 40, 39, -1, 16, 17, 41, 40, -1, 17, 18, 42, 41, -1, 18, 19, 43, 42, -1, 19, 20, 44, 43, -1, 20, 21, 45, 44, -1, 21, 22, 46, 45, -1, 22, 23, 47, 46, -1
          ]
          creaseAngle 2
        }
      }
      Shape {
        appearance USE MID_GRAY
        geometry IndexedFaceSet {
          coord Coordinate {
            point [
              0.1059994 -0.120001 0.0599991 0.1059993 -0.140001 0.0599989 0.1269993 -0.1330011 0.0599991 0.1389993 -0.1250011 0.0599992 0.1599994 -0.1130012 0.0599994 0.1729995 -0.0910013 0.0599997 0.1849997 -0.0350013 0.0600003 0.1899998 -1.3e-06 0.0600007 0.1849999 0.0349987 0.060001 0.1730001 0.0909987 0.0600016 0.1600002 0.1129988 0.0600018 0.1390002 0.1249989 0.0600018 0.1270003 0.1329989 0.0600019 0.1060003 0.139999 0.0600019 0.1060002 0.119999 0.0600016 -0.1299998 0.1199998 0.0600008 -0.1300006 -0.1200002 0.0599983 0.1059993 -0.1200013 0.0854991 0.1059992 -0.1400013 0.0854989 0.1269992 -0.1330014 0.0854991 0.1389992 -0.1250014 0.0854992 0.1599993 -0.1130015 0.0854994 0.1729994 -0.0910015 0.0854997 0.1849996 -0.0350016 0.0855003 0.1899997 -1.6e-06 0.0855007 0.1849998 0.0349984 0.085501 0.173 0.0909985 0.0855016 0.1600001 0.1129985 0.0855018 0.1390001 0.1249986 0.0855018 0.1270002 0.1329986 0.0855019 0.1060002 0.1399987 0.0855019 0.1060001 0.1199987 0.0855016 -0.1299999 0.1199996 0.0855008 -0.1300007 -0.1200004 0.0854983
            ]
          }
          coordIndex [
            14, 8, 6, -1, 25, 26, 31, -1, 1, 17, 0, -1, 2, 18, 1, -1, 3, 19, 2, -1, 4, 20, 3, -1, 5, 21, 4, -1, 6, 22, 5, -1, 7, 23, 6, -1, 8, 24, 7, -1, 9, 25, 8, -1, 10, 26, 9, -1, 11, 27, 10, -1, 12, 28, 11, -1, 13, 29, 12, -1, 14, 30, 13, -1, 15, 31, 14, -1, 16, 32, 15, -1, 0, 33, 16, -1, 0, 16, 15, -1, 14, 13, 12, -1, 0, 15, 14, -1, 2, 1, 0, -1, 5, 4, 0, -1, 3, 2, 0, -1, 0, 14, 6, -1, 11, 10, 14, -1, 14, 12, 11, -1, 4, 3, 0, -1, 7, 6, 8, -1, 9, 8, 14, -1, 14, 10, 9, -1, 6, 5, 0, -1, 17, 18, 19, -1, 20, 21, 17, -1, 17, 19, 20, -1, 32, 33, 17, -1, 29, 30, 31, -1, 31, 32, 17, -1, 17, 21, 22, -1, 22, 23, 17, -1, 24, 25, 23, -1, 26, 27, 31, -1, 28, 29, 31, -1, 31, 23, 25, -1, 23, 31, 17, -1, 27, 28, 31, -1, 1, 18, 17, -1, 2, 19, 18, -1, 3, 20, 19, -1, 4, 21, 20, -1, 5, 22, 21, -1, 6, 23, 22, -1, 7, 24, 23, -1, 8, 25, 24, -1, 9, 26, 25, -1, 10, 27, 26, -1, 11, 28, 27, -1, 12, 29, 28, -1, 13, 30, 29, -1, 14, 31, 30, -1, 15, 32, 31, -1, 16, 33, 32, -1, 0, 17, 33, -1
          ]
          creaseAngle 2
        }
      }
      Shape {
        appearance USE MID_GRAY
        geometry IndexedFaceSet {
          coord Coordinate {
            point [
              -0.1185007 -0.072501 0.1349988 0.0349993 -0.0725015 0.1349994 0.0349998 0.0724985 0.1350009 -0.1185002 0.072499 0.1350003 -0.1185007 -0.072501 0.1349988 -0.118501 -0.0725017 0.1999988 0.034999 -0.0725022 0.1999994 0.0349995 0.0724978 0.2000009 -0.1185005 0.0724983 0.2000003 -0.118501 -0.0725017 0.1999988
            ]
          }
          coordIndex [
            4, 3, 2, 1, 0, -1, 5, 6, 7, 8, 9, -1, 0, 1, 6, 5, -1, 1, 2, 7, 6, -1, 2, 3, 8, 7, -1, 3, 4, 9, 8, -1
          ]
        }
      }
      Shape {
        appearance PBRAppearance {
          baseColor 0 0 0
          metalness 0
          roughness 0.4
        }
        geometry IndexedFaceSet {
          coord Coordinate {
            point [
              0.0449997 0.0549984 0.1350007 0.0449995 0.0549979 0.1850007 0.0449991 -0.0550021 0.1849996 0.0449993 -0.0550016 0.1349996
            ]
          }
          coordIndex [
            0, 1, 2, 3, -1
          ]
        }
      }
      Shape {
        appearance PBRAppearance {
          baseColor 0.2 0.2 0.2
          metalness 0
          roughness 0.4
        }
        geometry IndexedFaceSet {
          coord Coordinate {
            point [
              0.1299998 0.087498 0.1450014 0.0349998 0.0874984 0.145001 0.0349992 -0.0875016 0.1449992 0.1299992 -0.087502 0.1449995
            ]
          }
          coordIndex [
            0, 1, 2, 3, -1
          ]
        }
      }
      Solid {
        translation 0.09 0.1425 0.0425
        rotation -0.577352 0.577348 0.577352 -2.094405
        children [
          DEF LeftWheel Pose {
            rotation 0 1 0 -1.57
            children [
              Shape {
                appearance PBRAppearance {
                  baseColor 0 0 0
                  metalness 0
                  roughness 0.4
                }
                geometry Cylinder {
                  height 0.04
                  radius 0.0425
                }
              }
              Pose {
                translation 0 0 0.02
                children [
                  Shape {
                    appearance PBRAppearance {
                      metalness 0
                      roughness 0.4
                    }
                    geometry Cylinder {
                      height 0.0001
                      radius 0.021
                    }
                  }
                  Shape {
                    appearance PBRAppearance {
                      baseColor 0.7 0.7 0.8
                      metalness 0
                      roughness 0.4
                    }
                    geometry Box {
                      size 0.01 0.01 0.005
                    }
                  }
                ]
              }
            ]
          }
        ]
        name "wheel(1)"
        boundingObject DEF WHEEL_BOUNDING_OBJECT Pose {
          rotation 0 1 0 1.57
          children [
            Cylinder {
              height 0.04
              radius 0.0425
            }
          ]
        }
      }
      HingeJoint {
        jointParameters HingeJointParameters {
          axis 0.0 1 0.0
          anchor 0 0 0.0425
        }
        device [
          RotationalMotor {
            name "left wheel motor"
          }
          PositionSensor {
            name "left wheel sensor"
          }
        ]
        endPoint Solid {
          translation 0 0.1425 0.0425
          rotation 0.091549 -0.091559 0.991582 -1.579252
          children [
            USE LeftWheel
          ]
          name "wheel(2)"
          boundingObject USE WHEEL_BOUNDING_OBJECT
        }
      }
      Solid {
        translation -0.09 0.1425 0.0425
        rotation -0.577352 0.577348 0.577352 -2.094405
        children [
          USE LeftWheel
        ]
        name "wheel(3)"
        boundingObject USE WHEEL_BOUNDING_OBJECT
      }
      Solid {
        translation 0.09 -0.1425 0.0425
        rotation -0.577352 0.577348 0.577352 -2.094405
        children [
          DEF RightWheel Pose {
            rotation 0 -1 0 1.57
            children [
              Shape {
                appearance PBRAppearance {
                  baseColor 0 0 0
                  metalness 0
                  roughness 0.4
                }
                geometry Cylinder {
                  height 0.04
                  radius 0.0425
                }
              }
              Pose {
                translation 0 0 -0.02
                children [
                  Shape {
                    appearance PBRAppearance {
                      metalness 0
                      roughness 0.4
                    }
                    geometry Cylinder {
                      height 0.0001
                      radius 0.021
                    }
                  }
                  Shape {
                    appearance PBRAppearance {
                      baseColor 0.7 0.7 0.8
                      metalness 0
                      roughness 0.4
                    }
                    geometry Box {
                      size 0.01 0.01 0.005
                    }
                  }
                ]
              }
            ]
          }
        ]
        name "wheel(4)"
        boundingObject USE WHEEL_BOUNDING_OBJECT
      }
      HingeJoint {
        jointParameters HingeJointParameters {
          axis 0 1 0
          anchor 0 0 0.0425
        }
        device [
          RotationalMotor {
            name "right wheel motor"
          }
          PositionSensor {
            name "right wheel sensor"
          }
        ]
        endPoint Solid {
          translation 0 -0.1425 0.0425
          rotation 0.463377 -0.463386 0.755351 -1.847756
          children [
            USE RightWheel
          ]
          name "wheel(5)"
          boundingObject USE WHEEL_BOUNDING_OBJECT
        }
      }
      Solid {
        translation -0.09 -0.1425 0.0425
        rotation -0.577352 0.577348 0.577352 -2.094405
        children [
          USE RightWheel
        ]
        name "wheel(6)"
        boundingObject USE WHEEL_BOUNDING_OBJECT
      }
      Pose {
        translation 0 -0.1075 0.045
        children [
          Shape {
            appearance USE MID_GRAY
            geometry Box {
              size 0.22 0.03 0.03
            }
          }
        ]
      }
      Pose {
        translation 0 0.1075 0.045
        children [
          Shape {
            appearance USE MID_GRAY
            geometry Box {
              size 0.22 0.03 0.03
            }
          }
        ]
      }
      DistanceSensor {
        translation 0.175 -0.015 0.102
        rotation -0.997505 0.049918 0.049915 -1.573305
        children [
          DEF Sensor Shape {
            appearance PBRAppearance {
              baseColor 0 0 0
              metalness 0
              roughness 0.4
            }
            geometry Box {
              size 0.01 0.015 0.017
            }
          }
        ]
        name "ds0"
        lookupTable [
          0 1024 0
          0.5 0 0.01
        ]
        type "infra-red"
      }
      DistanceSensor {
        translation 0.169 -0.04 0.102
        rotation -0.990083 0.09934 0.099338 -1.580774
        children [
          USE Sensor
        ]
        name "ds1"
        lookupTable [
          0 1024 0
          0.5 0 0.01
        ]
        type "infra-red"
      }
      DistanceSensor {
        translation 0.16 -0.07 0.102
        rotation -0.977912 0.147797 0.147795 -1.593141
        children [
          USE Sensor
        ]
        name "ds2"
        lookupTable [
          0 1024 0
          0.5 0 0.01
        ]
        type "infra-red"
      }
      DistanceSensor {
        translation 0.14 -0.12 0.102
        rotation 0.85828 -0.362874 -0.362875 1.723042
        children [
          USE Sensor
        ]
        name "ds3"
        lookupTable [
          0 1024 0
          0.35 0 0.01
        ]
        type "infra-red"
      }
      DistanceSensor {
        translation 0.055 -0.14 0.102
        rotation -0.577352 0.577348 0.577352 -2.094405
        children [
          USE Sensor
        ]
        name "ds4"
        lookupTable [
          0 1024 0
          0.5 0 0.01
        ]
        type "infra-red"
      }
      DistanceSensor {
        translation -0.05 -0.14 0.102
        rotation -0.577352 0.577348 0.577352 -2.094405
        children [
          USE Sensor
        ]
        name "ds5"
        lookupTable [
          0 1024 0
          0.5 0 0.01
        ]
        type "infra-red"
      }
      DistanceSensor {
        translation -0.12 -0.125 0.102
        rotation 0.25662 -0.683424 -0.683431 2.639204
        children [
          USE Sensor
        ]
        name "ds6"
        lookupTable [
          0 1024 0
          0.35 0 0.01
        ]
        type "infra-red"
      }
      DistanceSensor {
        translation -0.13 -0.0475 0.107
        rotation 0 0.707103 0.70711 3.141585
        children [
          USE Sensor
        ]
        name "ds7"
        lookupTable [
          0 1024 0
          0.5 0 0.01
        ]
        type "infra-red"
      }
      DistanceSensor {
        translation -0.13 0.0475 0.107
        rotation 0 0.707103 0.70711 3.141585
        children [
          USE Sensor
        ]
        name "ds8"
        lookupTable [
          0 1024 0
          0.5 0 0.01
        ]
        type "infra-red"
      }
      DistanceSensor {
        translation -0.12 0.125 0.102
        rotation 0.28248 0.678305 0.678313 2.59098
        children [
          USE Sensor
        ]
        name "ds9"
        lookupTable [
          0 1024 0
          0.35 0 0.01
        ]
        type "infra-red"
      }
      DistanceSensor {
        translation -0.05 0.14 0.102
        rotation 0.577277 0.577383 0.577391 2.094511
        children [
          USE Sensor
        ]
        name "ds10"
        lookupTable [
          0 1024 0
          0.5 0 0.01
        ]
        type "infra-red"
      }
      DistanceSensor {
        translation 0.055 0.14 0.102
        rotation 0.577354 0.577344 0.577352 2.094396
        children [
          USE Sensor
        ]
        name "ds11"
        lookupTable [
          0 1024 0
          0.5 0 0.01
        ]
        type "infra-red"
      }
      DistanceSensor {
        translation 0.14 0.125 0.102
        rotation 0.858281 0.36287 0.362877 1.723038
        children [
          USE Sensor
        ]
        name "ds12"
        lookupTable [
          0 1024 0
          0.35 0 0.01
        ]
        type "infra-red"
      }
      DistanceSensor {
        translation 0.16 0.07 0.102
        rotation -0.977912 -0.147794 -0.147799 -1.59314
        children [
          USE Sensor
        ]
        name "ds13"
        lookupTable [
          0 1024 0
          0.5 0 0.01
        ]
        type "infra-red"
      }
      DistanceSensor {
        translation 0.169 0.04 0.102
        rotation -0.990083 -0.099337 -0.099341 -1.580773
        children [
          USE Sensor
        ]
        name "ds14"
        lookupTable [
          0 1024 0
          0.5 0 0.01
        ]
        type "infra-red"
      }
      DistanceSensor {
        translation 0.175 0.015 0.102
        rotation -0.997505 -0.049915 -0.049919 -1.573305
        children [
          USE Sensor
        ]
        name "ds15"
        lookupTable [
          0 1024 0
          0.5 0 0.01
        ]
        type "infra-red"
      }
    ]
    model "Koala"
    description "designed by Edo Franzi, Francesco Mondada (K-Team SA)"
    boundingObject Group {
      children [
        Pose {
          translation 0.025 -0.0 0.105
          children [
            Box {
              size 0.3 0.15 0.2
            }
          ]
        }
        Pose {
          translation -0.01 -0.0 0.105
          children [
            Box {
              size 0.23 0.28 0.2
            }
          ]
        }
        Pose {
          translation 0.105 -0.07 0.105
          children [
            Cylinder {
              height 0.2
              radius 0.07
            }
          ]
        }
        Pose {
          translation 0.105 0.07 0.105
          children [
            Cylinder {
              height 0.2
              radius 0.07
            }
          ]
        }
      ]
    }
  }
}
