#VRML_SIM R2023b utf8

EXTERNPROTO "webots://projects/objects/backgrounds/protos/TexturedBackground.proto"
EXTERNPROTO "webots://projects/objects/backgrounds/protos/TexturedBackgroundLight.proto"
EXTERNPROTO "webots://projects/objects/gear/protos/Gear.proto"

WorldInfo {
  info [
    "Example of meshing gears"
  ]
  title "Gears example"
  basicTimeStep 8
}
Viewpoint {
  orientation 0 0 1 4.71238898038469
  position -0.041748615977272176 0.27118552471245 -0.0005254140023221207
}
TexturedBackground {
  texture "empty_office"
}
TexturedBackgroundLight {
}
Robot {
  rotation 0 0 1 1.5708
  children [
    DEF MOTORIZED HingeJoint {
      jointParameters HingeJointParameters {
      }
      device [
        PositionSensor {
        }
        RotationalMotor {
        }
      ]
      endPoint Gear {
        translation 0 0 0
        appearance PBRAppearance {
          baseColor 0.8 0 0
          roughness 0.5
        }
        teeth 20
        toothDepth 0.007
        density 0.01
        bodyBoundingObject FALSE
        teethBoundingObject TRUE
      }
    }
    DEF PASSIVE HingeJoint {
      jointParameters HingeJointParameters {
        anchor 0 0.083 0
        dampingConstant 1e-08
      }
      endPoint Gear {
        translation 0 0.083 0
        rotation 1 0 0 0.261799
        appearance PBRAppearance {
          baseColor 0.203922 0.396078 0.643137
          roughness 0.5
        }
        name "gear2"
        teeth 20
        toothDepth 0.007
        density 0.01
        bodyBoundingObject FALSE
        teethBoundingObject TRUE
      }
    }
  ]
  controller "gears"
  selfCollision TRUE
}
