#VRML_SIM R2021c utf8
# license: Copyright Cyberbotics Ltd. Licensed for use only with Webots.
# license url: https://cyberbotics.com/webots_assets_license
# documentation url: https://www.cyberbotics.com/doc/guide/mir100
# Designed by Mobile Industrial Robotics (MIR), MiR100 is a six-wheeled robot (4 caster wheels and 2 regular ones at the
# center). Used in industrial environments, it can carry a payload of up to 100kg.

PROTO Mir100 [
  field  SFVec3f     translation      0 0 0               # Is `Transform.translation`.
  field  SFRotation  rotation         0 0 1 0             # Is `Transform.rotation`.
  field  SFString    name             "Mir100"            # Is `Robot.name`.
  field  SFString    controller       "keyboard_control"  # Is `Robot.controller`.
  field  MFString    controllerArgs   []                  # Is `Robot.controllerArgs`.
  field  SFString    customData       ""                  # Is `Robot.customData`.
  field  SFBool      supervisor       FALSE               # Is `Robot.supervisor`.
  field  SFBool      synchronization  TRUE                # Is `Robot.synchronization`.
  field  SFColor     color            0 0.9 1             # Middle section color of the robot.
  field  MFNode      frontLidarSlot   []                  # Extends the robot with a lidar sensor at the front.
  field  MFNode      backLidarSlot    []                  # Extends the robot with a lidar sensor at the back.
  field  MFNode      bodySlot         []                  # Extends the robot with new nodes located in the body.
]
{
  Robot {
    translation IS translation
    rotation IS rotation
    controller IS controller
    controllerArgs IS controllerArgs
    customData IS customData
    supervisor IS supervisor
    synchronization IS synchronization
    name IS name
    model  "Mobile Industrial Robots' MiR100"
    children [
      Transform {
        translation 0.037646 0 0
        children [
          Shape {
            appearance DEF WHITE Plastic {
            }
            geometry Mesh {
              url [
                "webots://projects/robots/mir/mir100/protos/meshes/mir_100_base.obj"
              ]
            }
          }
          Shape {
            appearance USE WHITE
            geometry Mesh {
              url [
                "webots://projects/robots/mir/mir100/protos/meshes/mir_100_inside.obj"
              ]
            }
          }
          Shape {
            appearance Plastic {
              colorOverride 0.93 0.93 0.93
            }
            geometry Mesh {
              url [
                "webots://projects/robots/mir/mir100/protos/meshes/mir_100_logos.dae"
              ]
            }
          }
          Shape {
            appearance DEF BLACK Plastic {
              colorOverride 0 0 0
            }
            geometry Mesh {
              url [
                "webots://projects/robots/mir/mir100/protos/meshes/mir_100_base_corners.dae"
              ]
            }
          }
          Shape {
            appearance DEF BLACK Plastic {
              colorOverride 0 0 0
            }
            geometry Mesh {
              url [
                "webots://projects/robots/mir/mir100/protos/meshes/mir_100_top_plugs.dae"
              ]
            }
          }
        ]
      }
      DEF IMU Transform {
        translation 0 0 0.25
        children [
          Accelerometer {
            name "imu_data accelerometer"
            lookupTable [
              -100 -100 -0.002
              100 100 0.002
            ]
          }
          Gyro {
            name "imu_data gyro"
            lookupTable [
              -100 -100 -0.002
              100 100 0.002
            ]
          }
          Compass {
            name "imu_data compass"
            lookupTable [
              -1 -1 -0.2
              1 1 0.2
            ]
          }
        ]
      }
      Transform {
        translation 0.4288 0.2358 0.188
        rotation -0.2811 -0.6786 0.6786 2.5936
        children IS frontLidarSlot
      }
      Transform {
        translation -0.3548 -0.2352 0.188
        rotation 0.8629 -0.3574 0.3574 -1.7178
        children IS backLidarSlot
      }
      Transform {
        translation 0.037646 0 0.349
        children IS bodySlot
      }
      DEF CAMERA_RIGHT Transform {
        translation 0.448325 -0.063463 0.110114
        rotation -0.5314699172926579 -0.816513872934121 0.22548796490956566 -1.7730453071795864
        scale 1.0003465485345713 0.92893 0.92893
        children [
          Shape {
            appearance Appearance {
              material Material {
                emissiveColor 1 1 1
              }
              texture ImageTexture {
                url [
                  "webots://projects/robots/mir/mir100/protos/textures/camera.png"
                ]
              }
              textureTransform TextureTransform {
                rotation 3.1415926
              }
            }
            geometry Plane {
              size 0.08 0.015
            }
          }
        ]
      }
      DEF CAMERA_LEFT Transform {
        translation 0.448325 0.063463 0.110114
        rotation 0.6425837390040647 0.41825883011730935 0.6419857392469521 -2.7903353071795864
        scale 1.0003465485345713 0.92893 0.92893
        children [
          Shape {
            appearance Appearance {
              material Material {
                emissiveColor 1 1 1
              }
              texture ImageTexture {
                url [
                  "webots://projects/robots/mir/mir100/protos/textures/camera.png"
                ]
              }
            }
            geometry Plane {
              size 0.08 0.015
            }
          }
        ]
      }
      Mir100UltrasonicSensor {
        translation 0.415448 -0.108238 0.08
        rotation 0.8628559982596194 -0.35740699927911007 -0.35740699927911007 1.71777
        name "ds0"
        lookupTable [
          0.2 1000 0
          0.3 0 0
        ]
      }
      Mir100UltrasonicSensor {
        translation -0.3844 -0.1328 0.156
        rotation 0 0 1 3.141592653589793
        name "ds1"
        lookupTable [
          0.01 1000 0
          0.35 0 0
        ]
      }
      Mir100UltrasonicSensor {
        translation -0.3844 0.1328 0.156
        rotation 0 0 1 3.141592653589793
        name "ds2"
        lookupTable [
          0.01 1000 0
          0.35 0 0
        ]
      }
      Mir100UltrasonicSensor {
        translation 0.415448 0.108238 0.08
        rotation 0.8628559982596194 0.35740699927911007 0.35740699927911007 1.71777
        name "ds3"
        lookupTable [
          0.2 1000 0
          0.3 0 0
        ]
      }
      RangeFinder {
        translation 0.464 0 0.18
        rotation -0.5773509358560258 0.577349935856137 0.577349935856137 -2.094395307179586
        name "depth_camera"
        fieldOfView 2.05949
        minRange 0.18
        maxRange 1.95
        width 1280
        height 720
      }
      Transform {
        translation 0.03733 0.0005 0.2085
        children [
          DEF LIGHT_FRONT Transform {
            translation 0.392 0 0
            children [
              DEF LIGHT_WIDTH_SHAPE Shape {
                appearance PBRAppearance {
                  baseColor 1 1 1
                  emissiveColor IS color
                  transparency 0.5
                }
                geometry Box {
                  size 0.001 0.4723 0.053
                }
              }
            ]
          }
          DEF LIGHT_BACK Transform {
            translation -0.392 0 0
            children [
              USE LIGHT_WIDTH_SHAPE
            ]
          }
          DEF LIGHT_LEFT Transform {
            translation 0 0.2355 0
            children [
              DEF LIGHT_WIDTH_SHAPE Shape {
                appearance PBRAppearance {
                  baseColor 1 1 1
                  emissiveColor IS color
                  transparency 0.5
                }
                geometry Box {
                  size 0.783 0.001 0.053
                }
              }
            ]
          }
          DEF LIGHT_RIGHT Transform {
            translation 0 -0.2355 0
            children [
              USE LIGHT_WIDTH_SHAPE
            ]
          }
        ]
      }

      DEF US_1_FRAME Solid {
        translation 0.45 -0.12 0.16
        name "us_1_frame"
      }
      DEF US_2_FRAME Solid {
        translation 0.45 0.12 0.16
        name "us_2_frame"
      }
      DEF LEFT_WHEEL_JOINT HingeJoint {
        jointParameters HingeJointParameters {
          axis 0 1 0
          anchor 0 0.222604 0.0625
        }
        device [
          RotationalMotor {
            name "middle_left_wheel_joint"
            maxVelocity 20
            maxTorque 100
          }
          PositionSensor {
            name "middle_left_wheel_joint_sensor"
          }
        ]
        endPoint DEF LEFT_WHEEL_LINK Solid {
          translation 0 0.222604 0.0625
          children [
            Group {
              children [
                DEF RIM Shape {
                  appearance CorrodedMetal {
                  }
                  geometry Cylinder {
                      radius 0.0465
                      height 0.032
                  }
                }
                SolidTorus {
                  majorRadius 0.0465
                  minorRadius 0.016
                  enableBoundingObject FALSE
                  appearance DEF WHEEL_RUBBER PBRAppearance {
                    baseColor 0 0 0
                    roughness 1
                    metalness 0
                  }
                }
              ]
            }
          ]
          name "left_wheel_link"
          contactMaterial "wheel"
          boundingObject DEF WHEEL_BO Cylinder {
            radius 0.0625
            height 0.01
          }
          physics Physics {
            density -1
            mass 1
            centerOfMass [
              0 0 0
            ]
            inertiaMatrix [
              0.001061895 0.001953125 0.001061895
              0 0 5.457207e-20
            ]
          }
        }
      }
      DEF RIGHT_WHEEL_JOINT HingeJoint {
        jointParameters HingeJointParameters {
          axis 0 1 0
          anchor 0 -0.222604 0.0625
        }
        device [
          RotationalMotor {
            name "middle_right_wheel_joint"
            maxVelocity 20
            maxTorque 100
          }
          PositionSensor {
            name "middle_right_wheel_joint_sensor"
          }
        ]
        endPoint DEF RIGHT_WHEEL_LINK Solid {
          translation 0 -0.222604 0.0625
          children [
            Group {
              children [
                USE RIM
                SolidTorus {
                  majorRadius 0.0465
                  minorRadius 0.016
                  enableBoundingObject FALSE
                  appearance USE WHEEL_RUBBER
                }
              ]
            }
          ]
          name "right_wheel_link"
          contactMaterial "wheel"
          boundingObject USE WHEEL_BO
          physics Physics {
            density -1
            mass 1
            centerOfMass [
              0 0 0
            ]
            inertiaMatrix [
              0.001061895 0.001953125 0.001061895
              0 0 5.457207e-20
            ]
          }
        }
      }
      DEF FL_CASTER_ROTATION_JOINT HingeJoint {
        jointParameters HingeJointParameters {
          axis 0 0 1
          anchor 0.341346 0.203 0.1565
          dampingConstant 0.01
        }
        device [
          PositionSensor {
            name "front_left_caster_joint_sensor"
          }
        ]
        endPoint DEF FL_CASTER_ROTATION_LINK Solid {
          translation 0.341346 0.203 0.1565
          rotation 0 0 1 0
          children [
            DEF CASTER_WHEEL_BASE Shape {
              appearance PBRAppearance {
                baseColor 0.35 0.35 0.35
                roughness 1
                metalness 0
              }
              geometry Mesh {
                url [
                  "webots://projects/robots/mir/mir100/protos/meshes/caster_wheel_base.dae"
                ]
              }
            }
            DEF FL_CASTER_WHEEL_JOINT HingeJoint {
              jointParameters HingeJointParameters {
                axis 0 1 0
                anchor -0.0382 0 -0.094
              }
              device [
                PositionSensor {
                  name "front_left_wheel_joint_sensor"
                }
              ]
              endPoint DEF FL_CASTER_WHEEL_LINK Solid {
                translation -0.0382 0 -0.094
                children [
                  Group {
                    children [
                      USE RIM
                      SolidTorus {
                        majorRadius 0.0465
                        minorRadius 0.016
                        enableBoundingObject FALSE
                        appearance USE WHEEL_RUBBER
                      }
                    ]
                  }
                ]
                name "fl_caster_wheel_link"
                contactMaterial "wheel"
                boundingObject USE WHEEL_BO
                physics Physics {
                  density -1
                  mass 1
                  centerOfMass [
                    0 0 0
                  ]
                  inertiaMatrix [
                    0.001061895 0.001953125 0.001061895
                    0 0 5.457207e-20
                  ]
                }
              }
            }
          ]
          name "fl_caster_rotation_link"
          boundingObject Transform {
            translation 0 0 -0.028
            rotation 1 0 0 1.5708003061004252
            children [
              DEF SWIVEL Cylinder {
                height 0.055
                radius 0.0298
              }
            ]
          }
          physics Physics {
            density -1
            mass 0.309754
            centerOfMass [
              0 0 -0.0425
            ]
            inertiaMatrix [
              0.0005287255 0.000517415 0.0002462724
              -7.734275e-21 -1.120566e-20 -0.0001505672
            ]
          }
        }
      }
      DEF FR_CASTER_ROTATION_JOINT HingeJoint {
        jointParameters HingeJointParameters {
          axis 0 0 1
          anchor 0.341346 -0.203 0.1565
          dampingConstant 0.01
        }
        device [
          PositionSensor {
            name "front_right_caster_joint_sensor"
          }
        ]
        endPoint DEF FR_CASTER_ROTATION_LINK Solid {
          translation 0.341346 -0.203 0.1565
          rotation 0 0 1 0
          children [
            USE CASTER_WHEEL_BASE
            DEF FR_CASTER_WHEEL_JOINT HingeJoint {
              jointParameters HingeJointParameters {
                axis 0 1 0
                anchor -0.0382 0 -0.094
              }
              device [
                PositionSensor {
                  name "front_right_wheel_joint_sensor"
                }
              ]
              endPoint DEF FR_CASTER_WHEEL_LINK Solid {
                translation -0.0382 0 -0.094
                children [
                  Group {
                    children [
                      USE RIM
                      SolidTorus {
                        majorRadius 0.0465
                        minorRadius 0.016
                        enableBoundingObject FALSE
                        appearance USE WHEEL_RUBBER
                      }
                    ]
                  }
                ]
                name "fr_caster_wheel_link"
                contactMaterial "wheel"
                boundingObject USE WHEEL_BO
                physics Physics {
                  density -1
                  mass 1
                  centerOfMass [
                    0 0 0
                  ]
                  inertiaMatrix [
                    0.001061895 0.001953125 0.001061895
                    0 0 5.457207e-20
                  ]
                }
              }
            }
          ]
          name "fr_caster_rotation_link"
          boundingObject Transform {
            translation 0 0 -0.028
            rotation 1 0 0 1.5707996938995747
            children [
              USE SWIVEL
            ]
          }
          physics Physics {
            density -1
            mass 0.309754
            centerOfMass [
              0 0 -0.0425
            ]
            inertiaMatrix [
              0.0005287255 0.000517415 0.0002462724
              -7.734275e-21 -1.120566e-20 -0.0001505672
            ]
          }
        }
      }
      DEF BL_CASTER_ROTATION_JOINT HingeJoint {
        jointParameters HingeJointParameters {
          axis 0 0 1
          anchor -0.270154 0.203 0.1565
          dampingConstant 0.01
        }
        device [
          PositionSensor {
            name "back_left_caster_joint_sensor"
          }
        ]
        endPoint DEF BL_CASTER_ROTATION_LINK Solid {
          translation -0.270154 0.203 0.1565
          rotation 0 0 1 0
          children [
            USE CASTER_WHEEL_BASE
            DEF BL_CASTER_WHEEL_JOINT HingeJoint {
              jointParameters HingeJointParameters {
                axis 0 1 0
                anchor -0.0382 0 -0.094
              }
              device [
                PositionSensor {
                  name "back_left_wheel_joint_sensor"
                }
              ]
              endPoint DEF BL_CASTER_WHEEL_LINK Solid {
                translation -0.0382 0 -0.094
                children [
                  Group {
                    children [
                      USE RIM
                      SolidTorus {
                        majorRadius 0.0465
                        minorRadius 0.016
                        enableBoundingObject FALSE
                        appearance USE WHEEL_RUBBER
                      }
                    ]
                  }
                ]
                name "bl_caster_wheel_link"
                contactMaterial "wheel"
                boundingObject USE WHEEL_BO
                physics Physics {
                  density -1
                  mass 1
                  centerOfMass [
                    0 0 0
                  ]
                  inertiaMatrix [
                    0.001061895 0.001953125 0.001061895
                    0 0 5.457207e-20
                  ]
                }
              }
            }
          ]
          name "bl_caster_rotation_link"
          boundingObject Transform {
            translation 0 0 -0.028
            rotation 1 0 0 1.5707996938995747
            children [
              USE SWIVEL
            ]
          }
          physics Physics {
            density -1
            mass 0.309754
            centerOfMass [
              0 0 -0.0425
            ]
            inertiaMatrix [
              0.0005287255 0.000517415 0.0002462724
              -7.734275e-21 -1.120566e-20 -0.0001505672
            ]
          }
        }
      }
      DEF BR_CASTER_ROTATION_JOINT HingeJoint {
        jointParameters HingeJointParameters {
          axis 0 0 1
          anchor -0.270154 -0.203 0.1565
          dampingConstant 0.01
        }
        device [
          PositionSensor {
            name "back_right_caster_joint_sensor"
          }
        ]
        endPoint DEF BR_CASTER_ROTATION_LINK Solid {
          translation -0.270154 -0.203 0.1565
          rotation 0 0 1 0
          children [
            USE CASTER_WHEEL_BASE
            DEF BR_CASTER_WHEEL_JOINT HingeJoint {
              jointParameters HingeJointParameters {
                axis 0 1 0
                anchor -0.0382 0 -0.094
              }
              device [
                PositionSensor {
                  name "back_right_wheel_joint_sensor"
                }
              ]
              endPoint DEF BR_CASTER_WHEEL_LINK Solid {
                translation -0.0382 0 -0.094
                children [
                  Group {
                    children [
                      USE RIM
                      SolidTorus {
                        majorRadius 0.0465
                        minorRadius 0.016
                        enableBoundingObject FALSE
                        appearance USE WHEEL_RUBBER
                      }
                    ]
                  }
                ]
                name "br_caster_wheel_link"
                contactMaterial "wheel"
                boundingObject USE WHEEL_BO
                physics Physics {
                  density -1
                  mass 1
                  centerOfMass [
                    0 0 0
                  ]
                  inertiaMatrix [
                    0.001061895 0.001953125 0.001061895
                    0 0 5.457207e-20
                  ]
                }
              }
            }
          ]
          name "br_caster_rotation_link"
          boundingObject Transform {
            translation 0 0 -0.028
            rotation 1 0 0 1.5707996938995747
            children [
              USE SWIVEL
            ]
          }
          physics Physics {
            density -1
            mass 0.309754
            centerOfMass [
              0 0 -0.0425
            ]
            inertiaMatrix [
              0.0005287255 0.000517415 0.0002462724
              -7.734275e-21 -1.120566e-20 -0.0001505672
            ]
          }
        }
      }
      DEF SURFACE Solid {
        translation 0.037646 0 0.352
        name "surface"
      }
    ]
    boundingObject Group {
      children [
        DEF TOP Transform {
          translation 0.0375 0.0005 0.334
          children [
            Box {
              size 0.774 0.461 0.04
            }
          ]
        }
        DEF MIDDLE_CENTER Transform {
          translation 0.0375 0.0005 0.262
          children [
            Box {
              size 0.857 0.44 0.096
            }
          ]
        }
        DEF MIDDLE_RIGHT_SIDE Transform {
          translation 0.0375 -0.25 0.262
          children [
            Box {
              size 0.774 0.041 0.096
            }
          ]
        }
        DEF MIDDLE_LEFT_SIDE Transform {
          translation 0.0375 0.25 0.262
          children [
            Box {
              size 0.774 0.041 0.096
            }
          ]
        }
        DEF CYL_BR Transform {
          translation -0.3555 -0.2353 0.262
          rotation 1 0 0 1.5707996938995747
          children [
            Cylinder {
              height 0.096
              radius 0.054
            }
          ]
        }
        DEF CYL_FL Transform {
          translation 0.4306 0.2364 0.262
          rotation 1 0 0 1.5707996938995747
          children [
            Cylinder {
              height 0.096
              radius 0.054
            }
          ]
        }
        DEF CYL_FR Transform {
          translation 0.415 -0.221 0.262
          rotation 1 0 0 1.5707996938995747
          children [
            Cylinder {
              height 0.096
              radius 0.049
            }
          ]
        }
        DEF CYL_BL Transform {
          translation -0.341 0.222 0.262
          rotation 1 0 0 1.5707996938995747
          children [
            Cylinder {
              height 0.096
              radius 0.049
            }
          ]
        }
        DEF MIDLOW Transform {
          translation 0.03733 0.0005 0.204
          children [
            Box {
              size 0.7806 0.4665 0.04
            }
          ]
        }
        DEF LOW Transform {
          translation 0.0374 0.0005 0.16
          children [
            Box {
              size 0.85 0.536 0.039
            }
          ]
        }
        DEF BOTTOM_LEFT Transform {
          translation 0.0374 0.2486 0.09425
          children [
            Box {
              size 0.35 0.04 0.0925
            }
          ]
        }
        DEF BOTTOM_RIGHT Transform {
          translation 0.0374 -0.2476 0.09425
          children [
            Box {
              size 0.35 0.04 0.0925
            }
          ]
        }
        DEF BOTTOM_CENTER Transform {
          translation 0.0375 0.0005 0.094
          children [
            Box {
              size 0.857 0.2 0.092
            }
          ]
        }
      ]
    }
    physics Physics {
      density -1
      mass 70
    }
  }
}
