#VRML_SIM R2023b utf8

EXTERNPROTO "webots://projects/objects/backgrounds/protos/TexturedBackground.proto"
EXTERNPROTO "webots://projects/objects/backgrounds/protos/TexturedBackgroundLight.proto"
EXTERNPROTO "webots://projects/objects/balls/protos/SoccerBall.proto"

WorldInfo {
  info [
    "A soccer game."
    "This example demonstrates several capabilities of the supervisor:"
    "- read and modify the position of objects"
    "- display text on the simulation window"
    "- send messages to robot controllers"
  ]
  title "Soccer Game"
  optimalThreadCount 8
}
Viewpoint {
  orientation 0.251373707362422 -0.5312808559637874 -0.8090438253477107 5.22481331228121
  position -1.4893505881226752 -1.770666324752664 1.4413878323834504
}
TexturedBackground {
}
TexturedBackgroundLight {
}
DEF SOCCER_FIELD Solid {
  children [
    DEF GROUND Shape {
      appearance PBRAppearance {
        baseColorMap ImageTexture {
          url [
            "webots://projects/samples/demos/worlds/textures/soccer/soccer-256.jpg"
          ]
        }
        roughness 1
        metalness 0
      }
      geometry Plane {
        size 1.5 1.5
      }
    }
    DEF YELLOW_GOAL_GROUND Shape {
      appearance PBRAppearance {
        baseColorMap ImageTexture {
          url [
            "webots://projects/samples/demos/worlds/textures/soccer/soccer-256.jpg"
          ]
        }
        roughness 1
        metalness 0
      }
      geometry IndexedFaceSet {
        coord Coordinate {
          point [
            -0.95 -0.75 0
            -0.75 -0.75 0
            -0.75 0.75 0
            -0.95 0.75 0
          ]
        }
        texCoord TextureCoordinate {
          point [
            0 0
            0 0
            0 0
            0 0
          ]
        }
        coordIndex [
          0, 1, 2, 3
        ]
        texCoordIndex [
          0, 1, 2, 3
        ]
      }
    }
    DEF BLUE_GOAL_GROUND Shape {
      appearance PBRAppearance {
        baseColorMap ImageTexture {
          url [
            "webots://projects/samples/demos/worlds/textures/soccer/soccer-256.jpg"
          ]
        }
        roughness 1
        metalness 0
      }
      geometry IndexedFaceSet {
        coord Coordinate {
          point [
            0.95 -0.75 0
            0.75 -0.75 0
            0.75 0.75 0
            0.95 0.75 0
          ]
        }
        texCoord TextureCoordinate {
          point [
            0 0
            0 0
            0 0
            0 0
          ]
        }
        ccw FALSE
        coordIndex [
          0, 1, 2, 3
        ]
        texCoordIndex [
          0, 1, 2, 3
        ]
      }
    }
    DEF NORTH_WALL Shape {
      appearance DEF WALL_APPEARANCE PBRAppearance {
        baseColor 0.388235 0.388235 0.388235
        roughness 1
        metalness 0
      }
      geometry IndexedFaceSet {
        coord Coordinate {
          point [
            0.76 -0.66 0
            0.76 -0.21 0
            0.75 -0.21 0
            0.75 -0.59 0
            0.69 -0.65 0
            -0.69 -0.65 0
            -0.75 -0.59 0
            -0.75 -0.21 0
            -0.76 -0.21 0
            -0.76 -0.65 0
            -0.76 -0.66 0
            0.76 -0.66 0.05
            0.76 -0.21 0.05
            0.75 -0.21 0.05
            0.75 -0.59 0.05
            0.69 -0.65 0.05
            -0.69 -0.65 0.05
            -0.75 -0.59 0.05
            -0.75 -0.21 0.05
            -0.76 -0.21 0.05
            -0.76 -0.65 0.05
            -0.76 -0.66 0.05
          ]
        }
        coordIndex [
          0, 10, 9, -1, 9, 8, 7, -1, 9, 7, 6, -1, 2, 1, 0, -1, 3, 2, 0, -1, 9, 6, 5, -1, 4, 3, 0, -1, 0, 9, 5, -1, 0, 5, 4, -1, 11, 12, 13, -1, 11, 13, 14, -1, 20, 21, 11, -1, 18, 19, 20, -1, 17, 18, 20, -1, 11, 14, 15, -1, 16, 17, 20, -1, 11, 15, 16, -1, 11, 16, 20, -1, 0, 1, 12, 11, -1, 1, 2, 13, 12, -1, 2, 3, 14, 13, -1, 3, 4, 15, 14, -1, 4, 5, 16, 15, -1, 5, 6, 17, 16, -1, 6, 7, 18, 17, -1, 7, 8, 19, 18, -1, 8, 9, 20, 19, -1, 9, 10, 21, 20, -1, 10, 0, 11, 21, -1
        ]
      }
    }
    DEF SOUTH_WALL Shape {
      appearance USE WALL_APPEARANCE
      geometry IndexedFaceSet {
        coord Coordinate {
          point [
            0.76 0.66 0
            -0.76 0.66 0
            -0.76 0.65 0
            -0.76 0.21 0
            -0.75 0.21 0
            -0.75 0.59 0
            -0.69 0.65 0
            0.69 0.65 0
            0.75 0.59 0
            0.75 0.21 0
            0.76 0.21 0
            0.76 0.66 0.05
            -0.76 0.66 0.05
            -0.76 0.65 0.05
            -0.76 0.21 0.05
            -0.75 0.21 0.05
            -0.75 0.59 0.05
            -0.69 0.65 0.05
            0.69 0.65 0.05
            0.75 0.59 0.05
            0.75 0.21 0.05
            0.76 0.21 0.05
          ]
        }
        coordIndex [
          0, 10, 9, -1, 0, 9, 8, -1, 2, 1, 0, -1, 4, 3, 2, -1, 5, 4, 2, -1, 0, 8, 7, -1, 6, 5, 2, -1, 0, 7, 6, -1, 0, 6, 2, -1, 11, 12, 13, -1, 13, 14, 15, -1, 13, 15, 16, -1, 20, 21, 11, -1, 19, 20, 11, -1, 13, 16, 17, -1, 18, 19, 11, -1, 11, 13, 17, -1, 11, 17, 18, -1, 0, 1, 12, 11, -1, 1, 2, 13, 12, -1, 2, 3, 14, 13, -1, 3, 4, 15, 14, -1, 4, 5, 16, 15, -1, 5, 6, 17, 16, -1, 6, 7, 18, 17, -1, 7, 8, 19, 18, -1, 8, 9, 20, 19, -1, 9, 10, 21, 20, -1, 10, 0, 11, 21, -1
        ]
      }
    }
    DEF BLUE_GOAL Shape {
      appearance PBRAppearance {
        baseColor 0 0 1
        roughness 1
        metalness 0
      }
      geometry IndexedFaceSet {
        coord Coordinate {
          point [
            0.86 -0.21 0
            0.86 0.21 0
            0.75 0.21 0
            0.75 0.2 0
            0.85 0.2 0
            0.85 -0.2 0
            0.75 -0.2 0
            0.75 -0.21 0
            0.86 -0.21 0
            0.86 -0.21 0.12
            0.86 0.21 0.12
            0.75 0.21 0.12
            0.75 0.2 0.12
            0.85 0.2 0.12
            0.85 -0.2 0.12
            0.75 -0.2 0.12
            0.75 -0.21 0.12
            0.86 -0.21 0.12
          ]
        }
        coordIndex [
          0, 1, 2, 3, 4, 5, 6, 7, 8, -1, 0, 1, 10, 9, -1, 1, 2, 11, 10, -1, 2, 3, 12, 11, -1, 3, 4, 13, 12, -1, 4, 5, 14, 13, -1, 5, 6, 15, 14, -1, 6, 7, 16, 15, -1, 7, 8, 17, 16, -1
        ]
      }
    }
    DEF YELLOW_GOAL Shape {
      appearance PBRAppearance {
        baseColor 1 1 0
        roughness 1
        metalness 0
      }
      geometry IndexedFaceSet {
        coord Coordinate {
          point [
            -0.86 -0.21 0
            -0.75 -0.21 0
            -0.75 -0.2 0
            -0.85 -0.2 0
            -0.85 0.2 0
            -0.75 0.2 0
            -0.75 0.21 0
            -0.86 0.21 0
            -0.86 -0.21 0
            -0.86 -0.21 0.12
            -0.75 -0.21 0.12
            -0.75 -0.2 0.12
            -0.85 -0.2 0.12
            -0.85 0.2 0.12
            -0.75 0.2 0.12
            -0.75 0.21 0.12
            -0.86 0.21 0.12
            -0.86 -0.21 0.12
          ]
        }
        coordIndex [
          0, 1, 2, 3, 4, 5, 6, 7, 8, -1, 0, 1, 10, 9, -1, 1, 2, 11, 10, -1, 2, 3, 12, 11, -1, 3, 4, 13, 12, -1, 4, 5, 14, 13, -1, 5, 6, 15, 14, -1, 6, 7, 16, 15, -1, 7, 8, 17, 16, -1
        ]
      }
    }
  ]
  name "soccer field"
  boundingObject Group {
    children [
      USE GROUND
      DEF NOTH_BBOX Pose {
        translation 0 0.655 0.0252
        children [
          Box {
            size 1.5 0.01 0.05
          }
        ]
      }
      DEF SOUTH_BBOX Pose {
        translation 0 -0.655 0.0251
        children [
          Box {
            size 1.5 0.01 0.05
          }
        ]
      }
      DEF NW_BBOX Pose {
        translation -0.755 0.43 0.0251
        children [
          Box {
            size 0.01 0.435 0.05
          }
        ]
      }
      DEF NE_BBOX Pose {
        translation 0.755 0.43 0.0251
        children [
          Box {
            size 0.01 0.435 0.05
          }
        ]
      }
      DEF SW_BBOX Pose {
        translation -0.755 -0.43 0.0251
        children [
          Box {
            size 0.01 0.435 0.05
          }
        ]
      }
      DEF SE_BBOX Pose {
        translation 0.755 -0.43 0.0251
        children [
          Box {
            size 0.01 0.435 0.05
          }
        ]
      }
      DEF NWC_BBOX Pose {
        translation 0.725 -0.62 0.0251
        rotation 0 0 1 -0.7853
        children [
          Box {
            size 0.01 0.09 0.05
          }
        ]
      }
      DEF NEC_BBOX Pose {
        translation -0.725 -0.62 0.0251
        rotation 0 0 1 0.7853
        children [
          Box {
            size 0.01 0.09 0.05
          }
        ]
      }
      DEF SWC_BBOX Pose {
        translation 0.725 0.62 0.0251
        rotation 0 0 1 0.7853
        children [
          Box {
            size 0.01 0.09 0.05
          }
        ]
      }
      DEF SEC_BBOX Pose {
        translation -0.725 0.62 0.0251
        rotation 0 0 1 -0.7853
        children [
          Box {
            size 0.01 0.09 0.05
          }
        ]
      }
      DEF YG_BBOX Pose {
        translation -0.855 0 0.061
        children [
          Box {
            size 0.01 0.42 0.12
          }
        ]
      }
      DEF BG_BBOX Pose {
        translation 0.855 0 0.061
        children [
          Box {
            size 0.01 0.42 0.12
          }
        ]
      }
      DEF BGS_BBOX Pose {
        translation 0.8 -0.205 0.061
        children [
          Box {
            size 0.1 0.01 0.12
          }
        ]
      }
      DEF BGN_BBOX Pose {
        translation 0.8 0.205 0.061
        children [
          Box {
            size 0.1 0.01 0.12
          }
        ]
      }
      DEF YGS_BBOX Pose {
        translation -0.8 -0.205 0.061
        children [
          Box {
            size 0.1 0.01 0.12
          }
        ]
      }
      DEF YGN_BBOX Pose {
        translation -0.8 0.205 0.061
        children [
          Box {
            size 0.1 0.01 0.12
          }
        ]
      }
    ]
  }
  locked TRUE
}
DEF BALL SoccerBall {
  translation -0.182283 0.297774 0.05
  rotation 0.7071067811865477 0 0.7071067811865477 2.62318
  radius 0.021
  mass 0.05
}
DEF B1 Robot {
  translation -0.0349213 0.301715 0.0381772
  rotation 0 0 1 3.14159
  children [
    HingeJoint {
      jointParameters HingeJointParameters {
        axis 0 1 0
        anchor 0 0.045 -0.0176
      }
      device [
        RotationalMotor {
          name "left wheel motor"
        }
        PositionSensor {
          name "left wheel sensor"
        }
      ]
      endPoint Solid {
        translation 0 0.045 -0.0176
        rotation 1 0 0 1.5708
        children [
          Pose {
            rotation 0 0 1 1.57
            children [
              DEF WHEEL_SHAPE Shape {
                appearance PBRAppearance {
                  roughness 1
                  metalness 0
                }
                geometry Cylinder {
                  height 0.01
                  radius 0.02
                }
              }
            ]
          }
        ]
        name "left wheel"
        boundingObject Pose {
          rotation 0 0 1 1.57
          children [
            USE WHEEL_SHAPE
          ]
        }
        physics DEF WHEEL_PHYSICS Physics {
          density -1
          mass 0.005
        }
      }
    }
    HingeJoint {
      jointParameters HingeJointParameters {
        axis 0 1 0
        anchor 0 -0.045 -0.0176
      }
      device [
        RotationalMotor {
          name "right wheel motor"
        }
        PositionSensor {
          name "right wheel sensor"
        }
      ]
      endPoint Solid {
        translation 0 -0.045 -0.0176
        rotation 1 0 0 1.5708
        children [
          Pose {
            rotation 0 0 1 1.57
            children [
              Shape {
                appearance PBRAppearance {
                  roughness 1
                  metalness 0
                }
                geometry Cylinder {
                  height 0.01
                  radius 0.02
                }
              }
            ]
          }
        ]
        name "right wheel"
        boundingObject Pose {
          rotation 0 0 1 1.57
          children [
            Shape {
              appearance PBRAppearance {
                roughness 1
                metalness 0
              }
              geometry Cylinder {
                height 0.01
                radius 0.02
              }
            }
          ]
        }
        physics USE WHEEL_PHYSICS
      }
    }
    DEF BLUE_ROBOT_SHAPE Shape {
      appearance PBRAppearance {
        baseColorMap ImageTexture {
          url [
            "webots://projects/samples/demos/worlds/textures/soccer/blue.png"
          ]
        }
        roughness 1
        metalness 0
      }
      geometry Box {
        size 0.075 0.075 0.075
      }
    }
    Receiver {
    }
  ]
  name "b1"
  boundingObject USE BLUE_ROBOT_SHAPE
  physics DEF ROBOT_PHYSICS Physics {
    density -1
    mass 0.2
  }
  controller "soccer_player"
}
DEF B2 Robot {
  translation 0.271657 -0.289311 0.0381772
  rotation 0 0 1 2.72043
  children [
    HingeJoint {
      jointParameters HingeJointParameters {
        axis 0 1 0
        anchor 0 0.045 -0.0176
      }
      device [
        RotationalMotor {
          name "left wheel motor"
        }
        PositionSensor {
          name "left wheel sensor"
        }
      ]
      endPoint Solid {
        translation 0 0.045 -0.0176
        rotation 1 0 0 1.5707996938995747
        children [
          Pose {
            rotation 0 0 1 1.57
            children [
              DEF WHEEL_SHAPE Shape {
                appearance PBRAppearance {
                  roughness 1
                  metalness 0
                }
                geometry Cylinder {
                  height 0.01
                  radius 0.02
                }
              }
            ]
          }
        ]
        name "left wheel"
        boundingObject Pose {
          rotation 0 0 1 1.57
          children [
            USE WHEEL_SHAPE
          ]
        }
        physics DEF WHEEL_PHYSICS Physics {
          density -1
          mass 0.005
        }
      }
    }
    HingeJoint {
      jointParameters HingeJointParameters {
        axis 0 1 0
        anchor 0 -0.045 -0.0176
      }
      device [
        RotationalMotor {
          name "right wheel motor"
        }
        PositionSensor {
          name "right wheel sensor"
        }
      ]
      endPoint Solid {
        translation 0 -0.045 -0.0176
        rotation 1 0 0 1.5708003061004252
        children [
          Pose {
            rotation 0 0 1 1.57
            children [
              Shape {
                appearance PBRAppearance {
                  roughness 1
                  metalness 0
                }
                geometry Cylinder {
                  height 0.01
                  radius 0.02
                }
              }
            ]
          }
        ]
        name "right wheel"
        boundingObject Pose {
          rotation 0 0 1 1.57
          children [
            Shape {
              appearance PBRAppearance {
                roughness 1
                metalness 0
              }
              geometry Cylinder {
                height 0.01
                radius 0.02
              }
            }
          ]
        }
        physics USE WHEEL_PHYSICS
      }
    }
    DEF BLUE_ROBOT_SHAPE Shape {
      appearance PBRAppearance {
        baseColorMap ImageTexture {
          url [
            "webots://projects/samples/demos/worlds/textures/soccer/blue.png"
          ]
        }
        roughness 1
        metalness 0
      }
      geometry Box {
        size 0.075 0.075 0.075
      }
    }
    Receiver {
    }
  ]
  name "b2"
  boundingObject USE BLUE_ROBOT_SHAPE
  physics USE ROBOT_PHYSICS
  controller "soccer_player"
}
DEF B3 Robot {
  translation 0.718395 0.0459804 0.0381772
  rotation 0 0 1 -1.5319153071795863
  children [
    HingeJoint {
      jointParameters HingeJointParameters {
        axis 0 1 0
        anchor 0 0.045 -0.0176
      }
      device [
        RotationalMotor {
          name "left wheel motor"
        }
        PositionSensor {
          name "left wheel sensor"
        }
      ]
      endPoint Solid {
        translation 0 0.045 -0.0176
        rotation 1 0 0 1.5707996938995747
        children [
          Pose {
            rotation 0 0 1 1.57
            children [
              DEF WHEEL_SHAPE Shape {
                appearance PBRAppearance {
                  roughness 1
                  metalness 0
                }
                geometry Cylinder {
                  height 0.01
                  radius 0.02
                }
              }
            ]
          }
        ]
        name "left wheel"
        boundingObject Pose {
          rotation 0 0 1 1.57
          children [
            USE WHEEL_SHAPE
          ]
        }
        physics DEF WHEEL_PHYSICS Physics {
          density -1
          mass 0.005
        }
      }
    }
    HingeJoint {
      jointParameters HingeJointParameters {
        axis 0 1 0
        anchor 0 -0.045 -0.0176
      }
      device [
        RotationalMotor {
          name "right wheel motor"
        }
        PositionSensor {
          name "right wheel sensor"
        }
      ]
      endPoint Solid {
        translation 0 -0.045 -0.0176
        rotation 1 0 0 1.5707996938995747
        children [
          Pose {
            rotation 0 0 1 1.57
            children [
              Shape {
                appearance PBRAppearance {
                  roughness 1
                  metalness 0
                }
                geometry Cylinder {
                  height 0.01
                  radius 0.02
                }
              }
            ]
          }
        ]
        name "right wheel"
        boundingObject Pose {
          rotation 0 0 1 1.57
          children [
            Shape {
              appearance PBRAppearance {
                roughness 1
                metalness 0
              }
              geometry Cylinder {
                height 0.01
                radius 0.02
              }
            }
          ]
        }
        physics USE WHEEL_PHYSICS
      }
    }
    DEF BLUE_ROBOT_SHAPE Shape {
      appearance PBRAppearance {
        baseColorMap ImageTexture {
          url [
            "webots://projects/samples/demos/worlds/textures/soccer/blue.png"
          ]
        }
        roughness 1
        metalness 0
      }
      geometry Box {
        size 0.075 0.075 0.075
      }
    }
    Receiver {
    }
  ]
  name "b3"
  boundingObject USE BLUE_ROBOT_SHAPE
  physics USE ROBOT_PHYSICS
  controller "soccer_player"
}
DEF Y1 Robot {
  translation -0.344136 0.407555 0.0381772
  rotation 0 0 1 -0.4665753071795864
  children [
    HingeJoint {
      jointParameters HingeJointParameters {
        axis 0 1 0
        anchor 0 0.045 -0.0176
      }
      device [
        RotationalMotor {
          name "left wheel motor"
        }
        PositionSensor {
          name "left wheel sensor"
        }
      ]
      endPoint Solid {
        translation 0 0.045 -0.0176
        rotation 1 0 0 1.5707996938995747
        children [
          Pose {
            rotation 0 0 1 1.57
            children [
              DEF WHEEL_SHAPE Shape {
                appearance PBRAppearance {
                  roughness 1
                  metalness 0
                }
                geometry Cylinder {
                  height 0.01
                  radius 0.02
                }
              }
            ]
          }
        ]
        name "left wheel"
        boundingObject Pose {
          rotation 0 0 1 1.57
          children [
            USE WHEEL_SHAPE
          ]
        }
        physics DEF WHEEL_PHYSICS Physics {
          density -1
          mass 0.005
        }
      }
    }
    HingeJoint {
      jointParameters HingeJointParameters {
        axis 0 1 0
        anchor 0 -0.045 -0.0176
      }
      device [
        RotationalMotor {
          name "right wheel motor"
        }
        PositionSensor {
          name "right wheel sensor"
        }
      ]
      endPoint Solid {
        translation 0 -0.045 -0.0176
        rotation 1 0 0 1.5707996938995747
        children [
          Pose {
            rotation 0 0 1 1.57
            children [
              Shape {
                appearance PBRAppearance {
                  roughness 1
                  metalness 0
                }
                geometry Cylinder {
                  height 0.01
                  radius 0.02
                }
              }
            ]
          }
        ]
        name "right wheel"
        boundingObject Pose {
          rotation 0 0 1 1.57
          children [
            Shape {
              appearance PBRAppearance {
                roughness 1
                metalness 0
              }
              geometry Cylinder {
                height 0.01
                radius 0.02
              }
            }
          ]
        }
        physics USE WHEEL_PHYSICS
      }
    }
    DEF YELLOW_ROBOT_SHAPE Shape {
      appearance PBRAppearance {
        baseColorMap ImageTexture {
          url [
            "webots://projects/samples/demos/worlds/textures/soccer/yellow.png"
          ]
        }
        roughness 1
        metalness 0
      }
      geometry Box {
        size 0.075 0.075 0.075
      }
    }
    Receiver {
    }
  ]
  name "y1"
  boundingObject USE YELLOW_ROBOT_SHAPE
  physics USE ROBOT_PHYSICS
  controller "soccer_player"
}
DEF Y2 Robot {
  translation -0.392446 -0.0946615 0.0381772
  rotation 0 0 1 0.464067
  children [
    HingeJoint {
      jointParameters HingeJointParameters {
        axis 0 1 0
        anchor 0 0.045 -0.0176
      }
      device [
        RotationalMotor {
          name "left wheel motor"
        }
        PositionSensor {
          name "left wheel sensor"
        }
      ]
      endPoint Solid {
        translation 0 0.045 -0.0176
        rotation 1 0 0 1.5707996938995747
        children [
          Pose {
            rotation 0 0 1 1.57
            children [
              DEF WHEEL_SHAPE Shape {
                appearance PBRAppearance {
                  roughness 1
                  metalness 0
                }
                geometry Cylinder {
                  height 0.01
                  radius 0.02
                }
              }
            ]
          }
        ]
        name "left wheel"
        boundingObject Pose {
          rotation 0 0 1 1.57
          children [
            USE WHEEL_SHAPE
          ]
        }
        physics DEF WHEEL_PHYSICS Physics {
          density -1
          mass 0.005
        }
      }
    }
    HingeJoint {
      jointParameters HingeJointParameters {
        axis 0 1 0
        anchor 0 -0.045 -0.0176
      }
      device [
        RotationalMotor {
          name "right wheel motor"
        }
        PositionSensor {
          name "right wheel sensor"
        }
      ]
      endPoint Solid {
        translation 0 -0.045 -0.0176
        rotation 1 0 0 1.5707996938995747
        children [
          Pose {
            rotation 0 0 1 1.57
            children [
              Shape {
                appearance PBRAppearance {
                  roughness 1
                  metalness 0
                }
                geometry Cylinder {
                  height 0.01
                  radius 0.02
                }
              }
            ]
          }
        ]
        name "right wheel"
        boundingObject Pose {
          rotation 0 0 1 1.57
          children [
            Shape {
              appearance PBRAppearance {
                roughness 1
                metalness 0
              }
              geometry Cylinder {
                height 0.01
                radius 0.02
              }
            }
          ]
        }
        physics USE WHEEL_PHYSICS
      }
    }
    DEF YELLOW_ROBOT_SHAPE Shape {
      appearance PBRAppearance {
        baseColorMap ImageTexture {
          url [
            "webots://projects/samples/demos/worlds/textures/soccer/yellow.png"
          ]
        }
        roughness 1
        metalness 0
      }
      geometry Box {
        size 0.075 0.075 0.075
      }
    }
    Receiver {
    }
  ]
  name "y2"
  boundingObject USE YELLOW_ROBOT_SHAPE
  physics USE ROBOT_PHYSICS
  controller "soccer_player"
}
DEF Y3 Robot {
  translation -0.710919 0.114706 0.0381772
  rotation 0 0 -1 1.5613
  children [
    HingeJoint {
      jointParameters HingeJointParameters {
        axis 0 1 0
        anchor 0 -0.045 -0.0176
      }
      device [
        RotationalMotor {
          name "left wheel motor"
        }
        PositionSensor {
          name "left wheel sensor"
        }
      ]
      endPoint Solid {
        translation 0 -0.045 -0.0176
        rotation 1 0 0 1.5707996938995747
        children [
          Pose {
            rotation 0 0 1 1.57
            children [
              DEF WHEEL_SHAPE Shape {
                appearance PBRAppearance {
                  roughness 1
                  metalness 0
                }
                geometry Cylinder {
                  height 0.01
                  radius 0.02
                }
              }
            ]
          }
        ]
        name "left wheel"
        boundingObject Pose {
          rotation 0 0 1 1.57
          children [
            USE WHEEL_SHAPE
          ]
        }
        physics DEF WHEEL_PHYSICS Physics {
          density -1
          mass 0.005
        }
      }
    }
    HingeJoint {
      jointParameters HingeJointParameters {
        axis 0 1 0
        anchor 0 0.045 -0.0176
      }
      device [
        RotationalMotor {
          name "right wheel motor"
        }
        PositionSensor {
          name "right wheel sensor"
        }
      ]
      endPoint Solid {
        translation 0 0.045 -0.0176
        rotation 1 0 0 1.5707996938995747
        children [
          Pose {
            rotation 0 0 1 1.57
            children [
              Shape {
                appearance PBRAppearance {
                  roughness 1
                  metalness 0
                }
                geometry Cylinder {
                  height 0.01
                  radius 0.02
                }
              }
            ]
          }
        ]
        name "right wheel"
        boundingObject Pose {
          rotation 0 0 1 1.57
          children [
            Shape {
              appearance PBRAppearance {
                roughness 1
                metalness 0
              }
              geometry Cylinder {
                height 0.01
                radius 0.02
              }
            }
          ]
        }
        physics USE WHEEL_PHYSICS
      }
    }
    DEF YELLOW_ROBOT_SHAPE Shape {
      appearance PBRAppearance {
        baseColorMap ImageTexture {
          url [
            "webots://projects/samples/demos/worlds/textures/soccer/yellow.png"
          ]
        }
        roughness 1
        metalness 0
      }
      geometry Box {
        size 0.075 0.075 0.075
      }
    }
    Receiver {
    }
  ]
  name "y3"
  boundingObject USE YELLOW_ROBOT_SHAPE
  physics USE ROBOT_PHYSICS
  controller "soccer_player"
}
Robot {
  children [
    Emitter {
      range 10
      baudRate 115200
    }
  ]
  controller "soccer_referee_supervisor"
  supervisor TRUE
}
