#VRML_SIM R2023b utf8
# license: Apache License 2.0.
# license url: https://www.apache.org/licenses/LICENSE-2.0
# documentation url: https://webots.cloud/run?url=https://github.com/cyberbotics/webots/blob/released/projects/robots/pal_robotics/tiago_extensions/protos/TiagoLeftArm.proto
# keywords: robot/extension
# This is a PROTO file for Webots for the robot TIAGo from PAL Robotics (Spain).
# It is the robot's left arm that can be connected to the TIAGo body.

EXTERNPROTO "webots://projects/appearances/protos/GlossyPaint.proto"
EXTERNPROTO "webots://projects/appearances/protos/MattePaint.proto"
EXTERNPROTO "webots://projects/appearances/protos/BrushedAluminium.proto"

PROTO TiagoLeftArm [
  field  SFVec3f     translation      0 0 0
  field  SFRotation  rotation         0 0 1 0
  field  SFString    name             "TIAGo left arm"
  field  SFNode      endEffectorSlot  NULL # Extends the arm with an end-effector (such as the TiagoGripper or the TiagoLeftHey5 for example).
]
{
  Slot {
    type "tiago left arm"
    endPoint Solid {
      translation IS translation
      rotation IS rotation
      name IS name
      children [
        DEF LEFT_SHOULDER Shape {
          appearance GlossyPaint {
            baseColor 0.823529 0.776471 0.776471
            textureTransform TextureTransform {
              scale 4 4
            }
            IBLStrength 1.8
          }
          geometry Mesh {
            url "meshes/shoulder.obj"
          }
        }
        DEF ARM_LEFT_1_JOINT HingeJoint {
          jointParameters HingeJointParameters {
            axis 0 0 -1
            anchor 0.025 0.194 -0.16
            dampingConstant 1
            staticFriction 1
          }
          device [
            RotationalMotor {
              name "arm_left_1_joint"
              maxVelocity 1.95
              minPosition -1.11
              maxPosition 1.5
              maxTorque 43
            }
            PositionSensor {
              name "arm_left_1_joint_sensor"
            }
          ]
          endPoint DEF ARM_LEFT_1 Solid {
            translation 0.0251 0.194 -0.171
            rotation 0 0 1 1.5708
            children [
              DEF ARM_LEFT_1_SH1 Shape {
                appearance GlossyPaint {
                  baseColor 0.823529 0.776471 0.776471
                  textureTransform TextureTransform {
                    scale 4 4
                  }
                  IBLStrength 1.8
                }
                geometry Mesh {
                  url "meshes/arm_1_sh1.obj"
                }
              }
              DEF ARM_LEFT_1_SH2 Shape {
                appearance MattePaint {
                  baseColor 0.133333 0.133333 0.133333
                }
                geometry Mesh {
                  url "meshes/arm_1_sh2.obj"
                }
              }
              DEF ARM_LEFT_1_SH3 Shape {
                appearance GlossyPaint {
                  baseColor 0.823529 0.776471 0.776471
                  textureTransform TextureTransform {
                    scale 4 4
                  }
                  IBLStrength 1.8
                }
                geometry Mesh {
                  url "meshes/arm_1_sh3.obj"
                }
              }
              DEF ARM_LEFT_2_JOINT HingeJoint {
                jointParameters HingeJointParameters {
                  axis 0 1 0
                  anchor 0.125 0.0195 -0.031
                  dampingConstant 1
                  staticFriction 1
                }
                device [
                  RotationalMotor {
                    name "arm_left_2_joint"
                    maxVelocity 1.95
                    minPosition -1.11
                    maxPosition 1.5
                    maxTorque 43
                  }
                  PositionSensor {
                    name "arm_left_2_joint_sensor"
                  }
                ]
                endPoint DEF ARM_LEFT_2 Solid {
                  translation 0.125 0.018 -0.031
                  rotation 1 0 0 1.5708
                  children [
                    DEF ARM_LEFT_2_SH1 Shape {
                      appearance MattePaint {
                        baseColor 0.133333 0.133333 0.133333
                      }
                      geometry Mesh {
                        url "meshes/arm_2_sh1.obj"
                      }
                    }
                    DEF ARM_LEFT_3_JOINT HingeJoint {
                      jointParameters HingeJointParameters {
                        anchor 0.0895 0 -0.0015
                        dampingConstant 1
                        staticFriction 1
                      }
                      device [
                        RotationalMotor {
                          name "arm_left_3_joint"
                          maxVelocity 2.35
                          minPosition -0.72
                          maxPosition 3.86
                          maxTorque 26
                        }
                        PositionSensor {
                          name "arm_left_3_joint_sensor"
                        }
                      ]
                      endPoint DEF ARM_LEFT_3 Solid {
                        translation 0.0872 0 -0.0015
                        rotation -0.5773 0.5774 0.5773 -2.0944
                        children [
                          DEF ARM_LEFT_3_SH1 Shape {
                            appearance GlossyPaint {
                              baseColor 0.0470588 0.0470588 0.0470588
                            }
                            geometry Mesh {
                              url "meshes/arm_3_sh1.obj"
                            }
                          }
                          DEF ARM_LEFT_3_SH2 Shape {
                            appearance GlossyPaint {
                              baseColor 0.0470588 0.0470588 0.0470588
                            }
                            geometry Mesh {
                              url "meshes/arm_3_sh2.obj"
                            }
                          }
                          DEF ARM_LEFT_3_SH3 Shape {
                            appearance MattePaint {
                              baseColor 0.133333 0.133333 0.133333
                            }
                            geometry Mesh {
                              url "meshes/arm_3_sh3.obj"
                            }
                          }
                          DEF ARM_LEFT_4_JOINT HingeJoint {
                            jointParameters HingeJointParameters {
                              axis 0 1 0
                              anchor -0.02 -0.027 -0.222
                              dampingConstant 1
                              staticFriction 1
                            }
                            device [
                              RotationalMotor {
                                name "arm_left_4_joint"
                                maxVelocity 2.35
                                minPosition -0.32
                                maxPosition 2.29
                                maxTorque 26
                              }
                              PositionSensor {
                                name "arm_left_4_joint_sensor"
                              }
                            ]
                            endPoint DEF ARM_LEFT_4 Solid {
                              translation -0.02 -0.027 -0.222
                              rotation -0.5774 -0.5774 -0.5774 2.0944
                              children [
                                DEF ARM_LEFT_4_SH1 Shape {
                                  appearance MattePaint {
                                    baseColor 0.133333 0.133333 0.133333
                                  }
                                  geometry Mesh {
                                    url "meshes/arm_4_sh1.obj"
                                  }
                                }
                                DEF ARM_LEFT_4_SH2 Shape {
                                  appearance GlossyPaint {
                                    baseColor 0.0470588 0.0470588 0.0470588
                                  }
                                  geometry Mesh {
                                    url "meshes/arm_4_sh2.obj"
                                  }
                                }
                                DEF ARM_LEFT_4_SH3 Shape {
                                  appearance GlossyPaint {
                                    baseColor 0.0470588 0.0470588 0.0470588
                                  }
                                  geometry Mesh {
                                    url "meshes/arm_4_sh3.obj"
                                  }
                                }
                                DEF ARM_LEFT_5_JOINT HingeJoint {
                                  jointParameters HingeJointParameters {
                                    anchor -0.162 0.02 0.027
                                    dampingConstant 1
                                    staticFriction 1
                                  }
                                  device [
                                    RotationalMotor {
                                      name "arm_left_5_joint"
                                      maxVelocity 1.95
                                      minPosition -2.07
                                      maxPosition 2.07
                                      maxTorque 3
                                    }
                                    PositionSensor {
                                      name "arm_left_5_joint_sensor"
                                    }
                                  ]
                                  endPoint DEF ARM_LEFT_5 Solid {
                                    translation -0.162 0.02 0.027
                                    rotation 0 -1 0 1.5708
                                    children [
                                      DEF ARM_LEFT_5_SH1 Shape {
                                        appearance GlossyPaint {
                                          baseColor 0.823529 0.776471 0.776471
                                          textureTransform TextureTransform {
                                            scale 4 4
                                          }
                                          IBLStrength 1.8
                                        }
                                        geometry Mesh {
                                          url "meshes/arm_5_sh1.obj"
                                        }
                                      }
                                      DEF ARM_LEFT_6_JOINT HingeJoint {
                                        jointParameters HingeJointParameters {
                                          axis 0 -1 0
                                          anchor 0 0 0.15
                                          dampingConstant 1
                                          staticFriction 1
                                        }
                                        device [
                                          RotationalMotor {
                                            name "arm_left_6_joint"
                                            maxVelocity 1.76
                                            minPosition -1.39
                                            maxPosition 1.39
                                            maxTorque 6.6
                                          }
                                          PositionSensor {
                                            name "arm_left_6_joint_sensor"
                                          }
                                        ]
                                        endPoint DEF ARM_LEFT_6 Solid {
                                          translation 0 0 0.15
                                          rotation -0.5774 -0.5774 -0.5774 2.0944
                                          children [
                                            DEF ARM_LEFT_6_SH1 Shape {
                                              appearance GlossyPaint {
                                                baseColor 0.823529 0.776471 0.776471
                                                textureTransform TextureTransform {
                                                  scale 4 4
                                                }
                                                IBLStrength 1.8
                                              }
                                              geometry Mesh {
                                                url "meshes/arm_6_sh1.obj"
                                              }
                                            }
                                            DEF ARM_LEFT_7_JOINT HingeJoint {
                                              jointParameters HingeJointParameters {
                                                axis -1 0 0
                                                dampingConstant 1
                                                staticFriction 1
                                              }
                                              device [
                                                RotationalMotor {
                                                  name "arm_left_7_joint"
                                                  maxVelocity 1.76
                                                  minPosition -2.07
                                                  maxPosition 2.07
                                                  maxTorque 6.6
                                                }
                                                PositionSensor {
                                                  name "arm_left_7_joint_sensor"
                                                }
                                              ]
                                              endPoint DEF WRIST Solid {
                                                translation 0.055 0 0
                                                rotation 0.5774 0.5774 0.5774 2.0944
                                                children [
                                                  Pose {
                                                    rotation 1 0 0 1.570796
                                                    children [
                                                      DEF ARM_LEFT_7_SH1 Shape {
                                                        appearance GlossyPaint {
                                                          baseColor 0.823529 0.776471 0.776471
                                                          textureTransform TextureTransform {
                                                            scale 4 4
                                                          }
                                                          IBLStrength 1.8
                                                        }
                                                        geometry Mesh {
                                                          url "meshes/arm_7_sh1.obj"
                                                        }
                                                      }
                                                    ]
                                                  }
                                                  DEF WRIST_LEFT_CONNECTOR Solid {
                                                    translation 0 0 0.012725
                                                    rotation -0.5774 -0.5774 -0.5774 2.0944
                                                    children [
                                                      Pose {
                                                        rotation 0 0 1 -1.5708
                                                        children [
                                                          Slot {
                                                            type "tiago hand"
                                                            endPoint IS endEffectorSlot
                                                          }
                                                        ]
                                                      }
                                                      Pose {
                                                        rotation 0.5774 0.5774 -0.5774 2.0944
                                                        children [
                                                          Shape {
                                                            appearance BrushedAluminium {
                                                              textureTransform TextureTransform {
                                                                scale 3 5
                                                              }
                                                            }
                                                            geometry Mesh {
                                                              url "meshes/wrist_connector.obj"
                                                            }
                                                          }
                                                        ]
                                                      }
                                                    ]
                                                    name "wrist_left_ft_tool_link"
                                                    boundingObject Pose {
                                                      rotation 0 1 0 -1.5708
                                                      children [
                                                        Cylinder {
                                                          height 0.011
                                                          radius 0.0253
                                                        }
                                                      ]
                                                    }
                                                    physics Physics {
                                                      density -1
                                                      mass 0.1
                                                    }
                                                  }
                                                ]
                                                name "arm_left_7_link"
                                                boundingObject Pose {
                                                  children [
                                                    Cylinder {
                                                      height 0.0157
                                                      radius 0.0225
                                                    }
                                                  ]
                                                }
                                                physics Physics {
                                                  density -1
                                                  mass 0.234
                                                }
                                                translationStep 0.001
                                              }
                                            }
                                          ]
                                          name "arm_left_6_link"
                                          boundingObject Pose {
                                            translation 0.0409 0 0
                                            rotation 0 1 0 -1.5708
                                            children [
                                              Cylinder {
                                                height 0.013
                                                radius 0.0226
                                              }
                                            ]
                                          }
                                          physics Physics {
                                            density -1
                                            mass 0.370063
                                          }
                                        }
                                      }
                                    ]
                                    name "arm_left_5_link"
                                    boundingObject Group {
                                      children [
                                        Pose {
                                          translation 0 0 0.04
                                          children [
                                            Cylinder {
                                              height 0.062
                                              radius 0.063
                                            }
                                          ]
                                        }
                                        Pose {
                                          translation 0 0 0.099
                                          children [
                                            Cylinder {
                                              height 0.06
                                              radius 0.057
                                            }
                                          ]
                                        }
                                        Pose {
                                          translation 0 0 0.156
                                          children [
                                            Cylinder {
                                              height 0.06
                                              radius 0.053
                                            }
                                          ]
                                        }
                                      ]
                                    }
                                    physics Physics {
                                      density -1
                                      mass 1.655819
                                    }
                                  }
                                }
                              ]
                              name "arm_left_4_link"
                              boundingObject Group {
                                children [
                                  Pose {
                                    translation 0 0.001 -0.002
                                    children [
                                      Cylinder {
                                        height 0.056
                                        radius 0.054
                                      }
                                    ]
                                  }
                                  Pose {
                                    translation -0.093 0.019 0.027
                                    rotation 0 1 0 -1.5708
                                    children [
                                      Cylinder {
                                        height 0.191
                                        radius 0.052
                                      }
                                    ]
                                  }
                                ]
                              }
                              physics Physics {
                                density -1
                                mass 1.432697
                              }
                            }
                          }
                        ]
                        name "arm_left_3_link"
                        boundingObject Group {
                          children [
                            Pose {
                              translation 0 0 -0.106
                              children [
                                Cylinder {
                                  height 0.23
                                  radius 0.053
                                }
                              ]
                            }
                            Pose {
                              translation -0.0169 0.03 -0.221
                              rotation 1 0 0 -1.5708
                              children [
                                Cylinder {
                                  height 0.056
                                  radius 0.056
                                }
                              ]
                            }
                          ]
                        }
                        physics Physics {
                          density -1
                          mass 2.343502
                        }
                        translationStep 0.0001
                      }
                    }
                  ]
                  name "arm_left_2_link"
                  boundingObject Group {
                    children [
                      Pose {
                        translation 0.056 0 -0.002
                        rotation 0 1 0 1.5708
                        children [
                          Cylinder {
                            height 0.048
                            radius 0.052
                          }
                        ]
                      }
                      Pose {
                        translation 0 0 0.028
                        children [
                          Cylinder {
                            height 0.057
                            radius 0.053
                          }
                        ]
                      }
                    ]
                  }
                  physics Physics {
                    density -1
                    mass 1.800397
                  }
                }
              }
            ]
            name "TIAGo_left_arm"
            boundingObject Group {
              children [
                Pose {
                  translation 0 0 0.013
                  children [
                    Cylinder {
                      height 0.052
                      radius 0.0522
                    }
                  ]
                }
                Pose {
                  translation 0.033 0.001 0.012
                  children [
                    Box {
                      size 0.08 0.1044 0.048
                    }
                  ]
                }
                Pose {
                  translation 0.072 0.029 -0.012
                  children [
                    Box {
                      size 0.035 0.09 0.081
                    }
                  ]
                }
                Pose {
                  translation 0.125 0.053 -0.031
                  rotation 1 0 0 -1.5708
                  children [
                    Cylinder {
                      height 0.069
                      radius 0.053
                    }
                  ]
                }
              ]
            }
            physics Physics {
              density -1
              mass 1.563428
            }
          }
        }
      ]
      name "Left shoulder"
      boundingObject Group {
        children [
          DEF SHOULDER_LEFT_SH1 Pose {
            translation 0.026 0.14 -0.232
            rotation 0 0 1 1.5708
            children [
              Box {
                size 0.042 0.094 0.094
              }
            ]
          }
          DEF SHOULDER_LEFT_SH2 Pose {
            translation 0.0256 0.1868 -0.2661
            rotation 0.129458216086738 -0.129443776708339 0.983099628196004 1.587825628968736
            children [
              Cylinder {
                height 0.016
                radius 0.053
              }
            ]
            translationStep 0.001
          }
          DEF SHOULDER_LEFT_SH3 Pose {
            translation 0.026 0.19 -0.221
            children [
              Cylinder {
                height 0.075
                radius 0.053
              }
            ]
            translationStep 0.001
          }
        ]
      }
      physics Physics {
        density -1
        mass 6.93198
      }
    }
  }
}
