#VRML_SIM R2023b utf8

EXTERNPROTO "webots://projects/objects/backgrounds/protos/TexturedBackground.proto"
EXTERNPROTO "webots://projects/objects/floors/protos/Floor.proto"
EXTERNPROTO "webots://projects/objects/apartment_structure/protos/Wall.proto"
EXTERNPROTO "webots://projects/appearances/protos/Roughcast.proto"
EXTERNPROTO "webots://projects/robots/gctronic/e-puck/protos/E-puck.proto"
EXTERNPROTO "webots://projects/objects/plants/protos/PottedTree.proto"
EXTERNPROTO "webots://projects/objects/paintings/protos/LandscapePainting.proto"
EXTERNPROTO "webots://projects/objects/paintings/protos/PortraitPainting.proto"
EXTERNPROTO "webots://projects/objects/chairs/protos/Chair.proto"
EXTERNPROTO "webots://projects/objects/living_room_furniture/protos/Sofa.proto"
EXTERNPROTO "webots://projects/samples/robotbenchmark/inverted_pendulum/protos/InvertedPendulumBenchmark.proto"

WorldInfo {
  info [
    "Benchmark objective:"
    "keep the pendulum in equilibrium as long as possible."
    "Perturbations with increasing strength are applied to the pendulum."
    "measure the simulation time "
  ]
  title "Inverted Pendulum"
  window "inverted_pendulum"
  physics "inverted_pendulum_perturbation"
  basicTimeStep 4
  lineScale 0.01
}
Viewpoint {
  orientation 0.14531676566957988 0.00568264232883965 -0.9893688620486774 3.1670920620286416
  position 2.246643201853611 0.17220873656899566 0.4957618929695692
  follow "e-puck"
}
TexturedBackground {
  texture "entrance_hall"
  luminosity 0.6
}
SpotLight {
  attenuation 0 0 1
  beamWidth 0.33
  cutOffAngle 0.56
  intensity 16
  location -0.3 0 6.5
  radius 8
  castShadows TRUE
}
SpotLight {
  attenuation 0 0 1
  beamWidth 0.58
  cutOffAngle 0.757
  intensity 16
  location -0.3 -11 8
  radius 20
  castShadows TRUE
}
SpotLight {
  attenuation 0 0 1
  beamWidth 0.5
  cutOffAngle 0.72
  intensity 16
  location -0.3 8 6
  radius 8
  castShadows TRUE
}
Floor {
  size 5 40
  appearance PBRAppearance {
    baseColorMap ImageTexture {
      url [
        "webots://projects/default/worlds/textures/interlaced_parquetry.jpg"
      ]
    }
    roughness 1
    metalness 0
  }
}
Wall {
  translation -2.52 0 0
  size 0.2 40 2.4
  appearance Roughcast {
    textureTransform TextureTransform {
      scale 20 1.2
    }
  }
}
E-puck {
  translation 0.98 0 0
  rotation 0 0 1 1.5707963000000003
  controller "inverted_pendulum"
  window ""
  turretSlot [
    Pose {
      translation 0.01 0 0
      rotation -1 0 0 1.5707997
      children [
        Shape {
          appearance PBRAppearance {
            baseColor 0.8 0.8 0.8
            metalness 0.2
            textureTransform TextureTransform {
              rotation 1.5708
            }
          }
          geometry DEF JOINT_GEOM Cylinder {
            height 0.01
            radius 0.004
          }
        }
      ]
    }
    HingeJoint {
      jointParameters DEF PENDULUM_PARAMETERS HingeJointParameters {
        position -0.05
        axis 0 -1 0
        anchor 0.01 0 0
        minStop -1.6
        maxStop 1.6
      }
      device [
        PositionSensor {
          name "pendulum sensor"
          resolution 1e-05
        }
      ]
      endPoint DEF PENDULUM Solid {
        translation 0.013998333000000002 8.673617379884035e-19 0.07990002100000006
        rotation 0 0.9999999999999999 0 1.6207999999999998
        children [
          DEF POLE Pose {
            translation 0.04 0 0
            rotation 0 -1 0 1.5707997
            children [
              Shape {
                appearance PBRAppearance {
                  baseColor 0.8 0.8 0.8
                  baseColorMap ImageTexture {
                    url [
                      "webots://projects/default/worlds/textures/wood.jpg"
                    ]
                  }
                  roughness 1
                  metalness 0
                  textureTransform TextureTransform {
                  }
                }
                geometry Cylinder {
                  height 0.075
                  radius 0.0015
                }
              }
            ]
          }
          DEF BALL Pose {
            rotation 0 -1 0 4.712389
            children [
              Shape {
                appearance PBRAppearance {
                  baseColor 0.8 0.8 0.8
                  baseColorMap ImageTexture {
                    url [
                      "webots://projects/samples/robotbenchmark/inverted_pendulum/worlds/textures/red_rubber.jpg"
                    ]
                  }
                  roughness 1
                  metalness 0
                  textureTransform TextureTransform {
                  }
                }
                geometry Sphere {
                  radius 0.0075
                  subdivision 3
                }
              }
            ]
          }
        ]
        boundingObject USE BALL
        physics Physics {
          density -1
          mass 0.05
        }
      }
    }
  ]
}
PottedTree {
  translation -1.5713239 -2.3590843 2.3314684e-15
  rotation 0 0 -1 3.1415927
}
PottedTree {
  translation -1.7283871 8.1991063 2.3314684e-15
  rotation 0 0 -1 4.712389
  name "potted tree(1)"
}
PottedTree {
  translation -1.6952438 -6.9386009 2.3314684e-15
  rotation 0 0 -1 4.712389
  name "potted tree(2)"
}
LandscapePainting {
  translation -2.4 -4.93 1.41
}
DEF PAINTING PortraitPainting {
  translation -2.4 4.09 1.515
}
Chair {
  translation -1.6094394 6.7892764 0
  rotation 0 0 1 4.692820414042842e-06
}
Chair {
  translation -1.6194171 5.8129552 0
  rotation 0 0 1 4.692820414042842e-06
  name "chair(1)"
}
Sofa {
  translation -1.5328805 -0.46911152 -4.5519144e-14
  rotation 0 0 1 4.692820414042842e-06
}
InvertedPendulumBenchmark {
}
