#VRML_SIM R2023a utf8
# license: Copyright Cyberbotics Ltd. Licensed for use only with Webots.
# license url: https://cyberbotics.com/webots_assets_license
# documentation url: https://cyberbotics.com/doc/guide/mavic-2-pro
# A quadcopter drone mounted with a motorized camera by the DJI company.

EXTERNPROTO "webots://projects/appearances/protos/GlossyPaint.proto"
EXTERNPROTO "webots://projects/appearances/protos/MattePaint.proto"

PROTO Mavic2Pro [
  field SFVec3f    translation         0 0 0                               # Is `Transform.translation`.
  field SFRotation rotation            0 0 1 0                             # Is `Transform.rotation`.
  field SFString   name                "Mavic 2 PRO"                       # Is `Solid.name`.
  field SFString   controller          "mavic2pro"                         # Is `Robot.controller`.
  field MFString   controllerArgs      []                                  # Is `Robot.controllerArgs`.
  field SFString   window              "<generic>"                         # Is `Robot.window`.
  field SFString   customData          ""                                  # Is `Robot.customData`.
  field SFBool     supervisor          FALSE                               # Is `Robot.supervisor`.
  field SFBool     synchronization     TRUE                                # Is `Robot.synchronization`.
  field MFFloat    battery             []                                  # Is `Robot.battery`.
  field MFNode     bodySlot            []                                  # Extends the robot with new nodes in the turret slot.
  field MFNode     cameraSlot          [ Camera { width 400 height 240 } ] # Extends the robot with a Camera.
]
{
Robot {
  translation IS translation
  rotation IS rotation
  children [
    DEF BODY_SLOT Group {
      children IS bodySlot
    }
    Shape {
      appearance DEF GREY_PLASTIC PBRAppearance {
        baseColor 0.5 0.5 0.5
        metalness 0
        roughness 0.8
      }
      geometry Mesh {
        url "Mavic2Pro/meshes/body.obj"
      }
    }
    Shape {
      appearance DEF METAL_APPEARANCE PBRAppearance {
        roughness 0.5
      }
      geometry Mesh {
        url "Mavic2Pro/meshes/body_metal_parts.obj"
      }
    }
    Shape {
      appearance DEF GLASS PBRAppearance {
        baseColor 0.523146 0.8 0.627785
        transparency 0.9
        roughness 0.5
        metalness 0
      }
      geometry Mesh {
        url "Mavic2Pro/meshes/body_lenses.obj"
      }
    }
    DEF COMPASS Compass {
    }
    DEF GPS GPS {
    }
    DEF GYRO Gyro {
    }
    DEF INERTIAL_UNIT InertialUnit {
    }
    DEF REAR_LEFT_HP_HELIX Propeller {
      shaftAxis 0 0 1
      centerOfThrust -0.177179 0.127453 -0.0320282
      thrustConstants -0.00026 0
      torqueConstants 0.0000052 0
      fastHelixThreshold 50
      device RotationalMotor {
        name "rear left propeller"
        maxVelocity 576
        maxTorque 30.0
      }
      fastHelix Solid {
        translation -0.177179 0.127453 -0.0320282
        children [
          Shape {
            appearance USE METAL_APPEARANCE
            geometry Mesh {
              url "Mavic2Pro/meshes/helix_a_joint.obj"
            }
          }
          Shape {
            appearance GlossyPaint {
              baseColor 0.1 0.1 0.1
            }
            geometry Mesh {
              url "Mavic2Pro/meshes/helix_a_plates.obj"
            }
          }
          Transform {
            translation 0 0 0.02
            children [
              Shape {
                appearance PBRAppearance {
                  baseColor 0.5 0.5 0.5
                  baseColorMap ImageTexture {
                    url "Mavic2Pro/textures/mavic_fast_helix.png"
                  }
                  metalness 0
                  roughness 0
                }
                geometry Cylinder {
                  radius 0.12
                  height 0.001
                  side FALSE
                }
              }
            ]
          }
        ]
        boundingObject Group {
          children [
            Transform {
              translation 0 0 0.015
              children [
                Cylinder {
                  height 0.025
                  radius 0.12
                }
              ]
            }
          ]
        }
        physics Physics {
          density -1
          mass 0.1
        }
      }
      slowHelix Solid {
        translation -0.177179 0.127453 -0.0320282
        children [
          Shape {
            appearance USE GREY_PLASTIC
            geometry Mesh {
              url "Mavic2Pro/meshes/helix_a.obj"
            }
          }
          Shape {
            appearance USE METAL_APPEARANCE
            geometry Mesh {
              url "Mavic2Pro/meshes/helix_a_joint.obj"
            }
          }
          Shape {
            appearance GlossyPaint {
              baseColor 0.1 0.1 0.1
            }
            geometry Mesh {
              url "Mavic2Pro/meshes/helix_a_plates.obj"
            }
          }
        ]
        name "rear left propeller"
        boundingObject Group {
          children [
            Transform {
              translation 0 0 0.015
              children [
                Cylinder {
                  height 0.025
                  radius 0.013
                }
              ]
            }
            Transform {
              translation 0 0 0.023
              rotation 0 0 1 0.7854
              children [
                Box {
                  size 0.23 0.018 0.005
                }
              ]
            }
          ]
        }
        physics Physics {
          density -1
          mass 0.1
        }
      }
    }
    DEF REAR_RIGHT_HP_HELIX Propeller {
      shaftAxis 0 0 1
      centerOfThrust -0.177179 -0.127453 -0.0320282
      thrustConstants 0.00026 0
      torqueConstants 0.0000052 0
      fastHelixThreshold 50
      device RotationalMotor {
        name "rear right propeller"
        maxVelocity 576
        maxTorque 30.0
      }
      fastHelix Solid {
        translation -0.177179 -0.127453 -0.0320282
        children [
          Shape {
            appearance USE METAL_APPEARANCE
            geometry Mesh {
              url "Mavic2Pro/meshes/helix_b_joint.obj"
            }
          }
          Shape {
            appearance GlossyPaint {
              baseColor 0.1 0.1 0.1
            }
            geometry Mesh {
              url "Mavic2Pro/meshes/helix_b_plates.obj"
            }
          }
          Transform {
            translation 0 0 0.02
            children [
              Shape {
                appearance PBRAppearance {
                  baseColor 0.5 0.5 0.5
                  baseColorMap ImageTexture {
                    url "Mavic2Pro/textures/mavic_fast_helix.png"
                  }
                  metalness 0
                  roughness 0
                }
                geometry Cylinder {
                  radius 0.12
                  height 0.001
                  side FALSE
                }
              }
            ]
          }
        ]
        boundingObject Group {
          children [
            Transform {
              translation 0 0 0.015
              children [
                Cylinder {
                  height 0.025
                  radius 0.12
                }
              ]
            }
          ]
        }
        physics Physics {
          density -1
          mass 0.1
        }
      }
      slowHelix Solid {
        translation -0.177179 -0.127453 -0.0320282
        children [
          Shape {
            appearance MattePaint {
              baseColor 0.5 0.5 0.5
            }
            geometry Mesh {
              url "Mavic2Pro/meshes/helix_b.obj"
            }
          }
          Shape {
            appearance USE METAL_APPEARANCE
            geometry Mesh {
              url "Mavic2Pro/meshes/helix_b_joint.obj"
            }
          }
          Shape {
            appearance GlossyPaint {
              baseColor 0.1 0.1 0.1
            }
            geometry Mesh {
              url "Mavic2Pro/meshes/helix_b_plates.obj"
            }
          }
        ]
        name "rear right propeller"
        boundingObject Group {
          children [
            Transform {
              translation 0 0 0.015
              children [
                Cylinder {
                  height 0.025
                  radius 0.013
                }
              ]
            }
            Transform {
              translation 0 0 0.023
              rotation 0 0 1 -0.7854
              children [
                Box {
                  size 0.23 0.018 0.005
                }
              ]
            }
          ]
        }
        physics Physics {
          density -1
          mass 0.1
        }
      }
    }
    DEF FRONT_RIGHT_HP_HELIX Propeller {
      shaftAxis 0 0 1
      centerOfThrust 0.0548537 -0.151294 -0.00280468
      thrustConstants -0.00026 0
      torqueConstants 0.0000052 0
      fastHelixThreshold 50
      device RotationalMotor {
        name "front right propeller"
        maxVelocity 576
        maxTorque 30.0
      }
      fastHelix Solid {
        translation 0.0548537 -0.151294 -0.00280468
        children [
          Shape {
            appearance USE METAL_APPEARANCE
            geometry Mesh {
              url "Mavic2Pro/meshes/helix_a_joint.obj"
            }
          }
          Shape {
            appearance GlossyPaint {
              baseColor 0.1 0.1 0.1
            }
            geometry Mesh {
              url "Mavic2Pro/meshes/helix_a_plates.obj"
            }
          }
          Transform {
            translation 0 0 0.02
            children [
              Shape {
                appearance PBRAppearance {
                  baseColor 0.5 0.5 0.5
                  baseColorMap ImageTexture {
                    url "Mavic2Pro/textures/mavic_fast_helix.png"
                  }
                  metalness 0
                  roughness 0
                }
                geometry Cylinder {
                  radius 0.12
                  height 0.001
                  side FALSE
                }
              }
            ]
          }
        ]
        boundingObject Group {
          children [
            Transform {
              translation 0 0 0.015
              children [
                Cylinder {
                  height 0.025
                  radius 0.12
                }
              ]
            }
          ]
        }
        physics Physics {
          density -1
          mass 0.1
        }
      }
      slowHelix Solid {
        translation 0.0548537 -0.151294 -0.00280468
        children [
          Shape {
            appearance MattePaint {
              baseColor 0.5 0.5 0.5
            }
            geometry Mesh {
              url "Mavic2Pro/meshes/helix_a.obj"
            }
          }
          Shape {
            appearance USE METAL_APPEARANCE
            geometry Mesh {
              url "Mavic2Pro/meshes/helix_a_joint.obj"
            }
          }
          Shape {
            appearance GlossyPaint {
              baseColor 0.1 0.1 0.1
            }
            geometry Mesh {
              url "Mavic2Pro/meshes/helix_a_plates.obj"
            }
          }
        ]
        name "front right propeller"
        boundingObject Group {
          children [
            Transform {
              translation 0 0 0.015
              children [
                Cylinder {
                  height 0.025
                  radius 0.013
                }
              ]
            }
            Transform {
              translation 0 0 0.023
              rotation 0 0 1 0.7854
              children [
                Box {
                  size 0.23 0.018 0.005
                }
              ]
            }
          ]
        }
        physics Physics {
          density -1
          mass 0.1
        }
      }
    }
    DEF CAMERA_YAW HingeJoint {
      jointParameters HingeJointParameters {
        axis 0 0 1
        anchor 0.0412774 -0.00469654 -0.00405862
      }
      device [
        RotationalMotor {
          name "camera yaw"
          minPosition -1.7
          maxPosition 1.7
        }
        PositionSensor {
          name "camera yaw sensor"
        }
      ]
      endPoint Solid {
        translation 0.0412774 -0.00469654 -0.00405862
        rotation 0 0 1 0
        children [
          Shape {
            appearance USE METAL_APPEARANCE
            geometry Mesh {
              url "Mavic2Pro/meshes/camera_yaw.obj"
            }
          }
          DEF CAMERA_PITCH HingeJoint {
            jointParameters HingeJointParameters {
              axis 0 1 0
              anchor 0.000625212 -0.00530346 -0.0207448
            }
            device [
              RotationalMotor {
                name "camera pitch"
                minPosition -0.5
                maxPosition 1.7
              }
              PositionSensor {
                name "camera pitch sensor"
              }
            ]
            endPoint Solid {
              translation 0.000625212 -0.00530346 -0.0207448
              children [
                Shape {
                  appearance USE METAL_APPEARANCE
                  geometry Mesh {
                    url "Mavic2Pro/meshes/camera_pitch.obj"
                  }
                }
                DEF CAMERA_ROLL HingeJoint {
                  jointParameters HingeJointParameters {
                    anchor 0.00754686 0.0160388 -0.00586401
                  }
                  device [
                    RotationalMotor {
                      name "camera roll"
                      minPosition -0.5
                      maxPosition 0.5
                    }
                    PositionSensor {
                      name "camera roll sensor"
                    }
                  ]
                  endPoint Solid {
                    translation 0.00754686 0.0160388 -0.00586401
                    rotation 1 0 0 0
                    children [
                      Shape {
                        appearance USE METAL_APPEARANCE
                        geometry Mesh {
                          url "Mavic2Pro/meshes/camera_chassis.obj"
                        }
                      }
                      Shape {
                        appearance USE GLASS
                        geometry Mesh {
                          url "Mavic2Pro/meshes/camera_lens.obj"
                        }
                      }
                      DEF CAMERA_SLOT Transform {
                        children IS cameraSlot
                      }
                    ]
                    name "camera roll"
                    boundingObject Transform {
                      translation -0.00915058 -1.86265e-08 -0.000983764
                      children [
                        Box {
                          size 0.0236511 0.0205141 0.0225186
                        }
                      ]
                    }
                    physics Physics {
                      density -1
                      mass 0.0333
                    }
                  }
                }
              ]
              name "camera pitch"
              boundingObject Transform {
                translation -0.00248347 0.00776876 0.00183829
                children [
                  Box {
                    size 0.0239878 0.0349393 0.0314891
                  }
                ]
              }
              physics Physics {
                density -1
                mass 0.0333
              }
            }
          }
        ]
        name "camera yaw"
        boundingObject Transform {
          translation -1.86265e-09 -0.00304481 -0.0140589
          children [
            Box {
              size 0.0208626 0.0260333 0.0307844
            }
          ]
        }
        physics Physics {
          density -1
          mass 0.0333
        }
      }
    }
    DEF LED_RIGHT LED {
      children [
        Transform {
          translation 0.0617 -0.1654 -0.0074
          children [
            Shape {
              appearance PBRAppearance {
                roughness 0.2
                metalness 0.5
                emissiveIntensity 50
              }
              geometry Mesh {
                url "Mavic2Pro/meshes/front_led.obj"
              }
            }
          ]
        }
      ]
      name "front right led"
      boundingObject Transform {
        translation 0.060348 -0.163659 -0.00760072
        children [
          Box {
            size 0.0152149 0.0106945 0.00694674
          }
        ]
      }
      physics Physics {
        density -1
        mass 0.0035
      }
    }
    DEF LED_LEFT LED {
      children [
        Transform {
          translation 0.0617 0.1654 -0.0074
          rotation 0 0 1 2.1944
          children [
            Shape {
              appearance PBRAppearance {
                roughness 0.2
                metalness 0.5
                emissiveIntensity 50
              }
              geometry Mesh {
                url "Mavic2Pro/meshes/front_led.obj"
              }
            }
          ]
        }
      ]
      name "front left led"
      boundingObject Transform {
        translation 0.060348 0.163919 -0.00760069
        children [
          Box {
            size 0.0152149 0.0106945 0.0069468
          }
        ]
      }
      physics Physics {
        density -1
        mass 0.0035
      }
    }
    DEF FRONT_LEFT_HP_HELIX Propeller {
      shaftAxis 0 0 1
      centerOfThrust 0.0548537 0.151294 -0.00280468
      thrustConstants 0.00026 0
      torqueConstants 0.0000052 0
      fastHelixThreshold 50
      device RotationalMotor {
        name "front left propeller"
        maxVelocity 576
        maxTorque 30.0
      }
      fastHelix Solid {
        translation 0.0548537 0.151294 -0.00280468
        children [
          Shape {
            appearance USE METAL_APPEARANCE
            geometry Mesh {
              url "Mavic2Pro/meshes/helix_b_joint.obj"
            }
          }
          Shape {
            appearance GlossyPaint {
              baseColor 0.1 0.1 0.1
            }
            geometry Mesh {
              url "Mavic2Pro/meshes/helix_b_plates.obj"
            }
          }
          Transform {
            translation 0 0 0.02
            children [
              Shape {
                appearance PBRAppearance {
                  baseColor 0.5 0.5 0.5
                  baseColorMap ImageTexture {
                    url "Mavic2Pro/textures/mavic_fast_helix.png"
                  }
                  metalness 0
                  roughness 0
                }
                geometry Cylinder {
                  radius 0.12
                  height 0.001
                  side FALSE
                }
              }
            ]
          }
        ]
        boundingObject Group {
          children [
            Transform {
              translation 0 0 0.015
              children [
                Cylinder {
                  height 0.025
                  radius 0.12
                }
              ]
            }
          ]
        }
        physics Physics {
          density -1
          mass 0.1
        }
      }
      slowHelix Solid {
        translation 0.0548537 0.151294 -0.00280468
        children [
          Shape {
            appearance MattePaint {
              baseColor 0.5 0.5 0.5
            }
            geometry Mesh {
              url "Mavic2Pro/meshes/helix_b.obj"
            }
          }
          Shape {
            appearance USE METAL_APPEARANCE
            geometry Mesh {
              url "Mavic2Pro/meshes/helix_b_joint.obj"
            }
          }
          Shape {
            appearance GlossyPaint {
              baseColor 0.1 0.1 0.1
            }
            geometry Mesh {
              url "Mavic2Pro/meshes/helix_b_plates.obj"
            }
          }
        ]
        name "front left propeller"
        boundingObject Group {
          children [
            Transform {
              translation 0 0 0.015
              children [
                Cylinder {
                  height 0.025
                  radius 0.013
                }
              ]
            }
            Transform {
              translation 0 0 0.023
              rotation 0 0 1 -0.7854
              children [
                Box {
                  size 0.23 0.018 0.005
                }
              ]
            }
          ]
        }
        physics Physics {
          density -1
          mass 0.1
        }
      }
    }
  ]
  name IS name
  model "DJI Mavic 2 PRO"
  boundingObject Group {
    children [
      Transform {
        translation -0.03 0 0.002
        children [
          Box {
            size 0.21 0.085 0.027
          }
        ]
      }
      Transform {
        translation -0.06 0 -0.03
        children [
          Box {
            size 0.15 0.06 0.053
          }
        ]
      }
      Transform {
        translation 0.03 0.09 -0.001
        rotation 0 0 1 -0.3926996938995747
        children [
          Box {
            size 0.01 0.15 0.025
          }
        ]
      }
      Transform {
        translation 0.03 -0.09 -0.001
        rotation 0 0 1 0.3927
        children [
          Box {
            size 0.01 0.15 0.025
          }
        ]
      }
      Transform {
        translation -0.138 0.08 -0.032
        rotation 0 0 1 0.68
        children [
          Box {
            size 0.01 0.12 0.018
          }
        ]
      }
      Transform {
        translation -0.138 -0.08 -0.032
        rotation 0 0 1 -0.68
        children [
          Box {
            size 0.01 0.12 0.018
          }
        ]
      }
      Transform {
        translation 0.06 0.15 -0.039
        rotation 1 0 0 -0.29
        children [
          Box {
            size 0.01 0.014 0.06
          }
        ]
      }
      Transform {
        translation 0.06 -0.15 -0.039
        rotation 1 0 0 0.29
        children [
          Box {
            size 0.01 0.014 0.06
          }
        ]
      }
    ]
  }
  physics Physics {
    density -1
    mass 0.4
    centerOfMass [
      -0.088 0 -0.04
    ]
  }
  controller IS controller
  controllerArgs IS controllerArgs
  window IS window
  customData IS customData
  supervisor IS supervisor
  synchronization IS synchronization
  battery IS battery
}
}
