#VRML_SIM R2023b utf8

EXTERNPROTO "webots://projects/objects/backgrounds/protos/TexturedBackground.proto"
EXTERNPROTO "webots://projects/objects/floors/protos/Floor.proto"

WorldInfo {
  info [
    "An example of hot to solve the Inverted Pendulum problem using a PID controller"
  ]
  title "Inverted Pendulum"
  contactProperties [
    ContactProperties {
      material1 "robot_basis"
      material2 "floor"
      coulombFriction [
        0.2
      ]
    }
  ]
}
Viewpoint {
  orientation -0.0996069518072968 -0.03685053329082472 0.9943442529364971 3.666446119327704
  position 10.735611636783911 9.264148536386676 3.6992721334967498
  follow "robot:solid"
}
TexturedBackground {
}
Floor {
  size 1000 2
  appearance PBRAppearance {
    baseColorMap ImageTexture {
      url [
        "webots://projects/default/worlds/textures/checkered_marble.jpg"
      ]
    }
    roughness 1
    metalness 0
  }
}
Robot {
  rotation 0 0 1 3.14159
  children [
    SliderJoint {
      jointParameters JointParameters {
        axis 1 0 0
        dampingConstant 1.5
      }
      device [
        LinearMotor {
          name "horizontal_motor"
          maxForce 40
        }
        PositionSensor {
          name "horizontal position sensor"
        }
      ]
      endPoint Solid {
        translation 0 0 0.06
        children [
          DEF ROBOT_SHAPE Shape {
            appearance PBRAppearance {
              baseColor 0.2443427176317998 0.704051270313573 0.1756923781185626
              roughness 1
              metalness 0
            }
            geometry Box {
              size 0.3 0.1 0.1
            }
          }
          DEF HIP HingeJoint {
            jointParameters HingeJointParameters {
              position 0.000161402
              axis 0 1 0
              anchor 0 0 0.03
            }
            device [
              PositionSensor {
                name "hip"
              }
            ]
            endPoint DEF THIGH_BB Solid {
              translation 0 -0.061 0.33000000000000007
              rotation 0 1 0 0
              children [
                Shape {
                  appearance PBRAppearance {
                    baseColor 0.8496833752956435 0.07072556649118791 0.09393453879606317
                    roughness 1
                    metalness 0
                  }
                  geometry DEF THIGH_BOX Box {
                    size 0.05 0.02 0.6
                  }
                }
              ]
              boundingObject USE THIGH_BOX
              physics Physics {
                density -1
                mass 0.05
                centerOfMass [
                  0 0.061 -0.27
                ]
              }
            }
          }
          PointLight {
            attenuation 0 0 1
            intensity 5
            location 0 0 2
          }
        ]
        contactMaterial "robot_basis"
        boundingObject USE ROBOT_SHAPE
        physics Physics {
          density -1
          mass 1
        }
      }
    }
  ]
  boundingObject Box {
    size 200 0.1 0.01
  }
  physics Physics {
    density -1
    mass 30
  }
  controller "inverted_pendulum"
}
