#VRML_SIM R2023b utf8
# license: Copyright Cyberbotics Ltd. Licensed for use only with Webots.
# license url: https://cyberbotics.com/webots_assets_license
# documentation url: https://webots.cloud/run?url=https://github.com/cyberbotics/webots/blob/released/projects/vehicles/protos/generic/TruckTank.proto
# keywords: vehicle/truck
# A non-controllable truck tank model with physics properties.

EXTERNPROTO "TruckRearLight.proto"
EXTERNPROTO "TruckTankMesh.proto"
EXTERNPROTO "TruckWheel.proto"

PROTO TruckTank [
  field SFString name    "truck tank"    # Identifies the truck tank.
  field SFColor  color   0.66 0.66 0.66  # Defines the color of the truck tank.
]
{
  Slot {
    type "truck trailer"
    endPoint Solid {
      children [
        DEF REAR_LIGHTS LED {
          children [
            TruckRearLight {
            }
          ]
          name "rear_lights"
          color 0.7 0.12 0.12
        }
        TruckTankMesh {
          color IS color
        }
        DEF FRONT_RIGHT_WHEEL Pose {
          translation -5.45 -1 0
          children [
            HingeJoint {
              jointParameters HingeJointParameters {
                axis 0 -1 0
                suspensionAxis 0 1 0
                suspensionSpringConstant 1e+06
                suspensionDampingConstant 10000
              }
              endPoint Slot {
                type "vehicle wheel"
                endPoint TruckWheel {
                  name "front right wheel"
                  physics Physics {
                    density -1
                    mass 100
                  }
                }
              }
            }
          ]
        }
        DEF FRONT_LEFT_WHEEL Pose {
          translation -5.45 1 0
          rotation 0 0 1 3.14156
          children [
            HingeJoint {
              jointParameters HingeJointParameters {
                axis 0 1 0
                suspensionAxis 0 1 0
                suspensionSpringConstant 1e+06
                suspensionDampingConstant 10000
              }
              endPoint Slot {
                type "vehicle wheel"
                endPoint TruckWheel {
                  name "front left wheel"
                  wheelSide TRUE
                  physics Physics {
                    density -1
                    mass 100
                  }
                }
              }
            }
          ]
        }
        DEF CENTER_RIGHT_WHEEL Pose {
          translation -6.55 -1 0
          children [
            HingeJoint {
              jointParameters HingeJointParameters {
                axis 0 -1 0
                suspensionAxis 0 1 0
                suspensionSpringConstant 1e+06
                suspensionDampingConstant 10000
              }
              endPoint Slot {
                type "vehicle wheel"
                endPoint TruckWheel {
                  name "central right wheel"
                  physics Physics {
                    density -1
                    mass 100
                  }
                }
              }
            }
          ]
        }
        DEF CENTER_LEFT_WHEEL Pose {
          translation -6.55 1 0
          rotation 0 0 1 3.14156
          children [
            HingeJoint {
              jointParameters HingeJointParameters {
                axis 0 1 0
                suspensionAxis 0 1 0
                suspensionSpringConstant 1e+06
                suspensionDampingConstant 10000
              }
              endPoint Slot {
                type "vehicle wheel"
                endPoint TruckWheel {
                  name "central left wheel"
                  wheelSide TRUE
                  physics Physics {
                    density -1
                    mass 100
                  }
                }
              }
            }
          ]
        }
        DEF REAR_RIGHT_WHEEL Pose {
          translation -7.65 -1 0
          children [
            HingeJoint {
              jointParameters HingeJointParameters {
                axis 0 -1 0
                suspensionAxis 0 1 0
                suspensionSpringConstant 1e+06
                suspensionDampingConstant 10000
              }
              endPoint Slot {
                type "vehicle wheel"
                endPoint TruckWheel {
                  name "rear right wheel"
                  physics Physics {
                    density -1
                    mass 100
                  }
                }
              }
            }
          ]
        }
        DEF REAR_LEFT_WHEEL Pose {
          translation -7.65 1 0
          rotation 0 0 1 3.14156
          children [
            HingeJoint {
              jointParameters HingeJointParameters {
                axis 0 1 0
                suspensionAxis 0 1 0
                suspensionSpringConstant 1e+06
                suspensionDampingConstant 10000
              }
              endPoint Slot {
                type "vehicle wheel"
                endPoint TruckWheel {
                  name "rear left wheel"
                  wheelSide TRUE
                  physics Physics {
                    density -1
                    mass 100
                  }
                }
              }
            }
          ]
        }
      ]
      name IS name
      model "truck tank"
      boundingObject Group {
        children [
          Pose {
            translation -3.1 0 2.21
            children [
              Box {
                size 11.15 2.5 3.05
              }
            ]
          }
          Pose {
            translation -6.33 0 0.27
            children [
              Box {
                size 4.5 2.5 0.87
              }
            ]
          }
        ]
      }
      physics Physics {
        density -1
        mass 5000
        centerOfMass [
          -3.5 0 0.1
        ]
      }
    }
  }
}
