#VRML_SIM R2023b utf8
# license: Apache License 2.0
# license url: https://www.apache.org/licenses/LICENSE-2.0
# documentation url: https://webots.cloud/run?url=https://github.com/cyberbotics/webots/blob/released/projects/robots/universal_robots/protos/UR3e.proto
# keywords: robot/arm
# An Universal Robots UR3e robotic arm.
# template language: javascript

EXTERNPROTO "webots://projects/appearances/protos/OldSteel.proto"
EXTERNPROTO "webots://projects/appearances/protos/ScrewThread.proto"

PROTO UR3e [
  field SFVec3f    translation     0 0 0        # Is `Pose.translation`.
  field SFRotation rotation        0 0 1 0      # Is `Pose.rotation`.
  field SFString   name            "UR3e"       # Is `Solid.name`.
  field SFString   controller      "<generic>"  # Is `Robot.controller`.
  field MFString   controllerArgs  []           # Is `Robot.controllerArgs`.
  field SFString   window          "<generic>"  # Is `Robot.window`.
  field SFBool     supervisor      FALSE        # Is `Robot.supervisor`.
  field SFBool     synchronization TRUE         # Is `Robot.synchronization`.
  field SFBool     selfCollision   TRUE         # Is `Robot.selfCollision`.
  field MFNode     toolSlot        []           # Extend the robot with new nodes at the end of the arm.
  field SFBool     staticBase      TRUE         # Defines if the robot base should be pinned to the static environment.
]
{
  Robot {
    translation IS translation
    rotation IS rotation
    children [
      Pose {
        translation -0.0392 0.0392 0.0244
        rotation 1 0 0 -3.1415923071795864
        children [
          DEF SCREW Group {
            children [
              Transform {
                scale 1.1 1.1 1.1
                children [
                  Shape {
                    appearance OldSteel {
                    }
                    geometry Mesh {
                      url "UR3e/meshes/screw.obj"
                    }
                  }
                ]
              }
              DEF CYLINDER Pose {
                translation 0 0 0.02
                rotation -0.707107 0.707107 0 -3.141593
                children [
                  Shape {
                    appearance ScrewThread {
                      textureTransform TextureTransform {
                        rotation 1.5708
                        scale 1.6 2
                      }
                    }
                    geometry Cylinder {
                      height 0.04
                      radius 0.0044
                    }
                  }
                ]
              }
            ]
          }
        ]
      }
      Pose {
        translation -0.0392 -0.0392 0.0244
        rotation 1 0 0 -3.1415923071795864
        children [
          USE SCREW
        ]
      }
      Pose {
        translation 0.0392 -0.0392 0.0244
        rotation 1 0 0 -3.1415923071795864
        children [
          USE SCREW
        ]
      }
      Pose {
        translation 0.0392 0.0392 0.0244
        rotation 1 0 0 -3.1415923071795864
        children [
          USE SCREW
        ]
      }
      Shape {
        appearance DEF METAL_APPEARANCE PBRAppearance {
          baseColor 0.6 0.6 0.6
          roughness 0.7
        }
        geometry Mesh {
          url "UR3e/meshes/base_link_0.obj"
        }
      }
      Shape {
        appearance DEF JOINT_APPEARANCE PBRAppearance {
          baseColor 0 0 0
          roughness 1
          metalness 0
        }
        geometry Mesh {
          url "UR3e/meshes/base_link_1.obj"
        }
      }
      HingeJoint {
        jointParameters HingeJointParameters {
          axis 0 0 1
          anchor 0 0 0.152
        }
        device [
          RotationalMotor {
            name "shoulder_pan_joint"
            maxVelocity 3.14
            minPosition -6.28318530718
            maxPosition 6.28318530718
            maxTorque 330
          }
          PositionSensor {
            name "shoulder_pan_joint_sensor"
          }
        ]
        endPoint Solid {
          translation 0 0 0.152
          children [
            Shape {
              appearance DEF SCREW_APPEARANCE PBRAppearance {
              }
              geometry Mesh {
                url "UR3e/meshes/shoulder_link_0.obj"
              }
            }
            Shape {
              appearance USE METAL_APPEARANCE
              geometry Mesh {
                url "UR3e/meshes/shoulder_link_1.obj"
              }
            }
            Shape {
              appearance USE JOINT_APPEARANCE
              geometry Mesh {
                url "UR3e/meshes/shoulder_link_2.obj"
              }
            }
            Shape {
              appearance PBRAppearance {
                baseColor 0.490196 0.678431 0.8
                roughness 0.96875
                metalness 0
                normalMap ImageTexture {
                  url [
                    "UR3e/textures/normal_0.jpg"
                  ]
                }
                occlusionMap ImageTexture {
                  url [
                    "UR3e/textures/occlusion_0.jpg"
                  ]
                }
              }
              geometry Mesh {
                url "UR3e/meshes/shoulder_link_3.obj"
              }
            }
            HingeJoint {
              jointParameters HingeJointParameters {
                axis 0 1 0
                anchor 0 0.12 0
              }
              device [
                RotationalMotor {
                  name "shoulder_lift_joint"
                  maxVelocity 3.14
                  minPosition -6.28318530718
                  maxPosition 6.28318530718
                  maxTorque 330
                }
                PositionSensor {
                  name "shoulder_lift_joint_sensor"
                }
              ]
              endPoint Solid {
                translation 0 0.12 0
                rotation 0 1 0 1.570796
                children [
                  Shape {
                    appearance USE SCREW_APPEARANCE
                    geometry Mesh {
                      url "UR3e/meshes/upper_arm_link_0.obj"
                    }
                  }
                  Shape {
                    appearance USE SCREW_APPEARANCE
                    geometry Mesh {
                      url "UR3e/meshes/upper_arm_link_1.obj"
                    }
                  }
                  Shape {
                    appearance USE JOINT_APPEARANCE
                    geometry Mesh {
                      url "UR3e/meshes/upper_arm_link_2.obj"
                    }
                  }
                  Shape {
                    appearance USE METAL_APPEARANCE
                    geometry Mesh {
                      url "UR3e/meshes/upper_arm_link_3.obj"
                    }
                  }
                  Shape {
                    appearance PBRAppearance {
                      baseColor 0.490196 0.678431 0.8
                      roughness 0.96875
                      metalness 0
                      normalMap ImageTexture {
                        url [
                          "UR3e/textures/normal_1.jpg"
                        ]
                      }
                      occlusionMap ImageTexture {
                        url [
                          "UR3e/textures/occlusion_1.jpg"
                        ]
                      }
                    }
                    geometry Mesh {
                      url "UR3e/meshes/upper_arm_link_4.obj"
                    }
                  }
                  Shape {
                    appearance USE METAL_APPEARANCE
                    geometry Mesh {
                      url "UR3e/meshes/upper_arm_link_5.obj"
                    }
                  }
                  Shape {
                    appearance USE JOINT_APPEARANCE
                    geometry Mesh {
                      url "UR3e/meshes/upper_arm_link_6.obj"
                    }
                  }
                  Shape {
                    appearance DEF METAL_APPEARANCE_LIGHT PBRAppearance {
                      roughness 0.7
                    }
                    geometry Mesh {
                      url "UR3e/meshes/upper_arm_link_7.obj"
                    }
                  }
                  Shape {
                    appearance USE JOINT_APPEARANCE
                    geometry Mesh {
                      url "UR3e/meshes/upper_arm_link_8.obj"
                    }
                  }
                  Shape {
                    appearance PBRAppearance {
                      baseColor 0.490196 0.678431 0.8
                      roughness 0.96875
                      metalness 0
                      normalMap ImageTexture {
                        url [
                          "UR3e/textures/normal_2.jpg"
                        ]
                      }
                      occlusionMap ImageTexture {
                        url [
                          "UR3e/textures/occlusion_2.jpg"
                        ]
                      }
                    }
                    geometry Mesh {
                      url "UR3e/meshes/upper_arm_link_9.obj"
                    }
                  }
                  Shape {
                    appearance USE JOINT_APPEARANCE
                    geometry Mesh {
                      url "UR3e/meshes/upper_arm_link_10.obj"
                    }
                  }
                  HingeJoint {
                    jointParameters HingeJointParameters {
                      axis 0 1 0
                      anchor 0 -0.093 0.244
                    }
                    device [
                      RotationalMotor {
                        name "elbow_joint"
                        maxVelocity 3.14
                        minPosition -3.14159265359
                        maxPosition 3.14159265359
                        maxTorque 150
                      }
                      PositionSensor {
                        name "elbow_joint_sensor"
                      }
                    ]
                    endPoint Solid {
                      translation 0 -0.093 0.244
                      children [
                        Shape {
                          appearance USE SCREW_APPEARANCE
                          geometry Mesh {
                            url "UR3e/meshes/forearm_link_0.obj"
                          }
                        }
                        Shape {
                          appearance USE METAL_APPEARANCE
                          geometry Mesh {
                            url "UR3e/meshes/forearm_link_1.obj"
                          }
                        }
                        Shape {
                          appearance USE METAL_APPEARANCE
                          geometry Mesh {
                            url "UR3e/meshes/forearm_link_2.obj"
                          }
                        }
                        Shape {
                          appearance USE JOINT_APPEARANCE
                          geometry Mesh {
                            url "UR3e/meshes/forearm_link_3.obj"
                          }
                        }
                        Shape {
                          appearance USE METAL_APPEARANCE_LIGHT
                          geometry Mesh {
                            url "UR3e/meshes/forearm_link_4.obj"
                          }
                        }
                        Shape {
                          appearance USE JOINT_APPEARANCE
                          geometry Mesh {
                            url "UR3e/meshes/forearm_link_5.obj"
                          }
                        }
                        Shape {
                          appearance PBRAppearance {
                            baseColor 0.490196 0.678431 0.8
                            roughness 0.96875
                            metalness 0
                            normalMap ImageTexture {
                              url [
                                "UR3e/textures/normal_3.jpg"
                              ]
                            }
                            occlusionMap ImageTexture {
                              url [
                                "UR3e/textures/occlusion_3.jpg"
                              ]
                            }
                          }
                          geometry Mesh {
                            url "UR3e/meshes/forearm_link_6.obj"
                          }
                        }
                        Shape {
                          appearance USE JOINT_APPEARANCE
                          geometry Mesh {
                            url "UR3e/meshes/forearm_link_7.obj"
                          }
                        }
                        HingeJoint {
                          jointParameters HingeJointParameters {
                            axis 0 1 0
                            anchor 0 0 0.213
                          }
                          device [
                            RotationalMotor {
                              name "wrist_1_joint"
                              maxVelocity 6.28
                              minPosition -6.28318530718
                              maxPosition 6.28318530718
                              maxTorque 54
                            }
                            PositionSensor {
                              name "wrist_1_joint_sensor"
                            }
                          ]
                          endPoint Solid {
                            translation 0 0 0.213
                            rotation 0 1 0 1.570796
                            children [
                              Shape {
                                appearance USE SCREW_APPEARANCE
                                geometry Mesh {
                                  url "UR3e/meshes/wrist_1_link_0.obj"
                                }
                              }
                              Shape {
                                appearance USE METAL_APPEARANCE
                                geometry Mesh {
                                  url "UR3e/meshes/wrist_1_link_1.obj"
                                }
                              }
                              Shape {
                                appearance USE JOINT_APPEARANCE
                                geometry Mesh {
                                  url "UR3e/meshes/wrist_1_link_2.obj"
                                }
                              }
                              Shape {
                                appearance PBRAppearance {
                                  baseColor 0.490196 0.678431 0.8
                                  roughness 0.96875
                                  metalness 0
                                  normalMap ImageTexture {
                                    url [
                                      "UR3e/textures/normal_4.jpg"
                                    ]
                                  }
                                  occlusionMap ImageTexture {
                                    url [
                                      "UR3e/textures/occlusion_4.jpg"
                                    ]
                                  }
                                }
                                geometry Mesh {
                                  url "UR3e/meshes/wrist_1_link_3.obj"
                                }
                              }
                              HingeJoint {
                                jointParameters HingeJointParameters {
                                  axis 0 0 1
                                  anchor 0 0.104 0
                                }
                                device [
                                  RotationalMotor {
                                    name "wrist_2_joint"
                                    maxVelocity 6.28
                                    minPosition -6.28318530718
                                    maxPosition 6.28318530718
                                    maxTorque 54
                                  }
                                  PositionSensor {
                                    name "wrist_2_joint_sensor"
                                  }
                                ]
                                endPoint Solid {
                                  translation 0 0.104 0
                                  children [
                                    Shape {
                                      appearance USE SCREW_APPEARANCE
                                      geometry Mesh {
                                        url "UR3e/meshes/wrist_2_link_0.obj"
                                      }
                                    }
                                    Shape {
                                      appearance USE METAL_APPEARANCE
                                      geometry Mesh {
                                        url "UR3e/meshes/wrist_2_link_1.obj"
                                      }
                                    }
                                    Shape {
                                      appearance USE JOINT_APPEARANCE
                                      geometry Mesh {
                                        url "UR3e/meshes/wrist_2_link_2.obj"
                                      }
                                    }
                                    Shape {
                                      appearance PBRAppearance {
                                        baseColor 0.490196 0.678431 0.8
                                        roughness 0.96875
                                        metalness 0
                                        normalMap ImageTexture {
                                          url [
                                            "UR3e/textures/normal_5.jpg"
                                          ]
                                        }
                                        occlusionMap ImageTexture {
                                          url [
                                            "UR3e/textures/occlusion_5.jpg"
                                          ]
                                        }
                                      }
                                      geometry Mesh {
                                        url "UR3e/meshes/wrist_2_link_3.obj"
                                      }
                                    }
                                    HingeJoint {
                                      jointParameters HingeJointParameters {
                                        axis 0 1 0
                                        anchor 0 0 0.085
                                      }
                                      device [
                                        RotationalMotor {
                                          name "wrist_3_joint"
                                          maxVelocity 6.28
                                          minPosition -6.28318530718
                                          maxPosition 6.28318530718
                                          maxTorque 54
                                        }
                                        PositionSensor {
                                          name "wrist_3_joint_sensor"
                                        }
                                      ]
                                      endPoint Solid {
                                        translation 0 0 0.085
                                        children [
                                          Shape {
                                            appearance USE METAL_APPEARANCE
                                            geometry Mesh {
                                              url "UR3e/meshes/wrist_3_link_0.obj"
                                            }
                                          }
                                          Pose {
                                            translation 0 0.09 0
                                            children IS toolSlot
                                          }
                                        ]
                                        name "wrist_3_link"
                                        boundingObject Group {
                                          children [
                                            Pose {
                                              translation 0 0.07 0
                                              rotation 1 0 0 -1.570796
                                              children [
                                                Cylinder {
                                                  height 0.044
                                                  radius 0.032
                                                }
                                              ]
                                            }
                                          ]
                                        }
                                        physics Physics {
                                          density -1
                                          mass 0.261
                                          centerOfMass [
                                            0 0 0
                                          ]
                                        }
                                      }
                                    }
                                  ]
                                  name "wrist_2_link"
                                  boundingObject Group {
                                    children [
                                      Pose {
                                        translation 0 0.002 0.0854
                                        rotation 1 0 0 -1.570796
                                        children [
                                          Cylinder {
                                            height 0.097
                                            radius 0.032
                                          }
                                        ]
                                      }
                                      Pose {
                                        translation 0 0 0.0636
                                        rotation 1 0 0 3.141593
                                        children [
                                          Cylinder {
                                            height 0.043
                                            radius 0.032
                                          }
                                        ]
                                      }
                                    ]
                                  }
                                  physics Physics {
                                    density -1
                                    mass 0.805
                                    centerOfMass [
                                      0 0 0
                                    ]
                                  }
                                }
                              }
                            ]
                            name "wrist_1_link"
                            boundingObject Group {
                              children [
                                Pose {
                                  translation 0 0.075 0
                                  rotation 1 0 0 -1.570796
                                  children [
                                    Cylinder {
                                      height 0.064
                                      radius 0.032
                                    }
                                  ]
                                }
                                Pose {
                                  translation 0 0.104 0.003
                                  rotation 1 0 0 -3.141593
                                  children [
                                    Cylinder {
                                      height 0.1
                                      radius 0.033
                                    }
                                  ]
                                }
                              ]
                            }
                            physics Physics {
                              density -1
                              mass 0.871
                              centerOfMass [
                                0 0 0
                              ]
                            }
                          }
                        }
                      ]
                      name "forearm_link"
                      boundingObject Group {
                        children [
                          Pose {
                            translation 0 0 0.125
                            rotation 1 0 0 3.141593
                            children [
                              Cylinder {
                                height 0.18
                                radius 0.032
                              }
                            ]
                          }
                          Pose {
                            translation 0 0.002 0.213
                            rotation 1 0 0 -1.570796
                            children [
                              Cylinder {
                                height 0.1
                                radius 0.032
                              }
                            ]
                          }
                          Pose {
                            translation 0 0.05 0
                            rotation 1 0 0 -1.570796
                            children [
                              Capsule {
                                height 0.05
                                radius 0.037
                              }
                            ]
                          }
                          Pose {
                            translation 0 0 0.07
                            children [
                              Capsule {
                                height 0.1
                                radius 0.03
                              }
                            ]
                          }
                        ]
                      }
                      physics Physics {
                        density -1
                        mass 1.437
                        centerOfMass [
                          0 0 0.1065
                        ]
                      }
                    }
                  }
                ]
                name "upper_arm_link"
                boundingObject Group {
                  children [
                    Pose {
                      translation 0 0 0.035
                      rotation 1 0 0 3.141593
                      children [
                        Cylinder {
                          height 0.073
                          radius 0.046
                        }
                      ]
                    }
                    Pose {
                      translation 0 0 0.157
                      rotation 1 0 0 3.141593
                      children [
                        Cylinder {
                          height 0.186
                          radius 0.038
                        }
                      ]
                    }
                    Pose {
                      rotation 1 0 0 -1.570796
                      children [
                        Cylinder {
                          height 0.119
                          radius 0.046
                        }
                      ]
                    }
                    Pose {
                      translation 0 0.002 0.2435
                      rotation 1 0 0 -1.570796
                      children [
                        Cylinder {
                          height 0.11
                          radius 0.038
                        }
                      ]
                    }
                  ]
                }
                physics Physics {
                  density -1
                  mass 3.4445
                  centerOfMass [
                    0 0 0.122
                  ]
                }
              }
            }
          ]
          name "shoulder_link"
          boundingObject Group {
            children [
              Pose {
                translation 0 0 -0.003
                rotation 1 0 0 3.141593
                children [
                  Cylinder {
                    height 0.121
                    radius 0.046
                  }
                ]
              }
              Pose {
                translation 0 0.03 0
                rotation 1 0 0 -1.570796
                children [
                  Cylinder {
                    height 0.066
                    radius 0.045
                  }
                ]
              }
            ]
          }
          physics Physics {
            density -1
            mass 1.98
            centerOfMass [
              0 0 0
            ]
          }
        }
      }
    ]
    name IS name
    model "UR3e"
    controller IS controller
    controllerArgs IS controllerArgs
    window IS window
    supervisor IS supervisor
    synchronization IS synchronization
    selfCollision IS selfCollision
    boundingObject Pose {
      translation 0 0 0.045
      rotation 1 0 0 3.141593
      children [
        Cylinder {
          height 0.09
          radius 0.064
        }
      ]
    }
    %< if (!fields.staticBase.value) { >%
    physics Physics {
      density -1
      mass 2
      centerOfMass [
        0 0 0
      ]
    }
    %< } >%
  }
}
