#VRML_SIM R2021a utf8
# license: Copyright Cyberbotics Ltd. Licensed for use only with Webots.
# license url: https://cyberbotics.com/webots_assets_license
# tags: static
# documentation url: https://www.cyberbotics.com/doc/guide/robotis-op2
# Robotis' DARwIn-OP is an open platform, miniature humanoid robot used for research, education and outreach.
# The DARwIn-OP model contains principally:
# - the 20 DOF
# - LEDs
# - accelerometer
# - gyro
# - camera
# - realistic physics

PROTO Darwin-op [
  field SFVec3f    translation     0 0 0                      # Is `Transform.translation`.
  field SFRotation rotation        0 1 0 0                    # Is `Transform.rotation`.
  field SFString   name            "DARwIn-OP"                # Is `Solid.name`.
  field SFString   controller      "motion_player"            # Is `Robot.controller`.
  field MFString   controllerArgs  []                         # Is `Robot.controllerArgs`.
  field SFString   customData      ""                         # Is `Robot.customData`.
  field SFBool     supervisor      FALSE                      # Is `Robot.supervisor`.
  field SFBool     synchronization TRUE                       # Is `Robot.synchronization`.
  field MFFloat    battery         []                         # Is `Robot.battery`.
  field SFBool     selfCollision   FALSE                      # Is `Robot.selfCollision`.
  field SFColor    plasticColor    0.301961 0.301961 0.301961 # Is `Material.plasticColor`.
  field SFInt32    cameraWidth     160                        # Is `Camera.width`.
  field SFInt32    cameraHeight    120                        # Is `Camera.height`.
  field SFNode     jersey          NULL                       # Extends the robot with a jersey: typically RobotisJersey.proto.
  field SFInt32    channel         0                          # Defines the channel for the `Emitter` and `Receiver` devices.
  field SFBool     showWindow      FALSE                      # Is `Robot.showWindow`.
  field MFNode     bodySlot        []                         # Extends the robot with new nodes in the body slot.
  field MFNode     headSlot        []                         # Extends the robot with new nodes in the head slot.
  field MFNode     leftFootSlot    []                         # Extends the robot with new nodes in the left foot slot.
  field MFNode     rightFootSlot   []                         # Extends the robot with new nodes in the right foot slot.
  field MFNode     leftHandSlot    []                         # Extends the robot with new nodes in the left hand slot.
  field MFNode     rightHandSlot   []                         # Extends the robot with new nodes in the right hand slot.
#protected
  hiddenField SFString _model       "DARwIn-OP"
  hiddenField SFString _description "Robotis' DARwIn-OP modeled by Fabien Rohrer"
]
{
  %{
    local has_jersey = fields.jersey.value
  }%
  Robot {
    translation IS translation
    rotation IS rotation
    battery IS battery
    children [
      DEF BODY_SLOT Group {
        children IS bodySlot
      }
      DEF JERSEY_SLOT Slot {
        type "robotis jersey"
        endPoint IS jersey
      }
      DEF DBodyShape Shape {
        appearance DEF PLASTIC_APPEARANCE PBRAppearance {
          baseColor IS plasticColor
          roughness 0.4
          metalness 0
        }
        geometry Mesh {
          url "Darwin-op/body.obj"
        }
      }
      LED {
        %{ if has_jersey then }%
          translation -0.005 -0.01 -0.056
        %{ else }%
          translation -0.005 -0.01 -0.076
        %{ end }%
        color [
          0 1 0
        ]
        name "BackLedGreen"
        children [
          Shape {
            appearance PBRAppearance {
              transparency 0.1
              metalness 0
              roughness 0.3
              emissiveIntensity 6
            }
            geometry Box {
              size 0.002 0.005 0.002
            }
          }
        ]
      }
      LED {
        %{ if has_jersey then }%
          translation 0 -0.01 -0.056
        %{ else }%
          translation 0 -0.01 -0.076
        %{ end }%
        color [
          0 0 1
        ]
        name "BackLedBlue"
        children [
          Shape {
            appearance PBRAppearance {
              transparency 0.1
              metalness 0
              roughness 0.3
              emissiveIntensity 6
            }
            geometry Box {
              size 0.002 0.005 0.002
            }
          }
        ]
      }
      LED {
        %{ if has_jersey then }%
          translation 0.005 -0.01 -0.056
        %{ else }%
          translation 0.005 -0.01 -0.076
        %{ end }%
        color [
          1 0 0
        ]
        name "BackLedRed"
        children [
          Shape {
            appearance PBRAppearance {
              metalness 0
              roughness 0.2
            }
            geometry Box {
              size 0.002 0.005 0.002
            }
          }
        ]
      }
      Speaker {
        translation 0 0 0.2
        rotation -0.129428 -0.983106 0.129428 1.58783
        name "Speaker"
      }
      Accelerometer {
        translation 0 -0.0684064 -0.01
        rotation 0.0 0.707107 0.707107 3.14159
        name "Accelerometer"
        lookupTable [
          -39.24 0 0, 39.24 1024 0
        ]
      }
      Gyro {
        translation 0 -0.0684064 0.01
        rotation -0.57735 0.57735 0.57735 2.0944
        name "Gyro"
        lookupTable [
          -27.925 0 0, 27.925 1024 0
        ]
      }
      DEF RECEIVER Receiver {
        name "receiver"
        channel IS channel
      }
      DEF EMITTER Emitter {
        name "emitter"
        channel IS channel
      }
      DEF SUPER_EMITTER Emitter {
        name "super_emitter"
        channel 2
      }
      DEF DNeck HingeJoint {
        device [
          RotationalMotor {
            name "Neck"
            acceleration 55
            maxVelocity 12.26
            minPosition -1.81
            maxPosition 1.81
            maxTorque 2.5
          }
          PositionSensor {
            name "NeckS"
          }
        ]
        jointParameters HingeJointParameters {
          axis 0 1 0
          anchor 0 0.051 0
          dampingConstant 0.002
          staticFriction 0.025
        }
        endPoint Solid {
          translation 0 0.051 0
          rotation 0 1 0 0
          children [
            DEF DNeckShape Shape {
              appearance DEF METAL_APPEARANCE PBRAppearance {
                  baseColor 0.7 0.7 0.7
                  roughness 0.2
              }
              geometry Mesh {
                url "Darwin-op/neck.obj"
              }
            }
            DEF DHead HingeJoint {
              device [
                RotationalMotor {
                  name "Head"
                  acceleration 55
                  maxVelocity 12.26
                  minPosition -0.36
                  maxPosition 0.94
                  maxTorque 2.5
                }
                PositionSensor {
                  name "HeadS"
                }
              ]
              jointParameters HingeJointParameters {
                axis -1 0 0
                position 0.19
                dampingConstant 0.002
                staticFriction 0.025
              }
              endPoint Solid {
                rotation -1 0 0 -0.5954
                children [
                  DEF HEAD_SLOT Transform {
                    translation 0 0.022 -0.012
                    children IS headSlot
                  }
                  DEF DHeadShape Group {
                    children [
                      Shape {
                        appearance USE PLASTIC_APPEARANCE
                        geometry Mesh {
                          url "Darwin-op/head.obj"
                        }
                      }
                      Shape {
                        appearance DEF PUPIL_APPEARANCE PBRAppearance {
                          baseColor 0.05 0.05 0.05
                          metalness 0
                          roughness 0
                        }
                        geometry Mesh {
                          url "Darwin-op/pupil.obj"
                        }
                      }
                    ]
                  }
                  Camera {
                    translation 0 0.0329074 0.0359816
                    rotation 0 -1 0 3.14159
                    children [
                      DEF DCameraShape Shape {
                        appearance DEF DCameraAppearance PBRAppearance {
                          metalness 0
                          roughness 0.3
                        }
                        geometry Mesh {
                          url "Darwin-op/camera.obj"
                        }
                      }
                    ]
                    name "Camera"
                    fieldOfView 1.0123
                    width IS cameraWidth
                    height IS cameraHeight
                    zoom Zoom {
                    }
                  }
                  DEF DEyeLED LED {
                    rotation 1 0 0 0
                    children [
                      DEF DEyeLedShape Shape {
                        appearance DEF DEyeLEDAppearance PBRAppearance {
                          baseColor 0.7 0.7 0.7
                          metalness 0
                          roughness 0.3
                          emissiveIntensity 6
                        }
                        geometry Mesh {
                          url "Darwin-op/eye_led.obj"
                        }
                      }
                    ]
                    name "EyeLed"
                    color [

                    ]
                    gradual TRUE
                  }
                  DEF DHeadLED LED {
                    rotation 1 0 0 0
                    children [
                      DEF DHeadLedShape Shape {
                        appearance DEF DHeadLEDAppearance PBRAppearance {
                          baseColor 0.7 0.7 0.7
                          metalness 0
                          roughness 0.3
                          emissiveIntensity 6
                        }
                        geometry Mesh {
                          url "Darwin-op/head_led.obj"
                        }
                      }
                    ]
                    name "HeadLed"
                    color [

                    ]
                    gradual TRUE
                  }
                ]
                boundingObject Transform {
                  translation 0 0.022 -0.012
                  rotation 1 0 0 1.5708
                  children [
                    Capsule {
                      height 0.018
                      radius 0.042
                    }
                  ]
                }
                physics Physics {
                  density -1
                  mass 0.158042
                  centerOfMass [
                    6.39198e-05 0.0185645 0.00766662
                  ]
                  inertiaMatrix [
                    1.2396830e-04 1.1783781e-04 1.1583601e-04, 7.8494368e-07 -7.6459790e-08 1.2199205e-05
                  ]
                }
              }
            }
          ]
          name "neck"
          boundingObject Transform {
            translation 0 -0.009 0
            children [
              Box {
                size 0.044 0.043 0.022
              }
            ]
          }
          physics Physics {
            density -1
            mass 0.0243577
            centerOfMass [
              0.00142428 -0.0165676 -0.000712811
            ]
            inertiaMatrix [
              5.1411124e-06 8.1915737e-06 1.1379812e-05, -5.7530255e-07 -2.4729049e-08 -1.9223094e-07
            ]
          }
        }
      }
      DEF DPelvYL HingeJoint {
        device [
          RotationalMotor {
            name "PelvYL"
            acceleration 55
            maxVelocity 12.26
            minPosition -0.69
            maxPosition 2.5
            maxTorque 2.5
          }
          PositionSensor {
            name "PelvYLS"
          }
        ]
        jointParameters HingeJointParameters {
          axis 0 -1 0
          anchor 0.037 -0.1222 -0.005
          position -0.02
          dampingConstant 0.002
          staticFriction 0.025
        }
        endPoint Solid {
          translation 0.037 -0.1222 -0.005
          rotation 0 -1 0 -0.02
          children [
            DEF DPelvYLShape Shape {
              appearance USE METAL_APPEARANCE
              geometry Mesh {
                url "Darwin-op/pelv_y_left.obj"
              }
            }
            DEF DPelvL HingeJoint {
              device [
                RotationalMotor {
                  name "PelvL"
                  acceleration 55
                  maxVelocity 12.26
                  minPosition -1
                  maxPosition 0.93
                  maxTorque 2.5
                }
                PositionSensor {
                  name "PelvLS"
                }
              ]
              jointParameters HingeJointParameters {
                axis 0 0 -1
                position -0.01
                dampingConstant 0.002
                staticFriction 0.025
              }
              endPoint Solid {
                rotation 0 0 -1 -0.01
                children [
                  DEF DPelvLShape Shape {
                    appearance DEF MOTOR_APPEARANCE PBRAppearance {
                      baseColor 0 0 0
                      roughness 0.4
                      metalness 0
                    }
                    geometry Mesh {
                      url "Darwin-op/pelv_left.obj"
                    }
                  }
                  DEF DLegUpperL HingeJoint {
                    device [
                      RotationalMotor {
                        name "LegUpperL"
                        acceleration 55
                        maxVelocity 12.26
                        minPosition -0.5
                        maxPosition 1.68
                        maxTorque 2.5
                      }
                      PositionSensor {
                        name "LegUpperLS"
                      }
                    ]
                    jointParameters HingeJointParameters {
                      axis -1 0 0
                      position 1.15
                      dampingConstant 0.002
                      staticFriction 0.025
                    }
                    endPoint Solid {
                      rotation -1 0 0 1.15
                      children [
                        DEF DLegUpperLShape Group {
                          children [
                            Shape {
                              appearance USE PLASTIC_APPEARANCE
                              geometry Mesh {
                                url "Darwin-op/leg_upper_left.obj"
                              }
                            }
                            Shape {
                              appearance USE MOTOR_APPEARANCE
                              geometry Mesh {
                                url "Darwin-op/leg_upper_motor_left.obj"
                              }
                            }
                          ]
                        }
                        DEF DLegLowerL HingeJoint {
                          device [
                            RotationalMotor {
                              name "LegLowerL"
                              acceleration 55
                              maxVelocity 12.26
                              minPosition -2.25
                              maxPosition 0.03
                              maxTorque 2.5
                            }
                            PositionSensor {
                              name "LegLowerLS"
                            }
                          ]
                          jointParameters HingeJointParameters {
                            axis -1 0 0
                            anchor -0 -0.093 0
                            position -2.25
                            dampingConstant 0.002
                            staticFriction 0.025
                          }
                          endPoint Solid {
                            translation -0 -0.093 0
                            rotation -1 0 0 -2.25
                            children [
                              DEF DLegLowerLShape Shape {
                                appearance USE PLASTIC_APPEARANCE
                                geometry Mesh {
                                  url "Darwin-op/leg_lower_left.obj"
                                }
                              }
                              DEF DAnkleL HingeJoint {
                                device [
                                  RotationalMotor {
                                    name "AnkleL"
                                    acceleration 55
                                    maxVelocity 12.26
                                    minPosition -1.39
                                    maxPosition 1.22
                                    maxTorque 2.5
                                  }
                                  PositionSensor {
                                    name "AnkleLS"
                                  }
                                ]
                                jointParameters HingeJointParameters {
                                  axis 1 0 0
                                  anchor 0 -0.093 0
                                  position -1.23
                                  dampingConstant 0.002
                                  staticFriction 0.025
                                }
                                endPoint Solid {
                                  translation 0 -0.093 0
                                  rotation 1 0 0 -1.23
                                  children [
                                    DEF DAnkleLShape Shape {
                                      appearance USE MOTOR_APPEARANCE
                                      geometry Mesh {
                                        url "Darwin-op/ankle_left.obj"
                                      }
                                    }
                                    DEF DFootL HingeJoint {
                                      device [
                                        RotationalMotor {
                                          name "FootL"
                                          acceleration 55
                                          maxVelocity 12.26
                                          minPosition -1.02
                                          maxPosition 0.6
                                          maxTorque 2.5
                                        }
                                        PositionSensor {
                                          name "FootLS"
                                        }
                                      ]
                                      jointParameters HingeJointParameters {
                                        axis 0 0 1
                                        position -0.02
                                        dampingConstant 0.002
                                        staticFriction 0.025
                                      }
                                      endPoint Solid {
                                        rotation 0 0 1 -0.02
                                        children [
                                          DEF LEFT_FOOT_SLOT Group {
                                            children IS leftFootSlot
                                          }
                                          DEF DFootLShape Group {
                                            children [
                                              Shape {
                                                appearance USE PLASTIC_APPEARANCE
                                                geometry Mesh {
                                                  url "Darwin-op/foot_left.obj"
                                                }
                                              }
                                              Shape {
                                                appearance USE METAL_APPEARANCE
                                                geometry Mesh {
                                                  url "Darwin-op/foot_motor_left.obj"
                                                }
                                              }
                                            ]
                                          }
                                        ]
                                        boundingObject Transform {
                                          translation 0.011 -0.027 -0.001
                                          children [
                                            Box {
                                              size 0.066 0.013 0.105
                                            }
                                          ]
                                        }
                                        physics Physics {
                                          density -1
                                          mass 0.0794462
                                          centerOfMass [
                                            0.00950588 -0.0259953 -0.000502877
                                          ]
                                          inertiaMatrix [
                                            6.8325629e-05 8.7890505e-05 3.5840758e-05, 2.5330463e-06 2.1869558e-07 9.7620541e-07
                                          ]
                                        }
                                      }
                                    }
                                  ]
                                  boundingObject Transform {
                                    translation 0 0.01 -0.0205
                                    children [
                                      Box {
                                        size 0.036 0.045 0.083
                                      }
                                    ]
                                  }
                                  physics Physics {
                                    density -1
                                    mass 0.167108
                                    centerOfMass [
                                      -0.000213732 0.0138731 -0.0185361
                                    ]
                                    inertiaMatrix [
                                      1.2079175e-04 1.0885465e-04 4.1871103e-05, -7.9781067e-07 -3.9322246e-07 7.0770117e-06
                                    ]
                                  }
                                }
                              }
                            ]
                            boundingObject Group {
                              children [
                                Transform {
                                  translation 0 -0.058 -0.001
                                  children [
                                    Box {
                                      size 0.064 0.034 0.041
                                    }
                                  ]
                                }
                                Transform {
                                  translation 0 -0.02 0.016
                                  rotation 1 0 0 0.04
                                  children [
                                    Box {
                                      size 0.062 0.073 0.027
                                    }
                                  ]
                                }
                              ]
                            }
                            physics Physics {
                              density -1
                              mass 0.0703098
                              centerOfMass [
                                -0.000592469 -0.0539545 0.00654763
                              ]
                              inertiaMatrix [
                                9.3369608e-05 4.6295534e-05 1.1351516e-04, -9.3567395e-07 -2.3992085e-07 -1.2858493e-05
                              ]
                            }
                          }
                        }
                      ]
                      boundingObject Transform {
                        translation 0 -0.058 0.006
                        children [
                          Box {
                            size 0.053 0.035 0.042
                          }
                        ]
                      }
                      physics Physics {
                        density -1
                        mass 0.119043
                        centerOfMass [
                          -0.000322635 -0.0629655 0.000691906
                        ]
                        inertiaMatrix [
                          9.7950272e-05 3.2848287e-05 1.1493509e-04, 1.2119368e-06 -2.1223016e-07 -1.9474021e-06
                        ]
                      }
                    }
                  }
                ]
                boundingObject Transform {
                  translation 0 -0.0105 -0.023
                  children [
                    Box {
                      size 0.036 0.043 0.077
                    }
                  ]
                }
                physics Physics {
                  density -1
                  mass 0.167108
                  centerOfMass [
                    7.99828e-05 -0.0138731 -0.0182424
                  ]
                  inertiaMatrix [
                    1.2259691e-04 1.1066637e-04 4.1877668e-05, 7.1127469e-07 8.1143913e-07 -7.1635476e-06
                  ]
                }
              }
            }
          ]
          name "pelvYL"
          boundingObject Transform {
            translation 0 0.017 0.001
            children [
              Box {
                size 0.022 0.028 0.05
              }
            ]
          }
          physics Physics {
            density -1
            mass 0.0270692
            centerOfMass [
              0 0.0184372 0.000480135
            ]
            inertiaMatrix [
              1.5019148e-05 1.1328768e-05 6.1825529e-06, 0.0000000e+00 0.0000000e+00 -7.3350016e-07
            ]
          }
        }
      }
      DEF DPelvYR HingeJoint {
        device [
          RotationalMotor {
            name "PelvYR"
            acceleration 55
            maxVelocity 12.26
            minPosition -2.42
            maxPosition 0.66
            maxTorque 2.5
          }
          PositionSensor {
            name "PelvYRS"
          }
        ]
        jointParameters HingeJointParameters {
          axis 0 -1 0
          anchor -0.037 -0.1222 -0.005
          position -0.01
          dampingConstant 0.002
          staticFriction 0.025
        }
        endPoint Solid {
          translation -0.037 -0.1222 -0.005
          rotation 0 -1 0 -0.01
          children [
            DEF DPelvYRShape Shape {
              appearance USE METAL_APPEARANCE
              geometry Mesh {
                url "Darwin-op/pelv_y_right.obj"
              }
            }
            DEF DPelvR HingeJoint {
              device [
                RotationalMotor {
                  name "PelvR"
                  acceleration 55
                  maxVelocity 12.26
                  minPosition -1.01
                  maxPosition 1.01
                  maxTorque 2.5
                }
                PositionSensor {
                  name "PelvRS"
                }
              ]
              jointParameters HingeJointParameters {
                axis 0 0 -1
                position 0.02
                dampingConstant 0.002
                staticFriction 0.025
              }
              endPoint Solid {
                rotation 0 0 -1 0.02
                children [
                  DEF DPelvRShape Shape {
                    appearance USE MOTOR_APPEARANCE
                    geometry Mesh {
                      url "Darwin-op/pelv_right.obj"
                    }
                  }
                  DEF DLegUpperR HingeJoint {
                    device [
                      RotationalMotor {
                        name "LegUpperR"
                        acceleration 55
                        maxVelocity 12.26
                        minPosition -1.77
                        maxPosition 0.45
                        maxTorque 2.5
                      }
                      PositionSensor {
                        name "LegUpperRS"
                      }
                    ]
                    jointParameters HingeJointParameters {
                      axis 1 0 0
                      position -1.15
                      dampingConstant 0.002
                      staticFriction 0.025
                    }
                    endPoint Solid {
                      rotation 1 0 0 -1.15
                      children [
                        DEF DLegUpperRShape Group {
                          children [
                            Shape {
                              appearance USE PLASTIC_APPEARANCE
                              geometry Mesh {
                                url "Darwin-op/leg_upper_right.obj"
                              }
                            }
                            Shape {
                              appearance USE MOTOR_APPEARANCE
                              geometry Mesh {
                                url "Darwin-op/leg_upper_motor_right.obj"
                              }
                            }
                          ]
                        }
                        DEF DLegLowerR HingeJoint {
                          device [
                            RotationalMotor {
                              name "LegLowerR"
                              acceleration 55
                              maxVelocity 12.26
                              minPosition -0.02
                              maxPosition 2.25
                              maxTorque 2.5
                            }
                            PositionSensor {
                              name "LegLowerRS"
                            }
                          ]
                          jointParameters HingeJointParameters {
                            axis 1 0 0
                            anchor -0 -0.093 0
                            position 2.25
                            dampingConstant 0.002
                            staticFriction 0.025
                          }
                          endPoint Solid {
                            translation -0 -0.093 0
                            rotation 1 0 0 2.25
                            children [
                              DEF DLegLowerRShape Shape {
                                appearance USE PLASTIC_APPEARANCE
                                geometry Mesh {
                                  url "Darwin-op/leg_lower_right.obj"
                                }
                              }
                              DEF DAnkleR HingeJoint {
                                device [
                                  RotationalMotor {
                                    name "AnkleR"
                                    acceleration 55
                                    maxVelocity 12.26
                                    minPosition -1.24
                                    maxPosition 1.38
                                    maxTorque 2.5
                                  }
                                  PositionSensor {
                                    name "AnkleRS"
                                  }
                                ]
                                jointParameters HingeJointParameters {
                                  axis -1 0 0
                                  anchor 0 -0.093 0
                                  position 1.22
                                  dampingConstant 0.002
                                  staticFriction 0.025
                                }
                                endPoint Solid {
                                  translation 0 -0.093 0
                                  rotation -1 0 0 1.22
                                  children [
                                    DEF DAnkleRShape Shape {
                                      appearance USE MOTOR_APPEARANCE
                                      geometry Mesh {
                                        url "Darwin-op/ankle_right.obj"
                                      }
                                    }
                                    DEF DFootR HingeJoint {
                                      device [
                                        RotationalMotor {
                                          name "FootR"
                                          acceleration 55
                                          maxVelocity 12.26
                                          minPosition -0.68
                                          maxPosition 1.04
                                          maxTorque 2.5
                                        }
                                        PositionSensor {
                                          name "FootRS"
                                        }
                                      ]
                                      jointParameters HingeJointParameters {
                                        axis 0 0 1
                                        position 0.05
                                        dampingConstant 0.002
                                        staticFriction 0.025
                                      }
                                      endPoint Solid {
                                        rotation 0 0 1 0.05
                                        children [
                                          DEF RIGHT_FOOT_SLOT Group {
                                            children IS rightFootSlot
                                          }
                                          DEF DFootRShape Group {
                                            children [
                                              Shape {
                                                appearance USE PLASTIC_APPEARANCE
                                                geometry Mesh {
                                                  url "Darwin-op/foot_right.obj"
                                                }
                                              }
                                              Shape {
                                                appearance USE METAL_APPEARANCE
                                                geometry Mesh {
                                                  url "Darwin-op/foot_motor_right.obj"
                                                }
                                              }
                                            ]
                                          }
                                        ]
                                        boundingObject Transform {
                                          translation -0.011 -0.027 -0.001
                                          children [
                                            Box {
                                              size 0.066 0.013 0.105
                                            }
                                          ]
                                        }
                                        physics Physics {
                                          density -1
                                          mass 0.0794462
                                          centerOfMass [
                                            -0.00950588 -0.0259953 -0.000502877
                                          ]
                                          inertiaMatrix [
                                            6.8325629e-05 8.7890505e-05 3.5840758e-05, -2.5330463e-06 -2.1869558e-07 9.7620541e-07
                                          ]
                                        }
                                      }
                                    }
                                  ]
                                  boundingObject Transform {
                                    translation 0 0.01 -0.0205
                                    children [
                                      Box {
                                        size 0.036 0.045 0.083
                                      }
                                    ]
                                  }
                                  physics Physics {
                                    density -1
                                    mass 0.167108
                                    centerOfMass [
                                      0.000213732 0.0138731 -0.0185361
                                    ]
                                    inertiaMatrix [
                                      1.2079175e-04 1.0885465e-04 4.1871103e-05, 7.9781067e-07 3.9322246e-07 7.0770117e-06
                                    ]
                                  }
                                }
                              }
                            ]
                            boundingObject Group {
                              children [
                                Transform {
                                  translation 0 -0.058 -0.001
                                  children [
                                    Box {
                                      size 0.064 0.034 0.041
                                    }
                                  ]
                                }
                                Transform {
                                  translation 0 -0.02 0.016
                                  rotation 1 0 0 0.04
                                  children [
                                    Box {
                                      size 0.062 0.073 0.027
                                    }
                                  ]
                                }
                              ]
                            }
                            physics Physics {
                              density -1
                              mass 0.0703098
                              centerOfMass [
                                0.000592469 -0.0539545 0.00654763
                              ]
                              inertiaMatrix [
                                9.3369608e-05 4.6295534e-05 1.1351516e-04, 9.3567395e-07 2.3992085e-07 -1.2858493e-05
                              ]
                            }
                          }
                        }
                      ]
                      boundingObject Transform {
                        translation 0 -0.058 0.006
                        children [
                          Box {
                            size 0.053 0.035 0.042
                          }
                        ]
                      }
                      physics Physics {
                        density -1
                        mass 0.119043
                        centerOfMass [
                          0.000322635 -0.0629655 0.000691906
                        ]
                        inertiaMatrix [
                          9.7950272e-05 3.2848287e-05 1.1493509e-04, -1.2119368e-06 2.1223016e-07 -1.9474021e-06
                        ]
                      }
                    }
                  }
                ]
                boundingObject Transform {
                  translation 0 -0.0105 -0.023
                  children [
                    Box {
                      size 0.036 0.043 0.077
                    }
                  ]
                }
                physics Physics {
                  density -1
                  mass 0.167108
                  centerOfMass [
                    -7.99828e-05 -0.0138731 -0.0182424
                  ]
                  inertiaMatrix [
                    1.2259691e-04 1.1066637e-04 4.1877668e-05, -7.1127469e-07 -8.1143913e-07 -7.1635476e-06
                  ]
                }
              }
            }
          ]
          name "pelvYR"
          boundingObject Transform {
            translation 0 0.017 0.001
            children [
              Box {
                size 0.022 0.028 0.05
              }
            ]
          }
          physics Physics {
            density -1
            mass 0.0270692
            centerOfMass [
              0 0.0184372 0.000480135
            ]
            inertiaMatrix [
              1.5019148e-05 1.1328768e-05 6.1825529e-06, -0.0000000e+00 -0.0000000e+00 -7.3350016e-07
            ]
          }
        }
      }
      DEF DShoulderL HingeJoint {
        device [
          RotationalMotor {
            name "ShoulderL"
            acceleration 55
            maxVelocity 12.26
            minPosition -3.14
            maxPosition 2.85
            maxTorque 2.5
          }
          PositionSensor {
            name "ShoulderLS"
          }
        ]
        jointParameters HingeJointParameters {
          axis 1 0 0
          anchor 0.082 0 0
          position 0.72
          dampingConstant 0.002
          staticFriction 0.025
        }
        endPoint Solid {
          translation 0.082 0 0
          rotation 1 0 0 0.72
          children [
            DEF DShoulderLShape Shape {
              appearance USE METAL_APPEARANCE
              geometry Mesh {
                url "Darwin-op/shoulder_left.obj"
              }
            }
            DEF DArmUpperL HingeJoint {
              device [
                RotationalMotor {
                  name "ArmUpperL"
                  acceleration 55
                  maxVelocity 12.26
                  minPosition -2.25
                  maxPosition 0.77
                  maxTorque 2.5
                }
                PositionSensor {
                  name "ArmUpperLS"
                }
              ]
              jointParameters HingeJointParameters {
                axis 0 0 -1
                anchor 0 -0.016 0
                position 0.36
                dampingConstant 0.002
                staticFriction 0.025
              }
              endPoint Solid {
                translation 0 -0.016 0
                rotation 0 0 -1 -0.4254
                children [
                  DEF DArmUpperLShape Group {
                    children [
                      Shape {
                        appearance USE PLASTIC_APPEARANCE
                        geometry Mesh {
                          url "Darwin-op/arm_upper_left.obj"
                        }
                      }
                      Shape {
                        appearance USE MOTOR_APPEARANCE
                        geometry Mesh {
                          url "Darwin-op/arm_upper_motor_left.obj"
                        }
                      }
                    ]
                  }
                  DEF DArmLowerL HingeJoint {
                    device [
                      RotationalMotor {
                        name "ArmLowerL"
                        acceleration 55
                        maxVelocity 12.26
                        minPosition -1.18
                        maxPosition 1.63
                        maxTorque 2.5
                      }
                      PositionSensor {
                        name "ArmLowerLS"
                      }
                    ]
                    jointParameters HingeJointParameters {
                      axis 1 0 0
                      anchor 0 -0.06 0.016
                      position -0.52
                      dampingConstant 0.002
                      staticFriction 0.025
                    }
                    endPoint Solid {
                      translation 0 -0.06 0.016
                      rotation 1 0 0 -2.0908
                      children [
                        DEF LEFT_HAND_SLOT Group {
                          children IS leftHandSlot
                        }
                        DEF DArmLowerLShape Group {
                          children [
                            Shape {
                              appearance USE PLASTIC_APPEARANCE
                              geometry Mesh {
                                url "Darwin-op/arm_lower_left.obj"
                              }
                            }
                            Shape {
                              appearance USE METAL_APPEARANCE
                              geometry Mesh {
                                url "Darwin-op/arm_lower_motor_left.obj"
                              }
                            }
                          ]
                        }
                      ]
                      boundingObject Transform {
                        translation 0.0075 -0.073 -0.016
                        children [
                          Box {
                            size 0.027 0.113 0.036
                          }
                        ]
                      }
                      physics Physics {
                        density -1
                        mass 0.0592885
                        centerOfMass [
                          0.00666564 -0.0458382 -0.0134901
                        ]
                        inertiaMatrix [
                          8.6855267e-05 2.1192085e-05 8.6845450e-05, 5.3020311e-06 4.3636051e-07 -6.4855932e-06
                        ]
                      }
                    }
                  }
                ]
                boundingObject Group {
                  children [
                    Transform {
                      translation 0 -0.019 0
                      children [
                        Box {
                          size 0.036 0.044 0.04
                        }
                      ]
                    }
                    Transform {
                      translation 0 -0.06 0.003
                      children [
                        Box {
                          size 0.036 0.036 0.051
                        }
                      ]
                    }
                  ]
                }
                physics Physics {
                  density -1
                  mass 0.168377
                  centerOfMass [
                    0.000659787 -0.036239 0.000734065
                  ]
                  inertiaMatrix [
                    1.2202839e-04 3.8088441e-05 1.1340830e-04, -2.0812626e-06 -8.8143449e-07 1.8251448e-06
                  ]
                }
              }
            }
          ]
          name "shoulderL"
          boundingObject Transform {
            translation -0.009 -0.0065 0
            rotation 0 0 1 -0.785398
            children [
              Box {
                size 0.027 0.022 0.044
              }
            ]
          }
          physics Physics {
            density -1
            mass 0.025913
            centerOfMass [
              -0.0135226 0.012641 0.00139357
            ]
            inertiaMatrix [
              9.7758165e-06 1.0511104e-05 5.4767980e-06, 1.6911839e-06 -4.5174329e-07 3.3406955e-07
            ]
          }
        }
      }
      DEF DShoulderR HingeJoint {
        device [
          RotationalMotor {
            name "ShoulderR"
            acceleration 55
            maxVelocity 12.26
            minPosition -3.14
            maxPosition 3.14
            maxTorque 2.5
          }
          PositionSensor {
            name "ShoulderRS"
          }
        ]
        jointParameters HingeJointParameters {
          axis -1 0 0
          anchor -0.082 0 0
          position -0.84
          dampingConstant 0.002
          staticFriction 0.025
        }
        endPoint Solid {
          translation -0.082 0 0
          rotation -1 0 0 -0.84
          children [
            DEF DShoulderRShape Shape {
              appearance USE METAL_APPEARANCE
              geometry Mesh {
                url "Darwin-op/shoulder_right.obj"
              }
            }
            DEF DArmUpperR HingeJoint {
              device [
                RotationalMotor {
                  name "ArmUpperR"
                  acceleration 55
                  maxVelocity 12.26
                  minPosition -0.68
                  maxPosition 2.3
                  maxTorque 2.5
                }
                PositionSensor {
                  name "ArmUpperRS"
                }
              ]
              jointParameters HingeJointParameters {
                axis 0 0 -1
                anchor 0 -0.016 0
                position -0.33
                dampingConstant 0.002
                staticFriction 0.025
              }
              endPoint Solid {
                translation 0 -0.016 0
                rotation 0 0 -1 0.4554
                children [
                  DEF DArmUpperRShape Group {
                    children [
                      Shape {
                        appearance USE PLASTIC_APPEARANCE
                        geometry Mesh {
                          url "Darwin-op/arm_upper_right.obj"
                        }
                      }
                      Shape {
                        appearance USE MOTOR_APPEARANCE
                        geometry Mesh {
                          url "Darwin-op/arm_upper_motor_right.obj"
                        }
                      }
                    ]
                  }
                  DEF DArmLowerR HingeJoint {
                    device [
                      RotationalMotor {
                        name "ArmLowerR"
                        acceleration 55
                        maxVelocity 12.26
                        minPosition -1.65
                        maxPosition 1.16
                        maxTorque 2.5
                      }
                      PositionSensor {
                        name "ArmLowerRS"
                      }
                    ]
                    jointParameters HingeJointParameters {
                      axis -1 0 0
                      anchor 0 -0.06 0.016
                      position 0.51
                      dampingConstant 0.002
                      staticFriction 0.025
                    }
                    endPoint Solid {
                      translation 0 -0.06 0.016
                      rotation -1 0 0 2.0808
                      children [
                        DEF RIGHT_HAND_SLOT Group {
                          children IS rightHandSlot
                        }
                        DEF DArmLowerRShape Group {
                          children [
                            Shape {
                              appearance USE PLASTIC_APPEARANCE
                              geometry Mesh {
                                url "Darwin-op/arm_lower_right.obj"
                              }
                            }
                            Shape {
                              appearance USE METAL_APPEARANCE
                              geometry Mesh {
                                url "Darwin-op/arm_lower_motor_right.obj"
                              }
                            }
                          ]
                        }
                      ]
                      boundingObject Transform {
                        translation -0.0075 -0.073 -0.016
                        children [
                          Box {
                            size 0.027 0.113 0.036
                          }
                        ]
                      }
                      physics Physics {
                        density -1
                        mass 0.0592885
                        centerOfMass [
                          -0.00666564 -0.0458382 -0.0134901
                        ]
                        inertiaMatrix [
                          8.6855267e-05 2.1192085e-05 8.6845450e-05, -5.3020311e-06 -4.3636051e-07 -6.4855932e-06
                        ]
                      }
                    }
                  }
                ]
                boundingObject Group {
                  children [
                    Transform {
                      translation 0 -0.019 0
                      children [
                        Box {
                          size 0.036 0.044 0.04
                        }
                      ]
                    }
                    Transform {
                      translation 0 -0.06 0.003
                      children [
                        Box {
                          size 0.036 0.036 0.051
                        }
                      ]
                    }
                  ]
                }
                physics Physics {
                  density -1
                  mass 0.168377
                  centerOfMass [
                    -0.000659787 -0.036239 0.000734065
                  ]
                  inertiaMatrix [
                    1.2202839e-04 3.8088441e-05 1.1340830e-04, 2.0812626e-06 8.8143449e-07 1.8251448e-06
                  ]
                }
              }
            }
          ]
          name "shoulderR"
          boundingObject Transform {
            translation 0.009 -0.0065 0
            rotation 0 0 1 0.785398
            children [
              Box {
                size 0.027 0.022 0.044
              }
            ]
          }
          physics Physics {
            density -1
            mass 0.025913
            centerOfMass [
              0.0135226 0.010241 0.00139357
            ]
            inertiaMatrix [
              9.7758165e-06 1.0511104e-05 5.4767980e-06, -1.6911839e-06 4.5174329e-07 3.3406955e-07
            ]
          }
        }
      }
      DEF DHeadBackLED Transform {
        %{ if has_jersey then }%
          translation -0.01 -0.01 -0.056
        %{ else }%
          translation -0.01 -0.01 -0.076
        %{ end }%
        children [
          Shape {
            appearance USE DHeadLEDAppearance
            geometry Box {
              size 0.002 0.005 0.002
            }
          }
        ]
      }
      DEF DEyeBackLED Transform {
        %{ if has_jersey then }%
          translation -0.015 -0.01 -0.056
        %{ else }%
          translation -0.015 -0.01 -0.076
        %{ end }%
        children [
          Shape {
            appearance USE DEyeLEDAppearance
            geometry Box {
              size 0.002 0.005 0.002
            }
          }
        ]
      }
    ]
    boundingObject Group {
      children [
        Transform {
          translation 0 -0.059 -0.025
          children [
            Box {
              size 0.1 0.058 0.091
            }
          ]
        }
        Transform {
          translation 0 -0.029 -0.038
          children [
            Box {
              size 0.114 0.045 0.076
            }
          ]
        }
        Transform {
          translation 0 -0.006 -0.027
          rotation 1 0 0 0.1
          children [
            Box {
              size 0.114 0.058 0.076
            }
          ]
        }
        Transform {
          translation 0 -0.042 0.028
          children [
            Box {
              size 0.114 0.046 0.016
            }
          ]
        }
      ]
    }
    name IS name
    model       IS _model
    description IS _description
    physics Physics {
      density -1
      mass 0.975599
      centerOfMass [
        0.0 -0.08 -0.05
      ]
      inertiaMatrix [
        3.1081800e-03 6.3787776e-03 5.3316425e-03, -2.5460189e-04 2.0318174e-03 1.6417863e-04
      ]
    }
    controller IS controller
    controllerArgs IS controllerArgs
    customData IS customData
    supervisor IS supervisor
    synchronization IS synchronization
    selfCollision IS selfCollision
    showWindow IS showWindow
    window "robotis-op2_window"
    remoteControl "robotis-op2_tcpip"
  }
}
