#VRML_SIM R2023b utf8

EXTERNPROTO "webots://projects/objects/backgrounds/protos/TexturedBackground.proto"
EXTERNPROTO "webots://projects/objects/backgrounds/protos/TexturedBackgroundLight.proto"
EXTERNPROTO "webots://projects/objects/floors/protos/RectangleArena.proto"

WorldInfo {
}
Viewpoint {
  orientation -0.2741151753619989 0.08532017912734163 0.9579046600105561 2.7029760290288127
  position 1.1438572185186204 -0.6351160973817138 1.1303934910826199
  follow "robot"
}
TexturedBackground {
}
TexturedBackgroundLight {
}
RectangleArena {
}
Robot {
  controller "center_of_mass"
  supervisor TRUE
}
Robot {
  translation 0 0 0.09
  children [
    HingeJoint {
      jointParameters HingeJointParameters {
        axis 0 0 1
        anchor 0 0 0.01
      }
      device [
        RotationalMotor {
        }
      ]
      endPoint Solid {
        translation 0 0 0.04
        children [
          DEF TOP_GROUP Group {
            children [
              Pose {
                rotation 0 -1 0 1.5708
                children [
                  Shape {
                    appearance DEF GRAY_APPEARANCE PBRAppearance {
                      baseColor 0.8 0.8 0.8
                      roughness 0.5
                      metalness 0
                    }
                    geometry Cylinder {
                      height 0.25
                      radius 0.006
                    }
                  }
                ]
              }
              Pose {
                translation -0.12 0 0
                children [
                  Shape {
                    appearance USE GRAY_APPEARANCE
                    geometry Sphere {
                      radius 0.01
                      subdivision 4
                    }
                  }
                ]
              }
              Pose {
                translation 0.14 0 0
                children [
                  Shape {
                    appearance USE GRAY_APPEARANCE
                    geometry Sphere {
                      radius 0.03
                      subdivision 3
                    }
                  }
                ]
              }
              Shape {
                appearance USE GRAY_APPEARANCE
                geometry Cylinder {
                  height 0.03
                  radius 0.03
                  subdivision 24
                }
              }
            ]
          }
        ]
        boundingObject USE TOP_GROUP
        physics Physics {
          density 1950
        }
      }
    }
    BallJoint {
      jointParameters BallJointParameters {
        anchor -0.025 -0.025 -0.075
      }
      endPoint Solid {
        translation -0.025 -0.025 -0.075
        children [
          DEF FOOT_SPHERE_SHAPE Shape {
            appearance PBRAppearance {
              baseColor 0.8 0.8 0.8
              roughness 1
              metalness 0
            }
            geometry Sphere {
              radius 0.01
            }
          }
        ]
        name "foot 1"
        boundingObject USE FOOT_SPHERE_SHAPE
        physics Physics {
        }
      }
    }
    BallJoint {
      jointParameters BallJointParameters {
        anchor 0.025 -0.025 -0.075
      }
      endPoint Solid {
        translation 0.025 -0.025 -0.075
        children [
          USE FOOT_SPHERE_SHAPE
        ]
        name "foot 2"
        boundingObject USE FOOT_SPHERE_SHAPE
        physics Physics {
        }
      }
    }
    BallJoint {
      jointParameters BallJointParameters {
        anchor 0.025 0.025 -0.075
      }
      endPoint Solid {
        translation 0.025 0.025 -0.075
        children [
          USE FOOT_SPHERE_SHAPE
        ]
        name "foot 3"
        boundingObject USE FOOT_SPHERE_SHAPE
        physics Physics {
        }
      }
    }
    BallJoint {
      jointParameters BallJointParameters {
        anchor -0.025 0.025 -0.075
      }
      endPoint Solid {
        translation -0.025 0.025 -0.075
        children [
          USE FOOT_SPHERE_SHAPE
        ]
        name "foot 4"
        boundingObject USE FOOT_SPHERE_SHAPE
        physics Physics {
        }
      }
    }
    DEF GROUP Group {
      children [
        Pose {
          translation -0.025 -0.025 -0.05
          children [
            DEF CYLINDER_SHAPE Shape {
              appearance PBRAppearance {
                baseColor 0 0 1
                roughness 1.1102230246251565e-16
                metalness 0
              }
              geometry DEF CYLINDER Cylinder {
                height 0.05
                radius 0.013
              }
            }
          ]
        }
        Pose {
          translation -0.025 0.025 -0.05
          children [
            USE CYLINDER_SHAPE
          ]
        }
        Pose {
          translation 0.025 0.025 -0.05
          children [
            USE CYLINDER_SHAPE
          ]
        }
        Pose {
          translation 0.025 -0.025 -0.05
          children [
            USE CYLINDER_SHAPE
          ]
        }
        Shape {
          appearance PBRAppearance {
            baseColor 0 0 1
            roughness 0.09966656699999998
            metalness 0
          }
          geometry Box {
            size 0.15 0.1 0.05
          }
        }
      ]
    }
  ]
  name "robot(1)"
  boundingObject USE GROUP
  physics Physics {
  }
  controller "rotation"
}
