#VRML_SIM R2021b utf8
WorldInfo {
  gravity 0
  coordinateSystem "NUE"
}
Viewpoint {
  orientation -0.6912755688323604 0.7109168256398194 0.12936519994843748 0.5147959918050843
  position 0.3729624738049243 0.20191593532441116 0.8494775441663882
}
TexturedBackground {
}
TexturedBackgroundLight {
}
Robot {
  children [
    DEF CLASSIC_HINGE HingeJoint {
      jointParameters HingeJointParameters {
        axis 0 0 1
      }
      device [
        PositionSensor {
          name "cJointPos"
        }
        RotationalMotor {
          name "cJointMot"
        }
      ]
      endPoint Solid {
        translation 0 -0.15 -0.1
        rotation 0 0 1 0
        children [
          Shape {
            appearance PBRAppearance {
              baseColor 0.8 0 0
            }
            geometry DEF PENDULUM Box {
              size 0.02 0.3 0.1
            }
          }
        ]
        name "solid(1)"
        boundingObject USE PENDULUM
        physics Physics {
          density -1
          mass 0.01
        }
      }
    }
    DEF AXIS1 HingeJoint {
      jointParameters HingeJointParameters {
        axis 0 0 1
      }
      device [
        PositionSensor {
          name "hJointPos"
        }
        RotationalMotor {
          name "hJointMot"
        }
      ]
      endPoint Solid {
        rotation 0 0 1 0
        children [
          Transform {
            rotation 1 0 0 -1.57
            children [
              Shape {
                appearance PBRAppearance {
                  baseColor 0 0 0
                }
                geometry Cylinder {
                  height 0.5
                  radius 0.001
                }
              }
            ]
          }
          DEF AXIS2 HingeJoint {
            jointParameters HingeJointParameters {
              axis 0 0 1
              minStop -0.1
              maxStop 0.1
              stopERP 0
            }
            device [
              PositionSensor {
                name "hJointPos2"
              }
            ]
            endPoint Solid {
              translation 0 -0.15 0
              rotation 0 0 1 0
              children [
                Shape {
                  appearance PBRAppearance {
                    baseColor 0.203922 0.396078 0.643137
                  }
                  geometry USE PENDULUM
                }
              ]
              boundingObject USE PENDULUM
              physics Physics {
                density -1
                mass 1
              }
            }
          }
        ]
        boundingObject Sphere {
          radius 0.01
        }
        physics Physics {
          density -1
          mass 0.001
        }
      }
    }
    HingeJointWithBacklash {
      jointParameters HingeJointParameters {
        axis 0 0 1
      }
      backlash 0.2
      device [
        PositionSensor {
          name "pJointPos"
        }
        RotationalMotor {
          name "pJointMot"
        }
      ]
      startPoint [
        Transform {
          translation 0 0 0.1
          rotation 1 0 0 -1.57
          children [
            Shape {
              appearance PBRAppearance {
                baseColor 0.305882 0.603922 0.0235294
              }
              geometry Box {
                size 0.05 0.06 0.05
              }
            }
          ]
        }
      ]
      endPoint Solid {
        translation 0 -0.15 0.1
        rotation 0 0 1 0
        children [
          Shape {
            appearance PBRAppearance {
              baseColor 0.45098 0.823529 0.0862745
            }
            geometry USE PENDULUM
          }
        ]
        boundingObject USE PENDULUM
        physics Physics {
          density -1
          mass 1
        }
      }
    }
  ]
  name "robot(1)"
  controller "hingewithbacklash"
}
