#VRML_SIM R2021b utf8
# license: Copyright Cyberbotics Ltd. Licensed for use only with Webots.
# license url: https://cyberbotics.com/webots_assets_license
# A cutomizable openable door.
# template language: javascript

PROTO Door [
  field SFVec3f    translation            0 0 0
  field SFRotation rotation               0 1 0 0
  field SFString   name                   "door"
  field SFVec3f    size                   1 2.4 0.2                 # Defines the width, height and thickness of the door wall frame.
  field SFBool     canBeOpen              TRUE                      # Defines whether the door is connected to the frame throught a hinge-joint.
  field SFFloat    position               0                         # Defines the position (aperture) of the door.
  field SFBool     jointAtLeft            TRUE                      # Defines on which side the door is connected to the frame.
  field SFBool     selfClosing            FALSE                     # Defines whether the door as a spring effect that makes it closing on itself.
  field SFFloat    doorThickness          0.05                      # Defines the thickness of the door.
  field SFFloat    frameHeight            2.0                       # Defines the height of the door frame. It should be must be less than or equal to `size.y`.
  field SFVec3f    frameSize              0.05 0.05 0.05            # Defines the size of the door frame.
  field SFFloat    mainMaterialDensity    200                       # Defines the density of the door.
  field SFNode     doorAppearance         GenericDoorAppearance {}  # Defines the door's appearance.
  field SFNode     wallAppearance         Roughcast {}              # Defines the wall's appearance.
  field SFNode     frameAppearance        VarnishedPine {}          # Defines the frame's appearance.
  field SFNode     doorHandle             DoorLever {}              # Defines an optional door handle.
  field MFNode     doorSlot               []                        # Extends the door with new nodes.
  field SFBool     castShadows            TRUE                      # Defines whether this object should cast shadows.
]
{
  %<
    let size = fields.size.value;
    if (size.x <= 0 || size.y <= 0 || size.z <= 0) {
      size = fields.size.defaultValue;
      console.error('\'size\' must be strictly positive. Value reset to (' + size.x + ', ' + size.y + ', ' + size.z + ').');
    }

    let doorThickness = fields.doorThickness.value;
    if (doorThickness <= 0.0) {
      doorThickness = fields.doorThickness.defaultValue;
      console.error('\'doorThickness\' must be strictly positive. Value reset to ' + doorThickness + '.');
    }

    let frameHeight = fields.frameHeight.value;
    if (frameHeight <= 0.0) {
      frameHeight = fields.frameHeight.defaultValue;
      console.error('\'frameHeight\' must be strictly positive. Value reset to ' + frameHeight + '.');
    } else if (frameHeight > size.y) {
      frameHeight = size.y;
      console.error('\'frameHeight\' must be less than or equal to \'size.y\'. Value reset to ' + frameHeight + '.');
    }

    let frameSize = fields.frameSize.value;
    if (frameSize.x <= 0 || frameSize.y <= 0 || frameSize.z <= 0) {
      frameSize = fields.frameSize.defaultValue;
      console.error('\'frameSize\' must be strictly positive. Value reset to (' + frameSize.x + ', ' + frameSize.y + ', ' + frameSize.z + ').');
    }

    let handle = fields.doorHandle.value;
    if (handle !== undefined) {
      if (handle.fields.jointAtLeft !== undefined && fields.jointAtLeft.value !== handle.fields.jointAtLeft.value)
        console.error('\'jointAtLeft\' field value of Door and doorHandle nodes does not match.');

      if (handle.fields.hasStaticParent !== undefined && handle.fields.hasStaticParent.value === fields.canBeOpen.value)
        console.error('\'doorHandle.hasStaticParent\' value is incorrect, the parent Door object is static.');
    }

    let mirrorFactor = fields.jointAtLeft.value ? -1 : 1;
  >%
  Solid {
    translation IS translation
    rotation IS rotation
    children [
      %<
       const topWallHeight = size.y - frameHeight;
       if (topWallHeight > 0) {
      >%
        Solid {
          translation 0 %<= size.y - 0.5 * topWallHeight >% 0
          children [
            Shape {
              appearance IS wallAppearance
              geometry Box {
                size %<= size.x >% %<= topWallHeight >% %<= size.z >%
              }
              castShadows IS castShadows
            }
          ]
          name "mobile part"
          boundingObject Box {
            size %<= size.x >% %<= topWallHeight >% %<= size.z >%
          }
        }
      %< } >%
      SolidBox { # top frame
        translation 0 %<= frameHeight - 0.5 * frameSize.y >% 0
        name "top frame"
        size %<= size.x - 2 * frameSize.x >% %<= frameSize.y >% %<= 2 * frameSize.z + size.z >%
        appearance IS frameAppearance
        castShadows IS castShadows
      }
      SolidBox { # left frame
        translation %<= -0.5 * size.x + 0.5 * frameSize.x >% %<= 0.5 * frameHeight >% 0
        name "left frame"
        size %<= frameSize.x >% %<= frameHeight >% %<= 2 * frameSize.z + size.z >%
        appearance IS frameAppearance
        castShadows IS castShadows
      }
      SolidBox { # right frame
        translation %<= 0.5 * size.x - 0.5 * frameSize.x >% %<= 0.5 * frameHeight >% 0
        name "right frame"
        size %<= frameSize.x >% %<= frameHeight >% %<= 2 * frameSize.z + size.z >%
        appearance IS frameAppearance
        castShadows IS castShadows
      }
      %< if (fields.canBeOpen.value) { >%
        HingeJoint {
          jointParameters HingeJointParameters {
            position IS position
            anchor %<= mirrorFactor * (0.5 * size.x - 0.5 * frameSize.x) >% %<= 0.5 * frameHeight >% %<= 0.5 * size.z + frameSize.z >%
            axis 0 1 0
            %< if (mirrorFactor > 0) { >%
              minStop -0.01
              maxStop 1.57
            %< } else { >%
              minStop -1.57
              maxStop 0.01
            %< } >%
            %< if (fields.selfClosing.value) { >%
              springConstant 5
            %< } >%
            dampingConstant 10
          }
          endPoint
      %< } >%
          Solid {
            translation 0 0 0.001 # small offset to not generates collisions
            children [
              Transform { # door
                translation 0 %<= 0.5 * frameHeight >% %<= 0.5 * size.z + frameSize.z + 0.5 * doorThickness >%
                rotation 0 1 0 -1.5708
                children [
                  Shape {
                    appearance IS doorAppearance
                    geometry TexturedBox { # texture is mirrored on the back face of the door
                      size %<= doorThickness >% %<= frameHeight - 0.5 * frameSize.y >% %<= size.x - frameSize.x >%
                    }
                    castShadows IS castShadows
                  }
                ]
              }
              Transform { # handle
                translation %<= - mirrorFactor * 0.4 * size.x >% %<= 0.5 * frameHeight >% %<= 0.5 * size.z + frameSize.z + 0.5 * doorThickness >%
                children [
                  Slot {
                    type "door handle"
                    endPoint IS doorHandle
                  }
                ]
              }
              Transform {
                translation 0 %<= 0.5 * frameHeight >% %<= 0.5 * size.z + frameSize.z + 0.5 * doorThickness >%
                children IS doorSlot
              }
            ]
            boundingObject Transform {
              translation 0 %<= 0.5 * frameHeight >% %<= 0.5 * size.z + frameSize.z + 0.5 * doorThickness >%
              children [
                Box {
                  size %<= size.x - frameSize.x >% %<= frameHeight - 0.5 * frameSize.y >% %<= doorThickness >%
                }
              ]
            }
            %< if (fields.canBeOpen.value) { >%
              physics Physics {
                density IS mainMaterialDensity
              }
            %< } >%
          }
      %< if (fields.canBeOpen.value) { >%
        }
      %< } >%
    ]
    name IS name
    model "door"
  }
}
