#VRML_SIM R2023b utf8
# license: Copyright Cyberbotics Ltd. Licensed for use only with Webots.
# license url: https://cyberbotics.com/webots_assets_license
# documentation url: https://webots.cloud/run?url=https://github.com/cyberbotics/webots/blob/released/projects/robots/adept/pioneer2/protos/Pioneer2.proto
# keywords: robot/wheeled
# The Pioneer 2 robot (Adept MobileRobots) is an all-purpose base, used for research and applications involving mapping, teleoperation, localization, monitoring, reconnaissance and other behaviors.

PROTO Pioneer2 [
  field SFVec3f    translation     0 0 0         # Is `Transform.translation`.
  field SFRotation rotation        0 0 1 0       # Is `Transform.rotation`.
  field SFString   name            "Pioneer 2"   # Is `Solid.name`.
  field SFString   controller      "braitenberg" # Is `Robot.controller`.
  field MFString   controllerArgs  []            # Is `Robot.controllerArgs`.
  field SFString   window          "<generic>"   # Is `Robot.window`.
  field SFString   customData      ""            # Is `Robot.customData`.
  field SFBool     supervisor      FALSE         # Is `Robot.supervisor`.
  field SFBool     synchronization TRUE          # Is `Robot.synchronization`.
  field MFNode     extensionSlot   []            # Extends the robot with new nodes in the extension slot.
]
{
  Robot {
    translation IS translation
    rotation IS rotation
    controller IS controller
    controllerArgs IS controllerArgs
    window IS window
    customData IS customData
    supervisor IS supervisor
    synchronization IS synchronization
    name IS name
    children [
      Group {
        children IS extensionSlot
      }
      Shape {
        appearance PBRAppearance {
          baseColor 1 0 0
          metalness 0
          roughness 0.3
        }
        geometry IndexedFaceSet {
          coord Coordinate {
            point [
              -0.215 0.1 0.059 -0.215 -0.1 0.059 -0.185 -0.135 0.059 0.095 -0.135 0.059 0.11 -0.08 0.059 0.11 0.08 0.059 0.095 0.135 0.059 -0.185 0.135 0.059 -0.215 0.1 0.059 -0.215 0.1 0.234 -0.215 -0.1 0.234 -0.185 -0.135 0.234 0.095 -0.135 0.234 0.11 -0.08 0.234 0.11 0.08 0.234 0.095 0.135 0.234 -0.185 0.135 0.234 -0.215 0.1 0.234
            ]
          }
          coordIndex [
            8, 7, 6, 5, 4, 3, 2, 1, 0, -1, 9, 10, 11, 12, 13, 14, 15, 16, 17, -1, 0, 1, 10, 9, -1, 1, 2, 11, 10, -1, 2, 3, 12, 11, -1, 3, 4, 13, 12, -1, 4, 5, 14, 13, -1, 5, 6, 15, 14, -1, 6, 7, 16, 15, -1, 7, 8, 17, 16, -1
          ]
        }
      }
      Shape {
        appearance PBRAppearance {
          baseColor 0.636415 0.655556 0.655556
          metalness 0
          roughness 0.3
        }
        geometry IndexedFaceSet {
          coord Coordinate {
            point [
              0.174 0 0.234 0.166 0.056 0.234 0.145 0.107 0.234 0.112 0.155 0.234 0.064 0.19 0.234 -0.074 0.19 0.234 -0.096 0.16 0.234 -0.151 0.16 0.234 -0.2 0.155 0.234 -0.236 0.107 0.234 -0.256 0.056 0.234 -0.264 0 0.234 -0.256 -0.056 0.234 -0.236 -0.107 0.234 -0.2 -0.155 0.234 -0.151 -0.16 0.234 -0.096 -0.16 0.234 -0.074 -0.19 0.234 0.064 -0.19 0.234 0.112 -0.155 0.234 0.145 -0.107 0.234 0.166 -0.056 0.234 0.174 0 0.234 0.174 0 0.245 0.166 0.056 0.245 0.145 0.107 0.245 0.112 0.155 0.245 0.064 0.19 0.245 -0.074 0.19 0.245 -0.096 0.16 0.245 -0.151 0.16 0.245 -0.2 0.155 0.245 -0.236 0.107 0.245 -0.256 0.056 0.245 -0.264 0 0.245 -0.256 -0.056 0.245 -0.236 -0.107 0.245 -0.2 -0.155 0.245 -0.151 -0.16 0.245 -0.096 -0.16 0.245 -0.074 -0.19 0.245 0.064 -0.19 0.245 0.112 -0.155 0.245 0.145 -0.107 0.245 0.166 -0.056 0.245 0.174 0 0.245
            ]
          }
          coordIndex [
            22, 21, 20, 19, 18, 17, 16, 15, 14, 13, 12, 11, 10, 9, 8, 7, 6, 5, 4, 3, 2, 1, 0, -1, 23, 24, 25, 26, 27, 28, 29, 30, 31, 32, 33, 34, 35, 36, 37, 38, 39, 40, 41, 42, 43, 44, 45, -1, 0, 1, 24, 23, -1, 1, 2, 25, 24, -1, 2, 3, 26, 25, -1, 3, 4, 27, 26, -1, 4, 5, 28, 27, -1, 5, 6, 29, 28, -1, 6, 7, 30, 29, -1, 7, 8, 31, 30, -1, 8, 9, 32, 31, -1, 9, 10, 33, 32, -1, 10, 11, 34, 33, -1, 11, 12, 35, 34, -1, 12, 13, 36, 35, -1, 13, 14, 37, 36, -1, 14, 15, 38, 37, -1, 15, 16, 39, 38, -1, 16, 17, 40, 39, -1, 17, 18, 41, 40, -1, 18, 19, 42, 41, -1, 19, 20, 43, 42, -1, 20, 21, 44, 43, -1, 21, 22, 45, 44, -1
          ]
        }
      }
      HingeJoint {
        jointParameters HingeJointParameters {
          axis 0 1 0
          anchor 0 0 0.0825
        }
        device [
          RotationalMotor {
            name "left wheel motor"
          }
          PositionSensor {
            name "left wheel sensor"
          }
        ]
        endPoint Solid {
          translation 0 0.1603 0.0825
          rotation -0.252684 0.252684 0.933971 -1.639053
          children [
            DEF WHEEL Pose {
              rotation 0.577657 0.577197 -0.577197 -2.093935
              children [
                Shape {
                  appearance PBRAppearance {
                    baseColor 0.0037037 0.0037037 0.0037037
                    metalness 0
                    roughness 0.3
                  }
                  geometry Cylinder {
                    height 0.037
                    radius 0.0825
                  }
                }
              ]
            }
          ]
          name "left wheel"
          boundingObject USE WHEEL
        }
      }
      HingeJoint {
        jointParameters HingeJointParameters {
          axis 0 1 0
          anchor 0 0 0.0825
        }
        device [
          RotationalMotor {
            name "right wheel motor"
          }
          PositionSensor {
            name "right wheel sensor"
          }
        ]
        endPoint Solid {
          translation 0 -0.1603 0.0825
          rotation 0.687968 -0.687968 -0.231086 2.687394
          children [
            USE WHEEL
          ]
          name "right wheel"
          boundingObject USE WHEEL
        }
      }
      Shape {
        appearance PBRAppearance {
          baseColor 1 0 0
          metalness 0
          roughness 0.3
        }
        geometry IndexedFaceSet {
          coord Coordinate {
            point [
              0.046 -0.136 0.184 0.096 -0.136 0.184 0.134 -0.101 0.184 0.159 -0.054 0.184 0.168 0 0.184 0.159 0.054 0.184 0.134 0.101 0.184 0.096 0.136 0.184 0.046 0.136 0.184 0.043 -0.136 0.184 0.046 -0.136 0.234 0.096 -0.136 0.234 0.134 -0.101 0.234 0.159 -0.054 0.234 0.168 0 0.234 0.159 0.054 0.234 0.134 0.101 0.234 0.096 0.136 0.234 0.046 0.136 0.234 0.043 -0.136 0.234
            ]
          }
          coordIndex [
            9, 8, 7, 6, 5, 4, 3, 2, 1, 0, -1, 10, 11, 12, 13, 14, 15, 16, 17, 18, 19, -1, 0, 1, 11, 10, -1, 1, 2, 12, 11, -1, 2, 3, 13, 12, -1, 3, 4, 14, 13, -1, 4, 5, 15, 14, -1, 5, 6, 16, 15, -1, 6, 7, 17, 16, -1, 7, 8, 18, 17, -1, 8, 9, 19, 18, -1, 9, 0, 10, 19, -1
          ]
        }
      }
      Shape {
        appearance PBRAppearance {
          baseColor 1 0 0
          metalness 0
          roughness 0.3
        }
        geometry IndexedFaceSet {
          coord Coordinate {
            point [
              -0.135 0.136 0.184 -0.185 0.136 0.184 -0.223 0.101 0.184 -0.248 0.054 0.184 -0.257 0 0.184 -0.248 -0.054 0.184 -0.223 -0.101 0.184 -0.185 -0.136 0.184 -0.135 -0.136 0.184 -0.135 0.136 0.184 -0.135 0.136 0.234 -0.185 0.136 0.234 -0.223 0.101 0.234 -0.248 0.054 0.234 -0.257 0 0.234 -0.248 -0.054 0.234 -0.223 -0.101 0.234 -0.185 -0.136 0.234 -0.135 -0.136 0.234 -0.135 0.136 0.234
            ]
          }
          coordIndex [
            9, 8, 7, 6, 5, 4, 3, 2, 1, 0, -1, 10, 11, 12, 13, 14, 15, 16, 17, 18, 19, -1, 0, 1, 11, 10, -1, 1, 2, 12, 11, -1, 2, 3, 13, 12, -1, 3, 4, 14, 13, -1, 4, 5, 15, 14, -1, 5, 6, 16, 15, -1, 6, 7, 17, 16, -1, 7, 8, 18, 17, -1, 8, 9, 19, 18, -1
          ]
        }
      }
      Pose {
        translation -0.2147 0 0.0325
        rotation 0.577197 0.577197 0.577657 -2.093935
        children [
          Shape {
            appearance PBRAppearance {
              baseColor 0.0037037 0.0037037 0.0037037
              metalness 0
              roughness 0.3
            }
            geometry Cylinder {
              height 0.024
              radius 0.0325
            }
          }
        ]
      }
      DistanceSensor {
        translation 0.164 0.027 0.209
        rotation 0 0 1 0.174203
        children [
          DEF SONAR Pose {
            rotation 0.577657 0.577197 -0.577197 -2.093935
            children [
              Shape {
                appearance PBRAppearance {
                  baseColor 1 1 0.0517103
                  metalness 0
                  roughness 0.3
                }
                geometry Cylinder {
                  height 0.002
                  radius 0.0175
                }
              }
            ]
          }
        ]
        name "ds0"
        lookupTable [
          0 1024 0 0.2 1024 0.1 0.4 0 0.1
        ]
        type "infra-red"
      }
      DistanceSensor {
        translation 0.147 0.077 0.209
        rotation 0.935206 0.25039 0.25039 1.637735
        children [
          USE SONAR
        ]
        name "ds1"
        lookupTable [
          0 1024 0 0.2 1024 0.1 0.4 0 0.1
        ]
        type "infra-red"
      }
      DistanceSensor {
        translation 0.116 0.118 0.209
        rotation 0.834969 0.389118 0.389118 1.750187
        children [
          USE SONAR
        ]
        name "ds2"
        lookupTable [
          0 1024 0 0.2 1024 0.1 0.4 0 0.1
        ]
        type "infra-red"
      }
      DistanceSensor {
        translation 0.071 0.136 0.209
        rotation 0.577963 0.577044 0.577044 2.093476
        children [
          USE SONAR
        ]
        name "ds3"
        lookupTable [
          0 1024 0 0.2 1024 0.1 0.4 0 0.1
        ]
        type "infra-red"
      }
      DistanceSensor {
        translation -0.16 0.136 0.209
        rotation -0.576737 -0.577657 -0.577657 -2.095315
        children [
          USE SONAR
        ]
        name "ds4"
        lookupTable [
          0 1024 0 0.2 1024 0.1 0.4 0 0.1
        ]
        type "infra-red"
      }
      DistanceSensor {
        translation -0.205 0.118 0.209
        rotation -0.312976 -0.671583 -0.671583 -2.534956
        children [
          USE SONAR
        ]
        name "ds5"
        lookupTable [
          0 1024 0 0.2 1024 0.1 0.4 0 0.1
        ]
        type "infra-red"
      }
      DistanceSensor {
        translation -0.236 0.077 0.209
        rotation -0.186015 -0.694766 -0.694766 -2.773767
        children [
          USE SONAR
        ]
        name "ds6"
        lookupTable [
          0 1024 0 0.2 1024 0.1 0.4 0 0.1
        ]
        type "infra-red"
      }
      DistanceSensor {
        translation -0.253 0.027 0.209
        rotation -0.061629 -0.705763 -0.705763 -3.01849
        children [
          USE SONAR
        ]
        name "ds7"
        lookupTable [
          0 1024 0 0.2 1024 0.1 0.4 0 0.1
        ]
        type "infra-red"
      }
      DistanceSensor {
        translation -0.253 -0.027 0.209
        rotation -0.061839 0.705753 0.705753 -3.018072
        children [
          USE SONAR
        ]
        name "ds8"
        lookupTable [
          0 1024 0 0.2 1024 0.1 0.4 0 0.1
        ]
        type "infra-red"
      }
      DistanceSensor {
        translation -0.236 -0.077 0.209
        rotation -0.186228 0.694737 0.694737 -2.773355
        children [
          USE SONAR
        ]
        name "ds9"
        lookupTable [
          0 1024 0 0.2 1024 0.1 0.4 0 0.1
        ]
        type "infra-red"
      }
      DistanceSensor {
        translation -0.205 -0.118 0.209
        rotation -0.313194 0.671532 0.671532 -2.534558
        children [
          USE SONAR
        ]
        name "ds10"
        lookupTable [
          0 1024 0 0.2 1024 0.1 0.4 0 0.1
        ]
        type "infra-red"
      }
      DistanceSensor {
        translation -0.16 -0.136 0.209
        rotation 0.57735 -0.57735 -0.57735 2.094395
        children [
          USE SONAR
        ]
        name "ds11"
        lookupTable [
          0 1024 0 0.2 1024 0.1 0.4 0 0.1
        ]
        type "infra-red"
      }
      DistanceSensor {
        translation 0.071 -0.136 0.209
        rotation 0.57735 -0.57735 -0.57735 2.094395
        children [
          USE SONAR
        ]
        name "ds12"
        lookupTable [
          0 1024 0 0.2 1024 0.1 0.4 0 0.1
        ]
        type "infra-red"
      }
      DistanceSensor {
        translation 0.116 -0.118 0.209
        rotation 0.834774 -0.389328 -0.389328 1.750417
        children [
          USE SONAR
        ]
        name "ds13"
        lookupTable [
          0 1024 0 0.2 1024 0.1 0.4 0 0.1
        ]
        type "infra-red"
      }
      DistanceSensor {
        translation 0.147 -0.077 0.209
        rotation 0.935067 -0.250649 -0.250649 1.637883
        children [
          USE SONAR
        ]
        name "ds14"
        lookupTable [
          0 1024 0 0.2 1024 0.1 0.4 0 0.1
        ]
        type "infra-red"
      }
      DistanceSensor {
        translation 0.164 -0.027 0.209
        rotation -0.99241 0.086956 0.086956 -1.578415
        children [
          USE SONAR
        ]
        name "ds15"
        lookupTable [
          0 1024 0 0.2 1024 0.1 0.4 0 0.1
        ]
        type "infra-red"
      }
    ]
    description "designed by Activmedia Robotics"
    boundingObject Pose {
      translation -0.0447 0 0.13
      rotation 0 0 1 -1.570796
      children [
        Cylinder {
          height 0.24
          radius 0.219
        }
      ]
    }
  }
}
