#VRML_SIM R2023b utf8
# license: Copyright Cyberbotics Ltd. Licensed for use only with Webots.
# license url: https://cyberbotics.com/webots_assets_license
# documentation url: https://webots.cloud/run?url=https://github.com/cyberbotics/webots/blob/released/projects/devices/generic/protos/Servo.proto
# keywords: actuator/motor
# A Servo represents a servomotor which adds one active degree of freedom (DOF) in a mechanical simulation.
# The Servo 'children' move with respect to the Servo parent.
# A Servo can be used to simulate a rotational or a linear motion.
# Spring and damping behavior can be specified.
# For loading performance reasons, it is suggested to use the joint and motor nodes directly instead of this node.
# tags: no3dView
# template language: javascript

PROTO Servo [
  field     SFVec3f    translation         0 0 0
  field     SFRotation rotation            0 0 1 0
  field     MFNode     children            []
  field     SFString   name                "servo"         # Defines the name of the motor, the position sensor is called: name + ' sensor'.
  field     SFString   model               ""
  field     SFString   description         ""
  field     SFString   contactMaterial     "default"
  field     MFNode     immersionProperties []
  field     SFNode     boundingObject      NULL
  field     SFNode     physics             NULL
  field     SFBool     locked              FALSE
  field     SFFloat    translationStep     0.01
  field     SFFloat    rotationStep        0.261799387
  field     SFFloat    radarCrossSection   0
  field     MFColor    recognitionColors   []
  field     SFString   type                "rotational"    # Defines the type of joint: "rotational" or "linear".
  field     SFFloat    maxVelocity         10              # Defines the max velocity (rad/s or m/s) of the motor.
  field     SFFloat    maxForce            10              # Defines the max force or torque (rad/s^2 or m/s^2) of the motor.
  field     SFFloat    controlP            10              # Defines the proportional PID parameter for control of the motor.
  field     SFFloat    acceleration        -1              # Defines the acceleration for control (rad/s^2 or m/s^2) of the motor.
  field     SFFloat    position            0               # Defines the current position of the joint.
  field     SFFloat    minPosition         0               # Defines the max position of the motor, ignored if maxPosition = minPosition.
  field     SFFloat    maxPosition         0               # Defines the min position of the motor, ignored if maxPosition = minPosition.
  field     SFFloat    minStop             0               # Defines the min position of the joint, low stop angle or position.
  field     SFFloat    maxStop             0               # Defines the max position of the joint, high stop angle or position.
  field     SFFloat    springConstant      0               # Defines the spring constant of the joint.
  field     SFFloat    dampingConstant     0               # Defines the damping constant of the joint.
  field     SFFloat    staticFriction      0               # Defines the static friction of the joint.
]
{
  %<
    let jointType = fields.type.value;
    if (jointType !== 'rotational' && jointType !== 'linear') {
      jointType = fields.type.defaultValue;
      console.error('\'type\' should be one of the following: \'rotational\' or \'linear\'. Value reset to ' + jointType + '.');
    }
    const rotation = fields.rotation.value;
  >%
  Solid {
    translation IS translation
    rotation IS rotation
    children [
      %< if (jointType === 'rotational') { >%
      HingeJoint {
        jointParameters HingeJointParameters {
          axis %<= rotation.x >% %<= rotation.y >% %<= rotation.z >%
      %< } else { >%
      SliderJoint {
        jointParameters JointParameters {
      %< } >%
          position IS position
          minStop IS minStop
          maxStop IS maxStop
          springConstant IS springConstant
          dampingConstant IS dampingConstant
          staticFriction IS staticFriction
        }
        device [
          PositionSensor {
            name %<= '"' + fields.name.value + ' sensor"' >%
          }
          %< if (jointType === 'rotational') { >%
          RotationalMotor {
            maxTorque IS maxForce
          %< } else { >%
          LinearMotor {
            maxForce IS maxForce
          %< } >%
            name IS name
            maxVelocity IS maxVelocity
            acceleration IS acceleration
            minPosition IS minPosition
            maxPosition IS maxPosition
            controlPID %<= fields.controlP.value >% 0 0
          }
        ]
        endPoint Solid {
          children IS children
          name IS name
          model IS model
          description IS description
          contactMaterial IS contactMaterial
          immersionProperties IS immersionProperties
          boundingObject IS boundingObject
          physics IS physics
          locked IS locked
          translationStep IS translationStep
          rotationStep IS rotationStep
          radarCrossSection IS radarCrossSection
          recognitionColors IS recognitionColors
        }
      }
    ]
  }
}
