
#VRML_SIM R2022a utf8
# license: Copyright Cyberbotics Ltd. Licensed for use only with Webots.
# license url: https://cyberbotics.com/webots_assets_license
# documentation url: https://www.cyberbotics.com/doc/guide/irb4600-40
# Tracked robot

PROTO TrackedRobot [
  field SFVec3f    translation     0 0 0.25              # Is `Transform.translation`.
  field SFRotation rotation        0 0 1 0               # Is `Transform.rotation`.
  field SFString   name            "TrackedRobot"        # Is `Solid.name`.
  field SFString   controller      ""                    # Is `Robot.controller`.
  field MFString   controllerArgs  []                    # Is `Robot.controllerArgs`.
  field SFString   customData      ""                    # Is `Robot.customData`.
  field SFBool     supervisor      FALSE                 # Is `Robot.supervisor`.
  field SFBool     synchronization TRUE                  # Is `Robot.synchronization`.
]
{
Robot {
  translation IS translation
  rotation IS rotation
  name IS name
  children [
    Transform {
      translation 0.61 0 0.01
      rotation 1 0 0 1.5708
      children [
        DEF GEOM_1 Shape {
          appearance Plastic {
            colorOverride 0.180392 0.203922 0.211765
          }
          geometry Cylinder {
            height 0.52
            radius 0.16
          }
        }
      ]
    }
    Transform {
      translation -0.55 0 0.01
      rotation 1 0 0 1.5708
      children [
        Shape {
          appearance Plastic {
            colorOverride 0.180392 0.203922 0.211765
          }
          geometry Cylinder {
            height 0.52
            radius 0.16
          }
        }
      ]
    }
    Transform {
      translation 0.031 0 0.0067
      rotation 0 1 0 0
      children [
        DEF GEOM Shape {
          appearance Plastic {
            colorOverride 0.180392 0.203922 0.211765
          }
          geometry Box {
            size 1.22 0.52 0.32
          }
        }
      ]
    }
    DEF LEFT_TRACK Track {
      translation 0.042 0.35 -0.0129
      scale 2 2 2
      children [
        DEF WHEEL1 TrackWheel {
          position -0.3 0.015
          radius 0.092
          children [
            DEF TRACK_WHEEL_BIG Transform {
              rotation -1 0 0 3.141589
              children [
                Shape {
                  appearance PBRAppearance {
                    baseColorMap ImageTexture {
                      url [
                        "https://raw.githubusercontent.com/cyberbotics/webots/master/projects/samples/devices/worlds/textures/tank_wheel.jpg"
                      ]
                    }
                    roughness 1
                    metalness 0
                  }
                  geometry Cylinder {
                    height 0.09
                    radius 0.092
                    side FALSE
                    subdivision 20
                  }
                }
                Shape {
                  appearance ThreadMetalPlate {
                    textureTransform TextureTransform {
                      scale 0.2 1
                    }
                  }
                  geometry Cylinder {
                    height 0.0899
                    radius 0.092
                    top FALSE
                    subdivision 20
                  }
                }
              ]
            }
          ]
        }
        DEF WHEEL2 TrackWheel {
          position 0.288 0.015
          radius 0.092
          children [
            USE TRACK_WHEEL_BIG
          ]
        }
        DEF WHEEL3 TrackWheel {
          position 0.185 -0.088
          radius 0.04
          children [
            DEF TRACK_WHEEL_SMALL Transform {
              rotation -1 0 0 3.141589
              children [
                Shape {
                  appearance PBRAppearance {
                    baseColorMap ImageTexture {
                      url [
                        "https://raw.githubusercontent.com/cyberbotics/webots/master/projects/samples/devices/worlds/textures/tank_wheel.jpg"
                      ]
                    }
                    roughness 1
                    metalness 0
                  }
                  geometry Cylinder {
                    height 0.09
                    radius 0.04
                    side FALSE
                    subdivision 20
                  }
                }
                Shape {
                  appearance ThreadMetalPlate {
                    textureTransform TextureTransform {
                      scale 0.2 1
                    }
                  }
                  geometry Cylinder {
                    height 0.0899
                    radius 0.04
                    top FALSE
                    subdivision 20
                  }
                }
              ]
            }
          ]
        }
        DEF WHEEL4 TrackWheel {
          position 0.09135 -0.088
          radius 0.04
          children [
            USE TRACK_WHEEL_SMALL
          ]
        }
        DEF WHEEL5 TrackWheel {
          position -0.00245 -0.088
          radius 0.04
          children [
            USE TRACK_WHEEL_SMALL
          ]
        }
        DEF WHEEL6 TrackWheel {
          position -0.09625 -0.088
          radius 0.04
          children [
            USE TRACK_WHEEL_SMALL
          ]
        }
        DEF WHEEL7 TrackWheel {
          position -0.19 -0.088
          radius 0.04
          children [
            USE TRACK_WHEEL_SMALL
          ]
        }
      ]
      name "left track"
      contactMaterial "track material"
      boundingObject DEF TRACK_BO Group {
        children [
          Transform {
            translation 0 0 -0.009
            rotation 1 0 0 1.570796
            children [
              Box {
                size 0.39 0.248 0.09
              }
            ]
          }
          Transform {
            translation 0.237434 0 -0.06918
            rotation 0.9561247250869316 -0.20715394043734683 0.20715394043734683 1.615648
            children [
              Box {
                size 0.13 0.08 0.09
              }
            ]
            translationStep 0.001
            rotationStep 0.00261799
          }
          Transform {
            translation -0.242803 0 -0.070833
            rotation 0.959691189146035 0.19873703916918628 -0.19873703916918628 1.611928
            children [
              Box {
                size 0.13 0.08 0.09
              }
            ]
            translationStep 0.001
            rotationStep 0.00261799
          }
          Transform {
            translation -0.302 0 0.017
            rotation 1 0 0 1.5708
            children [
              DEF WHEEL_BO Cylinder {
                height 0.09
                radius 0.1
                subdivision 16
              }
            ]
          }
          Transform {
            translation 0.288 0 0.017
            rotation 1 0 0 1.5708
            children [
              USE WHEEL_BO
            ]
          }
        ]
      }
      physics Physics {
      }
      device [
        LinearMotor {
          name "left motor"
        }
      ]
      animatedGeometry DEF ANIMATED_GEOM Group {
        children [
          Shape {
            appearance PBRAppearance {
              baseColor 0.141176 0.141176 0.141176
              roughness 1
              metalness 0
            }
            geometry Box {
              size 0.044 0.09 0.005
            }
          }
          Transform {
            translation 0 0 0.003
            children [
              Shape {
                appearance PBRAppearance {
                  baseColor 0.141176 0.141176 0.141176
                  roughness 1
                  metalness 0
                }
                geometry Box {
                  size 0.02 0.09 0.011
                }
              }
            ]
          }
        ]
      }
      geometriesCount 40
    }
    Track {
      translation 0.042 -0.35 -0.0129
      scale 2 2 2
      children [
        USE WHEEL1
        USE WHEEL2
        USE WHEEL3
        USE WHEEL4
        USE WHEEL5
        USE WHEEL6
        USE WHEEL7
      ]
      name "right track"
      contactMaterial "track material"
      boundingObject USE TRACK_BO
      physics Physics {
      }
      device [
        LinearMotor {
          name "right motor"
        }
      ]
      animatedGeometry USE ANIMATED_GEOM
      geometriesCount 40
    }
    DEF CAMERA Transform {
      translation 0.54 0 0.117
      rotation 0 0 1 3.14159
      children [
        DEF CAMERA_TILT HingeJoint {
          jointParameters HingeJointParameters {
            axis 0 0 1
            anchor 0 0 0.065
          }
          device [
            RotationalMotor {
              name "camera_tilt_motor"
              minPosition -3.14159
              maxPosition 3.14159
            }
          ]
          endPoint Solid {
            children [
              DEF LENS Transform {
                translation -0.0255 0 0.2735
                rotation 0 1 0 -1.5707953071795862
                children [
                  Shape {
                    appearance PBRAppearance {
                    }
                    geometry Cylinder {
                      height 0.001
                      radius 0.0023
                    }
                  }
                ]
              }
              DEF SHAFT Transform {
                children [
                  Shape {
                    appearance Plastic {
                      colorOverride 0.180392 0.203922 0.211765
                    }
                    geometry Mesh {
                      url [
                        "webots://projects/robots/generic/trackedRobot/protos/meshes/shaft.obj"
                      ]
                    }
                  }
                ]
              }
              DEF CAMERA_PAN HingeJoint {
                jointParameters HingeJointParameters {
                  axis 0 1 0
                  anchor 0 0 0.273
                }
                device [
                  RotationalMotor {
                    name "camera_pan_motor"
                    minPosition -1.35
                    maxPosition 1.35
                  }
                ]
                endPoint Solid {
                  children [
                    Shape {
                      appearance Plastic {
                        colorOverride 0.180392 0.203922 0.211765
                      }
                      geometry Mesh {
                        url [
                          "webots://projects/robots/generic/trackedRobot/protos/meshes/camera.obj"
                        ]
                      }
                    }
                    Camera {
                      translation -0.02 0 0.273
                      rotation 0 0 1 3.14156
                    }
                  ]
                }
              }
            ]
          }
        }
      ]
    }
    DEF ANTENNA_1 Transform {
      translation -0.773 -0.137 0.023
      rotation 0.11611260301955266 0.17784936149720515 -0.9771834362263105 1.58783
      children [
        Shape {
          appearance Plastic {
            colorOverride 0.180392 0.203922 0.211765
          }
          geometry Mesh {
            url [
              "webots://projects/robots/generic/trackedRobot/protos/meshes/antenna.obj"
            ]
          }
        }
      ]
    }
    DEF ANTENNA_2 Transform {
      translation -0.773 0.137 0.023
      rotation -0.14253600610763875 -0.08370290358665233 -0.9862440422603559 1.56261
      children [
        Shape {
          appearance Plastic {
            colorOverride 0.180392 0.203922 0.211765
          }
          geometry Mesh {
            url [
              "webots://projects/robots/generic/trackedRobot/protos/meshes/antenna.obj"
            ]
          }
        }
      ]
    }
  ]
  name "TrackedRobot"
  boundingObject Group {
    children [
      USE GEOM
      Transform {
        translation 0.611 0 0.01
        rotation 1 0 0 1.5708
        children [
          USE GEOM_1
        ]
      }
      Transform {
        translation -0.55 0 0.01
        rotation 1 0 0 1.5708
        children [
          USE GEOM_1
        ]
      }
    ]
  }
  physics Physics {
    density -1
    mass 40
  }
  controller IS controller
  controllerArgs IS controllerArgs
  customData IS customData
  supervisor IS supervisor
  synchronization IS synchronization
}
}
