#VRML_SIM R2023b utf8
# license: Copyright Cyberbotics Ltd. Licensed for use only with Webots.
# license url: https://cyberbotics.com/webots_assets_license
# documentation url: https://webots.cloud/run?url=https://github.com/cyberbotics/webots/blob/released/projects/objects/computers/protos/Laptop.proto
# keywords: household/electronics
# A simple laptop.

PROTO Laptop [
  field SFVec3f    translation 0 0 0
  field SFRotation rotation    0 0 1 0
  field SFString   name        "laptop"
  field SFString   controller  "laptop_switch_on"  # Defines the controller of the laptop which can use the Display device to show images.
  field SFString   window      "<none>"            # Is `Robot.window`.
  field SFBool     supervisor  FALSE               # Is `Robot.supervisor`.
]
{
  Robot {
    translation IS translation
    rotation IS rotation
    controller IS controller
    window IS window
    supervisor IS supervisor
    children [
      HingeJoint {
        jointParameters HingeJointParameters {
          anchor -0.0546 0.0 0.0142
          axis 0 -1 0
          minStop -2.105
          maxStop 0.01
          staticFriction 0.8
        }
        device PositionSensor {
        }
        endPoint Solid {
          translation -0.1 -0.014 0.13
          rotation 0.57731 -0.57741 -0.57734 2.09446
          children [
            Shape {
              appearance PBRAppearance {
                baseColorMap ImageTexture {
                  url [
                    "textures/laptop_screen_base_color.jpg"
                  ]
                }
                roughnessMap ImageTexture {
                  url [
                    "textures/laptop_screen_roughness.jpg"
                  ]
                }
                normalMap ImageTexture {
                  url [
                    "textures/laptop_screen_normal.jpg"
                  ]
                }
                metalness 0
              }
              geometry IndexedFaceSet {
                coord Coordinate {
                  point [
                    0.15393 -0.121846 -0.030726 0.15393 0.068025 0.081871 -0.192175 0.068025 0.081871 -0.192175 -0.121846 -0.030726 0.160877 -0.121901 -0.042869 0.160877 0.079694 0.07668 -0.199123 0.079694 0.07668 -0.199123 -0.121901 -0.042869 0.098279 -0.122127 -0.049684 0.098279 -0.122126 -0.032252 0.083065 -0.122126 -0.032252 0.083065 -0.122127 -0.049684 0.098279 -0.107256 -0.049684 0.098279 -0.107256 -0.032252 0.083065 -0.107256 -0.032252 0.083065 -0.107256 -0.049684 -0.115506 -0.122127 -0.049684 -0.115506 -0.122126 -0.032252 -0.13072 -0.122126 -0.032252 -0.13072 -0.122127 -0.049684 -0.115506 -0.107256 -0.049684 -0.115506 -0.107256 -0.032252 -0.13072 -0.107256 -0.032252 -0.13072 -0.107256 -0.049684
                  ]
                }
                texCoord TextureCoordinate {
                  point [
                    0.936 0.5783 0.919 0.5783 0.9356 0.5696 0.9237 0.5632 0.9313 0.5632 0.9238 0.5658 0.9126 0.5577 0.9174 0.5577 0.9128 0.5601 0.9303 0.5437 0.9197 0.5437 0.9301 0.5401 0.919 0.5965 0.919 0.5881 0.9321 0.5965 0.9795 0.3669 0.9795 0.9912 0.0205 0.9912 0.0075 0.435 0.0075 0.435 0.008 0.436 0.0075 0.435 0.0075 0.435 0.008 0.436 0.0075 0.435 0.0075 0.435 0.008 0.436 0.0075 0.435 0.0075 0.435 0.008 0.436 0.0075 0.435 0.0075 0.435 0.008 0.436 0.0075 0.435 0.0075 0.435 0.008 0.436 0.0075 0.435 0.0075 0.435 0.008 0.436 0.0075 0.435 0.0075 0.435 0.008 0.436 0.0075 0.435 0.0075 0.435 0.008 0.436 0.0075 0.435 0.0075 0.435 0.008 0.436 0.0075 0.435 0.0075 0.435 0.008 0.436 0.0075 0.435 0.0075 0.435 0.008 0.436 0.919 0.5783 0.9195 0.5696 0.9356 0.5696 0.9313 0.5632 0.9312 0.5658 0.9238 0.5658 0.9174 0.5577 0.9172 0.5601 0.9128 0.5601 0.9197 0.5437 0.9199 0.5401 0.9301 0.5401 0.919 0.5881 0.9321 0.5881 0.9321 0.5965 0.0205 0.3669 0.9795 0.3669 0.0205 0.9912 0.0075 0.435 0.0075 0.435 0.008 0.436 0.0075 0.435 0.0075 0.435 0.008 0.436 0.0075 0.435 0.0075 0.435 0.008 0.436 0.0075 0.435 0.0075 0.435 0.008 0.436 0.0075 0.435 0.0075 0.435 0.008 0.436 0.0075 0.435 0.0075 0.435 0.008 0.436 0.0075 0.435 0.0075 0.435 0.008 0.436 0.0075 0.435 0.0075 0.435 0.008 0.436 0.0075 0.435 0.0075 0.435 0.008 0.436 0.0075 0.435 0.0075 0.435 0.008 0.436 0.0075 0.435 0.0075 0.435 0.008 0.436 0.0075 0.435 0.0075 0.435 0.008 0.436
                  ]
                }
                coordIndex [
                  4 5 0 -1 5 6 1 -1 6 7 2 -1 7 4 3 -1 0 1 3 -1 7 6 5 -1 12 13 9 -1 13 14 9 -1 14 15 11 -1 15 12 11 -1 8 9 11 -1 15 14 12 -1 20 21 16 -1 21 22 17 -1 22 23 19 -1 23 20 16 -1 16 17 19 -1 23 22 21 -1 5 1 0 -1 6 2 1 -1 7 3 2 -1 4 0 3 -1 1 2 3 -1 4 7 5 -1 8 12 9 -1 14 10 9 -1 10 14 11 -1 12 8 11 -1 9 10 11 -1 14 13 12 -1 21 17 16 -1 22 18 17 -1 18 22 19 -1 19 23 16 -1 17 18 19 -1 20 23 21 -1
                ]
                texCoordIndex [
                  0 1 2 -1 3 4 5 -1 6 7 8 -1 9 10 11 -1 12 13 14 -1 15 16 17 -1 18 19 20 -1 21 22 23 -1 24 25 26 -1 27 28 29 -1 30 31 32 -1 33 34 35 -1 36 37 38 -1 39 40 41 -1 42 43 44 -1 45 46 47 -1 48 49 50 -1 51 52 53 -1 54 55 56 -1 57 58 59 -1 60 61 62 -1 63 64 65 -1 66 67 68 -1 69 70 71 -1 72 73 74 -1 75 76 77 -1 78 79 80 -1 81 82 83 -1 84 85 86 -1 87 88 89 -1 90 91 92 -1 93 94 95 -1 96 97 98 -1 99 100 101 -1 102 103 104 -1 105 106 107 -1
                ]
                creaseAngle 2
              }
            }
            Display {
              translation -0.014 -0.127 -0.101
              children [
                Shape {
                  appearance PBRAppearance {
                    metalness 0
                    roughness 0.25
                    baseColorMap ImageTexture {
                    }
                  }
                  geometry IndexedFaceSet {
                    coord Coordinate {
                      point [
                        0.163694 0.187436 0.165589 -0.17284 0.026052 0.070159 -0.172755 0.186595 0.165139 0.166293 0.027674 0.071251
                      ]
                    }
                    texCoord TextureCoordinate {
                      point [
                        0 1 1 0 1 1 0 0
                      ]
                    }
                    coordIndex [
                      2 0 1 -1 0 3 1 -1
                    ]
                  }
                }
              ]
              width 620
              height 400
            }
          ]
          boundingObject Pose {
            translation -0.02 -0.023 0.022
            rotation 1 0 0 0.532
            children [
              Box {
                size 0.359 0.232 0.011
              }
            ]
          }
          physics Physics {
            density -1
            mass 0.5
          }
        }
      }
      Shape {
        appearance PBRAppearance {
          baseColorMap ImageTexture {
            url [
              "textures/laptop_keyboard_base_color.jpg"
            ]
          }
          normalMap ImageTexture {
            url [
              "textures/laptop_keyboard_normal.jpg"
            ]
          }
          occlusionMap ImageTexture {
            url [
              "textures/laptop_keyboard_occlusion.jpg"
            ]
          }
          metalness 0
          roughness 0.7
        }
        geometry IndexedFaceSet {
          coord Coordinate {
            point [
              0.1594853 -0.1540157 0 -0.0422127 -0.1540161 0 -0.0422133 0.1622219 0 0.1594847 0.1622223 0 0.1758252 -0.1758966 0.0197972 -0.0585528 -0.175897 0.0197964 -0.0585534 0.184103 0.0197952 0.1758246 0.1841034 0.019796
            ]
          }
          texCoord TextureCoordinate {
            point [
              0.2672 0.5894 0.0609 0.5894 0.2528 0.3878 0.0317 0.3946 0.2808 0.3946 0.0468 0.5528 0.2623 0.5999 0.0384 0.5999 0.0541 0.3811 0.2622 0.5458 0.0659 0.5458 0.2503 0.4212 0.0151 0.5659 0.0151 0.3884 0.2935 0.5659 0.9927 0.3583 0.9927 0.9998 0.0073 0.3583 0.0609 0.5894 0.0753 0.3878 0.2528 0.3878 0.2808 0.3946 0.2657 0.5528 0.0468 0.5528 0.2467 0.3811 0.2623 0.5999 0.0541 0.3811 0.0659 0.5458 0.0778 0.4212 0.2503 0.4212 0.0151 0.3884 0.2935 0.3884 0.2935 0.5659 0.9927 0.9998 0.0073 0.9998 0.0073 0.3583
            ]
          }
          coordIndex [
            4 5 0 -1 5 6 1 -1 6 7 3 -1 7 4 3 -1 0 1 3 -1 7 6 4 -1 5 1 0 -1 6 2 1 -1 2 6 3 -1 4 0 3 -1 1 2 3 -1 6 5 4 -1
          ]
          texCoordIndex [
            0 1 2 -1 3 4 5 -1 6 7 8 -1 9 10 11 -1 12 13 14 -1 15 16 17 -1 18 19 20 -1 21 22 23 -1 24 25 26 -1 27 28 29 -1 30 31 32 -1 33 34 35 -1
          ]
          creaseAngle 2
        }
      }
    ]
    name IS name
    model "laptop"
    boundingObject Pose {
      rotation 0.57731 -0.57741 -0.57734 2.09446
      translation 0.058 0 0.01
      children [
        Box {
          size 0.36 0.02 0.233
        }
      ]
    }
    physics Physics {
      density 1200
    }
  }
}
