#VRML_SIM R2023b utf8
# license: Apache License 2.0.
# license url: https://www.apache.org/licenses/LICENSE-2.0
# documentation url: https://webots.cloud/run?url=https://github.com/cyberbotics/webots/blob/released/projects/robots/pal_robotics/tiago_base/protos/TiagoBase.proto
# keywords: robot/wheeled
# This is a PROTO file for Webots for the robot TIAGo from PAL Robotics (Spain).
# It is the TIAGo base robot that can be extended with different features to fullfil your requirement.

EXTERNPROTO "webots://projects/appearances/protos/GlossyPaint.proto"
EXTERNPROTO "webots://projects/appearances/protos/MattePaint.proto"
EXTERNPROTO "webots://projects/appearances/protos/Asphalt.proto"
EXTERNPROTO "webots://projects/appearances/protos/BrushedAluminium.proto"

PROTO TiagoBase [
  field  SFVec3f     translation      0 0 0.095
  field  SFRotation  rotation         0 0 1 0
  field  SFString    name             "TIAGo Base"
  field  SFString    controller       "tiago_base"
  field  MFString    controllerArgs   []
  field  SFString    window          "<generic>"
  field  SFString    customData       ""
  field  SFBool      supervisor       FALSE
  field  SFBool      synchronization  TRUE
  field  SFBool      selfCollision    FALSE   # Enables/disables the detection of collisions within the robot.
  field  SFString    model            "PAL Robotics - TIAGo Base"
  field  MFNode      bodySlot         []      # Extends the robot with a body (such as the TiagoBody or fixed shelves, safety box, roller conveyor, boxes, lifter for example).
  field  MFNode      lidarSlot        []      # Extends the robot with a lidar sensor (such as Sick TIM551 or Hokuyo URG 04LX_UG01 for example).
]
{
  Robot {
    translation IS translation
    rotation IS rotation
    controller IS controller
    controllerArgs IS controllerArgs
    window IS window
    customData IS customData
    supervisor IS supervisor
    synchronization IS synchronization
    selfCollision IS selfCollision
    name IS name
    model IS model
    children [
      DEF BODY_EXTENSION Pose {
        children IS bodySlot
      }
      DEF LIDAR Pose {
        translation 0.202 0 -0.004
        children IS lidarSlot
      }
      Accelerometer {
      }
      InertialUnit {
      }
      Gyro {
      }
      Solid {
        name "base_footprint"
        translation 0 0 -0.095
      }
      DEF BASE_MOBILE_SHAPE Group {
        children [
          DEF BASE Shape {
            appearance GlossyPaint {
              baseColor 0.823529 0.776471 0.776471
              textureTransform TextureTransform {
                scale 4 4
              }
              IBLStrength 1.8
            }
            geometry Mesh {
              url "meshes/base.obj"
            }
          }
          DEF ANTENNA_LEFT Pose {
            translation -0.201 0.1062 0.195
            children [
              DEF ANTENNA_SHAPE Shape {
                appearance MattePaint {
                  baseColor 0.133333 0.133333 0.133333
                }
                geometry Mesh {
                  url "meshes/antenna_shape.obj"
                }
              }
            ]
          }
          DEF ANTENNA_RIGHT Pose {
            translation -0.201 -0.1062 0.195
            children [
              USE ANTENNA_SHAPE
            ]
          }
        ]
      }
      DEF FRONT_SENSOR_1 Pose {
        translation 0.1714 -0.1110 0.002
        rotation 0.47980308243485 -0.620398662991083 0.620398662994121 -2.246872814929654
        children [
          Shape {
            appearance PBRAppearance {
              baseColor 0 0 0
            }
            geometry Cylinder {
              height 0.01
              radius 0.01
            }
          }
        ]
        translationStep 0.001
        rotationStep 0.001
      }
      DEF FRONT_SENSOR_2 Pose {
        translation 0.1714 0.111 0.002
        rotation 0.47980308243485 0.620398662991083 0.620398662994121 2.246872814929654
        children [
          Shape {
            appearance PBRAppearance {
              baseColor 0 0 0
            }
            geometry Cylinder {
              height 0.01
              radius 0.01
            }
          }
        ]
        rotationStep 0.001
      }
      DEF BUMPER TouchSensor {
        translation 0 0 0.03
        children [
          DEF BUMPER_SHAPE Shape {
            appearance PBRAppearance {
              baseColor 1 0.552941 0.184314
              transparency 0.01
              roughness 0.1
              metalness 0
            }
            geometry Mesh {
              url "meshes/bumper_shape.obj"
            }
          }
        ]
        name "base_cover_link"
        boundingObject Pose {
          translation 0 0 0.043
          children [
            Cylinder {
              height 0.086
              radius 0.272
            }
          ]
        }
        physics Physics {
          density -1
          mass 0.25821
        }
      }
      DEF DISTANCE_SENSOR_BACK_LEFT DistanceSensor {
        translation -0.183 0.183 0.173
        rotation 0 0 1 2.3562
        children [
          DEF DS_SHAPE Group {
            children [
              DEF DS_SH_1 Pose {
                translation 0 -0.0115 0
                rotation 0 0 1 -1.5707896938995747
                children [
                  Shape {
                    appearance MattePaint {
                      baseColor 0 0 0
                    }
                  }
                ]
              }
              DEF DS_SH_2 Pose {
                translation 0 0.0115 0
                rotation 0 0 1 -1.5707896938995747
                children [
                  Shape {
                    appearance MattePaint {
                      baseColor 0 0 0
                    }
                  }
                ]
              }
            ]
          }
        ]
        name "base_sonar_03_link"
      }
      DEF DISTANCE_SENSOR_BACK_MIDDLE DistanceSensor {
        translation -0.259 0 0.173
        rotation 0 0 1 3.1416
        children [
          USE DS_SHAPE
        ]
        name "base_sonar_02_link"
      }
      DEF DISTANCE_SENSOR_BACK_RIGHT DistanceSensor {
        translation -0.183 -0.183 0.173
        rotation 0 0 1 3.927
        children [
          USE DS_SHAPE
        ]
        name "base_sonar_01_link"
      }
      DEF RIGHT_WHEEL_JOINT HingeJoint {
        jointParameters HingeJointParameters {
          axis 0 1 0
          anchor 0 -0.2022 0
          suspensionSpringConstant 0
          suspensionDampingConstant 0
          suspensionAxis 0 0 1
        }
        device [
          RotationalMotor {
            name "wheel_right_joint"
            acceleration 5.0762
            maxVelocity 10.1523
            maxTorque 10
          }
          PositionSensor {
            name "wheel_right_joint_sensor"
          }
        ]
        endPoint DEF RIGHT_WHEEL Solid {
          translation 0 -0.202 0
          rotation 1 0 0 1.5708
          children [
            DEF BIG_WHEEL Group {
              children [
                Pose {
                  translation 0 0 0.042
                  children [
                    Shape {
                      appearance PBRAppearance {
                        baseColor 0 0 0
                        roughness 1
                        metalness 0
                      }
                      geometry Cylinder {
                        height 0.005
                        radius 0.016
                      }
                    }
                  ]
                }
                DEF TIRE Shape {
                  appearance Asphalt {
                    textureTransform TextureTransform {
                      scale 25 25
                    }
                    IBLStrength 0.5
                  }
                  geometry Mesh {
                    url "meshes/tire.obj"
                  }
                }
                DEF RIM Shape {
                  appearance PBRAppearance {
                    baseColorMap ImageTexture {
                      url [
                        "textures/metal_stainless_clean_base_color.jpg"
                      ]
                    }
                    roughnessMap ImageTexture {
                      url [
                        "textures/metal_stainless_clean_roughness.jpg"
                      ]
                    }
                    metalness 0.9
                    textureTransform TextureTransform {
                      scale 10 10
                    }
                  }
                  geometry Mesh {
                    url "meshes/rim.obj"
                  }
                }
              ]
            }
          ]
          name "wheel_right_link"
          boundingObject Pose {
            children [
              Cylinder {
                height 0.04
                radius 0.0985
              }
            ]
          }
          physics Physics {
            density -1
            mass 1.82362
          }
        }
      }
      DEF LEFT_WHEEL_JOINT HingeJoint {
        jointParameters HingeJointParameters {
          axis 0 1 0
          anchor 0 0.2022 0
          suspensionSpringConstant 0
          suspensionDampingConstant 0
          suspensionAxis 0 0 1
        }
        device [
          RotationalMotor {
            name "wheel_left_joint"
            acceleration 5.0762
            maxVelocity 10.1523
            maxTorque 10
          }
          PositionSensor {
            name "wheel_left_joint_sensor"
          }
        ]
        endPoint DEF LEFT_WHEEL Solid {
          translation 0 0.202 0
          rotation 1 0 0 1.5708
          children [
            Pose {
              rotation -1 0 0 3.141593
              children [
                DEF BIG_WHEEL Group {
                  children [
                    Pose {
                      translation 0 0 0.042
                      children [
                        Shape {
                          appearance PBRAppearance {
                            baseColor 0 0 0
                            roughness 1
                            metalness 0
                          }
                          geometry Cylinder {
                            height 0.005
                            radius 0.016
                          }
                        }
                      ]
                    }
                    DEF TIRE Shape {
                      appearance Asphalt {
                        textureTransform TextureTransform {
                          scale 25 25
                        }
                        IBLStrength 0.5
                      }
                      geometry Mesh {
                        url "meshes/tire.obj"
                      }
                    }
                    DEF RIM Shape {
                      appearance PBRAppearance {
                        baseColorMap ImageTexture {
                          url [
                            "textures/metal_stainless_clean_base_color.jpg"
                          ]
                        }
                        roughnessMap ImageTexture {
                          url [
                            "textures/metal_stainless_clean_roughness.jpg"
                          ]
                        }
                        metalness 0.9
                        textureTransform TextureTransform {
                          scale 10 10
                        }
                      }
                      geometry Mesh {
                        url "meshes/rim.obj"
                      }
                    }
                  ]
                }
              ]
            }
          ]
          name "wheel_left_link"
          boundingObject Pose {
            children [
              Cylinder {
                height 0.04
                radius 0.0985
              }
            ]
          }
          physics Physics {
            density -1
            mass 1.82362
          }
        }
      }
      DEF CASTER_WHEEL_FRONT_RIGHT_JOINT HingeJoint {
        jointParameters HingeJointParameters {
          axis 0 0 1
          anchor 0.1695 -0.102 -0.0335
          dampingConstant 0
          suspensionSpringConstant 250000
          suspensionDampingConstant 0
          suspensionAxis 0 0 1
        }
        device [
        ]
        endPoint DEF CASTER_WHEEL_FRONT_RIGHT Solid {
          translation 0.1695 -0.102 -0.0335
          rotation 0 0 1 0
          children [
            DEF SMALL_WHEEL_JOINT HingeJoint {
              jointParameters HingeJointParameters {
                axis 0 1 0
                anchor -0.016 0 -0.04
              }
              device [
              ]
              endPoint DEF SMALL_WHEEL Solid {
                translation -0.016 0 -0.04
                rotation -1 0 0 1.5708
                children [
                  DEF SMALL_WHEEL_SHAPE Shape {
                    appearance Asphalt {
                      textureTransform TextureTransform {
                        scale 25 25
                      }
                      IBLStrength 0.5
                    }
                    geometry Mesh {
                      url "meshes/small_wheel_shape.obj"
                    }
                  }
                ]
                name "caster_front_right_2_link"
                boundingObject DEF SMALL_WHEEL_BO Pose {
                  children [
                    Cylinder {
                      height 0.015
                      radius 0.025
                    }
                  ]
                }
                physics DEF SMALL_WHEEL_PHYSIC Physics {
                  density -1
                  mass 0.088558
                }
              }
            }
            DEF CASTER_SUPPORT Shape {
              appearance BrushedAluminium {
                textureTransform TextureTransform {
                  rotation -1.57
                  scale 2 2
                }
              }
              geometry Mesh {
                url "meshes/caster_support.obj"
              }
            }
          ]
          name "caster_front_right_1_link"
          boundingObject DEF CASTER_WHEEL_BO Pose {
            translation -0.003 0 -0.022
            children [
              DEF CASTER_SUPPORT_BO Box {
                size 0.036 0.032 0.04
              }
            ]
          }
          physics DEF CASTER_WHEEL_PHYSIC Physics {
            density -1
            mass 0.051448
          }
        }
      }
      DEF CASTER_WHEEL_FRONT_LEFT_JOINT HingeJoint {
        jointParameters HingeJointParameters {
          axis 0 0 1
          anchor 0.1695 0.102 -0.0335
          dampingConstant 0
          suspensionSpringConstant 250000
          suspensionDampingConstant 0
          suspensionAxis 0 0 1
        }
        device [
        ]
        endPoint DEF CASTER_WHEEL_FRONT_LEFT Solid {
          translation 0.1695 0.102 -0.0335
          rotation 0 0 1 0
          children [
            DEF SMALL_WHEEL_JOINT HingeJoint {
              jointParameters HingeJointParameters {
                axis 0 1 0
                anchor -0.016 0 -0.04
              }
              device [
              ]
              endPoint DEF SMALL_WHEEL Solid {
                translation -0.016 0 -0.04
                rotation -1 0 0 1.5708
                children [
                  DEF SMALL_WHEEL_SHAPE Shape {
                    appearance Asphalt {
                      textureTransform TextureTransform {
                        scale 25 25
                      }
                      IBLStrength 0.5
                    }
                    geometry Mesh {
                      url "meshes/small_wheel_shape.obj"
                    }
                  }
                ]
                name "caster_front_left_2_link"
                boundingObject DEF SMALL_WHEEL_BO Pose {
                  children [
                    Cylinder {
                      height 0.015
                      radius 0.025
                    }
                  ]
                }
                physics DEF SMALL_WHEEL_PHYSIC Physics {
                  density -1
                  mass 0.088558
                }
              }
            }
            DEF CASTER_SUPPORT Shape {
              appearance BrushedAluminium {
                textureTransform TextureTransform {
                  rotation -1.57
                  scale 2 2
                }
              }
              geometry Mesh {
                url "meshes/caster_support.obj"
              }
            }
          ]
          name "caster_front_left_1_link"
          boundingObject DEF CASTER_WHEEL_BO Pose {
            translation -0.003 0 -0.022
            children [
              DEF CASTER_SUPPORT_BO Box {
                size 0.036 0.032 0.04
              }
            ]
          }
          physics DEF CASTER_WHEEL_PHYSIC Physics {
            density -1
            mass 0.051448
          }
        }
      }
      DEF CASTER_WHEEL_BACK_RIGHT_JOINT HingeJoint {
        jointParameters HingeJointParameters {
          axis 0 0 1
          anchor -0.1735 -0.102 -0.0335
          dampingConstant 0
          suspensionSpringConstant 250000
          suspensionDampingConstant 0
          suspensionAxis 0 0 1
        }
        device [
        ]
        endPoint DEF CASTER_WHEEL_BACK_RIGHT Solid {
          translation -0.1735 -0.102 -0.0335
          rotation 0 0 1 0
          children [
            DEF SMALL_WHEEL_JOINT HingeJoint {
              jointParameters HingeJointParameters {
                axis 0 1 0
                anchor -0.016 0 -0.04
              }
              device [
              ]
              endPoint DEF SMALL_WHEEL_JOINT Solid {
                translation -0.016 0 -0.04
                rotation -1 0 0 1.5708
                children [
                  DEF SMALL_WHEEL_SHAPE Shape {
                    appearance Asphalt {
                      textureTransform TextureTransform {
                        scale 25 25
                      }
                      IBLStrength 0.5
                    }
                    geometry Mesh {
                      url "meshes/small_wheel_shape.obj"
                    }
                  }
                ]
                name "caster_back_right_2_link"
                boundingObject DEF SMALL_WHEEL_BO Pose {
                  children [
                    Cylinder {
                      height 0.015
                      radius 0.025
                    }
                  ]
                }
                physics DEF SMALL_WHEEL_PHYSIC Physics {
                  density -1
                  mass 0.088558
                }
              }
            }
            DEF CASTER_SUPPORT Shape {
              appearance BrushedAluminium {
                textureTransform TextureTransform {
                  rotation -1.57
                  scale 2 2
                }
              }
              geometry Mesh {
                url "meshes/caster_support.obj"
              }
            }
          ]
          name "caster_back_right_1_link"
          boundingObject DEF CASTER_WHEEL_BO Pose {
            translation -0.003 0 -0.022
            children [
              DEF CASTER_SUPPORT_BO Box {
                size 0.036 0.032 0.04
              }
            ]
          }
          physics DEF CASTER_WHEEL_PHYSIC Physics {
            density -1
            mass 0.051448
          }
        }
      }
      DEF CASTER_WHEEL_BACK_LEFT_JOINT HingeJoint {
        jointParameters HingeJointParameters {
          axis 0 0 1
          anchor -0.1735 0.102 -0.0335
          dampingConstant 0
          suspensionSpringConstant 250000
          suspensionDampingConstant 0
          suspensionAxis 0 0 1
        }
        device [
        ]
        endPoint DEF CASTER_WHEEL_BACK_LEFT Solid {
          translation -0.1735 0.102 -0.0335
          rotation 0 0 1 0
          children [
            DEF SMALL_WHEEL_JOINT HingeJoint {
              jointParameters HingeJointParameters {
                axis 0 1 0
                anchor -0.016 0 -0.04
              }
              device [
              ]
              endPoint DEF SMALL_WHEEL Solid {
                translation -0.016 0 -0.04
                rotation -1 0 0 1.5708
                children [
                  DEF SMALL_WHEEL_SHAPE Shape {
                    appearance Asphalt {
                      textureTransform TextureTransform {
                        scale 25 25
                      }
                      IBLStrength 0.5
                    }
                    geometry Mesh {
                      url "meshes/small_wheel_shape.obj"
                    }
                  }
                ]
                name "caster_back_left_2_link"
                boundingObject DEF SMALL_WHEEL_BO Pose {
                  children [
                    Cylinder {
                      height 0.015
                      radius 0.025
                    }
                  ]
                }
                physics DEF SMALL_WHEEL_PHYSIC Physics {
                  density -1
                  mass 0.088558
                }
              }
            }
            DEF CASTER_SUPPORT Shape {
              appearance BrushedAluminium {
                textureTransform TextureTransform {
                  rotation -1.57
                  scale 2 2
                }
              }
              geometry Mesh {
                url "meshes/caster_support.obj"
              }
            }
          ]
          name "caster_back_left_1_link"
          boundingObject DEF CASTER_WHEEL_BO Pose {
            translation -0.003 0 -0.022
            children [
              DEF CASTER_SUPPORT_BO Box {
                size 0.036 0.032 0.04
              }
            ]
          }
          physics DEF CASTER_WHEEL_PHYSIC Physics {
            density -1
            mass 0.051448
          }
        }
      }
    ]
    name "TIAGo base"
    boundingObject Group {
      children [
        DEF BASE_BO Pose {
          translation 0 0 0.06
          children [
            Shape {
              geometry Cylinder {
                height 0.276
                radius 0.265
              }
            }
          ]
        }
        DEF ANTENNA_LEFT_BO Pose {
          translation -0.201 0.1062 0.28
          children [
            DEF ANTENNA_BO Cylinder {
              height 0.173
              radius 0.007
            }
          ]
        }
        DEF ANTENNA_RIGHT_BO Pose {
          translation -0.201 -0.1062 0.28
          children [
            USE ANTENNA_BO
          ]
        }
      ]
    }
    physics Physics {
      density -1
      mass 28.26649
    }
  }
}
