#VRML_SIM R2023b utf8
# license: Copyright Cyberbotics Ltd. Licensed for use only with Webots.
# license url: https://cyberbotics.com/webots_assets_license
# tags: hidden
# A drawer for the Cabinet PROTO.
# template language: javascript

EXTERNPROTO "CabinetHandle.proto"
EXTERNPROTO "webots://projects/objects/solids/protos/SolidBox.proto"

PROTO CabinetDrawer [
  field SFVec3f  translation         0 0 0
  field SFString name                "cabinet drawer"
  field SFVec3f  size                0.2 0.3 0.2       # Defines the size of the drawer.
  field SFFloat  thickness           0.03              # Defines the thickness of the drawer.
  field SFFloat  mass                1.5               # Defines the mass of the drawer.
  field SFNode   handle              CabinetHandle {}  # Defines the drawer handle.
  field SFNode   primaryAppearance   NULL              # Defines the primary appearance.
  field SFNode   secondaryAppearance NULL              # Defines the secondary appearance.
]
{
  %<
    let size = fields.size.value;
    if (size.x <= 0.0 || size.y <= 0.0 || size.z <= 0.0) { // avoid negative values
      size = fields.size.defaultValue;
      console.error('\'size\' must contain positive values. Value reset to (' + size.x + ', ' + size.y + ', ' + size.z + ').');
    }

    let thickness = fields.thickness.value;
    if (thickness <= 0.0) {
      thickness = fields.thickness.defaultValue;
      console.error('\'thickness\' must be positive. Value reset to ' + thickness + '.');
    }

    let mass = fields.mass.value;
    if (mass <= 0.0) {
      mass = fields.mass.defaultValue;
      console.error('\'mass\' must be positive. Value reset to ' + mass + '.');
    }
  >%
  Solid {
    translation IS translation
    children [
      SliderJoint {
        jointParameters JointParameters {
          axis 1 0 0
          minStop -0.01
          maxStop %<= size.z >%
          dampingConstant 5
        }
        endPoint Solid {
          children [
            SolidBox { # back of the Drawer
              translation %<= - size.x + 0.5 * thickness >% 0 0
              name "back box"
              size %<= thickness >% %<= size.y - thickness >% %<= size.z - thickness >%
              appearance IS primaryAppearance
              physics Physics {
                density -1
                mass 0.01
              }
            }
            SolidBox { # bottom side of the Drawer
              translation %<= -0.5 * size.x >% 0 %<= - 0.5 * size.z + thickness >%
              name "bottom box"
              size %<= size.x - 2 * thickness >%  %<= size.y - thickness >% %<= thickness >%
              appearance IS primaryAppearance
              physics Physics {
                density -1
                mass 0.01
              }
            }
            SolidBox { # front of the Drawer
              translation %<= - 0.5 * thickness >% 0 0
              name "front box"
              size %<= thickness >% %<= size.y >% %<= size.z >%
              appearance IS secondaryAppearance
              physics Physics {
                density -1
                mass 0.01
              }
            }
            SolidBox { # right side of the Drawer
              translation %<= - 0.5 * size.x >% %<= -0.5 * size.y + thickness >% %<= 0.5 * thickness >%
              name "right box"
              size %<= size.x - 2 * thickness >% %<= thickness >% %<= size.z - 2 * thickness >%
              appearance IS primaryAppearance
              physics Physics {
                density -1
                mass 0.01
              }
            }
            SolidBox { # left side of the Drawer
              translation %<= - 0.5 * size.x >% %<= 0.5 * size.y - thickness >% %<= 0.5 * thickness >%
              name "left box"
              size %<= size.x - 2 * thickness >% %<= thickness >% %<= size.z - 2 * thickness >%
              appearance IS primaryAppearance
              physics Physics {
                density -1
                mass 0.01
              }
            }
            Slot {
              endPoint IS handle
            }
          ]
          physics Physics {
            density -1
            mass %<= mass >%
          }
          boundingObject Pose {
            translation %<= - 0.5 * thickness >% 0 0
            children [
              Sphere {
                radius %<= 0.5 * thickness >%
              }
            ]
          }
        }
      }
    ]
    name IS name
    model "cabinet drawer"
  }
}
