#VRML_SIM R2023b utf8
# license: Copyright Cyberbotics Ltd. Licensed for use only with Webots.
# license url: https://cyberbotics.com/webots_assets_license
# tags: hidden
# A door for the Cabinet PROTO.
# template language: javascript

EXTERNPROTO "CabinetHandle.proto"
EXTERNPROTO "webots://projects/objects/solids/protos/SolidBox.proto"

PROTO CabinetDoor [
  field SFVec3f  translation         0 0 0
  field SFString name                "cabinet door"
  field SFVec3f  size                0.2 0.3 0.2       # Defines the size of the door.
  field SFBool   rightSided          TRUE              # Defines on which side the door is connected.
  field SFFloat  thickness           0.03              # Defines the thickness of the door.
  field SFFloat  mass                1.5               # Defines the mass of the door.
  field SFNode   handle              CabinetHandle {}  # Defines door handle.
  field SFNode   secondaryAppearance NULL              # Defines the secondary appearance.
]
{
  %<
    let size = fields.size.value;
    if (size.x <= 0.0 || size.y <= 0.0 || size.z <= 0.0) { // avoid negative values
      size = fields.size.defaultValue;
      console.error('\'size\' must contain positive values. Value reset to (' + size.x + ', ' + size.y + ', ' + size.z + ').');
    }

    let thickness = fields.thickness.value;
    if (thickness <= 0.0) {
      thickness = fields.thickness.defaultValue;
      console.error('\'thickness\' must be positive. Value reset to ' + thickness + '.');
    }

    let mass = fields.mass.value;
    if (mass <= 0.0) {
      mass = fields.mass.defaultValue;
      console.error('\'mass\' must be positive. Value reset to ' + mass + '.');
    }

    let rightSided = fields.rightSided.value ? -1 : 1;
  >%
  Solid {
    translation IS translation
    children [
      HingeJoint {
        jointParameters HingeJointParameters {
          anchor 0 %<= rightSided * 0.5 * size.y >% 0
          axis 0 0 1
          %< if (rightSided > 0) { >%
            minStop -0.01
            maxStop 1.57
          %< } else { >%
            minStop -1.57
            maxStop 0.01
          %< } >%
          dampingConstant 5
        }
        endPoint Solid {
          children [
            SolidBox {
              translation %<= -0.5 * thickness >% 0 0
              size %<= thickness >% %<= size.y >% %<= size.z >%
              appearance IS secondaryAppearance
              physics Physics {
                density -1
                mass %<= mass >%
              }
            }
            Pose {
              translation 0 %<= -rightSided * 0.4 * size.y >% 0
              rotation 1 0 0 1.57
              children [
                Slot {
                   endPoint IS handle
                }
              ]
            }
          ]
          physics Physics {
            density -1
            mass 0.01
          }
          boundingObject Pose {
            translation %<= - 0.5 * thickness >% 0 0
            children [
              Sphere {
                radius %<= 0.5 * thickness >%
              }
            ]
          }
        }
      }
    ]
    name IS name
    model "cabinet door"
  }
}
