#VRML_SIM R2023b utf8

EXTERNPROTO "webots://projects/objects/backgrounds/protos/TexturedBackground.proto"
EXTERNPROTO "webots://projects/objects/backgrounds/protos/TexturedBackgroundLight.proto"
EXTERNPROTO "webots://projects/objects/floors/protos/RectangleArena.proto"

WorldInfo {
  info [
    "Example of force control"
  ]
  title "Force control example"
  gravity 0
  basicTimeStep 4
}
Viewpoint {
  orientation -0.4102543149026958 -0.44760129013820765 0.7945718860935943 4.572910088361569
  position -0.1725679703260921 1.6772711064588912 2.5500283356290763
}
TexturedBackground {
}
TexturedBackgroundLight {
}
RectangleArena {
}
DEF ROBOT Robot {
  translation 0.122829 -0.138023 0.1
  rotation 0 0 1 11.6321
  children [
    DEF RED_BOX_SHAPE Shape {
      appearance PBRAppearance {
        baseColor 1 0 0
        roughness 1
        metalness 0
      }
      geometry Box {
        size 0.1 0.1 0.1
      }
    }
    DEF SLIDER_JOINT SliderJoint {
      jointParameters JointParameters {
        axis -1 0 0
      }
      device [
        LinearMotor {
          name "slider"
          maxForce 100000
        }
        PositionSensor {
        }
      ]
      endPoint Solid {
        translation -0.4 0 0
        rotation 0 0 1 -5.307179586466759e-06
        children [
          DEF BLUE_BOX_SHAPE Shape {
            appearance PBRAppearance {
              baseColor 0 0 1
              roughness 1
              metalness 0
            }
            geometry Box {
              size 0.1 0.1 0.095
            }
          }
        ]
        boundingObject Box {
          size 0.1 0.1 0.1
        }
        physics Physics {
          density -1
          mass 1
        }
      }
    }
  ]
  boundingObject Box {
    size 0.1 0.1 0.1
  }
  physics Physics {
    density -1
    mass 1
  }
  controller "force_control"
}
