#VRML_SIM R2023a utf8
# license: Copyright Cyberbotics Ltd. Licensed for use only with Webots.
# license url: https://cyberbotics.com/webots_assets_license
# documentation url: https://cyberbotics.com/doc/guide/rosbot
# A ROS powered 4x4 drive autonomous mobile robot platform equipped with various sensors.

EXTERNPROTO "webots://projects/appearances/protos/GlossyPaint.proto"
EXTERNPROTO "webots://projects/appearances/protos/MattePaint.proto"
EXTERNPROTO "webots://projects/appearances/protos/BrushedAluminium.proto"
EXTERNPROTO "webots://projects/appearances/protos/Rubber.proto"
EXTERNPROTO "webots://projects/devices/tdk/protos/Mpu-9250.proto"
EXTERNPROTO "webots://projects/devices/slamtec/protos/RpLidarA2.proto"
EXTERNPROTO "webots://projects/devices/orbbec/protos/Astra.proto"

PROTO Rosbot [
  field  SFVec3f     translation     0 0 0
  field  SFRotation  rotation        0 0 1 0
  field  SFString    name            "Rosbot"  # Is `Robot.name`.
  field  SFString    controller      "rosbot"  # Is `Robot.controller`.
  field  MFString    controllerArgs  []        # Is `Robot.controllerArgs`.
  field  SFString    customData      ""        # Is `Robot.customData`.
  field  SFBool      supervisor      FALSE     # Is `Robot.supervisor`.
  field  SFBool      synchronization TRUE      # Is `Robot.synchronization`.
  field  SFBool      selfCollision   FALSE     # Is `Robot.selfCollision`.
  field  MFNode      cameraSlot      [ Astra { name "camera" translation -0.02 0 0.15 } ] # Extends the robot with an Astra RGBD camera.
  field  MFNode      lidarSlot       [ RpLidarA2 { name "lidar" translation 0.02 0 0.088 } ] # Extends the robot with a RpLidar A2 lidar.
]
{
  Robot {
    translation IS translation
    rotation IS rotation
    controller IS controller
    controllerArgs IS controllerArgs
    customData IS customData
    supervisor IS supervisor
    synchronization IS synchronization
    selfCollision IS selfCollision
    children [
      Transform {
        translation 0.000000 0.000000 -0.020000
        rotation 0.000000 0.000000 1.000000 0.000000
        children [
          Shape {
            appearance MattePaint {
              baseColor 1.000000 1.000000 1.000000
            }
            geometry Mesh {
              url "meshes/box.obj"
            }
          }
        ]
      }
      Transform {
        translation 0 0 0.018
        rotation 0 0 1 0
        children [
          Shape {
            appearance GlossyPaint {
              baseColor 0.000000 0.000000 0.000000
            }
            geometry Box {
              size 0.15 0.14 0.07
            }
          }
        ]
      }
      Solid {
        translation 0.000000 0.000000 0.000000
        rotation 0.000000 0.000000 1.000000 0.000000
        children [
          Transform {
            translation 0.000000 0.000000 0.055000
            rotation 0.000000 0.000000 1.000000 0.000000
            children [
              Shape {
                appearance GlossyPaint {
                  baseColor 0.800000 0.000000 0.000000
                }
                geometry Mesh {
                  url "meshes/upper.obj"
                }
              }
            ]
          }
        ]
        name "top"
      }
      Transform {
        translation 0.053 0.092 -0.002
        rotation 1 0 0 -1.5707953071795862
        children [
          Shape {
            appearance GlossyPaint {
              baseColor 0.110000 0.110000 0.110000
            }
            geometry Cylinder {
              height 0.037
              radius 0.005
            }
          }
        ]
      }
      Transform {
        translation 0.053 -0.092 -0.002
        rotation 1 0 0 -1.5707953071795862
        children [
          Shape {
            appearance GlossyPaint {
              baseColor 0.110000 0.110000 0.110000
            }
            geometry Cylinder {
              height 0.037
              radius 0.005
            }
          }
        ]
      }
      Transform {
        translation -0.054 0.092 -0.002
        rotation 1 0 0 -1.5707953071795862
        children [
          Shape {
            appearance GlossyPaint {
              baseColor 0.110000 0.110000 0.110000
            }
            geometry Cylinder {
              height 0.037
              radius 0.005
            }
          }
        ]
      }
      Transform {
        translation -0.054 -0.092 -0.002
        rotation 1 0 0 -1.5707953071795862
        children [
          Shape {
            appearance GlossyPaint {
              baseColor 0.110000 0.110000 0.110000
            }
            geometry Cylinder {
              height 0.037
              radius 0.005
            }
          }
        ]
      }
      HingeJoint {
        jointParameters HingeJointParameters {
          axis 0.000000 1.000000 0.000000
          anchor 0.050000 0.110000 0.000000
          dampingConstant 5.0
          staticFriction 1.0
        }
        device [
          RotationalMotor {
            name "front left wheel motor"
            maxVelocity 26.0
            maxTorque 100.0
          }
          PositionSensor {
            name "front left wheel motor sensor"
          }
        ]
        endPoint Solid {
          translation 0.050000 0.110000 0.000000
          rotation 0.000000 0.000000 1.000000 0.000000
          children [
            Transform {
              translation 0.000000 0.000000 0.000000
              rotation 0.000000 0.000000 1.000000 0.000000
              children [
                DEF RIM_AND_TIRE_SHAPES Group {
                  children [
                    DEF RIM_SHAPE Shape {
                      appearance BrushedAluminium {
                        colorOverride 1 1 1
                        textureTransform NULL
                        IBLStrength 1
                      }
                      geometry Mesh {
                        url "meshes/wheel_rim.obj"
                      }
                    }
                    DEF TIRE_SHAPE Shape {
                      appearance Rubber {
                        type "flat"
                      }
                      geometry Mesh {
                        url "meshes/wheel_tire.obj"
                      }
                    }
                  ]
                }
                
              ]
            }
          ]
          name "front left wheel"
          boundingObject DEF LEFT_WHEEL_CYLINDER Transform {
            translation 0.000000 -0.011500 0.000000
            rotation 1.000000 0.000000 0.000000 -1.570800
            children [
              DEF WHEEL_CYLINDER Cylinder {
                height 0.035
                radius 0.043
              }
            ]
          }
          physics DEF WHEEL_PHYSICS Physics {
            density -1
            mass 0.500000
          }
        }
      }
      HingeJoint {
        jointParameters HingeJointParameters {
          axis 0.000000 1.000000 0.000000
          anchor 0.050000 -0.110000 0.000000
          dampingConstant 5.0
          staticFriction 1.0
        }
        device [
          RotationalMotor {
            name "front right wheel motor"
            maxVelocity 26.0
            maxTorque 100.0
          }
          PositionSensor {
            name "front right wheel motor sensor"
          }
        ]
        endPoint Solid {
          translation 0.050000 -0.110000 0.000000
          rotation 0.000000 0.000000 1.000000 0.000000
          children [
            Transform {
              translation 0.000000 0.000000 0.000000
              rotation 0.000000 0.000000 1.000000 3.141592
              children [
                USE RIM_AND_TIRE_SHAPES
              ]
            }
          ]
          name "front right wheel"
          boundingObject DEF RIGHT_WHEEL_CYLINDER Transform {
            translation 0.000000 0.011500 0.000000
            rotation 1.000000 0.000000 0.000000 -1.570800
            children [
              USE WHEEL_CYLINDER
            ]
          }
          physics USE WHEEL_PHYSICS
        }
      }
      HingeJoint {
        jointParameters HingeJointParameters {
          axis 0.000000 1.000000 0.000000
          anchor -0.055000 0.110000 0.000000
          dampingConstant 5.0
          staticFriction 1.0
        }
        device [
          RotationalMotor {
            name "rear left wheel motor"
            maxVelocity 26.0
            maxTorque 100.0
          }
          PositionSensor {
            name "rear left wheel motor sensor"
          }
        ]
        endPoint Solid {
          translation -0.055000 0.110000 0.000000
          rotation 0.000000 0.000000 1.000000 0.000000
          children [
            Transform {
              translation 0.000000 0.000000 0.000000
              rotation 0.000000 0.000000 1.000000 0.000000
              children [
                USE RIM_AND_TIRE_SHAPES
              ]
            }
          ]
          name "rear left wheel"
          boundingObject USE LEFT_WHEEL_CYLINDER
          physics USE WHEEL_PHYSICS
        }
      }
      HingeJoint {
        jointParameters HingeJointParameters {
          axis 0.000000 1.000000 0.000000
          anchor -0.055000 -0.110000 0.000000
          dampingConstant 5.0
          staticFriction 1.0
        }
        device [
          RotationalMotor {
            name "rear right wheel motor"
            maxVelocity 26.0
            maxTorque 100.0
          }
          PositionSensor {
            name "rear right wheel motor sensor"
          }
        ]
        endPoint Solid {
          translation -0.055000 -0.110000 0.000000
          rotation 0.000000 0.000000 1.000000 0.000000
          children [
            Transform {
              translation 0.000000 0.000000 0.000000
              rotation 0.000000 0.000000 1.000000 3.141592
              children [
                USE RIM_AND_TIRE_SHAPES
              ]
            }
          ]
          name "rear right wheel"
          boundingObject USE RIGHT_WHEEL_CYLINDER
          physics USE WHEEL_PHYSICS
        }
      }
      Mpu-9250 {
        translation 0.000000 0.000000 0.000000
        rotation 0.000000 0.000000 1.000000 0.000000
        name "imu"
      }
      DistanceSensor {
        translation 0.100000 0.050000 0.010000
        rotation 0.000000 0.000000 1.000000 0.130000
        name "front left distance sensor"
        redColorSensitivity 0
        lookupTable [ 0     0   0,
                      1     1   0,
                      2     2   0 ]
        type "infra-red"
      }
      DistanceSensor {
        translation 0.100000 -0.050000 0.010000
        rotation 0.000000 0.000000 1.000000 -0.130000
        name "front right distance sensor"
        redColorSensitivity 0
        lookupTable [ 0     0   0,
                      2     2   0 ]
        type "infra-red"
      }
      DistanceSensor {
        translation -0.100000 0.050000 0.0100000
        rotation 0.000000 0.000000 1.000000 3.010000
        name "rear left distance sensor"
        redColorSensitivity 0
        lookupTable [ 0     0   0,
                      2     2   0 ]
        type "infra-red"
      }
      DistanceSensor {
        translation -0.100000 -0.050000 0.010000
        rotation 0.000000 0.000000 1.000000 3.270000
        name "rear right distance sensor"
        redColorSensitivity 0
        lookupTable [ 0     0   0,
                      2     2   0 ]
        type "infra-red"
      }
      DEF CAMERA_SLOT Group {
        children IS cameraSlot
      }
      DEF LIDAR_SLOT Group {
        children IS lidarSlot
      }
    ]
    name IS name
    boundingObject Group {
      children [
        DEF MAIN_BODY_BOX Transform {
          translation 0.000000 0.000000 0.018200
          rotation 0.000000 0.000000 1.000000 0.000000
          children [
            Box {
              size 0.200000 0.150000 0.077000
            }
          ]
        }
        DEF LEFT_SUPPORT_LEG_BOX Transform {
          translation -0.048000 0.038000 0.090000
          rotation 0.000000 0.000000 1.000000 0.000000
          children [
            Box {
              size 0.040000 0.023000 0.065000
            }
          ]
        }
        DEF RIGHT_SUPPORT_LEG_BOX Transform {
          translation -0.048000 -0.038000 0.090000
          rotation 0.000000 0.000000 1.000000 0.000000
          children [
            Box {
              size 0.040000 0.023000 0.065000
            }
          ]
        }
        DEF SUPPORT_PLATE_BOX Transform {
          translation -0.048000 0.000000 0.120000
          rotation 0.000000 0.000000 1.000000 0.000000
          children [
            Box {
              size 0.040000 0.100000 0.001
            }
          ]
        }
      ]
    }
    physics Physics {
      density -1
      mass 0.450000
    }
  }
}
